Workbook
Name Deflatores: 'Tipo Projeto'!$J$3:$J$71
Name Matriz_INM: 'Tipo Projeto'!$J$3:$L$71
Name Matriz_UST: 'Tipo Projeto'!$D$2:$H$56
Name PF_INM: 'AFP - Estimativa'!$K$384
Name PF_INM: 'AFP - Detalhada'!$S$384
Name PF_UST: UST!$D$5
Name Print_Titles_0: 'AFP - Detalhada'!$1:$8
Name Print_Titles_0: 'AFP - Estimativa'!$1:$8
Name Print_Titles_0: 'AFP - Indicativa'!$1:$9
Name Print_Titles_0: 'INM - Detalhada'!$1:$10
Name Print_Titles_0: 'INM - Estimativa'!$1:$9
Name Print_Titles_0: UST!$1:$9
Name Print_Titles_0_0: 'AFP - Detalhada'!$1:$8
Name Print_Titles_0_0: 'AFP - Estimativa'!$1:$8
Name Print_Titles_0_0: 'AFP - Indicativa'!$1:$9
Name Print_Titles_0_0: 'INM - Detalhada'!$1:$10
Name Print_Titles_0_0: 'INM - Estimativa'!$1:$9
Name Print_Titles_0_0: UST!$1:$9
Name Print_Titles_0_0_0: 'AFP - Detalhada'!$1:$8
Name Print_Titles_0_0_0: 'AFP - Estimativa'!$1:$8
Name Print_Titles_0_0_0: 'AFP - Indicativa'!$1:$9
Name Print_Titles_0_0_0: 'INM - Detalhada'!$1:$10
Name Print_Titles_0_0_0: 'INM - Estimativa'!$1:$9
Name Print_Titles_0_0_0: UST!$1:$9
Name Print_Titles_0_0_0_0: 'AFP - Detalhada'!$1:$8
Name Print_Titles_0_0_0_0: 'AFP - Estimativa'!$1:$8
Name Print_Titles_0_0_0_0: 'AFP - Indicativa'!$1:$9
Name Print_Titles_0_0_0_0: 'INM - Detalhada'!$1:$10
Name Print_Titles_0_0_0_0: 'INM - Estimativa'!$1:$9
Name Print_Titles_0_0_0_0: UST!$1:$9
Name Print_Titles_0_0_0_0_0: 'AFP - Detalhada'!$1:$8
Name Print_Titles_0_0_0_0_0: 'AFP - Estimativa'!$1:$8
Name Print_Titles_0_0_0_0_0: 'AFP - Indicativa'!$1:$9
Name Print_Titles_0_0_0_0_0: 'INM - Detalhada'!$1:$10
Name Print_Titles_0_0_0_0_0: 'INM - Estimativa'!$1:$9
Name Print_Titles_0_0_0_0_0: UST!$1:$9
Name Print_Titles_0_0_0_0_0_0: 'AFP - Detalhada'!$1:$8
Name Print_Titles_0_0_0_0_0_0: 'AFP - Estimativa'!$1:$8
Name Print_Titles_0_0_0_0_0_0: 'AFP - Indicativa'!$1:$9
Name Print_Titles_0_0_0_0_0_0: 'INM - Detalhada'!$1:$10
Name Print_Titles_0_0_0_0_0_0: 'INM - Estimativa'!$1:$9
Name Print_Titles_0_0_0_0_0_0: UST!$1:$9
Name Tipo_Contagem: Resumo!$B$5
Name TipoProjeto: 'Tipo Projeto'!$A$3:$A$37
Name TipoSistema: 'Tipo Sistema'!$A$2:$A$8
Name UST: 'Tipo Projeto'!$D$2:$D$56

Sheet Instrução de Uso

Sheet Resumo
A1: Template V.1.6 | B1: Contagem de Pontos de Função
A3: Identificação
A4: O.S.: | E4: Tipo de Atividade: | F4: Desenvolvimento ou Manutenção
A5: Tipo de Contagem: | E5: Aplicação:
A6: Elaborador da contagem: | E6: Data da Contagem:
A7: Revisor da contagem: | B7: =IF($B$5="Detalhada",IF('AFP - Detalhada'!P5<>"",'AFP - Detalhada'!P5,""),IF($B$5="Estimativa",IF('AFP - Estimativa'!K5<>"",'AFP - Estimativa'!K5,""),IF($B$5="Indicativa",IF('AFP - Indicativa'!H5<>"",'AFP - Indicativa'!H5,""),""))) | E7: Data da Revisão: | F7: =IF($B$5="Detalhada",IF('AFP - Detalhada'!P6<>"",'AFP - Detalhada'!P6,""),IF($B$5="Estimativa",IF('AFP - Estimativa'!K6<>"",'AFP - Estimativa'!K6,""),IF($B$5="Indicativa",IF('AFP - Indicativa'!H6<>"",'AFP - Indicativa'!H6,""),"")))
A9: Propósito da Contagem
A10: =IF(Tipo_Contagem<>"","Obtenção do tamanho funcional (APF) "&IF(Tipo_Contagem="Estimativa","Estimado", IF(Tipo_Contagem="Indicativa", "Indicativo", "Detalhado"))&" das funcionalidades solicitadas/entregues na OS "&IF(B4<>"",B4,"em questão"),"")
A12: Escopo da Contagem
A15: Quadro Resumo | E15: Projeto de Desenvolvimento e Manutenção
A16: Arquivo de Interface Externa (AIE) | C16: =IF((IF($B$5="Detalhada",SUMIF('AFP - Detalhada'!$J$10:$J382,"AIE",'AFP - Detalhada'!$S$10:$S382),IF($B$5="Estimativa",SUMIF('AFP - Estimativa'!$J$10:$J382,"AIE",'AFP - Estimativa'!$K$10:$K382)*(1+'AFP - Estimativa'!$D$6),IF($B$5="Indicativa",SUMIF('AFP - Indicativa'!$H$10:$H$109,"AIE",'AFP - Indicativa'!$I$10:$I$109)*(1+'AFP - Indicativa'!$F$6))))),(IF($B$5="Detalhada",SUMIF('AFP - Detalhada'!$J$10:$J382,"AIE",'AFP - Detalhada'!$S$10:$S382),IF($B$5="Estimativa",SUMIF('AFP - Estimativa'!$J$10:$J382,"AIE",'AFP - Estimativa'!$K$10:$K382)*(1+'AFP - Estimativa'!$D$6),IF($B$5="Indicativa",SUMIF('AFP - Indicativa'!$H$10:$H$109,"AIE",'AFP - Indicativa'!$I$10:$I$109)*(1+'AFP - Indicativa'!$F$6))))),"") | E16: Distribuição de Esforço por Fase do Projeto (conforme item 6.1.2.1 do SISP 2.0)
A17: Arquivo Lógico Interno (ALI) | C17: =IF((IF($B$5="Detalhada",SUMIF('AFP - Detalhada'!$J$10:$J382,"ALI",'AFP - Detalhada'!$S$10:$S382),IF($B$5="Estimativa",SUMIF('AFP - Estimativa'!$J$10:$J382,"ALI",'AFP - Estimativa'!$K$10:$K382)*(1+'AFP - Estimativa'!$D$6),IF($B$5="Indicativa",SUMIF('AFP - Indicativa'!$H$10:$H$109,"ALI",'AFP - Indicativa'!$I$10:$I$109)*(1+'AFP - Indicativa'!$F$6))))),IF($B$5="Detalhada",SUMIF('AFP - Detalhada'!$J$10:$J382,"ALI",'AFP - Detalhada'!$S$10:$S382),IF($B$5="Estimativa",SUMIF('AFP - Estimativa'!$J$10:$J382,"ALI",'AFP - Estimativa'!$K$10:$K382)*(1+'AFP - Estimativa'!$D$6),IF($B$5="Indicativa",SUMIF('AFP - Indicativa'!$H$10:$H$109,"ALI",'AFP - Indicativa'!$I$10:$I$109)*(1+'AFP - Indicativa'!$F$6)))),"")
A18: Consulta Externa (CE) | C18: =IF($B$5="Detalhada",SUMIF('AFP - Detalhada'!$J$10:$J382,"CE",'AFP - Detalhada'!$S$10:$S382),IF($B$5="Estimativa",SUMIF('AFP - Estimativa'!$J$10:$J382,"CE",'AFP - Estimativa'!$K$10:$K382)*(1+'AFP - Estimativa'!$D$6),"")) | E18: Engenharia de Requisitos | G18: 0.25
A19: Entrada Externa (EE) | C19: =IF($B$5="Detalhada",SUMIF('AFP - Detalhada'!$J$10:$J382,"EE",'AFP - Detalhada'!$S$10:$S382),IF($B$5="Estimativa",SUMIF('AFP - Estimativa'!$J$10:$J382,"EE",'AFP - Estimativa'!$K$10:$K382)*(1+'AFP - Estimativa'!$D$6),"")) | E19: Design e Arquitetura | G19: 0.1
A20: Saída Externa (SE) | C20: =IF($B$5="Detalhada",SUMIF('AFP - Detalhada'!$J$10:$J382,"SE",'AFP - Detalhada'!$S$10:$S382),IF($B$5="Estimativa",SUMIF('AFP - Estimativa'!$J$10:$J382,"SE",'AFP - Estimativa'!$K$10:$K382)*(1+'AFP - Estimativa'!$D$6),"")) | E20: Implementação | G20: 0.4
A21: INM | C21: =IF($B$5="Detalhada",SUMIF('AFP - Detalhada'!$J$10:$J382,"INM",'AFP - Detalhada'!$S$10:$S382),IF($B$5="Estimativa",SUMIF('AFP - Estimativa'!$J$10:$J382,"INM",'AFP - Estimativa'!$K$10:$K382)*(1+'AFP - Estimativa'!$D$6),"")) | E21: Testes | G21: 0.15
A22: INM – Serviço | C22: =IF(B5="Estimativa",'INM - Estimativa'!K26,(IF(B5="Detalhada",'INM - Detalhada'!P27,""))) | E22: Homologação | G22: 0.05
A23: Total (A) | C23: =SUM(C16:C22) -> 0 | E23: Implantação | G23: 0.05
E24: Percentual de Esforço (E) | G24: =SUM(G18:G23) -> 1
A26: Total Scope Creep | C26: =IF($B$5="Estimativa",$C$23+($C$23*0.35),IF($B$5="Indicativa",$C$23+($C$23*0.5),"------")) -> ------ | E26: =CONCATENATE("Quantidade Final (A) x ",IF(F4<>"",IF(F4="Desenvolvimento ou manutenção","(E1)","(E2)"),"")) -> Quantidade Final (A) x (E1) | G26: =C23*IF(F4<>"",IF(F4="Desenvolvimento ou manutenção",G24,C30),0) -> 0
E27: Fator de criticidade | G27: 1
E28: Quantidade Final Ajustada | G28: =G26*G27 -> 0

Sheet AFP - Detalhada
A1: =Resumo!A1 -> Template V.1.6 | C1: Contagem de Pontos de Função Contagem Detalhada
J3: Elaborador da contagem:
J4: Data da Contagem:
A5: Quantidade de Pontos de Função: | D5: =TEXT(S384,"#.##0,0#") -> 0,0 | J5: Revisor da contagem:
J6: Data da Revisão:
A8: ID | B8: Tipo Projeto | C8: Fator Ajuste | D8: Item PT | E8: Release | F8: Módulo | G8: Requisito | H8: Processos elementares | I8: Qtd | J8: Tipo | K8: DER | L8: RL/AR | M8: Tipo (Q/%) | N8: C_T | O8: C_D | P8: Complexidade | Q8: PF_T | R8: PF_D | S8: PF | T8: Fund.
A9: Só inserir linhas depois desta.
C10: =IF($B10<>"",VLOOKUP($B10,Matriz_INM,2,0),0) -> 0 | M10: =IFERROR(VLOOKUP($B10,Matriz_INM,3,0),"") | N10: =IF(J10="EE",IF(OR(AND(OR(L10=1,L10=0),K10>0,K10<5),AND(OR(L10=1,L10=0),K10>4,K10<16),AND(L10=2,K10>0,K10<5)),"Simples",IF(OR(AND(OR(L10=1,L10=0),K10>15),AND(L10=2,K10>4,K10<16),AND(L10>2,K10>0,K10<5)),"Médio",IF(OR(AND(L10=2,K10>15),AND(L10>2,K10>4,K10<16),AND(L10>2,K10>15)),"Complexo",""))), IF(OR(J10="CE",J10="SE"),IF(OR(AND(OR(L10=1,L10=0),K10>0,K10<6),AND(OR(L10=1,L10=0),K10>5,K10<20),AND(L10>1,L10<4,K10>0,K10<6)),"Simples",IF(OR(AND(OR(L10=1,L10=0),K10>19),AND(L10>1,L10<4,K10>5,K10<20),AND(L10>3,K10>0,K10<6)),"Médio",IF(OR(AND(L10>1,L10<4,K10>19),AND(L10>3,K10>5,K10<20),AND(L10>3,K10>19)),"Complexo",""))),"")) | O10: =IF(J10="ALI",IF(OR(AND(OR(L10=1,L10=0),K10>0,K10<20),AND(OR(L10=1,L10=0),K10>19,K10<51),AND(L10>1,L10<6,K10>0,K10<20)),"Simples",IF(OR(AND(OR(L10=1,L10=0),K10>50),AND(L10>1,L10<6,K10>19,K10<51),AND(L10>5,K10>0,K10<20)),"Médio",IF(OR(AND(L10>1,L10<6,K10>50),AND(L10>5,K10>19,K10<51),AND(L10>5,K10>50)),"Complexo",""))), IF(J10="AIE",IF(OR(AND(OR(L10=1, L10=0),K10>0,K10<20),AND(OR(L10=1, L10=0),K10>19,K10<51),AND(L10>1,L10<6,K10>0,K10<20)),"Simples",IF(OR(AND(OR(L10=1, L10=0),K10>50),AND(L10>1,L10<6,K10>19,K10<51),AND(L10>5,K10>0,K10<20)),"Médio",IF(OR(AND(L10>1,L10<6,K10>50),AND(L10>5,K10>19,K10<51),AND(L10>5,K10>50)),"Complexo",""))),"")) | P10: =IF(N10="",O10,IF(O10="",N10,"")) | Q10: =IF(AND(OR(J10="EE",J10="CE"),P10="Simples"),3, IF(AND(OR(J10="EE",J10="CE"),P10="Médio"),4, IF(AND(OR(J10="EE",J10="CE"),P10="Complexo"),6, IF(AND(J10="SE",P10="Simples"),4, IF(AND(J10="SE",P10="Médio"),5, IF(AND(J10="SE",P10="Complexo"),7,0)))))) -> 0 | R10: =IF(AND(J10="ALI",O10="Simples"),7, IF(AND(J10="ALI",O10="Médio"),10, IF(AND(J10="ALI",O10="Complexo"),15, IF(AND(J10="AIE",O10="Simples"),5, IF(AND(J10="AIE",O10="Médio"),7, IF(AND(J10="AIE",O10="Complexo"),10,0)))))) -> 0 | S10: =IF($M10="%",($Q10+$R10)*$C10,$C10*$I10) -> 0
C11: =IF($B11<>"",VLOOKUP($B11,Matriz_INM,2,0),0) -> 0 | M11: =IFERROR(VLOOKUP($B11,Matriz_INM,3,0),"") | N11: =IF(J11="EE",IF(OR(AND(OR(L11=1,L11=0),K11>0,K11<5),AND(OR(L11=1,L11=0),K11>4,K11<16),AND(L11=2,K11>0,K11<5)),"Simples",IF(OR(AND(OR(L11=1,L11=0),K11>15),AND(L11=2,K11>4,K11<16),AND(L11>2,K11>0,K11<5)),"Médio",IF(OR(AND(L11=2,K11>15),AND(L11>2,K11>4,K11<16),AND(L11>2,K11>15)),"Complexo",""))), IF(OR(J11="CE",J11="SE"),IF(OR(AND(OR(L11=1,L11=0),K11>0,K11<6),AND(OR(L11=1,L11=0),K11>5,K11<20),AND(L11>1,L11<4,K11>0,K11<6)),"Simples",IF(OR(AND(OR(L11=1,L11=0),K11>19),AND(L11>1,L11<4,K11>5,K11<20),AND(L11>3,K11>0,K11<6)),"Médio",IF(OR(AND(L11>1,L11<4,K11>19),AND(L11>3,K11>5,K11<20),AND(L11>3,K11>19)),"Complexo",""))),"")) | O11: =IF(J11="ALI",IF(OR(AND(OR(L11=1,L11=0),K11>0,K11<20),AND(OR(L11=1,L11=0),K11>19,K11<51),AND(L11>1,L11<6,K11>0,K11<20)),"Simples",IF(OR(AND(OR(L11=1,L11=0),K11>50),AND(L11>1,L11<6,K11>19,K11<51),AND(L11>5,K11>0,K11<20)),"Médio",IF(OR(AND(L11>1,L11<6,K11>50),AND(L11>5,K11>19,K11<51),AND(L11>5,K11>50)),"Complexo",""))), IF(J11="AIE",IF(OR(AND(OR(L11=1, L11=0),K11>0,K11<20),AND(OR(L11=1, L11=0),K11>19,K11<51),AND(L11>1,L11<6,K11>0,K11<20)),"Simples",IF(OR(AND(OR(L11=1, L11=0),K11>50),AND(L11>1,L11<6,K11>19,K11<51),AND(L11>5,K11>0,K11<20)),"Médio",IF(OR(AND(L11>1,L11<6,K11>50),AND(L11>5,K11>19,K11<51),AND(L11>5,K11>50)),"Complexo",""))),"")) | P11: =IF(N11="",O11,IF(O11="",N11,"")) | Q11: =IF(AND(OR(J11="EE",J11="CE"),P11="Simples"),3, IF(AND(OR(J11="EE",J11="CE"),P11="Médio"),4, IF(AND(OR(J11="EE",J11="CE"),P11="Complexo"),6, IF(AND(J11="SE",P11="Simples"),4, IF(AND(J11="SE",P11="Médio"),5, IF(AND(J11="SE",P11="Complexo"),7,0)))))) -> 0 | R11: =IF(AND(J11="ALI",O11="Simples"),7, IF(AND(J11="ALI",O11="Médio"),10, IF(AND(J11="ALI",O11="Complexo"),15, IF(AND(J11="AIE",O11="Simples"),5, IF(AND(J11="AIE",O11="Médio"),7, IF(AND(J11="AIE",O11="Complexo"),10,0)))))) -> 0 | S11: =IF($M11="%",($Q11+$R11)*$C11,$C11*$I11) -> 0
C12: =IF($B12<>"",VLOOKUP($B12,Matriz_INM,2,0),0) -> 0 | M12: =IFERROR(VLOOKUP($B12,Matriz_INM,3,0),"") | N12: =IF(J12="EE",IF(OR(AND(OR(L12=1,L12=0),K12>0,K12<5),AND(OR(L12=1,L12=0),K12>4,K12<16),AND(L12=2,K12>0,K12<5)),"Simples",IF(OR(AND(OR(L12=1,L12=0),K12>15),AND(L12=2,K12>4,K12<16),AND(L12>2,K12>0,K12<5)),"Médio",IF(OR(AND(L12=2,K12>15),AND(L12>2,K12>4,K12<16),AND(L12>2,K12>15)),"Complexo",""))), IF(OR(J12="CE",J12="SE"),IF(OR(AND(OR(L12=1,L12=0),K12>0,K12<6),AND(OR(L12=1,L12=0),K12>5,K12<20),AND(L12>1,L12<4,K12>0,K12<6)),"Simples",IF(OR(AND(OR(L12=1,L12=0),K12>19),AND(L12>1,L12<4,K12>5,K12<20),AND(L12>3,K12>0,K12<6)),"Médio",IF(OR(AND(L12>1,L12<4,K12>19),AND(L12>3,K12>5,K12<20),AND(L12>3,K12>19)),"Complexo",""))),"")) | O12: =IF(J12="ALI",IF(OR(AND(OR(L12=1,L12=0),K12>0,K12<20),AND(OR(L12=1,L12=0),K12>19,K12<51),AND(L12>1,L12<6,K12>0,K12<20)),"Simples",IF(OR(AND(OR(L12=1,L12=0),K12>50),AND(L12>1,L12<6,K12>19,K12<51),AND(L12>5,K12>0,K12<20)),"Médio",IF(OR(AND(L12>1,L12<6,K12>50),AND(L12>5,K12>19,K12<51),AND(L12>5,K12>50)),"Complexo",""))), IF(J12="AIE",IF(OR(AND(OR(L12=1, L12=0),K12>0,K12<20),AND(OR(L12=1, L12=0),K12>19,K12<51),AND(L12>1,L12<6,K12>0,K12<20)),"Simples",IF(OR(AND(OR(L12=1, L12=0),K12>50),AND(L12>1,L12<6,K12>19,K12<51),AND(L12>5,K12>0,K12<20)),"Médio",IF(OR(AND(L12>1,L12<6,K12>50),AND(L12>5,K12>19,K12<51),AND(L12>5,K12>50)),"Complexo",""))),"")) | P12: =IF(N12="",O12,IF(O12="",N12,"")) | Q12: =IF(AND(OR(J12="EE",J12="CE"),P12="Simples"),3, IF(AND(OR(J12="EE",J12="CE"),P12="Médio"),4, IF(AND(OR(J12="EE",J12="CE"),P12="Complexo"),6, IF(AND(J12="SE",P12="Simples"),4, IF(AND(J12="SE",P12="Médio"),5, IF(AND(J12="SE",P12="Complexo"),7,0)))))) -> 0 | R12: =IF(AND(J12="ALI",O12="Simples"),7, IF(AND(J12="ALI",O12="Médio"),10, IF(AND(J12="ALI",O12="Complexo"),15, IF(AND(J12="AIE",O12="Simples"),5, IF(AND(J12="AIE",O12="Médio"),7, IF(AND(J12="AIE",O12="Complexo"),10,0)))))) -> 0 | S12: =IF($M12="%",($Q12+$R12)*$C12,$C12*$I12) -> 0
C13: =IF($B13<>"",VLOOKUP($B13,Matriz_INM,2,0),0) -> 0 | M13: =IFERROR(VLOOKUP($B13,Matriz_INM,3,0),"") | N13: =IF(J13="EE",IF(OR(AND(OR(L13=1,L13=0),K13>0,K13<5),AND(OR(L13=1,L13=0),K13>4,K13<16),AND(L13=2,K13>0,K13<5)),"Simples",IF(OR(AND(OR(L13=1,L13=0),K13>15),AND(L13=2,K13>4,K13<16),AND(L13>2,K13>0,K13<5)),"Médio",IF(OR(AND(L13=2,K13>15),AND(L13>2,K13>4,K13<16),AND(L13>2,K13>15)),"Complexo",""))), IF(OR(J13="CE",J13="SE"),IF(OR(AND(OR(L13=1,L13=0),K13>0,K13<6),AND(OR(L13=1,L13=0),K13>5,K13<20),AND(L13>1,L13<4,K13>0,K13<6)),"Simples",IF(OR(AND(OR(L13=1,L13=0),K13>19),AND(L13>1,L13<4,K13>5,K13<20),AND(L13>3,K13>0,K13<6)),"Médio",IF(OR(AND(L13>1,L13<4,K13>19),AND(L13>3,K13>5,K13<20),AND(L13>3,K13>19)),"Complexo",""))),"")) | O13: =IF(J13="ALI",IF(OR(AND(OR(L13=1,L13=0),K13>0,K13<20),AND(OR(L13=1,L13=0),K13>19,K13<51),AND(L13>1,L13<6,K13>0,K13<20)),"Simples",IF(OR(AND(OR(L13=1,L13=0),K13>50),AND(L13>1,L13<6,K13>19,K13<51),AND(L13>5,K13>0,K13<20)),"Médio",IF(OR(AND(L13>1,L13<6,K13>50),AND(L13>5,K13>19,K13<51),AND(L13>5,K13>50)),"Complexo",""))), IF(J13="AIE",IF(OR(AND(OR(L13=1, L13=0),K13>0,K13<20),AND(OR(L13=1, L13=0),K13>19,K13<51),AND(L13>1,L13<6,K13>0,K13<20)),"Simples",IF(OR(AND(OR(L13=1, L13=0),K13>50),AND(L13>1,L13<6,K13>19,K13<51),AND(L13>5,K13>0,K13<20)),"Médio",IF(OR(AND(L13>1,L13<6,K13>50),AND(L13>5,K13>19,K13<51),AND(L13>5,K13>50)),"Complexo",""))),"")) | P13: =IF(N13="",O13,IF(O13="",N13,"")) | Q13: =IF(AND(OR(J13="EE",J13="CE"),P13="Simples"),3, IF(AND(OR(J13="EE",J13="CE"),P13="Médio"),4, IF(AND(OR(J13="EE",J13="CE"),P13="Complexo"),6, IF(AND(J13="SE",P13="Simples"),4, IF(AND(J13="SE",P13="Médio"),5, IF(AND(J13="SE",P13="Complexo"),7,0)))))) -> 0 | R13: =IF(AND(J13="ALI",O13="Simples"),7, IF(AND(J13="ALI",O13="Médio"),10, IF(AND(J13="ALI",O13="Complexo"),15, IF(AND(J13="AIE",O13="Simples"),5, IF(AND(J13="AIE",O13="Médio"),7, IF(AND(J13="AIE",O13="Complexo"),10,0)))))) -> 0 | S13: =IF($M13="%",($Q13+$R13)*$C13,$C13*$I13) -> 0
C14: =IF($B14<>"",VLOOKUP($B14,Matriz_INM,2,0),0) -> 0 | M14: =IFERROR(VLOOKUP($B14,Matriz_INM,3,0),"") | N14: =IF(J14="EE",IF(OR(AND(OR(L14=1,L14=0),K14>0,K14<5),AND(OR(L14=1,L14=0),K14>4,K14<16),AND(L14=2,K14>0,K14<5)),"Simples",IF(OR(AND(OR(L14=1,L14=0),K14>15),AND(L14=2,K14>4,K14<16),AND(L14>2,K14>0,K14<5)),"Médio",IF(OR(AND(L14=2,K14>15),AND(L14>2,K14>4,K14<16),AND(L14>2,K14>15)),"Complexo",""))), IF(OR(J14="CE",J14="SE"),IF(OR(AND(OR(L14=1,L14=0),K14>0,K14<6),AND(OR(L14=1,L14=0),K14>5,K14<20),AND(L14>1,L14<4,K14>0,K14<6)),"Simples",IF(OR(AND(OR(L14=1,L14=0),K14>19),AND(L14>1,L14<4,K14>5,K14<20),AND(L14>3,K14>0,K14<6)),"Médio",IF(OR(AND(L14>1,L14<4,K14>19),AND(L14>3,K14>5,K14<20),AND(L14>3,K14>19)),"Complexo",""))),"")) | O14: =IF(J14="ALI",IF(OR(AND(OR(L14=1,L14=0),K14>0,K14<20),AND(OR(L14=1,L14=0),K14>19,K14<51),AND(L14>1,L14<6,K14>0,K14<20)),"Simples",IF(OR(AND(OR(L14=1,L14=0),K14>50),AND(L14>1,L14<6,K14>19,K14<51),AND(L14>5,K14>0,K14<20)),"Médio",IF(OR(AND(L14>1,L14<6,K14>50),AND(L14>5,K14>19,K14<51),AND(L14>5,K14>50)),"Complexo",""))), IF(J14="AIE",IF(OR(AND(OR(L14=1, L14=0),K14>0,K14<20),AND(OR(L14=1, L14=0),K14>19,K14<51),AND(L14>1,L14<6,K14>0,K14<20)),"Simples",IF(OR(AND(OR(L14=1, L14=0),K14>50),AND(L14>1,L14<6,K14>19,K14<51),AND(L14>5,K14>0,K14<20)),"Médio",IF(OR(AND(L14>1,L14<6,K14>50),AND(L14>5,K14>19,K14<51),AND(L14>5,K14>50)),"Complexo",""))),"")) | P14: =IF(N14="",O14,IF(O14="",N14,"")) | Q14: =IF(AND(OR(J14="EE",J14="CE"),P14="Simples"),3, IF(AND(OR(J14="EE",J14="CE"),P14="Médio"),4, IF(AND(OR(J14="EE",J14="CE"),P14="Complexo"),6, IF(AND(J14="SE",P14="Simples"),4, IF(AND(J14="SE",P14="Médio"),5, IF(AND(J14="SE",P14="Complexo"),7,0)))))) -> 0 | R14: =IF(AND(J14="ALI",O14="Simples"),7, IF(AND(J14="ALI",O14="Médio"),10, IF(AND(J14="ALI",O14="Complexo"),15, IF(AND(J14="AIE",O14="Simples"),5, IF(AND(J14="AIE",O14="Médio"),7, IF(AND(J14="AIE",O14="Complexo"),10,0)))))) -> 0 | S14: =IF($M14="%",($Q14+$R14)*$C14,$C14*$I14) -> 0
C15: =IF($B15<>"",VLOOKUP($B15,Matriz_INM,2,0),0) -> 0 | M15: =IFERROR(VLOOKUP($B15,Matriz_INM,3,0),"") | N15: =IF(J15="EE",IF(OR(AND(OR(L15=1,L15=0),K15>0,K15<5),AND(OR(L15=1,L15=0),K15>4,K15<16),AND(L15=2,K15>0,K15<5)),"Simples",IF(OR(AND(OR(L15=1,L15=0),K15>15),AND(L15=2,K15>4,K15<16),AND(L15>2,K15>0,K15<5)),"Médio",IF(OR(AND(L15=2,K15>15),AND(L15>2,K15>4,K15<16),AND(L15>2,K15>15)),"Complexo",""))), IF(OR(J15="CE",J15="SE"),IF(OR(AND(OR(L15=1,L15=0),K15>0,K15<6),AND(OR(L15=1,L15=0),K15>5,K15<20),AND(L15>1,L15<4,K15>0,K15<6)),"Simples",IF(OR(AND(OR(L15=1,L15=0),K15>19),AND(L15>1,L15<4,K15>5,K15<20),AND(L15>3,K15>0,K15<6)),"Médio",IF(OR(AND(L15>1,L15<4,K15>19),AND(L15>3,K15>5,K15<20),AND(L15>3,K15>19)),"Complexo",""))),"")) | O15: =IF(J15="ALI",IF(OR(AND(OR(L15=1,L15=0),K15>0,K15<20),AND(OR(L15=1,L15=0),K15>19,K15<51),AND(L15>1,L15<6,K15>0,K15<20)),"Simples",IF(OR(AND(OR(L15=1,L15=0),K15>50),AND(L15>1,L15<6,K15>19,K15<51),AND(L15>5,K15>0,K15<20)),"Médio",IF(OR(AND(L15>1,L15<6,K15>50),AND(L15>5,K15>19,K15<51),AND(L15>5,K15>50)),"Complexo",""))), IF(J15="AIE",IF(OR(AND(OR(L15=1, L15=0),K15>0,K15<20),AND(OR(L15=1, L15=0),K15>19,K15<51),AND(L15>1,L15<6,K15>0,K15<20)),"Simples",IF(OR(AND(OR(L15=1, L15=0),K15>50),AND(L15>1,L15<6,K15>19,K15<51),AND(L15>5,K15>0,K15<20)),"Médio",IF(OR(AND(L15>1,L15<6,K15>50),AND(L15>5,K15>19,K15<51),AND(L15>5,K15>50)),"Complexo",""))),"")) | P15: =IF(N15="",O15,IF(O15="",N15,"")) | Q15: =IF(AND(OR(J15="EE",J15="CE"),P15="Simples"),3, IF(AND(OR(J15="EE",J15="CE"),P15="Médio"),4, IF(AND(OR(J15="EE",J15="CE"),P15="Complexo"),6, IF(AND(J15="SE",P15="Simples"),4, IF(AND(J15="SE",P15="Médio"),5, IF(AND(J15="SE",P15="Complexo"),7,0)))))) -> 0 | R15: =IF(AND(J15="ALI",O15="Simples"),7, IF(AND(J15="ALI",O15="Médio"),10, IF(AND(J15="ALI",O15="Complexo"),15, IF(AND(J15="AIE",O15="Simples"),5, IF(AND(J15="AIE",O15="Médio"),7, IF(AND(J15="AIE",O15="Complexo"),10,0)))))) -> 0 | S15: =IF($M15="%",($Q15+$R15)*$C15,$C15*$I15) -> 0
C16: =IF($B16<>"",VLOOKUP($B16,Matriz_INM,2,0),0) -> 0 | M16: =IFERROR(VLOOKUP($B16,Matriz_INM,3,0),"") | N16: =IF(J16="EE",IF(OR(AND(OR(L16=1,L16=0),K16>0,K16<5),AND(OR(L16=1,L16=0),K16>4,K16<16),AND(L16=2,K16>0,K16<5)),"Simples",IF(OR(AND(OR(L16=1,L16=0),K16>15),AND(L16=2,K16>4,K16<16),AND(L16>2,K16>0,K16<5)),"Médio",IF(OR(AND(L16=2,K16>15),AND(L16>2,K16>4,K16<16),AND(L16>2,K16>15)),"Complexo",""))), IF(OR(J16="CE",J16="SE"),IF(OR(AND(OR(L16=1,L16=0),K16>0,K16<6),AND(OR(L16=1,L16=0),K16>5,K16<20),AND(L16>1,L16<4,K16>0,K16<6)),"Simples",IF(OR(AND(OR(L16=1,L16=0),K16>19),AND(L16>1,L16<4,K16>5,K16<20),AND(L16>3,K16>0,K16<6)),"Médio",IF(OR(AND(L16>1,L16<4,K16>19),AND(L16>3,K16>5,K16<20),AND(L16>3,K16>19)),"Complexo",""))),"")) | O16: =IF(J16="ALI",IF(OR(AND(OR(L16=1,L16=0),K16>0,K16<20),AND(OR(L16=1,L16=0),K16>19,K16<51),AND(L16>1,L16<6,K16>0,K16<20)),"Simples",IF(OR(AND(OR(L16=1,L16=0),K16>50),AND(L16>1,L16<6,K16>19,K16<51),AND(L16>5,K16>0,K16<20)),"Médio",IF(OR(AND(L16>1,L16<6,K16>50),AND(L16>5,K16>19,K16<51),AND(L16>5,K16>50)),"Complexo",""))), IF(J16="AIE",IF(OR(AND(OR(L16=1, L16=0),K16>0,K16<20),AND(OR(L16=1, L16=0),K16>19,K16<51),AND(L16>1,L16<6,K16>0,K16<20)),"Simples",IF(OR(AND(OR(L16=1, L16=0),K16>50),AND(L16>1,L16<6,K16>19,K16<51),AND(L16>5,K16>0,K16<20)),"Médio",IF(OR(AND(L16>1,L16<6,K16>50),AND(L16>5,K16>19,K16<51),AND(L16>5,K16>50)),"Complexo",""))),"")) | P16: =IF(N16="",O16,IF(O16="",N16,"")) | Q16: =IF(AND(OR(J16="EE",J16="CE"),P16="Simples"),3, IF(AND(OR(J16="EE",J16="CE"),P16="Médio"),4, IF(AND(OR(J16="EE",J16="CE"),P16="Complexo"),6, IF(AND(J16="SE",P16="Simples"),4, IF(AND(J16="SE",P16="Médio"),5, IF(AND(J16="SE",P16="Complexo"),7,0)))))) -> 0 | R16: =IF(AND(J16="ALI",O16="Simples"),7, IF(AND(J16="ALI",O16="Médio"),10, IF(AND(J16="ALI",O16="Complexo"),15, IF(AND(J16="AIE",O16="Simples"),5, IF(AND(J16="AIE",O16="Médio"),7, IF(AND(J16="AIE",O16="Complexo"),10,0)))))) -> 0 | S16: =IF($M16="%",($Q16+$R16)*$C16,$C16*$I16) -> 0
C17: =IF($B17<>"",VLOOKUP($B17,Matriz_INM,2,0),0) -> 0 | M17: =IFERROR(VLOOKUP($B17,Matriz_INM,3,0),"") | N17: =IF(J17="EE",IF(OR(AND(OR(L17=1,L17=0),K17>0,K17<5),AND(OR(L17=1,L17=0),K17>4,K17<16),AND(L17=2,K17>0,K17<5)),"Simples",IF(OR(AND(OR(L17=1,L17=0),K17>15),AND(L17=2,K17>4,K17<16),AND(L17>2,K17>0,K17<5)),"Médio",IF(OR(AND(L17=2,K17>15),AND(L17>2,K17>4,K17<16),AND(L17>2,K17>15)),"Complexo",""))), IF(OR(J17="CE",J17="SE"),IF(OR(AND(OR(L17=1,L17=0),K17>0,K17<6),AND(OR(L17=1,L17=0),K17>5,K17<20),AND(L17>1,L17<4,K17>0,K17<6)),"Simples",IF(OR(AND(OR(L17=1,L17=0),K17>19),AND(L17>1,L17<4,K17>5,K17<20),AND(L17>3,K17>0,K17<6)),"Médio",IF(OR(AND(L17>1,L17<4,K17>19),AND(L17>3,K17>5,K17<20),AND(L17>3,K17>19)),"Complexo",""))),"")) | O17: =IF(J17="ALI",IF(OR(AND(OR(L17=1,L17=0),K17>0,K17<20),AND(OR(L17=1,L17=0),K17>19,K17<51),AND(L17>1,L17<6,K17>0,K17<20)),"Simples",IF(OR(AND(OR(L17=1,L17=0),K17>50),AND(L17>1,L17<6,K17>19,K17<51),AND(L17>5,K17>0,K17<20)),"Médio",IF(OR(AND(L17>1,L17<6,K17>50),AND(L17>5,K17>19,K17<51),AND(L17>5,K17>50)),"Complexo",""))), IF(J17="AIE",IF(OR(AND(OR(L17=1, L17=0),K17>0,K17<20),AND(OR(L17=1, L17=0),K17>19,K17<51),AND(L17>1,L17<6,K17>0,K17<20)),"Simples",IF(OR(AND(OR(L17=1, L17=0),K17>50),AND(L17>1,L17<6,K17>19,K17<51),AND(L17>5,K17>0,K17<20)),"Médio",IF(OR(AND(L17>1,L17<6,K17>50),AND(L17>5,K17>19,K17<51),AND(L17>5,K17>50)),"Complexo",""))),"")) | P17: =IF(N17="",O17,IF(O17="",N17,"")) | Q17: =IF(AND(OR(J17="EE",J17="CE"),P17="Simples"),3, IF(AND(OR(J17="EE",J17="CE"),P17="Médio"),4, IF(AND(OR(J17="EE",J17="CE"),P17="Complexo"),6, IF(AND(J17="SE",P17="Simples"),4, IF(AND(J17="SE",P17="Médio"),5, IF(AND(J17="SE",P17="Complexo"),7,0)))))) -> 0 | R17: =IF(AND(J17="ALI",O17="Simples"),7, IF(AND(J17="ALI",O17="Médio"),10, IF(AND(J17="ALI",O17="Complexo"),15, IF(AND(J17="AIE",O17="Simples"),5, IF(AND(J17="AIE",O17="Médio"),7, IF(AND(J17="AIE",O17="Complexo"),10,0)))))) -> 0 | S17: =IF($M17="%",($Q17+$R17)*$C17,$C17*$I17) -> 0
C18: =IF($B18<>"",VLOOKUP($B18,Matriz_INM,2,0),0) -> 0 | M18: =IFERROR(VLOOKUP($B18,Matriz_INM,3,0),"") | N18: =IF(J18="EE",IF(OR(AND(OR(L18=1,L18=0),K18>0,K18<5),AND(OR(L18=1,L18=0),K18>4,K18<16),AND(L18=2,K18>0,K18<5)),"Simples",IF(OR(AND(OR(L18=1,L18=0),K18>15),AND(L18=2,K18>4,K18<16),AND(L18>2,K18>0,K18<5)),"Médio",IF(OR(AND(L18=2,K18>15),AND(L18>2,K18>4,K18<16),AND(L18>2,K18>15)),"Complexo",""))), IF(OR(J18="CE",J18="SE"),IF(OR(AND(OR(L18=1,L18=0),K18>0,K18<6),AND(OR(L18=1,L18=0),K18>5,K18<20),AND(L18>1,L18<4,K18>0,K18<6)),"Simples",IF(OR(AND(OR(L18=1,L18=0),K18>19),AND(L18>1,L18<4,K18>5,K18<20),AND(L18>3,K18>0,K18<6)),"Médio",IF(OR(AND(L18>1,L18<4,K18>19),AND(L18>3,K18>5,K18<20),AND(L18>3,K18>19)),"Complexo",""))),"")) | O18: =IF(J18="ALI",IF(OR(AND(OR(L18=1,L18=0),K18>0,K18<20),AND(OR(L18=1,L18=0),K18>19,K18<51),AND(L18>1,L18<6,K18>0,K18<20)),"Simples",IF(OR(AND(OR(L18=1,L18=0),K18>50),AND(L18>1,L18<6,K18>19,K18<51),AND(L18>5,K18>0,K18<20)),"Médio",IF(OR(AND(L18>1,L18<6,K18>50),AND(L18>5,K18>19,K18<51),AND(L18>5,K18>50)),"Complexo",""))), IF(J18="AIE",IF(OR(AND(OR(L18=1, L18=0),K18>0,K18<20),AND(OR(L18=1, L18=0),K18>19,K18<51),AND(L18>1,L18<6,K18>0,K18<20)),"Simples",IF(OR(AND(OR(L18=1, L18=0),K18>50),AND(L18>1,L18<6,K18>19,K18<51),AND(L18>5,K18>0,K18<20)),"Médio",IF(OR(AND(L18>1,L18<6,K18>50),AND(L18>5,K18>19,K18<51),AND(L18>5,K18>50)),"Complexo",""))),"")) | P18: =IF(N18="",O18,IF(O18="",N18,"")) | Q18: =IF(AND(OR(J18="EE",J18="CE"),P18="Simples"),3, IF(AND(OR(J18="EE",J18="CE"),P18="Médio"),4, IF(AND(OR(J18="EE",J18="CE"),P18="Complexo"),6, IF(AND(J18="SE",P18="Simples"),4, IF(AND(J18="SE",P18="Médio"),5, IF(AND(J18="SE",P18="Complexo"),7,0)))))) -> 0 | R18: =IF(AND(J18="ALI",O18="Simples"),7, IF(AND(J18="ALI",O18="Médio"),10, IF(AND(J18="ALI",O18="Complexo"),15, IF(AND(J18="AIE",O18="Simples"),5, IF(AND(J18="AIE",O18="Médio"),7, IF(AND(J18="AIE",O18="Complexo"),10,0)))))) -> 0 | S18: =IF($M18="%",($Q18+$R18)*$C18,$C18*$I18) -> 0
C19: =IF($B19<>"",VLOOKUP($B19,Matriz_INM,2,0),0) -> 0 | M19: =IFERROR(VLOOKUP($B19,Matriz_INM,3,0),"") | N19: =IF(J19="EE",IF(OR(AND(OR(L19=1,L19=0),K19>0,K19<5),AND(OR(L19=1,L19=0),K19>4,K19<16),AND(L19=2,K19>0,K19<5)),"Simples",IF(OR(AND(OR(L19=1,L19=0),K19>15),AND(L19=2,K19>4,K19<16),AND(L19>2,K19>0,K19<5)),"Médio",IF(OR(AND(L19=2,K19>15),AND(L19>2,K19>4,K19<16),AND(L19>2,K19>15)),"Complexo",""))), IF(OR(J19="CE",J19="SE"),IF(OR(AND(OR(L19=1,L19=0),K19>0,K19<6),AND(OR(L19=1,L19=0),K19>5,K19<20),AND(L19>1,L19<4,K19>0,K19<6)),"Simples",IF(OR(AND(OR(L19=1,L19=0),K19>19),AND(L19>1,L19<4,K19>5,K19<20),AND(L19>3,K19>0,K19<6)),"Médio",IF(OR(AND(L19>1,L19<4,K19>19),AND(L19>3,K19>5,K19<20),AND(L19>3,K19>19)),"Complexo",""))),"")) | O19: =IF(J19="ALI",IF(OR(AND(OR(L19=1,L19=0),K19>0,K19<20),AND(OR(L19=1,L19=0),K19>19,K19<51),AND(L19>1,L19<6,K19>0,K19<20)),"Simples",IF(OR(AND(OR(L19=1,L19=0),K19>50),AND(L19>1,L19<6,K19>19,K19<51),AND(L19>5,K19>0,K19<20)),"Médio",IF(OR(AND(L19>1,L19<6,K19>50),AND(L19>5,K19>19,K19<51),AND(L19>5,K19>50)),"Complexo",""))), IF(J19="AIE",IF(OR(AND(OR(L19=1, L19=0),K19>0,K19<20),AND(OR(L19=1, L19=0),K19>19,K19<51),AND(L19>1,L19<6,K19>0,K19<20)),"Simples",IF(OR(AND(OR(L19=1, L19=0),K19>50),AND(L19>1,L19<6,K19>19,K19<51),AND(L19>5,K19>0,K19<20)),"Médio",IF(OR(AND(L19>1,L19<6,K19>50),AND(L19>5,K19>19,K19<51),AND(L19>5,K19>50)),"Complexo",""))),"")) | P19: =IF(N19="",O19,IF(O19="",N19,"")) | Q19: =IF(AND(OR(J19="EE",J19="CE"),P19="Simples"),3, IF(AND(OR(J19="EE",J19="CE"),P19="Médio"),4, IF(AND(OR(J19="EE",J19="CE"),P19="Complexo"),6, IF(AND(J19="SE",P19="Simples"),4, IF(AND(J19="SE",P19="Médio"),5, IF(AND(J19="SE",P19="Complexo"),7,0)))))) -> 0 | R19: =IF(AND(J19="ALI",O19="Simples"),7, IF(AND(J19="ALI",O19="Médio"),10, IF(AND(J19="ALI",O19="Complexo"),15, IF(AND(J19="AIE",O19="Simples"),5, IF(AND(J19="AIE",O19="Médio"),7, IF(AND(J19="AIE",O19="Complexo"),10,0)))))) -> 0 | S19: =IF($M19="%",($Q19+$R19)*$C19,$C19*$I19) -> 0
C20: =IF($B20<>"",VLOOKUP($B20,Matriz_INM,2,0),0) -> 0 | M20: =IFERROR(VLOOKUP($B20,Matriz_INM,3,0),"") | N20: =IF(J20="EE",IF(OR(AND(OR(L20=1,L20=0),K20>0,K20<5),AND(OR(L20=1,L20=0),K20>4,K20<16),AND(L20=2,K20>0,K20<5)),"Simples",IF(OR(AND(OR(L20=1,L20=0),K20>15),AND(L20=2,K20>4,K20<16),AND(L20>2,K20>0,K20<5)),"Médio",IF(OR(AND(L20=2,K20>15),AND(L20>2,K20>4,K20<16),AND(L20>2,K20>15)),"Complexo",""))), IF(OR(J20="CE",J20="SE"),IF(OR(AND(OR(L20=1,L20=0),K20>0,K20<6),AND(OR(L20=1,L20=0),K20>5,K20<20),AND(L20>1,L20<4,K20>0,K20<6)),"Simples",IF(OR(AND(OR(L20=1,L20=0),K20>19),AND(L20>1,L20<4,K20>5,K20<20),AND(L20>3,K20>0,K20<6)),"Médio",IF(OR(AND(L20>1,L20<4,K20>19),AND(L20>3,K20>5,K20<20),AND(L20>3,K20>19)),"Complexo",""))),"")) | O20: =IF(J20="ALI",IF(OR(AND(OR(L20=1,L20=0),K20>0,K20<20),AND(OR(L20=1,L20=0),K20>19,K20<51),AND(L20>1,L20<6,K20>0,K20<20)),"Simples",IF(OR(AND(OR(L20=1,L20=0),K20>50),AND(L20>1,L20<6,K20>19,K20<51),AND(L20>5,K20>0,K20<20)),"Médio",IF(OR(AND(L20>1,L20<6,K20>50),AND(L20>5,K20>19,K20<51),AND(L20>5,K20>50)),"Complexo",""))), IF(J20="AIE",IF(OR(AND(OR(L20=1, L20=0),K20>0,K20<20),AND(OR(L20=1, L20=0),K20>19,K20<51),AND(L20>1,L20<6,K20>0,K20<20)),"Simples",IF(OR(AND(OR(L20=1, L20=0),K20>50),AND(L20>1,L20<6,K20>19,K20<51),AND(L20>5,K20>0,K20<20)),"Médio",IF(OR(AND(L20>1,L20<6,K20>50),AND(L20>5,K20>19,K20<51),AND(L20>5,K20>50)),"Complexo",""))),"")) | P20: =IF(N20="",O20,IF(O20="",N20,"")) | Q20: =IF(AND(OR(J20="EE",J20="CE"),P20="Simples"),3, IF(AND(OR(J20="EE",J20="CE"),P20="Médio"),4, IF(AND(OR(J20="EE",J20="CE"),P20="Complexo"),6, IF(AND(J20="SE",P20="Simples"),4, IF(AND(J20="SE",P20="Médio"),5, IF(AND(J20="SE",P20="Complexo"),7,0)))))) -> 0 | R20: =IF(AND(J20="ALI",O20="Simples"),7, IF(AND(J20="ALI",O20="Médio"),10, IF(AND(J20="ALI",O20="Complexo"),15, IF(AND(J20="AIE",O20="Simples"),5, IF(AND(J20="AIE",O20="Médio"),7, IF(AND(J20="AIE",O20="Complexo"),10,0)))))) -> 0 | S20: =IF($M20="%",($Q20+$R20)*$C20,$C20*$I20) -> 0
C21: =IF($B21<>"",VLOOKUP($B21,Matriz_INM,2,0),0) -> 0 | M21: =IFERROR(VLOOKUP($B21,Matriz_INM,3,0),"") | N21: =IF(J21="EE",IF(OR(AND(OR(L21=1,L21=0),K21>0,K21<5),AND(OR(L21=1,L21=0),K21>4,K21<16),AND(L21=2,K21>0,K21<5)),"Simples",IF(OR(AND(OR(L21=1,L21=0),K21>15),AND(L21=2,K21>4,K21<16),AND(L21>2,K21>0,K21<5)),"Médio",IF(OR(AND(L21=2,K21>15),AND(L21>2,K21>4,K21<16),AND(L21>2,K21>15)),"Complexo",""))), IF(OR(J21="CE",J21="SE"),IF(OR(AND(OR(L21=1,L21=0),K21>0,K21<6),AND(OR(L21=1,L21=0),K21>5,K21<20),AND(L21>1,L21<4,K21>0,K21<6)),"Simples",IF(OR(AND(OR(L21=1,L21=0),K21>19),AND(L21>1,L21<4,K21>5,K21<20),AND(L21>3,K21>0,K21<6)),"Médio",IF(OR(AND(L21>1,L21<4,K21>19),AND(L21>3,K21>5,K21<20),AND(L21>3,K21>19)),"Complexo",""))),"")) | O21: =IF(J21="ALI",IF(OR(AND(OR(L21=1,L21=0),K21>0,K21<20),AND(OR(L21=1,L21=0),K21>19,K21<51),AND(L21>1,L21<6,K21>0,K21<20)),"Simples",IF(OR(AND(OR(L21=1,L21=0),K21>50),AND(L21>1,L21<6,K21>19,K21<51),AND(L21>5,K21>0,K21<20)),"Médio",IF(OR(AND(L21>1,L21<6,K21>50),AND(L21>5,K21>19,K21<51),AND(L21>5,K21>50)),"Complexo",""))), IF(J21="AIE",IF(OR(AND(OR(L21=1, L21=0),K21>0,K21<20),AND(OR(L21=1, L21=0),K21>19,K21<51),AND(L21>1,L21<6,K21>0,K21<20)),"Simples",IF(OR(AND(OR(L21=1, L21=0),K21>50),AND(L21>1,L21<6,K21>19,K21<51),AND(L21>5,K21>0,K21<20)),"Médio",IF(OR(AND(L21>1,L21<6,K21>50),AND(L21>5,K21>19,K21<51),AND(L21>5,K21>50)),"Complexo",""))),"")) | P21: =IF(N21="",O21,IF(O21="",N21,"")) | Q21: =IF(AND(OR(J21="EE",J21="CE"),P21="Simples"),3, IF(AND(OR(J21="EE",J21="CE"),P21="Médio"),4, IF(AND(OR(J21="EE",J21="CE"),P21="Complexo"),6, IF(AND(J21="SE",P21="Simples"),4, IF(AND(J21="SE",P21="Médio"),5, IF(AND(J21="SE",P21="Complexo"),7,0)))))) -> 0 | R21: =IF(AND(J21="ALI",O21="Simples"),7, IF(AND(J21="ALI",O21="Médio"),10, IF(AND(J21="ALI",O21="Complexo"),15, IF(AND(J21="AIE",O21="Simples"),5, IF(AND(J21="AIE",O21="Médio"),7, IF(AND(J21="AIE",O21="Complexo"),10,0)))))) -> 0 | S21: =IF($M21="%",($Q21+$R21)*$C21,$C21*$I21) -> 0
... C382: =IF($B382<>"",VLOOKUP($B382,Matriz_INM,2,0),0) -> 0 | M382: =IFERROR(VLOOKUP($B382,Matriz_INM,3,0),"") | N382: =IF(J382="EE",IF(OR(AND(OR(L382=1,L382=0),K382>0,K382<5),AND(OR(L382=1,L382=0),K382>4,K382<16),AND(L382=2,K382>0,K382<5)),"Simples",IF(OR(AND(OR(L382=1,L382=0),K382>15),AND(L382=2,K382>4,K382<16),AND(L382>2,K382>0,K382<5)),"Médio",IF(OR(AND(L382=2,K382>15),AND(L382>2,K382>4,K382<16),AND(L382>2,K382>15)),"Complexo",""))), IF(OR(J382="CE",J382="SE"),IF(OR(AND(OR(L382=1,L382=0),K382>0,K382<6),AND(OR(L382=1,L382=0),K382>5,K382<20),AND(L382>1,L382<4,K382>0,K382<6)),"Simples",IF(OR(AND(OR(L382=1,L382=0),K382>19),AND(L382>1,L382<4,K382>5,K382<20),AND(L382>3,K382>0,K382<6)),"Médio",IF(OR(AND(L382>1,L382<4,K382>19),AND(L382>3,K382>5,K382<20),AND(L382>3,K382>19)),"Complexo",""))),"")) | O382: =IF(J382="ALI",IF(OR(AND(OR(L382=1,L382=0),K382>0,K382<20),AND(OR(L382=1,L382=0),K382>19,K382<51),AND(L382>1,L382<6,K382>0,K382<20)),"Simples",IF(OR(AND(OR(L382=1,L382=0),K382>50),AND(L382>1,L382<6,K382>19,K382<51),AND(L382>5,K382>0,K382<20)),"Médio",IF(OR(AND(L382>1,L382<6,K382>50),AND(L382>5,K382>19,K382<51),AND(L382>5,K382>50)),"Complexo",""))), IF(J382="AIE",IF(OR(AND(OR(L382=1, L382=0),K382>0,K382<20),AND(OR(L382=1, L382=0),K382>19,K382<51),AND(L382>1,L382<6,K382>0,K382<20)),"Simples",IF(OR(AND(OR(L382=1, L382=0),K382>50),AND(L382>1,L382<6,K382>19,K382<51),AND(L382>5,K382>0,K382<20)),"Médio",IF(OR(AND(L382>1,L382<6,K382>50),AND(L382>5,K382>19,K382<51),AND(L382>5,K382>50)),"Complexo",""))),"")) | P382: =IF(N382="",O382,IF(O382="",N382,"")) | Q382: =IF(AND(OR(J382="EE",J382="CE"),P382="Simples"),3, IF(AND(OR(J382="EE",J382="CE"),P382="Médio"),4, IF(AND(OR(J382="EE",J382="CE"),P382="Complexo"),6, IF(AND(J382="SE",P382="Simples"),4, IF(AND(J382="SE",P382="Médio"),5, IF(AND(J382="SE",P382="Complexo"),7,0)))))) -> 0 | R382: =IF(AND(J382="ALI",O382="Simples"),7, IF(AND(J382="ALI",O382="Médio"),10, IF(AND(J382="ALI",O382="Complexo"),15, IF(AND(J382="AIE",O382="Simples"),5, IF(AND(J382="AIE",O382="Médio"),7, IF(AND(J382="AIE",O382="Complexo"),10,0)))))) -> 0 | S382: =IF($M382="%",($Q382+$R382)*$C382,$C382*$I382) -> 0
A383: Só inserir linhas antes desta.
P384: Tamanho Funcional | R384: =IF(AND(J384="ALI",O384="Simples"),7, IF(AND(J384="ALI",O384="Médio"),10, IF(AND(J384="ALI",O384="Complexo"),15, IF(AND(J384="AIE",O384="Simples"),5, IF(AND(J384="AIE",O384="Médio"),7, IF(AND(J384="AIE",O384="Complexo"),10,0)))))) -> 0 | S384: =SUM(S9:S383) -> 0

Sheet INM - Detalhada
A1: 0 | C1: Serviços – Itens Não Mensuráveis – 8.7 TR Detalhada
L3: Elaborador da contagem:
L4: Data da Contagem:
A5: Quantidade de Pontos de Função: | C5: =TEXT(P27,"#.##0,0#") -> 0,0 | L5: Revisor da contagem:
L6: Data da Revisão:
F9: Estimado | J9: Executado | N9: Valor Final
A10: ID | B10: Tipo Serviço | C10: Item PT | D10: Requisito | E10: Descrição Serviço | F10: Tam. Equipe (TEp) | G10: Horas/Mês Execut. p/ Recurso (HrM) | H10: Produtividade (PHRp) | I10: PF Previsto (PFp) | J10: Tam. Equipe (TEe) | K10: Horas/Mês Execut. p/ Recurso (HrM) | L10: Produtividade (PHRe) | M10: PF Executado (PFe) | N10: Índice (Ia/Id/Ig) | O10: Índice Prod. (IPr) | P10: Valor Final (VF)
A11: Só inserir linhas depois desta.
H12: =IF($F12*$G12=0,"",$F12*$G12) | I12: =IFERROR($H12/15,"") | L12: =IF($K12*$J12=0,"",$K12*$J12) | M12: =IFERROR($L12/15,"") | N12: =IFERROR((IF($B12="Serviço de Gerência",$I12*0.87027272,$I12*0.5)),"") | O12: =(IFERROR($M12/$I12,"")) | P12: =IFERROR($N12*$O12,"")
H13: =IF($F13*$G13=0,"",$F13*$G13) | I13: =IFERROR($H13/15,"") | L13: =IF($K13*$J13=0,"",$K13*$J13) | M13: =IFERROR($L13/15,"") | N13: =IFERROR((IF($B13="Serviço de Gerência",$I13*0.87027272,$I13*0.5)),"") | O13: =(IFERROR($M13/$I13,"")) | P13: =IFERROR($N13*$O13,"")
H14: =IF($F14*$G14=0,"",$F14*$G14) | I14: =IFERROR($H14/15,"") | L14: =IF($K14*$J14=0,"",$K14*$J14) | M14: =IFERROR($L14/15,"") | N14: =IFERROR((IF($B14="Serviço de Gerência",$I14*0.87027272,$I14*0.5)),"") | O14: =(IFERROR($M14/$I14,"")) | P14: =IFERROR($N14*$O14,"")
H15: =IF($F15*$G15=0,"",$F15*$G15) | I15: =IFERROR($H15/15,"") | L15: =IF($K15*$J15=0,"",$K15*$J15) | M15: =IFERROR($L15/15,"") | N15: =IFERROR((IF($B15="Serviço de Gerência",$I15*0.87027272,$I15*0.5)),"") | O15: =(IFERROR($M15/$I15,"")) | P15: =IFERROR($N15*$O15,"")
H16: =IF($F16*$G16=0,"",$F16*$G16) | I16: =IFERROR($H16/15,"") | L16: =IF($K16*$J16=0,"",$K16*$J16) | M16: =IFERROR($L16/15,"") | N16: =IFERROR((IF($B16="Serviço de Gerência",$I16*0.87027272,$I16*0.5)),"") | O16: =(IFERROR($M16/$I16,"")) | P16: =IFERROR($N16*$O16,"")
H17: =IF($F17*$G17=0,"",$F17*$G17) | I17: =IFERROR($H17/15,"") | L17: =IF($K17*$J17=0,"",$K17*$J17) | M17: =IFERROR($L17/15,"") | N17: =IFERROR((IF($B17="Serviço de Gerência",$I17*0.87027272,$I17*0.5)),"") | O17: =(IFERROR($M17/$I17,"")) | P17: =IFERROR($N17*$O17,"")
H18: =IF($F18*$G18=0,"",$F18*$G18) | I18: =IFERROR($H18/15,"") | L18: =IF($K18*$J18=0,"",$K18*$J18) | M18: =IFERROR($L18/15,"") | N18: =IFERROR((IF($B18="Serviço de Gerência",$I18*0.87027272,$I18*0.5)),"") | O18: =(IFERROR($M18/$I18,"")) | P18: =IFERROR($N18*$O18,"")
H19: =IF($F19*$G19=0,"",$F19*$G19) | I19: =IFERROR($H19/15,"") | L19: =IF($K19*$J19=0,"",$K19*$J19) | M19: =IFERROR($L19/15,"") | N19: =IFERROR((IF($B19="Serviço de Gerência",$I19*0.87027272,$I19*0.5)),"") | O19: =(IFERROR($M19/$I19,"")) | P19: =IFERROR($N19*$O19,"")
H20: =IF($F20*$G20=0,"",$F20*$G20) | I20: =IFERROR($H20/15,"") | L20: =IF($K20*$J20=0,"",$K20*$J20) | M20: =IFERROR($L20/15,"") | N20: =IFERROR((IF($B20="Serviço de Gerência",$I20*0.87027272,$I20*0.5)),"") | O20: =(IFERROR($M20/$I20,"")) | P20: =IFERROR($N20*$O20,"")
H21: =IF($F21*$G21=0,"",$F21*$G21) | I21: =IFERROR($H21/15,"") | L21: =IF($K21*$J21=0,"",$K21*$J21) | M21: =IFERROR($L21/15,"") | N21: =IFERROR((IF($B21="Serviço de Gerência",$I21*0.87027272,$I21*0.5)),"") | O21: =(IFERROR($M21/$I21,"")) | P21: =IFERROR($N21*$O21,"")
H22: =IF($F22*$G22=0,"",$F22*$G22) | I22: =IFERROR($H22/15,"") | L22: =IF($K22*$J22=0,"",$K22*$J22) | M22: =IFERROR($L22/15,"") | N22: =IFERROR((IF($B22="Serviço de Gerência",$I22*0.87027272,$I22*0.5)),"") | O22: =(IFERROR($M22/$I22,"")) | P22: =IFERROR($N22*$O22,"")
H23: =IF($F23*$G23=0,"",$F23*$G23) | I23: =IFERROR($H23/15,"") | L23: =IF($K23*$J23=0,"",$K23*$J23) | M23: =IFERROR($L23/15,"") | N23: =IFERROR((IF($B23="Serviço de Gerência",$I23*0.87027272,$I23*0.5)),"") | O23: =(IFERROR($M23/$I23,"")) | P23: =IFERROR($N23*$O23,"")
... H25: =IF($F25*$G25=0,"",$F25*$G25) | I25: =IFERROR($H25/15,"") | L25: =IF($K25*$J25=0,"",$K25*$J25) | M25: =IFERROR($L25/15,"") | N25: =IFERROR((IF($B25="Serviço de Gerência",$I25*0.87027272,$I25*0.5)),"") | O25: =(IFERROR($M25/$I25,"")) | P25: =IFERROR($N25*$O25,"")
A26: Só inserir linhas depois desta.
O27: PF Total | P27: =SUM($P12:$P25) -> 0

Sheet AFP - Estimativa
A1: =Resumo!A1 -> Template V.1.6 | C1: Contagem de Pontos de Função Contagem Estimada
I3: Elaborador da contagem:
I4: Data da Contagem:
A5: Quantidade de Pontos de Função: | D5: =TEXT(K384,"#.##0,0#") -> 0,0 | I5: Revisor da contagem:
I6: Data da Revisão:
A8: ID | B8: Tipo Projeto | C8: Fator Ajuste | D8: Item PT | E8: Release | F8: Módulo | G8: Requisito | H8: Processos elementares | I8: Qtd | J8: Tipo | K8: PF | L8: Fund. | M8: Tipo (Q/%)
A9: Só inserir linhas depois desta.
C10: =IF($B10<>"",VLOOKUP($B10,Matriz_INM,2,0),0) -> 0 | K10: =IF(M10="%",(IF($J10="EE",4,IF($J10="CE",4,IF($J10="SE",5,IF($J10="ALI",7,IF($J10="AIE",5,0))))))*$C10,$C10*$I10) -> 0 | M10: =IFERROR(VLOOKUP($B10,Matriz_INM,3,0),"")
C11: =IF($B11<>"",VLOOKUP($B11,Matriz_INM,2,0),0) -> 0 | K11: =IF(M11="%",(IF($J11="EE",4,IF($J11="CE",4,IF($J11="SE",5,IF($J11="ALI",7,IF($J11="AIE",5,0))))))*$C11,$C11*$I11) -> 0 | M11: =IFERROR(VLOOKUP($B11,Matriz_INM,3,0),"")
C12: =IF($B12<>"",VLOOKUP($B12,Matriz_INM,2,0),0) -> 0 | K12: =IF(M12="%",(IF($J12="EE",4,IF($J12="CE",4,IF($J12="SE",5,IF($J12="ALI",7,IF($J12="AIE",5,0))))))*$C12,$C12*$I12) -> 0 | M12: =IFERROR(VLOOKUP($B12,Matriz_INM,3,0),"")
C13: =IF($B13<>"",VLOOKUP($B13,Matriz_INM,2,0),0) -> 0 | K13: =IF(M13="%",(IF($J13="EE",4,IF($J13="CE",4,IF($J13="SE",5,IF($J13="ALI",7,IF($J13="AIE",5,0))))))*$C13,$C13*$I13) -> 0 | M13: =IFERROR(VLOOKUP($B13,Matriz_INM,3,0),"")
C14: =IF($B14<>"",VLOOKUP($B14,Matriz_INM,2,0),0) -> 0 | K14: =IF(M14="%",(IF($J14="EE",4,IF($J14="CE",4,IF($J14="SE",5,IF($J14="ALI",7,IF($J14="AIE",5,0))))))*$C14,$C14*$I14) -> 0 | M14: =IFERROR(VLOOKUP($B14,Matriz_INM,3,0),"")
C15: =IF($B15<>"",VLOOKUP($B15,Matriz_INM,2,0),0) -> 0 | K15: =IF(M15="%",(IF($J15="EE",4,IF($J15="CE",4,IF($J15="SE",5,IF($J15="ALI",7,IF($J15="AIE",5,0))))))*$C15,$C15*$I15) -> 0 | M15: =IFERROR(VLOOKUP($B15,Matriz_INM,3,0),"")
C16: =IF($B16<>"",VLOOKUP($B16,Matriz_INM,2,0),0) -> 0 | K16: =IF(M16="%",(IF($J16="EE",4,IF($J16="CE",4,IF($J16="SE",5,IF($J16="ALI",7,IF($J16="AIE",5,0))))))*$C16,$C16*$I16) -> 0 | M16: =IFERROR(VLOOKUP($B16,Matriz_INM,3,0),"")
C17: =IF($B17<>"",VLOOKUP($B17,Matriz_INM,2,0),0) -> 0 | K17: =IF(M17="%",(IF($J17="EE",4,IF($J17="CE",4,IF($J17="SE",5,IF($J17="ALI",7,IF($J17="AIE",5,0))))))*$C17,$C17*$I17) -> 0 | M17: =IFERROR(VLOOKUP($B17,Matriz_INM,3,0),"")
C18: =IF($B18<>"",VLOOKUP($B18,Matriz_INM,2,0),0) -> 0 | K18: =IF(M18="%",(IF($J18="EE",4,IF($J18="CE",4,IF($J18="SE",5,IF($J18="ALI",7,IF($J18="AIE",5,0))))))*$C18,$C18*$I18) -> 0 | M18: =IFERROR(VLOOKUP($B18,Matriz_INM,3,0),"")
C19: =IF($B19<>"",VLOOKUP($B19,Matriz_INM,2,0),0) -> 0 | K19: =IF(M19="%",(IF($J19="EE",4,IF($J19="CE",4,IF($J19="SE",5,IF($J19="ALI",7,IF($J19="AIE",5,0))))))*$C19,$C19*$I19) -> 0 | M19: =IFERROR(VLOOKUP($B19,Matriz_INM,3,0),"")
C20: =IF($B20<>"",VLOOKUP($B20,Matriz_INM,2,0),0) -> 0 | K20: =IF(M20="%",(IF($J20="EE",4,IF($J20="CE",4,IF($J20="SE",5,IF($J20="ALI",7,IF($J20="AIE",5,0))))))*$C20,$C20*$I20) -> 0 | M20: =IFERROR(VLOOKUP($B20,Matriz_INM,3,0),"")
C21: =IF($B21<>"",VLOOKUP($B21,Matriz_INM,2,0),0) -> 0 | K21: =IF(M21="%",(IF($J21="EE",4,IF($J21="CE",4,IF($J21="SE",5,IF($J21="ALI",7,IF($J21="AIE",5,0))))))*$C21,$C21*$I21) -> 0 | M21: =IFERROR(VLOOKUP($B21,Matriz_INM,3,0),"")
... C382: =IF($B382<>"",VLOOKUP($B382,Matriz_INM,2,0),0) -> 0 | K382: =IF(M382="%",(IF($J382="EE",4,IF($J382="CE",4,IF($J382="SE",5,IF($J382="ALI",7,IF($J382="AIE",5,0))))))*$C382,$C382*$I382) -> 0 | M382: =IFERROR(VLOOKUP($B382,Matriz_INM,3,0),"")
A383: Só inserir linhas antes desta.
K384: =SUM(K9:K383) -> 0

Sheet UST
B1: Template V.1.6 | G1: Contagem de Unidade de Serviço Técnico - UST
B3: Quantidade de UST: | D3: =TEXT(J404,"#.##0,0#") -> 0,0 | I3: Elaborador da contagem:
I4: Data da Contagem:
B5: Quantidade UST em PF: | D5: =TEXT(K404,"#.##0,0#") -> 0,0 | I5: Revisor da contagem:
I6: Data da Revisão:
B8: ID | C8: Item Catálogo | D8: Complexidade | E8: Horas | F8: Item PT | G8: Requisito | I8: Descrição do Serviço Técnico / Atividade | J8: Desenvolvimento | L8: Fund.
J9: UST | K9: PF
B10: Só inserir linhas depois desta.
J11: =IF($C11<>"",$E11*1.5,"") | K11: =IFERROR($J11/10,"")
J12: =IF($C12<>"",$E12*1.5,"") | K12: =IFERROR($J12/10,"")
J13: =IF($C13<>"",$E13*1.5,"") | K13: =IFERROR($J13/10,"")
J14: =IF($C14<>"",$E14*1.5,"") | K14: =IFERROR($J14/10,"")
J15: =IF($C15<>"",$E15*1.5,"") | K15: =IFERROR($J15/10,"")
J16: =IF($C16<>"",$E16*1.5,"") | K16: =IFERROR($J16/10,"")
J17: =IF($C17<>"",$E17*1.5,"") | K17: =IFERROR($J17/10,"")
J18: =IF($C18<>"",$E18*1.5,"") | K18: =IFERROR($J18/10,"")
J19: =IF($C19<>"",$E19*1.5,"") | K19: =IFERROR($J19/10,"")
J20: =IF($C20<>"",$E20*1.5,"") | K20: =IFERROR($J20/10,"")
J21: =IF($C21<>"",$E21*1.5,"") | K21: =IFERROR($J21/10,"")
J22: =IF($C22<>"",$E22*1.5,"") | K22: =IFERROR($J22/10,"")
... J402: =IF($C402<>"",$E402*1.5,"") | K402: =IFERROR($J402/10,"")
B403: Só inserir linhas antes desta.
I404: Tamanho Total UST: | J404: =SUM(J11:J402) -> 0 | K404: =SUM(K11:K402) -> 0
I405: Tamnho UST em PF:

Sheet INM - Estimativa
A1: Template V.1.6 | D1: Serviços – Itens Não Mensuráveis – 8.7 TR Estimada
G3: Elaborador da contagem:
G4: Data da Contagem:
A5: Quantidade de Pontos de Função: | D5: =TEXT(K26,"#.##0,0#") -> 0,0 | G5: Revisor da contagem:
G6: Data da Revisão:
A9: ID | B9: Tipo Serviço | C9: Deflator | D9: Item PT | E9: Requisito | F9: Descrição Serviço | G9: Tam. Equipe (TEp) | H9: Horas/Mês Execut. p/ Recurso (HrM) | I9: Produtividade (PHRp) | J9: PF Previsto (PFp) | K9: PF Ajustado
A10: Só inserir linhas depois desta.
C11: =IF(B11<>"",IF(B11="Serviço de Gerência", 0.87027272,0.5),"") | I11: =IF($G11*$H11=0,"",$G11*$H11) | J11: =IF($I11="","",IFERROR($I11/15,"")) | K11: =IFERROR(($I11/15)*$C11,"")
C12: =IF(B12<>"",IF(B12="Serviço de Gerência", 0.87027272,0.5),"") | I12: =IF($G12*$H12=0,"",$G12*$H12) | J12: =IF($I12="","",IFERROR($I12/15,"")) | K12: =IFERROR(($I12/15)*$C12,"")
C13: =IF(B13<>"",IF(B13="Serviço de Gerência", 0.87027272,0.5),"") | I13: =IF($G13*$H13=0,"",$G13*$H13) | J13: =IF($I13="","",IFERROR($I13/15,"")) | K13: =IFERROR(($I13/15)*$C13,"")
C14: =IF(B14<>"",IF(B14="Serviço de Gerência", 0.87027272,0.5),"") | I14: =IF($G14*$H14=0,"",$G14*$H14) | J14: =IF($I14="","",IFERROR($I14/15,"")) | K14: =IFERROR(($I14/15)*$C14,"")
C15: =IF(B15<>"",IF(B15="Serviço de Gerência", 0.87027272,0.5),"") | I15: =IF($G15*$H15=0,"",$G15*$H15) | J15: =IF($I15="","",IFERROR($I15/15,"")) | K15: =IFERROR(($I15/15)*$C15,"")
C16: =IF(B16<>"",IF(B16="Serviço de Gerência", 0.87027272,0.5),"") | I16: =IF($G16*$H16=0,"",$G16*$H16) | J16: =IF($I16="","",IFERROR($I16/15,"")) | K16: =IFERROR(($I16/15)*$C16,"")
C17: =IF(B17<>"",IF(B17="Serviço de Gerência", 0.87027272,0.5),"") | I17: =IF($G17*$H17=0,"",$G17*$H17) | J17: =IF($I17="","",IFERROR($I17/15,"")) | K17: =IFERROR(($I17/15)*$C17,"")
C18: =IF(B18<>"",IF(B18="Serviço de Gerência", 0.87027272,0.5),"") | I18: =IF($G18*$H18=0,"",$G18*$H18) | J18: =IF($I18="","",IFERROR($I18/15,"")) | K18: =IFERROR(($I18/15)*$C18,"")
C19: =IF(B19<>"",IF(B19="Serviço de Gerência", 0.87027272,0.5),"") | I19: =IF($G19*$H19=0,"",$G19*$H19) | J19: =IF($I19="","",IFERROR($I19/15,"")) | K19: =IFERROR(($I19/15)*$C19,"")
C20: =IF(B20<>"",IF(B20="Serviço de Gerência", 0.87027272,0.5),"") | I20: =IF($G20*$H20=0,"",$G20*$H20) | J20: =IF($I20="","",IFERROR($I20/15,"")) | K20: =IFERROR(($I20/15)*$C20,"")
C21: =IF(B21<>"",IF(B21="Serviço de Gerência", 0.87027272,0.5),"") | I21: =IF($G21*$H21=0,"",$G21*$H21) | J21: =IF($I21="","",IFERROR($I21/15,"")) | K21: =IFERROR(($I21/15)*$C21,"")
C22: =IF(B22<>"",IF(B22="Serviço de Gerência", 0.87027272,0.5),"") | I22: =IF($G22*$H22=0,"",$G22*$H22) | J22: =IF($I22="","",IFERROR($I22/15,"")) | K22: =IFERROR(($I22/15)*$C22,"")
... C24: =IF(B24<>"",IF(B24="Serviço de Gerência", 0.87027272,0.5),"") | I24: =IF($G24*$H24=0,"",$G24*$H24) | J24: =IF($I24="","",IFERROR($I24/15,"")) | K24: =IFERROR(($I24/15)*$C24,"")
A25: Só inserir linhas depois desta.
I26: PF Total | K26: =SUM($K11:$K24) -> 0

Sheet AFP - Indicativa
A1: Template V.1.1 | E1: Contagem de Pontos de Função Contagem Indicativa
G3: Elaborador da contagem:
G4: Data da Contagem:
A5: Quantidade de Pontos de Função: | E5: =TEXT(I110,"#.##0,0#") -> 0,0 | G5: Revisor da contagem:
G6: Data da Revisão:
A8: ID | B8: Item PT | C8: Release | D8: Módulo | E8: Requisito | G8: Arquivos Lógicos | H8: Desenvolvimento | J8: Fund.
H9: Tipo | I9: PF
A10: Só inserir linhas depois desta.
I11: =IF(H11="ALI",35,IF(H11="AIE",15,""))
I12: =IF(H12="ALI",35,IF(H12="AIE",15,""))
I13: =IF(H13="ALI",35,IF(H13="AIE",15,""))
I14: =IF(H14="ALI",35,IF(H14="AIE",15,""))
I15: =IF(H15="ALI",35,IF(H15="AIE",15,""))
I16: =IF(H16="ALI",35,IF(H16="AIE",15,""))
I17: =IF(H17="ALI",35,IF(H17="AIE",15,""))
I18: =IF(H18="ALI",35,IF(H18="AIE",15,""))
I19: =IF(H19="ALI",35,IF(H19="AIE",15,""))
I20: =IF(H20="ALI",35,IF(H20="AIE",15,""))
I21: =IF(H21="ALI",35,IF(H21="AIE",15,""))
I22: =IF(H22="ALI",35,IF(H22="AIE",15,""))
... I108: =IF(H108="ALI",35,IF(H108="AIE",15,""))
A109: Só inserir linhas antes desta.
G110: Tamanho Funcional Indicativo: | I110: =SUM(I10:I109) -> 0

Sheet Fundamentação
A1: =Resumo!A1 -> Template V.1.6 | C1: Contagem de Pontos de Função Fundamentação
A3: Fundamentação da Contagem
A4: ID | B4: Título | C4: Imagem Tela / Link documentação / Justificativa
A5: 1
A6: 2

Sheet Redução de Prazo
B1: Template V.1.6 | D1: Contagem de Pontos de Função - SISP 2.0 Distribuição de Esforço/ Redução de Prazo
B2: DISTRIBUIÇÃO DE PRAZO DE PROJETO | J2: Prazo até 99 PF | M2: REDUÇÃO DE PRAZO
B3: P1 - Informe o tipo de Prazo (Úteis/Corridos): | G3: Úteis | J3: Tamanho do Projeto | K3: Dias Úteis | M3: DESCRIÇÃO | P3: VALORES
B4: P3 - Informe Tipo do Sistema: | G4: Sistema OO | H4: Expoente t para o Tipo: | M4: Data limite desejada
H5: =IF(G4="Sistema Comum – Mainframe", 0.33, IF(G4="Sistema Comum – WEB", 0.35, IF(G4="Sistema OO", 0.36, IF(G4="Sistema Cliente/Servidor (Alta complexidade)", 0.37,IF(G4="Sistemas Gerenciais Complexos", 0.39, IF(G4="Software Básico, Framework, Sistemas Comerciais", 0.4, IF(G4="Software Militar *Exclusivo SISP v2.0", 0.45, "ERRO - Selecione o Tipo novamente"))))))) -> 0.36 | K5: Complex. Baixa | M5: Prazo desejado p/conclusão (dias) | P5: =IF(AND(P4<>"",B16<>0),(P4-G10)+1,B16) -> Informe PF
B6: P4 - Informe a complexidade do projeto: | G6: Projetos com até 99 PF | J6: Até 10 PF | K6: 10 | M6: Taxa de redução do prazo-projeto | P6: =IF(G7<>0,P5/B16-1,"-") -> -
B7: P5 - Informe o tamanho do Projeto em PF: | J7: De 11 PF a 20 PF | K7: 20 | P7: SISP | Q7: LINEAR
B8: Fases do Projeto | D8: % SISP | E8: % OS | F8: Dias | G8: Cronograma | J8: De 21 PF a 30 PF | K8: 30 | M8: Taxa de aumento de esforço | P8: =IF(P5=B16,"-",GROWTH(Q22:Q24,P22:P24,P6,1)) -> - | Q8: =IF(P5=B16,"-",TREND(Q22:Q24,P22:P24,P6,0)) -> -
G9: Início | H9: Fim | J9: De 31 PF a 40 PF | K9: 40 | M9: Índice multiplicador de esforço | P9: =IF(P5=B16,"-",P8/100+1) -> - | Q9: =IF(P5=B16,"-",Q8/100+1) -> -
B10: Engenharia de Requisitos | D10: 0.25 | E10: 0.25 | F10: =IF(ISERR($B$16*E10),"ERRO",$B$16*E10) -> ERRO | H10: =IF(E10="",G10,(IF(G10="","-",IF(ISERR(IF(AND((G10>=0),(G10<=2958465)),G10+(F10-1),"-")),"-",IF(AND((G10>=0),(G10<=2958465)),G10+(F10-1),"-"))))) -> - | J10: De 41 PF a 50 PF | K10: 50 | M10: Novo Tamanho Funcional (PF) | P10: =IF(P5=B16,"-",(P8/100+1)*G7) -> - | Q10: =IF(P5=B16,"-",(Q8/100+1)*G7) -> -
B11: Arquitetura & Design | D11: 0.1 | E11: 0.1 | F11: =IF(ISERR($B$16*E11),"ERRO",$B$16*E11) -> ERRO | G11: =IF(AND((H10>=0),(H10<=2958465)),H10,"-") -> - | H11: =IF(G11="", "-",(IF(AND((G11>=0),(G11<=2958465)),G11+(F11),"-"))) -> - | J11: De 51 PF a 60 PF | K11: 60 | M11: CRONOGRAMA COM REDUÇÃO DE PRAZO
B12: Implementação | D12: 0.4 | E12: 0.4 | F12: =IF(ISERR($B$16*E12),"ERRO",$B$16*E12) -> ERRO | G12: =IF(AND((H11>=0),(H11<=2958465)),H11,"-") -> - | H12: =IF(G12="", "-",(IF(AND((G12>=0),(G12<=2958465)),G12+(F12),"-"))) -> - | J12: De 61 PF a 70 PF | K12: 70 | M12: Fases do Projeto | N12: % OS | O12: Dias | P12: Data Início | Q12: Data Fim
B13: Testes | D13: 0.15 | E13: 0.15 | F13: =IF(ISERR($B$16*E13),"ERRO",$B$16*E13) -> ERRO | G13: =IF(AND((H12>=0),(H12<=2958465)),H12,"-") -> - | H13: =IF(G13="", "-",(IF(AND((G13>=0),(G13<=2958465)),G13+(F13),"-"))) -> - | J13: De 71 PF a 85 PF | K13: 88 | M13: Engenharia de Requisitos | N13: =E10 -> 0.25 | O13: =IF(P5=B16,"-",IF(AND($G$7<>0,$G$10<>""),$P$5*N13,"-")) -> - | P13: =IF(P5=B16,"-",IF(G10="","-",G10)) -> - | Q13: =IF(P13<>"-",(IF(O13>1,((P13+O13)-1),(P13+O13))),"-") -> -
B14: Homologação | D14: 0.05 | E14: 0.05 | F14: =IF(ISERR($B$16*E14),"ERRO",$B$16*E14) -> ERRO | G14: =IF(AND((H13>=0),(H13<=2958465)),H13,"-") -> - | H14: =IF(G14="", "-",(IF(AND((G14>=0),(G14<=2958465)),G14+(F14),"-"))) -> - | J14: De 86 PF a 99 PF | K14: 104 | M14: Arquitetura & Design | N14: =E11 -> 0.1 | O14: =IF(P5=B16,"-",IF(AND($G$7<>0,$G$10<>""),$P$5*N14,"-")) -> - | P14: =Q13 -> - | Q14: =IF(P14<>"-",P14+O14,"-") -> -
B15: Implantação | D15: 0.05 | E15: 0.05 | F15: =IF(ISERR($B$16*E15),"ERRO",$B$16*E15) -> ERRO | G15: =IF(AND((H14>=0),(H14<=2958465)),H14,"-") -> - | H15: =IF(G15="", "-",(IF(AND((G15>=0),(G15<=2958465)),G15+(F15),"-"))) -> - | J15: + de 99 PF | K15: Cálculo pela fórmula de Capers Jones: Td = V^t | M15: Implementação | N15: =E12 -> 0.4 | O15: =IF(P5=B16,"-",IF(AND($G$7<>0,$G$10<>""),$P$5*N15,"-")) -> - | P15: =Q14 -> - | Q15: =IF(P15<>"-",P15+O15,"-") -> -
B16: =IF(G7="","Informe PF",IF(G6="Projetos com até 99 PF",(IF(G7<=10,K6,IF(G7<=20,K7,IF(G7<=30,K8,IF(G7<=40,K9,IF(G7<=50,K10,IF(G7<=60,K11,IF(G7<=70,K12,IF(G7<=85,K13,IF(G7<=99,K14,"ERRO - Insira novamente o tamanho em PF do projeto")))))))))),ROUND(POWER(G7,j3se(H5<>0,H5,0.35))*30,0))) -> Informe PF | C16: TOTAL | D16: 1 | E16: =SUM(E10:E15) -> 1 | F16: =IF(B16<>"ERRO - Insira novamente o tamanho em PF do projeto",SUM(F10:F15)&" dias","ERRO - Insira novamente PF") -> 0 dias | M16: Testes | N16: =E13 -> 0.15 | O16: =IF(P5=B16,"-",IF(AND($G$7<>0,$G$10<>""),$P$5*N16,"-")) -> - | P16: =Q15 -> - | Q16: =IF(P16<>"-",P16+O16,"-") -> -
M17: Homologação | N17: =E14 -> 0.05 | O17: =IF(P5=B16,"-",IF(AND($G$7<>0,$G$10<>""),$P$5*N17,"-")) -> - | P17: =Q16 -> - | Q17: =IF(P17<>"-",P17+O17,"-") -> -
M18: Implantação | N18: =E15 -> 0.05 | O18: =IF(P5=B16,"-",IF(AND($G$7<>0,$G$10<>""),$P$5*N18,"-")) -> - | P18: =Q17 -> - | Q18: =IF(P18<>"-",P18+O18,"-") -> -
P21: Redução do prazo | Q21: Aumento no esforço
P22: -0.1 | Q22: 20
P23: -0.2 | Q23: 50
P24: -0.25 | Q24: 70
P26: Redução do prazo | Q26: SISP | R26: Curva Linear
P27: -0.01 | Q27: =GROWTH($Q$22:$Q$24,$P$22:$P$24,P27,1) -> 9.4974871 | R27: =TREND($Q$22:$Q$24,$P$22:$P$24,P27,0) -> 2.6222222
P28: -0.02 | Q28: =GROWTH($Q$22:$Q$24,$P$22:$P$24,P28,1) -> 10.33673 | R28: =TREND($Q$22:$Q$24,$P$22:$P$24,P28,0) -> 5.2444444
P29: -0.03 | Q29: =GROWTH($Q$22:$Q$24,$P$22:$P$24,P29,1) -> 11.250132 | R29: =TREND($Q$22:$Q$24,$P$22:$P$24,P29,0) -> 7.8666667
P30: -0.04 | Q30: =GROWTH($Q$22:$Q$24,$P$22:$P$24,P30,1) -> 12.244247 | R30: =TREND($Q$22:$Q$24,$P$22:$P$24,P30,0) -> 10.488889
P31: -0.05 | Q31: =GROWTH($Q$22:$Q$24,$P$22:$P$24,P31,1) -> 13.326207 | R31: =TREND($Q$22:$Q$24,$P$22:$P$24,P31,0) -> 13.111111
P32: -0.06 | Q32: =GROWTH($Q$22:$Q$24,$P$22:$P$24,P32,1) -> 14.503774 | R32: =TREND($Q$22:$Q$24,$P$22:$P$24,P32,0) -> 15.733333
P33: -0.07 | Q33: =GROWTH($Q$22:$Q$24,$P$22:$P$24,P33,1) -> 15.785396 | R33: =TREND($Q$22:$Q$24,$P$22:$P$24,P33,0) -> 18.355556
P34: -0.08 | Q34: =GROWTH($Q$22:$Q$24,$P$22:$P$24,P34,1) -> 17.180268 | R34: =TREND($Q$22:$Q$24,$P$22:$P$24,P34,0) -> 20.977778
P35: -0.09 | Q35: =GROWTH($Q$22:$Q$24,$P$22:$P$24,P35,1) -> 18.698398 | R35: =TREND($Q$22:$Q$24,$P$22:$P$24,P35,0) -> 23.6
P36: -0.1 | Q36: =GROWTH($Q$22:$Q$24,$P$22:$P$24,P36,1) -> 20.350676 | R36: =TREND($Q$22:$Q$24,$P$22:$P$24,P36,0) -> 26.222222
P37: -0.11 | Q37: =GROWTH($Q$22:$Q$24,$P$22:$P$24,P37,1) -> 22.148958 | R37: =TREND($Q$22:$Q$24,$P$22:$P$24,P37,0) -> 28.844444
P38: -0.12 | Q38: =GROWTH($Q$22:$Q$24,$P$22:$P$24,P38,1) -> 24.106145 | R38: =TREND($Q$22:$Q$24,$P$22:$P$24,P38,0) -> 31.466667
... P45: -0.19 | Q45: =GROWTH($Q$22:$Q$24,$P$22:$P$24,P45,1) -> 43.606275 | R45: =TREND($Q$22:$Q$24,$P$22:$P$24,P45,0) -> 49.822222
P46: -0.2 | Q46: 50 | R46: =TREND($Q$22:$Q$24,$P$22:$P$24,P46,0) -> 52.444444
P47: -0.21 | Q47: =GROWTH($Q$22:$Q$24,$P$22:$P$24,P47,1) -> 51.65328 | R47: =TREND($Q$22:$Q$24,$P$22:$P$24,P47,0) -> 55.066667
P48: -0.22 | Q48: =GROWTH($Q$22:$Q$24,$P$22:$P$24,P48,1) -> 56.217608 | R48: =TREND($Q$22:$Q$24,$P$22:$P$24,P48,0) -> 57.688889
P49: -0.23 | Q49: =GROWTH($Q$22:$Q$24,$P$22:$P$24,P49,1) -> 61.185262 | R49: =TREND($Q$22:$Q$24,$P$22:$P$24,P49,0) -> 60.311111
...

Sheet Esforço
A1: =Resumo!A1 -> Template V.1.6 | C1: Contagem de Pontos de Função Esforço
A3: Produtividade (h/PFs) -----------> | C3: 8
D4: Engenharia de Requisitos | E4: Design e Arquitetura | F4: Implementação | G4: Testes | H4: Homologação | I4: Implantação
A5: Requisito | B5: Quant. PF | C5: Total | D5: =Resumo!G18 -> 0.25 | E5: =Resumo!G19 -> 0.1 | F5: =Resumo!G20 -> 0.4 | G5: =Resumo!G21 -> 0.15 | H5: =Resumo!G22 -> 0.05 | I5: =Resumo!G23 -> 0.05
B6: =IF(Resumo!$B$5="Detalhada",SUMIF('AFP - Detalhada'!$G$10:$G382,Esforço!$A6,'AFP - Detalhada'!$S$10:$S382), IF(Resumo!$B$5="Estimativa",SUMIF('AFP - Estimativa'!$G$10:$G382,Esforço!$A6,'AFP - Estimativa'!$K$10:$K382)*(1+'AFP - Estimativa'!$D$6),IF(Resumo!$B$5="Indicativa",SUMIF('AFP - Indicativa'!$E$10:$E$109,Esforço!$A6,'AFP - Indicativa'!$I$10:$I$109)*(1+'AFP - Indicativa'!$E$6),0))) -> 0 | C6: =ROUND(B6*$C$3,0) -> 0 | D6: =ROUND($C6*D$5,0) -> 0 | E6: =ROUND($C6*E$5,0) -> 0 | F6: =ROUND($C6*F$5,0) -> 0 | G6: =ROUND($C6*G$5,0) -> 0 | H6: =ROUND($C6*H$5,0) -> 0 | I6: =ROUND($C6*I$5,0) -> 0
B7: =IF(Resumo!$B$5="Detalhada",SUMIF('AFP - Detalhada'!$G$10:$G383,Esforço!$A7,'AFP - Detalhada'!$S$10:$S383), IF(Resumo!$B$5="Estimativa",SUMIF('AFP - Estimativa'!$G$10:$G383,Esforço!$A7,'AFP - Estimativa'!$K$10:$K383)*(1+'AFP - Estimativa'!$D$6),IF(Resumo!$B$5="Indicativa",SUMIF('AFP - Indicativa'!$E$10:$E$109,Esforço!$A7,'AFP - Indicativa'!$I$10:$I$109)*(1+'AFP - Indicativa'!$E$6),0))) -> 0 | C7: =ROUND(B7*$C$3,0) -> 0 | D7: =ROUND($C7*D$5,0) -> 0 | E7: =ROUND($C7*E$5,0) -> 0 | F7: =ROUND($C7*F$5,0) -> 0 | G7: =ROUND($C7*G$5,0) -> 0 | H7: =ROUND($C7*H$5,0) -> 0 | I7: =ROUND($C7*I$5,0) -> 0
B8: =IF(Resumo!$B$5="Detalhada",SUMIF('AFP - Detalhada'!$G$10:$G384,Esforço!$A8,'AFP - Detalhada'!$S$10:$S384), IF(Resumo!$B$5="Estimativa",SUMIF('AFP - Estimativa'!$G$10:$G384,Esforço!$A8,'AFP - Estimativa'!$K$10:$K384)*(1+'AFP - Estimativa'!$D$6),IF(Resumo!$B$5="Indicativa",SUMIF('AFP - Indicativa'!$E$10:$E$109,Esforço!$A8,'AFP - Indicativa'!$I$10:$I$109)*(1+'AFP - Indicativa'!$E$6),0))) -> 0 | C8: =ROUND(B8*$C$3,0) -> 0 | D8: =ROUND($C8*D$5,0) -> 0 | E8: =ROUND($C8*E$5,0) -> 0 | F8: =ROUND($C8*F$5,0) -> 0 | G8: =ROUND($C8*G$5,0) -> 0 | H8: =ROUND($C8*H$5,0) -> 0 | I8: =ROUND($C8*I$5,0) -> 0
B9: =IF(Resumo!$B$5="Detalhada",SUMIF('AFP - Detalhada'!$G$10:$G385,Esforço!$A9,'AFP - Detalhada'!$S$10:$S385), IF(Resumo!$B$5="Estimativa",SUMIF('AFP - Estimativa'!$G$10:$G385,Esforço!$A9,'AFP - Estimativa'!$K$10:$K385)*(1+'AFP - Estimativa'!$D$6),IF(Resumo!$B$5="Indicativa",SUMIF('AFP - Indicativa'!$E$10:$E$109,Esforço!$A9,'AFP - Indicativa'!$I$10:$I$109)*(1+'AFP - Indicativa'!$E$6),0))) -> 0 | C9: =ROUND(B9*$C$3,0) -> 0 | D9: =ROUND($C9*D$5,0) -> 0 | E9: =ROUND($C9*E$5,0) -> 0 | F9: =ROUND($C9*F$5,0) -> 0 | G9: =ROUND($C9*G$5,0) -> 0 | H9: =ROUND($C9*H$5,0) -> 0 | I9: =ROUND($C9*I$5,0) -> 0
B10: =IF(Resumo!$B$5="Detalhada",SUMIF('AFP - Detalhada'!$G$10:$G386,Esforço!$A10,'AFP - Detalhada'!$S$10:$S386), IF(Resumo!$B$5="Estimativa",SUMIF('AFP - Estimativa'!$G$10:$G386,Esforço!$A10,'AFP - Estimativa'!$K$10:$K386)*(1+'AFP - Estimativa'!$D$6),IF(Resumo!$B$5="Indicativa",SUMIF('AFP - Indicativa'!$E$10:$E$109,Esforço!$A10,'AFP - Indicativa'!$I$10:$I$109)*(1+'AFP - Indicativa'!$E$6),0))) -> 0 | C10: =ROUND(B10*$C$3,0) -> 0 | D10: =ROUND($C10*D$5,0) -> 0 | E10: =ROUND($C10*E$5,0) -> 0 | F10: =ROUND($C10*F$5,0) -> 0 | G10: =ROUND($C10*G$5,0) -> 0 | H10: =ROUND($C10*H$5,0) -> 0 | I10: =ROUND($C10*I$5,0) -> 0
B11: =IF(Resumo!$B$5="Detalhada",SUMIF('AFP - Detalhada'!$G$10:$G387,Esforço!$A11,'AFP - Detalhada'!$S$10:$S387), IF(Resumo!$B$5="Estimativa",SUMIF('AFP - Estimativa'!$G$10:$G387,Esforço!$A11,'AFP - Estimativa'!$K$10:$K387)*(1+'AFP - Estimativa'!$D$6),IF(Resumo!$B$5="Indicativa",SUMIF('AFP - Indicativa'!$E$10:$E$109,Esforço!$A11,'AFP - Indicativa'!$I$10:$I$109)*(1+'AFP - Indicativa'!$E$6),0))) -> 0 | C11: =ROUND(B11*$C$3,0) -> 0 | D11: =ROUND($C11*D$5,0) -> 0 | E11: =ROUND($C11*E$5,0) -> 0 | F11: =ROUND($C11*F$5,0) -> 0 | G11: =ROUND($C11*G$5,0) -> 0 | H11: =ROUND($C11*H$5,0) -> 0 | I11: =ROUND($C11*I$5,0) -> 0
B12: =IF(Resumo!$B$5="Detalhada",SUMIF('AFP - Detalhada'!$G$10:$G388,Esforço!$A12,'AFP - Detalhada'!$S$10:$S388), IF(Resumo!$B$5="Estimativa",SUMIF('AFP - Estimativa'!$G$10:$G388,Esforço!$A12,'AFP - Estimativa'!$K$10:$K388)*(1+'AFP - Estimativa'!$D$6),IF(Resumo!$B$5="Indicativa",SUMIF('AFP - Indicativa'!$E$10:$E$109,Esforço!$A12,'AFP - Indicativa'!$I$10:$I$109)*(1+'AFP - Indicativa'!$E$6),0))) -> 0 | C12: =ROUND(B12*$C$3,0) -> 0 | D12: =ROUND($C12*D$5,0) -> 0 | E12: =ROUND($C12*E$5,0) -> 0 | F12: =ROUND($C12*F$5,0) -> 0 | G12: =ROUND($C12*G$5,0) -> 0 | H12: =ROUND($C12*H$5,0) -> 0 | I12: =ROUND($C12*I$5,0) -> 0
B13: =IF(Resumo!$B$5="Detalhada",SUMIF('AFP - Detalhada'!$G$10:$G389,Esforço!$A13,'AFP - Detalhada'!$S$10:$S389), IF(Resumo!$B$5="Estimativa",SUMIF('AFP - Estimativa'!$G$10:$G389,Esforço!$A13,'AFP - Estimativa'!$K$10:$K389)*(1+'AFP - Estimativa'!$D$6),IF(Resumo!$B$5="Indicativa",SUMIF('AFP - Indicativa'!$E$10:$E$109,Esforço!$A13,'AFP - Indicativa'!$I$10:$I$109)*(1+'AFP - Indicativa'!$E$6),0))) -> 0 | C13: =ROUND(B13*$C$3,0) -> 0 | D13: =ROUND($C13*D$5,0) -> 0 | E13: =ROUND($C13*E$5,0) -> 0 | F13: =ROUND($C13*F$5,0) -> 0 | G13: =ROUND($C13*G$5,0) -> 0 | H13: =ROUND($C13*H$5,0) -> 0 | I13: =ROUND($C13*I$5,0) -> 0
