Workbook
Name TiposDeFuncao: Deflatores!$L$37:$L$64
Name TiposDeFuncao: Deflatores!$L$37:$L$64
Name TiposDeManutencao: Deflatores!$G$4:$G$38
Name TiposDeManutencao: Deflatores!$G$4:$G$38

Sheet Info Gerais
A1: Identificação da Contagem
A4: Empresa | F4: BASIS | O4: PF IFPUG | Q4: =Contagem_PF!N4 -> 0
A5: Aplicação | O5: PFBruto | Q5: =Contagem_PF!N5 -> 0
A6: Tipo de Contagem | O6: PF Deflator FS | Q6: =Contagem_PF!N6 -> 0
A7: Nível de Detalhe | O7: Tecnologia
A8: Projeto | O8: Versão do Guia
A9: Responsável | O9: Criação
A10: Revisor | O10: Revisão
A11: Propósito da Contagem
A12: Mensurar produtividade do time no projeto [SISTEMA] no mês de MÊS/ANO para SQX - SPT0X (Processo SEI: XXXXX.XXXXX/XXXX-XX)
A16: Escopo da Contagem
A21: Documentação Utilizada na Análise

Sheet Contagem_PF
A1: RELATÓRIO DE DESENVOLVIMENTO
U3: Versão 2.0
A4: ='Info Gerais'!A5&" : "&'Info Gerais'!F5 -> Aplicação : | B4: ='Info Gerais'!A8&" : "&'Info Gerais'!F8 -> Projeto : | M4: PF IFPUG | N4: =SUM(J8:J606) -> 0 | R4: Data da Revisão (FM): | U4: 46108
A5: ='Info Gerais'!A9&" : "&'Info Gerais'!F9 -> Responsável : | B5: ='Info Gerais'!A10&" : "&'Info Gerais'!F10 -> Revisor : | M5: PF Bruto | N5: =SUM(M8:M606) -> 0 | R5: Versão do parecer Técnico: | U5: 2.0
A6: ='Info Gerais'!A4&" : "&'Info Gerais'!F4 -> Empresa : BASIS | B6: ="Tipo da Contagem : "&'Info Gerais'!F6 -> Tipo da Contagem : | M6: PF Deflator FS | N6: =SUM(N8:N606) -> 0
A7: Item | C7: Manutenção | D7: DER | E7: Descrição DER | F7: RLR/ALR | G7: Descrição RLR/ ALR | H7: Complex. | I7: ctl | J7: PF IFPUG | K7: C | L7: ctl2 | M7: PF Bruto | N7: PF Deflator FS | O7: Iteração | P7: Referência do Produto | Q7: Referência do Projeto | R7: Processo SEI | S7: Medição de Referência | T7: Validação da contagem | U7: Justificativa FM
H8: =IF(ISBLANK(B8),"",IF(K8="L","Baixa",IF(K8="A","Média",IF(K8="","","Alta")))) | I8: =CONCATENATE(B8,K8) | J8: =IF(ISBLANK(B8),"",IF(B8="ALI",IF(K8="L",7,IF(K8="A",10,15)),IF(B8="AIE",IF(K8="L",5,IF(K8="A",7,10)),IF(B8="SE",IF(K8="L",4,IF(K8="A",5,7)),IF(OR(B8="EE",B8="CE"),IF(K8="L",3,IF(K8="A",4,6)),0))))) | K8: =IF(OR(ISBLANK(D8),ISBLANK(F8)),IF(OR(B8="ALI",B8="AIE"),"L",IF(OR(B8="EE",B8="SE",B8="CE"),"A","")),IF(B8="EE",IF(F8>=3,IF(D8>=5,"H","A"),IF(F8>=2,IF(D8>=16,"H",IF(D8<=4,"L","A")),IF(D8<=15,"L","A"))),IF(OR(B8="SE",B8="CE"),IF(F8>=4,IF(D8>=6,"H","A"),IF(F8>=2,IF(D8>=20,"H",IF(D8<=5,"L","A")),IF(D8<=19,"L","A"))),IF(OR(B8="ALI",B8="AIE"),IF(F8>=6,IF(D8>=20,"H","A"),IF(F8>=2,IF(D8>=51,"H",IF(D8<=19,"L","A")),IF(D8<=50,"L","A"))),"")))) | L8: =CONCATENATE(B8,C8) | M8: =IF(OR(J8="",J8=0),N8,J8) | N8: =IF(NOT(ISERROR(VLOOKUP(B8,Deflatores!G$42:H$64,2,FALSE))),VLOOKUP(B8,Deflatores!G$42:H$64,2,FALSE),IF(OR(ISBLANK(C8),ISBLANK(B8)),"",VLOOKUP(C8,Deflatores!G$4:H$38,2,FALSE)*J8+VLOOKUP(C8,Deflatores!G$4:I$38,3,FALSE)))
H9: =IF(ISBLANK(B9),"",IF(K9="L","Baixa",IF(K9="A","Média",IF(K9="","","Alta")))) | I9: =CONCATENATE(B9,K9) | J9: =IF(ISBLANK(B9),"",IF(B9="ALI",IF(K9="L",7,IF(K9="A",10,15)),IF(B9="AIE",IF(K9="L",5,IF(K9="A",7,10)),IF(B9="SE",IF(K9="L",4,IF(K9="A",5,7)),IF(OR(B9="EE",B9="CE"),IF(K9="L",3,IF(K9="A",4,6)),0))))) | K9: =IF(OR(ISBLANK(D9),ISBLANK(F9)),IF(OR(B9="ALI",B9="AIE"),"L",IF(OR(B9="EE",B9="SE",B9="CE"),"A","")),IF(B9="EE",IF(F9>=3,IF(D9>=5,"H","A"),IF(F9>=2,IF(D9>=16,"H",IF(D9<=4,"L","A")),IF(D9<=15,"L","A"))),IF(OR(B9="SE",B9="CE"),IF(F9>=4,IF(D9>=6,"H","A"),IF(F9>=2,IF(D9>=20,"H",IF(D9<=5,"L","A")),IF(D9<=19,"L","A"))),IF(OR(B9="ALI",B9="AIE"),IF(F9>=6,IF(D9>=20,"H","A"),IF(F9>=2,IF(D9>=51,"H",IF(D9<=19,"L","A")),IF(D9<=50,"L","A"))),"")))) | L9: =CONCATENATE(B9,C9) | M9: =IF(OR(J9="",J9=0),N9,J9) | N9: =IF(NOT(ISERROR(VLOOKUP(B9,Deflatores!G$42:H$64,2,FALSE))),VLOOKUP(B9,Deflatores!G$42:H$64,2,FALSE),IF(OR(ISBLANK(C9),ISBLANK(B9)),"",VLOOKUP(C9,Deflatores!G$4:H$38,2,FALSE)*J9+VLOOKUP(C9,Deflatores!G$4:I$38,3,FALSE)))
H10: =IF(ISBLANK(B10),"",IF(K10="L","Baixa",IF(K10="A","Média",IF(K10="","","Alta")))) | I10: =CONCATENATE(B10,K10) | J10: =IF(ISBLANK(B10),"",IF(B10="ALI",IF(K10="L",7,IF(K10="A",10,15)),IF(B10="AIE",IF(K10="L",5,IF(K10="A",7,10)),IF(B10="SE",IF(K10="L",4,IF(K10="A",5,7)),IF(OR(B10="EE",B10="CE"),IF(K10="L",3,IF(K10="A",4,6)),0))))) | K10: =IF(OR(ISBLANK(D10),ISBLANK(F10)),IF(OR(B10="ALI",B10="AIE"),"L",IF(OR(B10="EE",B10="SE",B10="CE"),"A","")),IF(B10="EE",IF(F10>=3,IF(D10>=5,"H","A"),IF(F10>=2,IF(D10>=16,"H",IF(D10<=4,"L","A")),IF(D10<=15,"L","A"))),IF(OR(B10="SE",B10="CE"),IF(F10>=4,IF(D10>=6,"H","A"),IF(F10>=2,IF(D10>=20,"H",IF(D10<=5,"L","A")),IF(D10<=19,"L","A"))),IF(OR(B10="ALI",B10="AIE"),IF(F10>=6,IF(D10>=20,"H","A"),IF(F10>=2,IF(D10>=51,"H",IF(D10<=19,"L","A")),IF(D10<=50,"L","A"))),"")))) | L10: =CONCATENATE(B10,C10) | M10: =IF(OR(J10="",J10=0),N10,J10) | N10: =IF(NOT(ISERROR(VLOOKUP(B10,Deflatores!G$42:H$64,2,FALSE))),VLOOKUP(B10,Deflatores!G$42:H$64,2,FALSE),IF(OR(ISBLANK(C10),ISBLANK(B10)),"",VLOOKUP(C10,Deflatores!G$4:H$38,2,FALSE)*J10+VLOOKUP(C10,Deflatores!G$4:I$38,3,FALSE)))
H11: =IF(ISBLANK(B11),"",IF(K11="L","Baixa",IF(K11="A","Média",IF(K11="","","Alta")))) | I11: =CONCATENATE(B11,K11) | J11: =IF(ISBLANK(B11),"",IF(B11="ALI",IF(K11="L",7,IF(K11="A",10,15)),IF(B11="AIE",IF(K11="L",5,IF(K11="A",7,10)),IF(B11="SE",IF(K11="L",4,IF(K11="A",5,7)),IF(OR(B11="EE",B11="CE"),IF(K11="L",3,IF(K11="A",4,6)),0))))) | K11: =IF(OR(ISBLANK(D11),ISBLANK(F11)),IF(OR(B11="ALI",B11="AIE"),"L",IF(OR(B11="EE",B11="SE",B11="CE"),"A","")),IF(B11="EE",IF(F11>=3,IF(D11>=5,"H","A"),IF(F11>=2,IF(D11>=16,"H",IF(D11<=4,"L","A")),IF(D11<=15,"L","A"))),IF(OR(B11="SE",B11="CE"),IF(F11>=4,IF(D11>=6,"H","A"),IF(F11>=2,IF(D11>=20,"H",IF(D11<=5,"L","A")),IF(D11<=19,"L","A"))),IF(OR(B11="ALI",B11="AIE"),IF(F11>=6,IF(D11>=20,"H","A"),IF(F11>=2,IF(D11>=51,"H",IF(D11<=19,"L","A")),IF(D11<=50,"L","A"))),"")))) | L11: =CONCATENATE(B11,C11) | M11: =IF(OR(J11="",J11=0),N11,J11) | N11: =IF(NOT(ISERROR(VLOOKUP(B11,Deflatores!G$42:H$64,2,FALSE))),VLOOKUP(B11,Deflatores!G$42:H$64,2,FALSE),IF(OR(ISBLANK(C11),ISBLANK(B11)),"",VLOOKUP(C11,Deflatores!G$4:H$38,2,FALSE)*J11+VLOOKUP(C11,Deflatores!G$4:I$38,3,FALSE)))
H12: =IF(ISBLANK(B12),"",IF(K12="L","Baixa",IF(K12="A","Média",IF(K12="","","Alta")))) | I12: =CONCATENATE(B12,K12) | J12: =IF(ISBLANK(B12),"",IF(B12="ALI",IF(K12="L",7,IF(K12="A",10,15)),IF(B12="AIE",IF(K12="L",5,IF(K12="A",7,10)),IF(B12="SE",IF(K12="L",4,IF(K12="A",5,7)),IF(OR(B12="EE",B12="CE"),IF(K12="L",3,IF(K12="A",4,6)),0))))) | K12: =IF(OR(ISBLANK(D12),ISBLANK(F12)),IF(OR(B12="ALI",B12="AIE"),"L",IF(OR(B12="EE",B12="SE",B12="CE"),"A","")),IF(B12="EE",IF(F12>=3,IF(D12>=5,"H","A"),IF(F12>=2,IF(D12>=16,"H",IF(D12<=4,"L","A")),IF(D12<=15,"L","A"))),IF(OR(B12="SE",B12="CE"),IF(F12>=4,IF(D12>=6,"H","A"),IF(F12>=2,IF(D12>=20,"H",IF(D12<=5,"L","A")),IF(D12<=19,"L","A"))),IF(OR(B12="ALI",B12="AIE"),IF(F12>=6,IF(D12>=20,"H","A"),IF(F12>=2,IF(D12>=51,"H",IF(D12<=19,"L","A")),IF(D12<=50,"L","A"))),"")))) | L12: =CONCATENATE(B12,C12) | M12: =IF(OR(J12="",J12=0),N12,J12) | N12: =IF(NOT(ISERROR(VLOOKUP(B12,Deflatores!G$42:H$64,2,FALSE))),VLOOKUP(B12,Deflatores!G$42:H$64,2,FALSE),IF(OR(ISBLANK(C12),ISBLANK(B12)),"",VLOOKUP(C12,Deflatores!G$4:H$38,2,FALSE)*J12+VLOOKUP(C12,Deflatores!G$4:I$38,3,FALSE)))
H13: =IF(ISBLANK(B13),"",IF(K13="L","Baixa",IF(K13="A","Média",IF(K13="","","Alta")))) | I13: =CONCATENATE(B13,K13) | J13: =IF(ISBLANK(B13),"",IF(B13="ALI",IF(K13="L",7,IF(K13="A",10,15)),IF(B13="AIE",IF(K13="L",5,IF(K13="A",7,10)),IF(B13="SE",IF(K13="L",4,IF(K13="A",5,7)),IF(OR(B13="EE",B13="CE"),IF(K13="L",3,IF(K13="A",4,6)),0))))) | K13: =IF(OR(ISBLANK(D13),ISBLANK(F13)),IF(OR(B13="ALI",B13="AIE"),"L",IF(OR(B13="EE",B13="SE",B13="CE"),"A","")),IF(B13="EE",IF(F13>=3,IF(D13>=5,"H","A"),IF(F13>=2,IF(D13>=16,"H",IF(D13<=4,"L","A")),IF(D13<=15,"L","A"))),IF(OR(B13="SE",B13="CE"),IF(F13>=4,IF(D13>=6,"H","A"),IF(F13>=2,IF(D13>=20,"H",IF(D13<=5,"L","A")),IF(D13<=19,"L","A"))),IF(OR(B13="ALI",B13="AIE"),IF(F13>=6,IF(D13>=20,"H","A"),IF(F13>=2,IF(D13>=51,"H",IF(D13<=19,"L","A")),IF(D13<=50,"L","A"))),"")))) | L13: =CONCATENATE(B13,C13) | M13: =IF(OR(J13="",J13=0),N13,J13) | N13: =IF(NOT(ISERROR(VLOOKUP(B13,Deflatores!G$42:H$64,2,FALSE))),VLOOKUP(B13,Deflatores!G$42:H$64,2,FALSE),IF(OR(ISBLANK(C13),ISBLANK(B13)),"",VLOOKUP(C13,Deflatores!G$4:H$38,2,FALSE)*J13+VLOOKUP(C13,Deflatores!G$4:I$38,3,FALSE)))
H14: =IF(ISBLANK(B14),"",IF(K14="L","Baixa",IF(K14="A","Média",IF(K14="","","Alta")))) | I14: =CONCATENATE(B14,K14) | J14: =IF(ISBLANK(B14),"",IF(B14="ALI",IF(K14="L",7,IF(K14="A",10,15)),IF(B14="AIE",IF(K14="L",5,IF(K14="A",7,10)),IF(B14="SE",IF(K14="L",4,IF(K14="A",5,7)),IF(OR(B14="EE",B14="CE"),IF(K14="L",3,IF(K14="A",4,6)),0))))) | K14: =IF(OR(ISBLANK(D14),ISBLANK(F14)),IF(OR(B14="ALI",B14="AIE"),"L",IF(OR(B14="EE",B14="SE",B14="CE"),"A","")),IF(B14="EE",IF(F14>=3,IF(D14>=5,"H","A"),IF(F14>=2,IF(D14>=16,"H",IF(D14<=4,"L","A")),IF(D14<=15,"L","A"))),IF(OR(B14="SE",B14="CE"),IF(F14>=4,IF(D14>=6,"H","A"),IF(F14>=2,IF(D14>=20,"H",IF(D14<=5,"L","A")),IF(D14<=19,"L","A"))),IF(OR(B14="ALI",B14="AIE"),IF(F14>=6,IF(D14>=20,"H","A"),IF(F14>=2,IF(D14>=51,"H",IF(D14<=19,"L","A")),IF(D14<=50,"L","A"))),"")))) | L14: =CONCATENATE(B14,C14) | M14: =IF(OR(J14="",J14=0),N14,J14) | N14: =IF(NOT(ISERROR(VLOOKUP(B14,Deflatores!G$42:H$64,2,FALSE))),VLOOKUP(B14,Deflatores!G$42:H$64,2,FALSE),IF(OR(ISBLANK(C14),ISBLANK(B14)),"",VLOOKUP(C14,Deflatores!G$4:H$38,2,FALSE)*J14+VLOOKUP(C14,Deflatores!G$4:I$38,3,FALSE)))
H15: =IF(ISBLANK(B15),"",IF(K15="L","Baixa",IF(K15="A","Média",IF(K15="","","Alta")))) | I15: =CONCATENATE(B15,K15) | J15: =IF(ISBLANK(B15),"",IF(B15="ALI",IF(K15="L",7,IF(K15="A",10,15)),IF(B15="AIE",IF(K15="L",5,IF(K15="A",7,10)),IF(B15="SE",IF(K15="L",4,IF(K15="A",5,7)),IF(OR(B15="EE",B15="CE"),IF(K15="L",3,IF(K15="A",4,6)),0))))) | K15: =IF(OR(ISBLANK(D15),ISBLANK(F15)),IF(OR(B15="ALI",B15="AIE"),"L",IF(OR(B15="EE",B15="SE",B15="CE"),"A","")),IF(B15="EE",IF(F15>=3,IF(D15>=5,"H","A"),IF(F15>=2,IF(D15>=16,"H",IF(D15<=4,"L","A")),IF(D15<=15,"L","A"))),IF(OR(B15="SE",B15="CE"),IF(F15>=4,IF(D15>=6,"H","A"),IF(F15>=2,IF(D15>=20,"H",IF(D15<=5,"L","A")),IF(D15<=19,"L","A"))),IF(OR(B15="ALI",B15="AIE"),IF(F15>=6,IF(D15>=20,"H","A"),IF(F15>=2,IF(D15>=51,"H",IF(D15<=19,"L","A")),IF(D15<=50,"L","A"))),"")))) | L15: =CONCATENATE(B15,C15) | M15: =IF(OR(J15="",J15=0),N15,J15) | N15: =IF(NOT(ISERROR(VLOOKUP(B15,Deflatores!G$42:H$64,2,FALSE))),VLOOKUP(B15,Deflatores!G$42:H$64,2,FALSE),IF(OR(ISBLANK(C15),ISBLANK(B15)),"",VLOOKUP(C15,Deflatores!G$4:H$38,2,FALSE)*J15+VLOOKUP(C15,Deflatores!G$4:I$38,3,FALSE)))
H16: =IF(ISBLANK(B16),"",IF(K16="L","Baixa",IF(K16="A","Média",IF(K16="","","Alta")))) | I16: =CONCATENATE(B16,K16) | J16: =IF(ISBLANK(B16),"",IF(B16="ALI",IF(K16="L",7,IF(K16="A",10,15)),IF(B16="AIE",IF(K16="L",5,IF(K16="A",7,10)),IF(B16="SE",IF(K16="L",4,IF(K16="A",5,7)),IF(OR(B16="EE",B16="CE"),IF(K16="L",3,IF(K16="A",4,6)),0))))) | K16: =IF(OR(ISBLANK(D16),ISBLANK(F16)),IF(OR(B16="ALI",B16="AIE"),"L",IF(OR(B16="EE",B16="SE",B16="CE"),"A","")),IF(B16="EE",IF(F16>=3,IF(D16>=5,"H","A"),IF(F16>=2,IF(D16>=16,"H",IF(D16<=4,"L","A")),IF(D16<=15,"L","A"))),IF(OR(B16="SE",B16="CE"),IF(F16>=4,IF(D16>=6,"H","A"),IF(F16>=2,IF(D16>=20,"H",IF(D16<=5,"L","A")),IF(D16<=19,"L","A"))),IF(OR(B16="ALI",B16="AIE"),IF(F16>=6,IF(D16>=20,"H","A"),IF(F16>=2,IF(D16>=51,"H",IF(D16<=19,"L","A")),IF(D16<=50,"L","A"))),"")))) | L16: =CONCATENATE(B16,C16) | M16: =IF(OR(J16="",J16=0),N16,J16) | N16: =IF(NOT(ISERROR(VLOOKUP(B16,Deflatores!G$42:H$64,2,FALSE))),VLOOKUP(B16,Deflatores!G$42:H$64,2,FALSE),IF(OR(ISBLANK(C16),ISBLANK(B16)),"",VLOOKUP(C16,Deflatores!G$4:H$38,2,FALSE)*J16+VLOOKUP(C16,Deflatores!G$4:I$38,3,FALSE)))
H17: =IF(ISBLANK(B17),"",IF(K17="L","Baixa",IF(K17="A","Média",IF(K17="","","Alta")))) | I17: =CONCATENATE(B17,K17) | J17: =IF(ISBLANK(B17),"",IF(B17="ALI",IF(K17="L",7,IF(K17="A",10,15)),IF(B17="AIE",IF(K17="L",5,IF(K17="A",7,10)),IF(B17="SE",IF(K17="L",4,IF(K17="A",5,7)),IF(OR(B17="EE",B17="CE"),IF(K17="L",3,IF(K17="A",4,6)),0))))) | K17: =IF(OR(ISBLANK(D17),ISBLANK(F17)),IF(OR(B17="ALI",B17="AIE"),"L",IF(OR(B17="EE",B17="SE",B17="CE"),"A","")),IF(B17="EE",IF(F17>=3,IF(D17>=5,"H","A"),IF(F17>=2,IF(D17>=16,"H",IF(D17<=4,"L","A")),IF(D17<=15,"L","A"))),IF(OR(B17="SE",B17="CE"),IF(F17>=4,IF(D17>=6,"H","A"),IF(F17>=2,IF(D17>=20,"H",IF(D17<=5,"L","A")),IF(D17<=19,"L","A"))),IF(OR(B17="ALI",B17="AIE"),IF(F17>=6,IF(D17>=20,"H","A"),IF(F17>=2,IF(D17>=51,"H",IF(D17<=19,"L","A")),IF(D17<=50,"L","A"))),"")))) | L17: =CONCATENATE(B17,C17) | M17: =IF(OR(J17="",J17=0),N17,J17) | N17: =IF(NOT(ISERROR(VLOOKUP(B17,Deflatores!G$42:H$64,2,FALSE))),VLOOKUP(B17,Deflatores!G$42:H$64,2,FALSE),IF(OR(ISBLANK(C17),ISBLANK(B17)),"",VLOOKUP(C17,Deflatores!G$4:H$38,2,FALSE)*J17+VLOOKUP(C17,Deflatores!G$4:I$38,3,FALSE)))
H18: =IF(ISBLANK(B18),"",IF(K18="L","Baixa",IF(K18="A","Média",IF(K18="","","Alta")))) | I18: =CONCATENATE(B18,K18) | J18: =IF(ISBLANK(B18),"",IF(B18="ALI",IF(K18="L",7,IF(K18="A",10,15)),IF(B18="AIE",IF(K18="L",5,IF(K18="A",7,10)),IF(B18="SE",IF(K18="L",4,IF(K18="A",5,7)),IF(OR(B18="EE",B18="CE"),IF(K18="L",3,IF(K18="A",4,6)),0))))) | K18: =IF(OR(ISBLANK(D18),ISBLANK(F18)),IF(OR(B18="ALI",B18="AIE"),"L",IF(OR(B18="EE",B18="SE",B18="CE"),"A","")),IF(B18="EE",IF(F18>=3,IF(D18>=5,"H","A"),IF(F18>=2,IF(D18>=16,"H",IF(D18<=4,"L","A")),IF(D18<=15,"L","A"))),IF(OR(B18="SE",B18="CE"),IF(F18>=4,IF(D18>=6,"H","A"),IF(F18>=2,IF(D18>=20,"H",IF(D18<=5,"L","A")),IF(D18<=19,"L","A"))),IF(OR(B18="ALI",B18="AIE"),IF(F18>=6,IF(D18>=20,"H","A"),IF(F18>=2,IF(D18>=51,"H",IF(D18<=19,"L","A")),IF(D18<=50,"L","A"))),"")))) | L18: =CONCATENATE(B18,C18) | M18: =IF(OR(J18="",J18=0),N18,J18) | N18: =IF(NOT(ISERROR(VLOOKUP(B18,Deflatores!G$42:H$64,2,FALSE))),VLOOKUP(B18,Deflatores!G$42:H$64,2,FALSE),IF(OR(ISBLANK(C18),ISBLANK(B18)),"",VLOOKUP(C18,Deflatores!G$4:H$38,2,FALSE)*J18+VLOOKUP(C18,Deflatores!G$4:I$38,3,FALSE)))
H19: =IF(ISBLANK(B19),"",IF(K19="L","Baixa",IF(K19="A","Média",IF(K19="","","Alta")))) | I19: =CONCATENATE(B19,K19) | J19: =IF(ISBLANK(B19),"",IF(B19="ALI",IF(K19="L",7,IF(K19="A",10,15)),IF(B19="AIE",IF(K19="L",5,IF(K19="A",7,10)),IF(B19="SE",IF(K19="L",4,IF(K19="A",5,7)),IF(OR(B19="EE",B19="CE"),IF(K19="L",3,IF(K19="A",4,6)),0))))) | K19: =IF(OR(ISBLANK(D19),ISBLANK(F19)),IF(OR(B19="ALI",B19="AIE"),"L",IF(OR(B19="EE",B19="SE",B19="CE"),"A","")),IF(B19="EE",IF(F19>=3,IF(D19>=5,"H","A"),IF(F19>=2,IF(D19>=16,"H",IF(D19<=4,"L","A")),IF(D19<=15,"L","A"))),IF(OR(B19="SE",B19="CE"),IF(F19>=4,IF(D19>=6,"H","A"),IF(F19>=2,IF(D19>=20,"H",IF(D19<=5,"L","A")),IF(D19<=19,"L","A"))),IF(OR(B19="ALI",B19="AIE"),IF(F19>=6,IF(D19>=20,"H","A"),IF(F19>=2,IF(D19>=51,"H",IF(D19<=19,"L","A")),IF(D19<=50,"L","A"))),"")))) | L19: =CONCATENATE(B19,C19) | M19: =IF(OR(J19="",J19=0),N19,J19) | N19: =IF(NOT(ISERROR(VLOOKUP(B19,Deflatores!G$42:H$64,2,FALSE))),VLOOKUP(B19,Deflatores!G$42:H$64,2,FALSE),IF(OR(ISBLANK(C19),ISBLANK(B19)),"",VLOOKUP(C19,Deflatores!G$4:H$38,2,FALSE)*J19+VLOOKUP(C19,Deflatores!G$4:I$38,3,FALSE)))
... H606: =IF(ISBLANK(B606),"",IF(K606="L","Baixa",IF(K606="A","Média",IF(K606="","","Alta")))) | I606: =CONCATENATE(B606,K606) | J606: =IF(ISBLANK(B606),"",IF(B606="ALI",IF(K606="L",7,IF(K606="A",10,15)),IF(B606="AIE",IF(K606="L",5,IF(K606="A",7,10)),IF(B606="SE",IF(K606="L",4,IF(K606="A",5,7)),IF(OR(B606="EE",B606="CE"),IF(K606="L",3,IF(K606="A",4,6)),0))))) | K606: =IF(OR(ISBLANK(D606),ISBLANK(F606)),IF(OR(B606="ALI",B606="AIE"),"L",IF(OR(B606="EE",B606="SE",B606="CE"),"A","")),IF(B606="EE",IF(F606>=3,IF(D606>=5,"H","A"),IF(F606>=2,IF(D606>=16,"H",IF(D606<=4,"L","A")),IF(D606<=15,"L","A"))),IF(OR(B606="SE",B606="CE"),IF(F606>=4,IF(D606>=6,"H","A"),IF(F606>=2,IF(D606>=20,"H",IF(D606<=5,"L","A")),IF(D606<=19,"L","A"))),IF(OR(B606="ALI",B606="AIE"),IF(F606>=6,IF(D606>=20,"H","A"),IF(F606>=2,IF(D606>=51,"H",IF(D606<=19,"L","A")),IF(D606<=50,"L","A"))),"")))) | L606: =CONCATENATE(B606,C606) | M606: =IF(OR(J606="",J606=0),N606,J606) | N606: =IF(NOT(ISERROR(VLOOKUP(B606,Deflatores!G$42:H$64,2,FALSE))),VLOOKUP(B606,Deflatores!G$42:H$64,2,FALSE),IF(OR(ISBLANK(C606),ISBLANK(B606)),"",VLOOKUP(C606,Deflatores!G$4:H$38,2,FALSE)*J606+VLOOKUP(C606,Deflatores!G$4:I$38,3,FALSE)))

Sheet Relatório de Divergências FSW
B1: RELATÓRIO DE DESENVOLVIMENTO
U3: Versão 2.0
A4: ='Info Gerais'!A5&" : "&'Info Gerais'!F5 -> Aplicação : | C4: ='Info Gerais'!A8&" : "&'Info Gerais'!F8 -> Projeto : | N4: PF IFPUG | O4: =SUM(K8:K606) -> 0 | S4: Data da Revisão (FM): | U4: 46108
A5: ='Info Gerais'!A9&" : "&'Info Gerais'!F9 -> Responsável : | C5: ='Info Gerais'!A10&" : "&'Info Gerais'!F10 -> Revisor : | N5: PF Bruto | O5: =SUM(N8:N606) -> 0 | S5: Versão do parecer Técnico: | U5: 3.0
A6: ='Info Gerais'!A4&" : "&'Info Gerais'!F4 -> Empresa : BASIS | C6: ="Tipo da Contagem : "&'Info Gerais'!F6 -> Tipo da Contagem : | N6: PF Deflator FS | O6: =SUM(O8:O55) -> 0
A7: Validação da contagem | B7: Processo Elementar | C7: Tipo da Contagem | D7: Manutenção | E7: DER | F7: Descrição DER | G7: RLR/ALR | H7: Descrição RLR/ ALR | I7: Complex. | J7: ctl | K7: PF IFPUG | L7: ctl | M7: C | N7: PF Bruto | O7: PF Deflator FS | P7: Iteração | Q7: Parecer Técnico Fábrica de Métricas (FM) | R7: Defesa Fábrica de Software (FSW) | S7: Parecer Técnico (RESPOSTA) Fábrica de Métricas (FM) | T7: Parecer Técnico (FINAL) Fábrica de Métricas (FM) | U7: Parecer Final (FM)
I8: =IF(ISBLANK(C8),"",IF(L8="L","Baixa",IF(L8="A","Média",IF(L8="","","Alta")))) | J8: =CONCATENATE(C8,L8) | K8: =IF(ISBLANK(C8),"",IF(C8="ALI",IF(L8="L",7,IF(L8="A",10,15)),IF(C8="AIE",IF(L8="L",5,IF(L8="A",7,10)),IF(C8="SE",IF(L8="L",4,IF(L8="A",5,7)),IF(OR(C8="EE",C8="CE"),IF(L8="L",3,IF(L8="A",4,6)),0))))) | L8: =IF(OR(ISBLANK(E8),ISBLANK(G8)),IF(OR(C8="ALI",C8="AIE"),"L",IF(OR(C8="EE",C8="SE",C8="CE"),"A","")),IF(C8="EE",IF(G8>=3,IF(E8>=5,"H","A"),IF(G8>=2,IF(E8>=16,"H",IF(E8<=4,"L","A")),IF(E8<=15,"L","A"))),IF(OR(C8="SE",C8="CE"),IF(G8>=4,IF(E8>=6,"H","A"),IF(G8>=2,IF(E8>=20,"H",IF(E8<=5,"L","A")),IF(E8<=19,"L","A"))),IF(OR(C8="ALI",C8="AIE"),IF(G8>=6,IF(E8>=20,"H","A"),IF(G8>=2,IF(E8>=51,"H",IF(E8<=19,"L","A")),IF(E8<=50,"L","A"))),"")))) | M8: =CONCATENATE(C8,D8) | N8: =IF(OR(K8="",K8=0),O8,K8) | O8: =IF(NOT(ISERROR(VLOOKUP(C8,Deflatores!G$42:H$64,2,FALSE))),VLOOKUP(C8,Deflatores!G$42:H$64,2,FALSE),IF(OR(ISBLANK(D8),ISBLANK(C8)),"",VLOOKUP(D8,Deflatores!G$4:H$38,2,FALSE)*K8+VLOOKUP(D8,Deflatores!G$4:I$38,3,FALSE)))
I9: =IF(ISBLANK(C9),"",IF(L9="L","Baixa",IF(L9="A","Média",IF(L9="","","Alta")))) | J9: =CONCATENATE(C9,L9) | K9: =IF(ISBLANK(C9),"",IF(C9="ALI",IF(L9="L",7,IF(L9="A",10,15)),IF(C9="AIE",IF(L9="L",5,IF(L9="A",7,10)),IF(C9="SE",IF(L9="L",4,IF(L9="A",5,7)),IF(OR(C9="EE",C9="CE"),IF(L9="L",3,IF(L9="A",4,6)),0))))) | L9: =IF(OR(ISBLANK(E9),ISBLANK(G9)),IF(OR(C9="ALI",C9="AIE"),"L",IF(OR(C9="EE",C9="SE",C9="CE"),"A","")),IF(C9="EE",IF(G9>=3,IF(E9>=5,"H","A"),IF(G9>=2,IF(E9>=16,"H",IF(E9<=4,"L","A")),IF(E9<=15,"L","A"))),IF(OR(C9="SE",C9="CE"),IF(G9>=4,IF(E9>=6,"H","A"),IF(G9>=2,IF(E9>=20,"H",IF(E9<=5,"L","A")),IF(E9<=19,"L","A"))),IF(OR(C9="ALI",C9="AIE"),IF(G9>=6,IF(E9>=20,"H","A"),IF(G9>=2,IF(E9>=51,"H",IF(E9<=19,"L","A")),IF(E9<=50,"L","A"))),"")))) | M9: =CONCATENATE(C9,D9) | N9: =IF(OR(K9="",K9=0),O9,K9) | O9: =IF(NOT(ISERROR(VLOOKUP(C9,Deflatores!G$42:H$64,2,FALSE))),VLOOKUP(C9,Deflatores!G$42:H$64,2,FALSE),IF(OR(ISBLANK(D9),ISBLANK(C9)),"",VLOOKUP(D9,Deflatores!G$4:H$38,2,FALSE)*K9+VLOOKUP(D9,Deflatores!G$4:I$38,3,FALSE)))
I10: =IF(ISBLANK(C10),"",IF(L10="L","Baixa",IF(L10="A","Média",IF(L10="","","Alta")))) | J10: =CONCATENATE(C10,L10) | K10: =IF(ISBLANK(C10),"",IF(C10="ALI",IF(L10="L",7,IF(L10="A",10,15)),IF(C10="AIE",IF(L10="L",5,IF(L10="A",7,10)),IF(C10="SE",IF(L10="L",4,IF(L10="A",5,7)),IF(OR(C10="EE",C10="CE"),IF(L10="L",3,IF(L10="A",4,6)),0))))) | L10: =IF(OR(ISBLANK(E10),ISBLANK(G10)),IF(OR(C10="ALI",C10="AIE"),"L",IF(OR(C10="EE",C10="SE",C10="CE"),"A","")),IF(C10="EE",IF(G10>=3,IF(E10>=5,"H","A"),IF(G10>=2,IF(E10>=16,"H",IF(E10<=4,"L","A")),IF(E10<=15,"L","A"))),IF(OR(C10="SE",C10="CE"),IF(G10>=4,IF(E10>=6,"H","A"),IF(G10>=2,IF(E10>=20,"H",IF(E10<=5,"L","A")),IF(E10<=19,"L","A"))),IF(OR(C10="ALI",C10="AIE"),IF(G10>=6,IF(E10>=20,"H","A"),IF(G10>=2,IF(E10>=51,"H",IF(E10<=19,"L","A")),IF(E10<=50,"L","A"))),"")))) | M10: =CONCATENATE(C10,D10) | N10: =IF(OR(K10="",K10=0),O10,K10) | O10: =IF(NOT(ISERROR(VLOOKUP(C10,Deflatores!G$42:H$64,2,FALSE))),VLOOKUP(C10,Deflatores!G$42:H$64,2,FALSE),IF(OR(ISBLANK(D10),ISBLANK(C10)),"",VLOOKUP(D10,Deflatores!G$4:H$38,2,FALSE)*K10+VLOOKUP(D10,Deflatores!G$4:I$38,3,FALSE)))
I11: =IF(ISBLANK(C11),"",IF(L11="L","Baixa",IF(L11="A","Média",IF(L11="","","Alta")))) | J11: =CONCATENATE(C11,L11) | K11: =IF(ISBLANK(C11),"",IF(C11="ALI",IF(L11="L",7,IF(L11="A",10,15)),IF(C11="AIE",IF(L11="L",5,IF(L11="A",7,10)),IF(C11="SE",IF(L11="L",4,IF(L11="A",5,7)),IF(OR(C11="EE",C11="CE"),IF(L11="L",3,IF(L11="A",4,6)),0))))) | L11: =IF(OR(ISBLANK(E11),ISBLANK(G11)),IF(OR(C11="ALI",C11="AIE"),"L",IF(OR(C11="EE",C11="SE",C11="CE"),"A","")),IF(C11="EE",IF(G11>=3,IF(E11>=5,"H","A"),IF(G11>=2,IF(E11>=16,"H",IF(E11<=4,"L","A")),IF(E11<=15,"L","A"))),IF(OR(C11="SE",C11="CE"),IF(G11>=4,IF(E11>=6,"H","A"),IF(G11>=2,IF(E11>=20,"H",IF(E11<=5,"L","A")),IF(E11<=19,"L","A"))),IF(OR(C11="ALI",C11="AIE"),IF(G11>=6,IF(E11>=20,"H","A"),IF(G11>=2,IF(E11>=51,"H",IF(E11<=19,"L","A")),IF(E11<=50,"L","A"))),"")))) | M11: =CONCATENATE(C11,D11) | N11: =IF(OR(K11="",K11=0),O11,K11) | O11: =IF(NOT(ISERROR(VLOOKUP(C11,Deflatores!G$42:H$64,2,FALSE))),VLOOKUP(C11,Deflatores!G$42:H$64,2,FALSE),IF(OR(ISBLANK(D11),ISBLANK(C11)),"",VLOOKUP(D11,Deflatores!G$4:H$38,2,FALSE)*K11+VLOOKUP(D11,Deflatores!G$4:I$38,3,FALSE)))
I12: =IF(ISBLANK(C12),"",IF(L12="L","Baixa",IF(L12="A","Média",IF(L12="","","Alta")))) | J12: =CONCATENATE(C12,L12) | K12: =IF(ISBLANK(C12),"",IF(C12="ALI",IF(L12="L",7,IF(L12="A",10,15)),IF(C12="AIE",IF(L12="L",5,IF(L12="A",7,10)),IF(C12="SE",IF(L12="L",4,IF(L12="A",5,7)),IF(OR(C12="EE",C12="CE"),IF(L12="L",3,IF(L12="A",4,6)),0))))) | L12: =IF(OR(ISBLANK(E12),ISBLANK(G12)),IF(OR(C12="ALI",C12="AIE"),"L",IF(OR(C12="EE",C12="SE",C12="CE"),"A","")),IF(C12="EE",IF(G12>=3,IF(E12>=5,"H","A"),IF(G12>=2,IF(E12>=16,"H",IF(E12<=4,"L","A")),IF(E12<=15,"L","A"))),IF(OR(C12="SE",C12="CE"),IF(G12>=4,IF(E12>=6,"H","A"),IF(G12>=2,IF(E12>=20,"H",IF(E12<=5,"L","A")),IF(E12<=19,"L","A"))),IF(OR(C12="ALI",C12="AIE"),IF(G12>=6,IF(E12>=20,"H","A"),IF(G12>=2,IF(E12>=51,"H",IF(E12<=19,"L","A")),IF(E12<=50,"L","A"))),"")))) | M12: =CONCATENATE(C12,D12) | N12: =IF(OR(K12="",K12=0),O12,K12) | O12: =IF(NOT(ISERROR(VLOOKUP(C12,Deflatores!G$42:H$64,2,FALSE))),VLOOKUP(C12,Deflatores!G$42:H$64,2,FALSE),IF(OR(ISBLANK(D12),ISBLANK(C12)),"",VLOOKUP(D12,Deflatores!G$4:H$38,2,FALSE)*K12+VLOOKUP(D12,Deflatores!G$4:I$38,3,FALSE)))
I13: =IF(ISBLANK(C13),"",IF(L13="L","Baixa",IF(L13="A","Média",IF(L13="","","Alta")))) | J13: =CONCATENATE(C13,L13) | K13: =IF(ISBLANK(C13),"",IF(C13="ALI",IF(L13="L",7,IF(L13="A",10,15)),IF(C13="AIE",IF(L13="L",5,IF(L13="A",7,10)),IF(C13="SE",IF(L13="L",4,IF(L13="A",5,7)),IF(OR(C13="EE",C13="CE"),IF(L13="L",3,IF(L13="A",4,6)),0))))) | L13: =IF(OR(ISBLANK(E13),ISBLANK(G13)),IF(OR(C13="ALI",C13="AIE"),"L",IF(OR(C13="EE",C13="SE",C13="CE"),"A","")),IF(C13="EE",IF(G13>=3,IF(E13>=5,"H","A"),IF(G13>=2,IF(E13>=16,"H",IF(E13<=4,"L","A")),IF(E13<=15,"L","A"))),IF(OR(C13="SE",C13="CE"),IF(G13>=4,IF(E13>=6,"H","A"),IF(G13>=2,IF(E13>=20,"H",IF(E13<=5,"L","A")),IF(E13<=19,"L","A"))),IF(OR(C13="ALI",C13="AIE"),IF(G13>=6,IF(E13>=20,"H","A"),IF(G13>=2,IF(E13>=51,"H",IF(E13<=19,"L","A")),IF(E13<=50,"L","A"))),"")))) | M13: =CONCATENATE(C13,D13) | N13: =IF(OR(K13="",K13=0),O13,K13) | O13: =IF(NOT(ISERROR(VLOOKUP(C13,Deflatores!G$42:H$64,2,FALSE))),VLOOKUP(C13,Deflatores!G$42:H$64,2,FALSE),IF(OR(ISBLANK(D13),ISBLANK(C13)),"",VLOOKUP(D13,Deflatores!G$4:H$38,2,FALSE)*K13+VLOOKUP(D13,Deflatores!G$4:I$38,3,FALSE)))
I14: =IF(ISBLANK(C14),"",IF(L14="L","Baixa",IF(L14="A","Média",IF(L14="","","Alta")))) | J14: =CONCATENATE(C14,L14) | K14: =IF(ISBLANK(C14),"",IF(C14="ALI",IF(L14="L",7,IF(L14="A",10,15)),IF(C14="AIE",IF(L14="L",5,IF(L14="A",7,10)),IF(C14="SE",IF(L14="L",4,IF(L14="A",5,7)),IF(OR(C14="EE",C14="CE"),IF(L14="L",3,IF(L14="A",4,6)),0))))) | L14: =IF(OR(ISBLANK(E14),ISBLANK(G14)),IF(OR(C14="ALI",C14="AIE"),"L",IF(OR(C14="EE",C14="SE",C14="CE"),"A","")),IF(C14="EE",IF(G14>=3,IF(E14>=5,"H","A"),IF(G14>=2,IF(E14>=16,"H",IF(E14<=4,"L","A")),IF(E14<=15,"L","A"))),IF(OR(C14="SE",C14="CE"),IF(G14>=4,IF(E14>=6,"H","A"),IF(G14>=2,IF(E14>=20,"H",IF(E14<=5,"L","A")),IF(E14<=19,"L","A"))),IF(OR(C14="ALI",C14="AIE"),IF(G14>=6,IF(E14>=20,"H","A"),IF(G14>=2,IF(E14>=51,"H",IF(E14<=19,"L","A")),IF(E14<=50,"L","A"))),"")))) | M14: =CONCATENATE(C14,D14) | N14: =IF(OR(K14="",K14=0),O14,K14) | O14: =IF(NOT(ISERROR(VLOOKUP(C14,Deflatores!G$42:H$64,2,FALSE))),VLOOKUP(C14,Deflatores!G$42:H$64,2,FALSE),IF(OR(ISBLANK(D14),ISBLANK(C14)),"",VLOOKUP(D14,Deflatores!G$4:H$38,2,FALSE)*K14+VLOOKUP(D14,Deflatores!G$4:I$38,3,FALSE)))
I15: =IF(ISBLANK(C15),"",IF(L15="L","Baixa",IF(L15="A","Média",IF(L15="","","Alta")))) | J15: =CONCATENATE(C15,L15) | K15: =IF(ISBLANK(C15),"",IF(C15="ALI",IF(L15="L",7,IF(L15="A",10,15)),IF(C15="AIE",IF(L15="L",5,IF(L15="A",7,10)),IF(C15="SE",IF(L15="L",4,IF(L15="A",5,7)),IF(OR(C15="EE",C15="CE"),IF(L15="L",3,IF(L15="A",4,6)),0))))) | L15: =IF(OR(ISBLANK(E15),ISBLANK(G15)),IF(OR(C15="ALI",C15="AIE"),"L",IF(OR(C15="EE",C15="SE",C15="CE"),"A","")),IF(C15="EE",IF(G15>=3,IF(E15>=5,"H","A"),IF(G15>=2,IF(E15>=16,"H",IF(E15<=4,"L","A")),IF(E15<=15,"L","A"))),IF(OR(C15="SE",C15="CE"),IF(G15>=4,IF(E15>=6,"H","A"),IF(G15>=2,IF(E15>=20,"H",IF(E15<=5,"L","A")),IF(E15<=19,"L","A"))),IF(OR(C15="ALI",C15="AIE"),IF(G15>=6,IF(E15>=20,"H","A"),IF(G15>=2,IF(E15>=51,"H",IF(E15<=19,"L","A")),IF(E15<=50,"L","A"))),"")))) | M15: =CONCATENATE(C15,D15) | N15: =IF(OR(K15="",K15=0),O15,K15) | O15: =IF(NOT(ISERROR(VLOOKUP(C15,Deflatores!G$42:H$64,2,FALSE))),VLOOKUP(C15,Deflatores!G$42:H$64,2,FALSE),IF(OR(ISBLANK(D15),ISBLANK(C15)),"",VLOOKUP(D15,Deflatores!G$4:H$38,2,FALSE)*K15+VLOOKUP(D15,Deflatores!G$4:I$38,3,FALSE)))
I16: =IF(ISBLANK(C16),"",IF(L16="L","Baixa",IF(L16="A","Média",IF(L16="","","Alta")))) | J16: =CONCATENATE(C16,L16) | K16: =IF(ISBLANK(C16),"",IF(C16="ALI",IF(L16="L",7,IF(L16="A",10,15)),IF(C16="AIE",IF(L16="L",5,IF(L16="A",7,10)),IF(C16="SE",IF(L16="L",4,IF(L16="A",5,7)),IF(OR(C16="EE",C16="CE"),IF(L16="L",3,IF(L16="A",4,6)),0))))) | L16: =IF(OR(ISBLANK(E16),ISBLANK(G16)),IF(OR(C16="ALI",C16="AIE"),"L",IF(OR(C16="EE",C16="SE",C16="CE"),"A","")),IF(C16="EE",IF(G16>=3,IF(E16>=5,"H","A"),IF(G16>=2,IF(E16>=16,"H",IF(E16<=4,"L","A")),IF(E16<=15,"L","A"))),IF(OR(C16="SE",C16="CE"),IF(G16>=4,IF(E16>=6,"H","A"),IF(G16>=2,IF(E16>=20,"H",IF(E16<=5,"L","A")),IF(E16<=19,"L","A"))),IF(OR(C16="ALI",C16="AIE"),IF(G16>=6,IF(E16>=20,"H","A"),IF(G16>=2,IF(E16>=51,"H",IF(E16<=19,"L","A")),IF(E16<=50,"L","A"))),"")))) | M16: =CONCATENATE(C16,D16) | N16: =IF(OR(K16="",K16=0),O16,K16) | O16: =IF(NOT(ISERROR(VLOOKUP(C16,Deflatores!G$42:H$64,2,FALSE))),VLOOKUP(C16,Deflatores!G$42:H$64,2,FALSE),IF(OR(ISBLANK(D16),ISBLANK(C16)),"",VLOOKUP(D16,Deflatores!G$4:H$38,2,FALSE)*K16+VLOOKUP(D16,Deflatores!G$4:I$38,3,FALSE)))
I17: =IF(ISBLANK(C17),"",IF(L17="L","Baixa",IF(L17="A","Média",IF(L17="","","Alta")))) | J17: =CONCATENATE(C17,L17) | K17: =IF(ISBLANK(C17),"",IF(C17="ALI",IF(L17="L",7,IF(L17="A",10,15)),IF(C17="AIE",IF(L17="L",5,IF(L17="A",7,10)),IF(C17="SE",IF(L17="L",4,IF(L17="A",5,7)),IF(OR(C17="EE",C17="CE"),IF(L17="L",3,IF(L17="A",4,6)),0))))) | L17: =IF(OR(ISBLANK(E17),ISBLANK(G17)),IF(OR(C17="ALI",C17="AIE"),"L",IF(OR(C17="EE",C17="SE",C17="CE"),"A","")),IF(C17="EE",IF(G17>=3,IF(E17>=5,"H","A"),IF(G17>=2,IF(E17>=16,"H",IF(E17<=4,"L","A")),IF(E17<=15,"L","A"))),IF(OR(C17="SE",C17="CE"),IF(G17>=4,IF(E17>=6,"H","A"),IF(G17>=2,IF(E17>=20,"H",IF(E17<=5,"L","A")),IF(E17<=19,"L","A"))),IF(OR(C17="ALI",C17="AIE"),IF(G17>=6,IF(E17>=20,"H","A"),IF(G17>=2,IF(E17>=51,"H",IF(E17<=19,"L","A")),IF(E17<=50,"L","A"))),"")))) | M17: =CONCATENATE(C17,D17) | N17: =IF(OR(K17="",K17=0),O17,K17) | O17: =IF(NOT(ISERROR(VLOOKUP(C17,Deflatores!G$42:H$64,2,FALSE))),VLOOKUP(C17,Deflatores!G$42:H$64,2,FALSE),IF(OR(ISBLANK(D17),ISBLANK(C17)),"",VLOOKUP(D17,Deflatores!G$4:H$38,2,FALSE)*K17+VLOOKUP(D17,Deflatores!G$4:I$38,3,FALSE)))
I18: =IF(ISBLANK(C18),"",IF(L18="L","Baixa",IF(L18="A","Média",IF(L18="","","Alta")))) | J18: =CONCATENATE(C18,L18) | K18: =IF(ISBLANK(C18),"",IF(C18="ALI",IF(L18="L",7,IF(L18="A",10,15)),IF(C18="AIE",IF(L18="L",5,IF(L18="A",7,10)),IF(C18="SE",IF(L18="L",4,IF(L18="A",5,7)),IF(OR(C18="EE",C18="CE"),IF(L18="L",3,IF(L18="A",4,6)),0))))) | L18: =IF(OR(ISBLANK(E18),ISBLANK(G18)),IF(OR(C18="ALI",C18="AIE"),"L",IF(OR(C18="EE",C18="SE",C18="CE"),"A","")),IF(C18="EE",IF(G18>=3,IF(E18>=5,"H","A"),IF(G18>=2,IF(E18>=16,"H",IF(E18<=4,"L","A")),IF(E18<=15,"L","A"))),IF(OR(C18="SE",C18="CE"),IF(G18>=4,IF(E18>=6,"H","A"),IF(G18>=2,IF(E18>=20,"H",IF(E18<=5,"L","A")),IF(E18<=19,"L","A"))),IF(OR(C18="ALI",C18="AIE"),IF(G18>=6,IF(E18>=20,"H","A"),IF(G18>=2,IF(E18>=51,"H",IF(E18<=19,"L","A")),IF(E18<=50,"L","A"))),"")))) | M18: =CONCATENATE(C18,D18) | N18: =IF(OR(K18="",K18=0),O18,K18) | O18: =IF(NOT(ISERROR(VLOOKUP(C18,Deflatores!G$42:H$64,2,FALSE))),VLOOKUP(C18,Deflatores!G$42:H$64,2,FALSE),IF(OR(ISBLANK(D18),ISBLANK(C18)),"",VLOOKUP(D18,Deflatores!G$4:H$38,2,FALSE)*K18+VLOOKUP(D18,Deflatores!G$4:I$38,3,FALSE)))
I19: =IF(ISBLANK(C19),"",IF(L19="L","Baixa",IF(L19="A","Média",IF(L19="","","Alta")))) | J19: =CONCATENATE(C19,L19) | K19: =IF(ISBLANK(C19),"",IF(C19="ALI",IF(L19="L",7,IF(L19="A",10,15)),IF(C19="AIE",IF(L19="L",5,IF(L19="A",7,10)),IF(C19="SE",IF(L19="L",4,IF(L19="A",5,7)),IF(OR(C19="EE",C19="CE"),IF(L19="L",3,IF(L19="A",4,6)),0))))) | L19: =IF(OR(ISBLANK(E19),ISBLANK(G19)),IF(OR(C19="ALI",C19="AIE"),"L",IF(OR(C19="EE",C19="SE",C19="CE"),"A","")),IF(C19="EE",IF(G19>=3,IF(E19>=5,"H","A"),IF(G19>=2,IF(E19>=16,"H",IF(E19<=4,"L","A")),IF(E19<=15,"L","A"))),IF(OR(C19="SE",C19="CE"),IF(G19>=4,IF(E19>=6,"H","A"),IF(G19>=2,IF(E19>=20,"H",IF(E19<=5,"L","A")),IF(E19<=19,"L","A"))),IF(OR(C19="ALI",C19="AIE"),IF(G19>=6,IF(E19>=20,"H","A"),IF(G19>=2,IF(E19>=51,"H",IF(E19<=19,"L","A")),IF(E19<=50,"L","A"))),"")))) | M19: =CONCATENATE(C19,D19) | N19: =IF(OR(K19="",K19=0),O19,K19) | O19: =IF(NOT(ISERROR(VLOOKUP(C19,Deflatores!G$42:H$64,2,FALSE))),VLOOKUP(C19,Deflatores!G$42:H$64,2,FALSE),IF(OR(ISBLANK(D19),ISBLANK(C19)),"",VLOOKUP(D19,Deflatores!G$4:H$38,2,FALSE)*K19+VLOOKUP(D19,Deflatores!G$4:I$38,3,FALSE)))
... I606: =IF(ISBLANK(C606),"",IF(L606="L","Baixa",IF(L606="A","Média",IF(L606="","","Alta")))) | J606: =CONCATENATE(C606,L606) | K606: =IF(ISBLANK(C606),"",IF(C606="ALI",IF(L606="L",7,IF(L606="A",10,15)),IF(C606="AIE",IF(L606="L",5,IF(L606="A",7,10)),IF(C606="SE",IF(L606="L",4,IF(L606="A",5,7)),IF(OR(C606="EE",C606="CE"),IF(L606="L",3,IF(L606="A",4,6)),0))))) | L606: =IF(OR(ISBLANK(E606),ISBLANK(G606)),IF(OR(C606="ALI",C606="AIE"),"L",IF(OR(C606="EE",C606="SE",C606="CE"),"A","")),IF(C606="EE",IF(G606>=3,IF(E606>=5,"H","A"),IF(G606>=2,IF(E606>=16,"H",IF(E606<=4,"L","A")),IF(E606<=15,"L","A"))),IF(OR(C606="SE",C606="CE"),IF(G606>=4,IF(E606>=6,"H","A"),IF(G606>=2,IF(E606>=20,"H",IF(E606<=5,"L","A")),IF(E606<=19,"L","A"))),IF(OR(C606="ALI",C606="AIE"),IF(G606>=6,IF(E606>=20,"H","A"),IF(G606>=2,IF(E606>=51,"H",IF(E606<=19,"L","A")),IF(E606<=50,"L","A"))),"")))) | M606: =CONCATENATE(C606,D606) | N606: =IF(OR(K606="",K606=0),O606,K606) | O606: =IF(NOT(ISERROR(VLOOKUP(C606,Deflatores!G$42:H$64,2,FALSE))),VLOOKUP(C606,Deflatores!G$42:H$64,2,FALSE),IF(OR(ISBLANK(D606),ISBLANK(C606)),"",VLOOKUP(D606,Deflatores!G$4:H$38,2,FALSE)*K606+VLOOKUP(D606,Deflatores!G$4:I$38,3,FALSE)))

Sheet Deflatores
A1: Itens Não Mensuráveis
A2: Tipo de Manutenção na Função | G2: Sigla | H2: Contribuição em PF Local | J2: PF Bruto | K2: PF Deflator FS
A3: Contrato | B3: Descrição | F3: Origem | H3: Percentual (%) | I3: Fixa (PF)
A4: Adicionada | B4: Inclusão | G4: I | H4: 1 | J4: =SUMIF(Contagem_PF!$C$8:$C$606,Deflatores!G4,Contagem_PF!$J$8:$J$606) -> 0 | K4: =IF(H4="",COUNTIF(Contagem_PF!C$8:C$606,G4)*I4,H4*J4) -> 0
A5: Alterada | B5: Alteração (sem conhecimento do Fator de Impacto) | F5: SISP – 4.2 Projeto de Melhoria | G5: A | H5: 0.5 | J5: =SUMIF(Contagem_PF!$C$8:$C$606,Deflatores!G5,Contagem_PF!$J$8:$J$606) -> 0 | K5: =IF(H5="",COUNTIF(Contagem_PF!C$8:C$606,G5)*I5,H5*J5) -> 0
A6: Excluída | B6: Exclusão | F6: SISP – 4.2 Projeto de Melhoria | G6: E | H6: 0.4 | J6: =SUMIF(Contagem_PF!$C$8:$C$606,Deflatores!G6,Contagem_PF!$J$8:$J$606) -> 0 | K6: =IF(H6="",COUNTIF(Contagem_PF!C$8:C$606,G6)*I6,H6*J6) -> 0
B7: Alteração (50%) de função desenvolvida ou já alterada pela empresa atual | F7: SISP – 4.2 Projeto de Melhoria | G7: A50 | H7: 0.5 | J7: =SUMIF(Contagem_PF!$C$8:$C$606,Deflatores!G7,Contagem_PF!$J$8:$J$606) -> 0 | K7: =IF(H7="",COUNTIF(Contagem_PF!C$8:C$606,G7)*I7,H7*J7) -> 0
B8: Alteração (75%) de função não desenv. e ainda não alterada pela empresa atual | F8: SISP – 4.2 Projeto de Melhoria | G8: A75 | H8: 0.75 | J8: =SUMIF(Contagem_PF!$C$8:$C$606,Deflatores!G8,Contagem_PF!$J$8:$J$606) -> 0 | K8: =IF(H8="",COUNTIF(Contagem_PF!C$8:C$606,G8)*I8,H8*J8) -> 0
B9: Alteração (75%+15%): o mesmo acima + redocumentar a função | F9: SISP – 4.2 Projeto de Melhoria | G9: A90 | H9: 0.9 | J9: =SUMIF(Contagem_PF!$C$8:$C$606,Deflatores!G9,Contagem_PF!$J$8:$J$606) -> 0 | K9: =IF(H9="",COUNTIF(Contagem_PF!C$8:C$606,G9)*I9,H9*J9) -> 0
B10: Migração de Dados | F10: SISP – 4.3 Projetos de Migração de Dados | G10: PMD | H10: 1 | J10: =SUMIF(Contagem_PF!$C$8:$C$606,Deflatores!G10,Contagem_PF!$J$8:$J$606) -> 0 | K10: =IF(H10="",COUNTIF(Contagem_PF!C$8:C$606,G10)*I10,H10*J10) -> 0
B11: Corretiva (sem conhecimento do Fator de Impacto) | F11: SISP – 4.4 Manutenção Corretiva | G11: COR | H11: 0.5 | J11: =SUMIF(Contagem_PF!$C$8:$C$606,Deflatores!G11,Contagem_PF!$J$8:$J$606) -> 0 | K11: =IF(H11="",COUNTIF(Contagem_PF!C$8:C$606,G11)*I11,H11*J11) -> 0
B12: Corretiva (50%) - Fora da garantia (mesma empresa) | F12: SISP – 4.4 Manutenção Corretiva | G12: COR50 | H12: 0.5 | J12: =SUMIF(Contagem_PF!$C$8:$C$606,Deflatores!G12,Contagem_PF!$J$8:$J$606) -> 0 | K12: =IF(H12="",COUNTIF(Contagem_PF!C$8:C$606,G12)*I12,H12*J12) -> 0
B13: Corretiva (75%) - Fora da garantia (outra empresa) | F13: SISP – 4.4 Manutenção Corretiva | G13: COR75 | H13: 0.75 | J13: =SUMIF(Contagem_PF!$C$8:$C$606,Deflatores!G13,Contagem_PF!$J$8:$J$606) -> 0 | K13: =IF(H13="",COUNTIF(Contagem_PF!C$8:C$606,G13)*I13,H13*J13) -> 0
B14: Corretiva (75%+15%) - Fora da garantia (outra empresa) + Redocumentação | F14: SISP – 4.4 Manutenção Corretiva | G14: COR90 | H14: 0.9 | J14: =SUMIF(Contagem_PF!$C$8:$C$606,Deflatores!G14,Contagem_PF!$J$8:$J$606) -> 0 | K14: =IF(H14="",COUNTIF(Contagem_PF!C$8:C$606,G14)*I14,H14*J14) -> 0
B15: Corretiva em Garantia | F15: SISP – 4.4 Manutenção Corretiva | G15: GAR | H15: 0 | J15: =SUMIF(Contagem_PF!$C$8:$C$606,Deflatores!G15,Contagem_PF!$J$8:$J$606) -> 0 | K15: =IF(H15="",COUNTIF(Contagem_PF!C$8:C$606,G15)*I15,H15*J15) -> 0
B16: Mudança de Plataforma - Linguagem de Programação | F16: SISP – 4.5.1 Mudança de Plataforma – Linguagem de Programação | G16: MLP | H16: 1 | J16: =SUMIF(Contagem_PF!$C$8:$C$606,Deflatores!G16,Contagem_PF!$J$8:$J$606) -> 0 | K16: =IF(H16="",COUNTIF(Contagem_PF!C$8:C$606,G16)*I16,H16*J16) -> 0
B17: Mudança de Plataforma - Banco de Dados (outro paradigma) | F17: SISP – 4.5.2 Mudança de Plataforma – Banco de Dados | G17: MBO | H17: 1 | J17: =SUMIF(Contagem_PF!$C$8:$C$606,Deflatores!G17,Contagem_PF!$J$8:$J$606) -> 0 | K17: =IF(H17="",COUNTIF(Contagem_PF!C$8:C$606,G17)*I17,H17*J17) -> 0
B18: Mudança de Plataforma - Banco de Dados (mesmo paradigma com alterações) | F18: SISP – 4.5.2 Mudança de Plataforma – Banco de Dados | G18: MBM | H18: 0.3 | J18: =SUMIF(Contagem_PF!$C$8:$C$606,Deflatores!G18,Contagem_PF!$J$8:$J$606) -> 0 | K18: =IF(H18="",COUNTIF(Contagem_PF!C$8:C$606,G18)*I18,H18*J18) -> 0
... B21: Atualização de Versão – Banco de Dados | F21: SISP – 4.6.3 Atualização de Versão – Banco de Dados | G21: ABD | H21: 0.3 | J21: =SUMIF(Contagem_PF!$C$8:$C$606,Deflatores!G21,Contagem_PF!$J$8:$J$606) -> 0 | K21: =IF(H21="",COUNTIF(Contagem_PF!C$8:C$606,G21)*I21,H21*J21) -> 0
B22: Manutenção Cosmética | F22: SISP – 4.7 Manutenção Cosmética | G22: COS | I22: 0.6 | J22: =SUMIF(Contagem_PF!$C$8:$C$606,Deflatores!G22,Contagem_PF!$J$8:$J$606) -> 0 | K22: =IF(H22="",COUNTIF(Contagem_PF!C$8:C$606,G22)*I22,H22*J22) -> 0
B23: Adaptação em Funcionalidades sem Alteração de Requisitos Funcionais (sem conhecimento do Fator de Impacto) | F23: SISP – 4.8 Adaptação em Funcionalidades sem Alteração de Requisitos Funcionais | G23: ARN | H23: 0.5 | J23: =SUMIF(Contagem_PF!$C$8:$C$606,Deflatores!G23,Contagem_PF!$J$8:$J$606) -> 0 | K23: =IF(H23="",COUNTIF(Contagem_PF!C$8:C$606,G23)*I23,H23*J23) -> 0
B24: Adaptação em Funcionalidades sem Alteração de Requisitos Funcionais (50%) (em função desenvolvida ou já alterada pela empresa atual) | F24: SISP – 4.8 Adaptação em Funcionalidades sem Alteração de Requisitos Funcionais | G24: ARN50 | H24: 0.5 | J24: =SUMIF(Contagem_PF!$C$8:$C$606,Deflatores!G24,Contagem_PF!$J$8:$J$606) -> 0 | K24: =IF(H24="",COUNTIF(Contagem_PF!C$8:C$606,G24)*I24,H24*J24) -> 0
B25: Adaptação em Funcionalidades sem Alteração de Requisitos Funcionais (75%) (em função não desenvolvida e ainda não alterada pela empresa atual) | F25: SISP – 4.8 Adaptação em Funcionalidades sem Alteração de Requisitos Funcionais | G25: ARN75 | H25: 0.75 | J25: =SUMIF(Contagem_PF!$C$8:$C$606,Deflatores!G25,Contagem_PF!$J$8:$J$606) -> 0 | K25: =IF(H25="",COUNTIF(Contagem_PF!C$8:C$606,G25)*I25,H25*J25) -> 0
B26: Atualização de Dados sem Consulta Prévia | F26: SISP – 4.9.1 Apuração Especial – Base de Dados | G26: ADS | H26: 1 | J26: =SUMIF(Contagem_PF!$C$8:$C$606,Deflatores!G26,Contagem_PF!$J$8:$J$606) -> 0 | K26: =IF(H26="",COUNTIF(Contagem_PF!C$8:C$606,G26)*I26,H26*J26) -> 0
B27: Consulta Prévia sem Atualização | F27: SISP – 4.9.1 Apuração Especial – Base de Dados | G27: CPA | H27: 1 | J27: =SUMIF(Contagem_PF!$C$8:$C$606,Deflatores!G27,Contagem_PF!$J$8:$J$606) -> 0 | K27: =IF(H27="",COUNTIF(Contagem_PF!C$8:C$606,G27)*I27,H27*J27) -> 0
B28: Atualização de Dados com Consulta Prévia | F28: SISP – 4.9.1 Apuração Especial – Base de Dados | G28: ADC | H28: 0.6 | J28: =SUMIF(Contagem_PF!$C$8:$C$606,Deflatores!G28,Contagem_PF!$J$8:$J$606) -> 0 | K28: =IF(H28="",COUNTIF(Contagem_PF!C$8:C$606,G28)*I28,H28*J28) -> 0
B29: Apuração Especial – Geração de Relatórios | F29: SISP – 4.9.2 Apuração Especial – Geração de Relatórios | G29: AGR | H29: 1 | J29: =SUMIF(Contagem_PF!$C$8:$C$606,Deflatores!G29,Contagem_PF!$J$8:$J$606) -> 0 | K29: =IF(H29="",COUNTIF(Contagem_PF!C$8:C$606,G29)*I29,H29*J29) -> 0
B30: Apuração Especial – Reexecução | F30: SISP – 4.9.3 Apuração Especial – Reexecução | G30: AER | H30: 0.1 | J30: =SUMIF(Contagem_PF!$C$8:$C$606,Deflatores!G30,Contagem_PF!$J$8:$J$606) -> 0 | K30: =IF(H30="",COUNTIF(Contagem_PF!C$8:C$606,G30)*I30,H30*J30) -> 0
B31: Atualização de Dados | F31: SISP – 4.10 Atualização de Dados | G31: ATD | H31: 0.1 | J31: =SUMIF(Contagem_PF!$C$8:$C$606,Deflatores!G31,Contagem_PF!$J$8:$J$606) -> 0 | K31: =IF(H31="",COUNTIF(Contagem_PF!C$8:C$606,G31)*I31,H31*J31) -> 0
B32: Manutenção de Documentação de Sistemas Legados | F32: SISP – 4.12 Manutenção de Documentação de Sistemas Legados | G32: MSL | H32: 0.25 | J32: =SUMIF(Contagem_PF!$C$8:$C$606,Deflatores!G32,Contagem_PF!$J$8:$J$606) -> 0 | K32: =IF(H32="",COUNTIF(Contagem_PF!C$8:C$606,G32)*I32,H32*J32) -> 0
B33: Verificação de Erros (Sem Documentação de Teste existente) | F33: SISP – 4.13 Verificação de Erros | G33: VES | H33: 0.2 | J33: =SUMIF(Contagem_PF!$C$8:$C$606,Deflatores!G33,Contagem_PF!$J$8:$J$606) -> 0 | K33: =IF(H33="",COUNTIF(Contagem_PF!C$8:C$606,G33)*I33,H33*J33) -> 0
B34: Verificação de Erros (Com Documentação de Teste existente) | F34: SISP – 4.13 Verificação de Erros | G34: VEC | H34: 0.15 | J34: =SUMIF(Contagem_PF!$C$8:$C$606,Deflatores!G34,Contagem_PF!$J$8:$J$606) -> 0 | K34: =IF(H34="",COUNTIF(Contagem_PF!C$8:C$606,G34)*I34,H34*J34) -> 0
... B36: Componente Interno Reusável | F36: SISP – 4.15 Componente Interno Reusável | G36: CIR | H36: 1 | J36: =SUMIF(Contagem_PF!$C$8:$C$606,Deflatores!G36,Contagem_PF!$J$8:$J$606) -> 0 | K36: =IF(H36="",COUNTIF(Contagem_PF!C$8:C$606,G36)*I36,H36*J36) -> 0
G37: . | J37: =SUMIF(Contagem_PF!$C$8:$C$606,Deflatores!G37,Contagem_PF!$J$8:$J$606) -> 0 | K37: =IF(H37="",COUNTIF(Contagem_PF!C$8:C$606,G37)*I37,H37*J37) -> 0 | L37: ALI
G38: . | J38: =SUMIF(Contagem_PF!$C$8:$C$606,Deflatores!G38,Contagem_PF!$J$8:$J$606) -> 0 | K38: =IF(H38="",COUNTIF(Contagem_PF!C$8:C$606,G38)*I38,H38*J38) -> 0 | L38: AIE
L39: EE
A40: Itens Não Mensuráveis | G40: Sigla | H40: Contribuição em PF Local | J40: Quantidade | K40: PF Local FS | L40: CE
A41: Contrato | B41: Descrição | F41: Origem | L41: SE
B42: Páginas Estáticas | F42: SISP – 4.11 Desenvolvimento, Manutenção e Publicação de Paginas Estáticas de Intranet, Internet ou Portal | G42: PAG | H42: 0.6 | J42: =COUNTIF(Contagem_PF!B$8:B$606,G42) -> 0 | K42: =SUMIF(Contagem_PF!B$8:B$606,$G42,Contagem_PF!M$8:M$606) -> 0 | L42: =""&G42 -> PAG
B43: Manutenção Cosmética (atrelada a algo não funcional) | F43: SISP – 4.7 Manutenção Cosmética | G43: COSNF | H43: 0.6 | J43: =COUNTIF(Contagem_PF!B$8:B$606,G43) -> 0 | K43: =SUMIF(Contagem_PF!B$8:B$606,$G43,Contagem_PF!M$8:M$606) -> 0 | L43: =""&G43 -> COSNF
...

Sheet Sumário 1
A1: Sumário da Contagem
A4: ='Info Gerais'!A5&" : "&'Info Gerais'!F5 -> Aplicação : | F4: ='Info Gerais'!A8&" : "&'Info Gerais'!F8 -> Projeto :
A5: ='Info Gerais'!A9&" : "&'Info Gerais'!F9 -> Responsável : | F5: ='Info Gerais'!A10&" : "&'Info Gerais'!F10 -> Revisor :
A6: ='Info Gerais'!A4&" : "&'Info Gerais'!F4 -> Empresa : BASIS | F6: ="Tipo de Contagem : "&'Info Gerais'!F6 -> Tipo de Contagem :
A7: Tipo de Função | C7: Complexidade Funcional | G7: Total PF IFPUG por Complexidade | H7: % | J7: Total PF Deflator FS por tipo de manutenção básica | L7: %
B10: EE | C10: =COUNTIF(Contagem_PF!I8:I606,"EEL") -> 0 | E10: Baixa | F10: x 3 | G10: =C10*3 -> 0 | J10: =Deflatores!$G$4&"=" -> I= | K10: =SUMIF(Contagem_PF!$L$8:$L$606,"EE"&Deflatores!G4,Contagem_PF!$N$8:$N$606) -> 0
C11: =COUNTIF(Contagem_PF!I8:I606,"EEA") -> 0 | E11: Média | F11: x 4 | G11: =C11*4 -> 0 | J11: =Deflatores!$G$5&"=" -> A= | K11: =SUMIF(Contagem_PF!$L$8:$L$606,"EE"&Deflatores!G5,Contagem_PF!$N$8:$N$606) -> 0
C12: =COUNTIF(Contagem_PF!I8:I606,"EEH") -> 0 | E12: Alta | F12: x 6 | G12: =C12*6 -> 0 | J12: =Deflatores!$G$6&"=" -> E= | K12: =SUMIF(Contagem_PF!$L$8:$L$606,"EE"&Deflatores!G6,Contagem_PF!$N$8:$N$606) -> 0
B14: Qtd Total | C14: =SUM(C10:C12) -> 0 | F14: Total | G14: =SUM(G10:G12) -> 0 | H14: =IF($G$45<>0,G14/$G$45,"") | K14: =SUM(K10:K13) -> 0 | L14: =IF('Sumário 2'!L11<>0,K14/'Sumário 2'!L11,"")
B17: SE | C17: =COUNTIF(Contagem_PF!I8:I606,"SEL") -> 0 | E17: Baixa | F17: x 4 | G17: =C17*4 -> 0 | J17: =Deflatores!$G$4&"=" -> I= | K17: =SUMIF(Contagem_PF!$L$8:$L$606,"SE"&Deflatores!$G$4,Contagem_PF!$N$8:$N$606) -> 0
C18: =COUNTIF(Contagem_PF!I8:I606,"SEA") -> 0 | E18: Média | F18: x 5 | G18: =C18*5 -> 0 | J18: =Deflatores!$G$5&"=" -> A= | K18: =SUMIF(Contagem_PF!$L$8:$L$606,"SE"&Deflatores!$G$5,Contagem_PF!$N$8:$N$606) -> 0
C19: =COUNTIF(Contagem_PF!I8:I606,"SEH") -> 0 | E19: Alta | F19: x 7 | G19: =C19*7 -> 0 | J19: =Deflatores!$G$6&"=" -> E= | K19: =SUMIF(Contagem_PF!$L$8:$L$606,"SE"&Deflatores!$G$6,Contagem_PF!$N$8:$N$606) -> 0
B21: Qtd Total | C21: =SUM(C17:C19) -> 0 | F21: Total | G21: =SUM(G17:G19) -> 0 | H21: =IF($G$45<>0,G21/$G$45,"") | K21: =SUM(K17:K20) -> 0 | L21: =IF('Sumário 2'!L11<>0,K21/'Sumário 2'!L11,"")
B24: CE | C24: =COUNTIF(Contagem_PF!I8:I606,"CEL") -> 0 | E24: Baixa | F24: x 3 | G24: =C24*3 -> 0 | J24: =Deflatores!$G$4&"=" -> I= | K24: =SUMIF(Contagem_PF!$L$8:$L$606,"CE"&Deflatores!$G$4,Contagem_PF!$N$8:$N$606) -> 0
C25: =COUNTIF(Contagem_PF!I8:I606,"CEA") -> 0 | E25: Média | F25: x 4 | G25: =C25*4 -> 0 | J25: =Deflatores!$G$5&"=" -> A= | K25: =SUMIF(Contagem_PF!$L$8:$L$606,"CE"&Deflatores!$G$5,Contagem_PF!$N$8:$N$606) -> 0
C26: =COUNTIF(Contagem_PF!I8:I606,"CEH") -> 0 | E26: Alta | F26: x 6 | G26: =C26*6 -> 0 | J26: =Deflatores!$G$6&"=" -> E= | K26: =SUMIF(Contagem_PF!$L$8:$L$606,"CE"&Deflatores!$G$6,Contagem_PF!$N$8:$N$606) -> 0
B28: Qtd Total | C28: =SUM(C24:C26) -> 0 | F28: Total | G28: =SUM(G24:G26) -> 0 | H28: =IF($G$45<>0,G28/$G$45,"") | K28: =SUM(K24:K27) -> 0 | L28: =IF('Sumário 2'!L11<>0,K28/'Sumário 2'!L11,"")
B31: ALI | C31: =COUNTIF(Contagem_PF!I8:I606,"ALIL") -> 0 | E31: Baixa | F31: x 7 | G31: =C31*7 -> 0 | J31: =Deflatores!$G$4&"=" -> I= | K31: =SUMIF(Contagem_PF!$L$8:$L$606,"ALI"&Deflatores!$G$4,Contagem_PF!$N$8:$N$606) -> 0
C32: =COUNTIF(Contagem_PF!I8:I606,"ALIA") -> 0 | E32: Média | F32: x 10 | G32: =C32*10 -> 0 | J32: =Deflatores!$G$5&"=" -> A= | K32: =SUMIF(Contagem_PF!$L$8:$L$606,"ALI"&Deflatores!$G$5,Contagem_PF!$N$8:$N$606) -> 0
C33: =COUNTIF(Contagem_PF!I8:I606,"ALIH") -> 0 | E33: Alta | F33: x 15 | G33: =C33*15 -> 0 | J33: =Deflatores!$G$6&"=" -> E= | K33: =SUMIF(Contagem_PF!$L$8:$L$606,"ALI"&Deflatores!$G$6,Contagem_PF!$N$8:$N$606) -> 0
B35: Qtd Total | C35: =SUM(C31:C33) -> 0 | F35: Total | G35: =SUM(G31:G33) -> 0 | H35: =IF($G$45<>0,G35/$G$45,"") | K35: =SUM(K31:K34) -> 0 | L35: =IF('Sumário 2'!L11<>0,K35/'Sumário 2'!L11,"")
B38: AIE | C38: =COUNTIF(Contagem_PF!I8:I606,"AIEL") -> 0 | E38: Baixa | F38: x 5 | G38: =C38*5 -> 0 | J38: =Deflatores!$G$4&"=" -> I= | K38: =SUMIF(Contagem_PF!$L$8:$L$606,"AIE"&Deflatores!$G$4,Contagem_PF!$N$8:$N$606) -> 0
C39: =COUNTIF(Contagem_PF!I8:I606,"AIEA") -> 0 | E39: Média | F39: x 7 | G39: =C39*7 -> 0 | J39: =Deflatores!$G$5&"=" -> A= | K39: =SUMIF(Contagem_PF!$L$8:$L$606,"AIE"&Deflatores!$G$5,Contagem_PF!$N$8:$N$606) -> 0
C40: =COUNTIF(Contagem_PF!I8:I606,"AIEH") -> 0 | E40: Alta | F40: x 10 | G40: =C40*10 -> 0 | J40: =Deflatores!$G$6&"=" -> E= | K40: =SUMIF(Contagem_PF!$L$8:$L$606,"AIE"&Deflatores!$G$6,Contagem_PF!$N$8:$N$606) -> 0
B42: Qtd Total | C42: =SUM(C38:C40) -> 0 | F42: Total | G42: =SUM(G38:G40) -> 0 | H42: =IF($G$45<>0,G42/$G$45,"") | K42: =SUM(K38:K41) -> 0 | L42: =IF('Sumário 2'!L11<>0,K42/'Sumário 2'!L11,"")
B45: Total PF não ajustados (contagem detalhada) | G45: =SUM(G14+G21+G28+G35+G42) -> 0
B46: Total PF não ajustados (contagem estimativa) | G46: =(C10+C11+C12)*4+(C17+C18+C19)*5+(C24+C25+C26)*4+(C31+C32+C33)*7+(C38+C39+C40)*5 -> 0
B47: Total PF não ajustados (contagem indicativa) | G47: =(C31+C32+C33)*35+(C38+C39+C40)*15 -> 0

Sheet Sumário 2
A1: Sumário por Deflatores e Itens não mensuráveis
A4: ='Info Gerais'!A5&" : "&'Info Gerais'!F5 -> Aplicação : | F4: ='Info Gerais'!A8&" : "&'Info Gerais'!F8 -> Projeto :
A5: ='Info Gerais'!A9&" : "&'Info Gerais'!F9 -> Responsável : | F5: ='Info Gerais'!A10&" : "&'Info Gerais'!F10 -> Revisor :
A6: ='Info Gerais'!A4&" : "&'Info Gerais'!F4 -> Empresa : BASIS | F6: ="Tipo de Contagem : "&'Info Gerais'!F6 -> Tipo de Contagem :
B9: Deflatores aplicados a Itens Funcionais | E9: Quantidade | F9: PF IFPUG | G9: Deflator | H9: Contrib. Fixa | I9: PF Deflator FS | J9: % LOCAL
B10: =""&Deflatores!B4 -> Inclusão | D10: =""&Deflatores!G4 -> I | E10: =IF(D10="","",COUNTIF(Contagem_PF!C$8:C$606,D10)) -> 0 | F10: =SUMIF(Contagem_PF!$C$8:$C$606,Deflatores!G4,Contagem_PF!$J$8:$J$606) -> 0 | G10: =IF(ISBLANK(Deflatores!H4),"",Deflatores!H4) -> 1 | H10: =IF(ISBLANK(Deflatores!I4),"",Deflatores!I4) | I10: =IF(F10=0,Deflatores!K4,F10*G10) -> 0 | J10: =IF($L$11<>0,I10/$L$11,"") | L10: PF Deflator FS
B11: =""&Deflatores!B5 -> Alteração (sem conhecimento do Fator de Impacto) | D11: =""&Deflatores!G5 -> A | E11: =IF(D11="","",COUNTIF(Contagem_PF!C$8:C$606,D11)) -> 0 | F11: =SUMIF(Contagem_PF!$C$8:$C$606,Deflatores!G5,Contagem_PF!$J$8:$J$606) -> 0 | G11: =IF(ISBLANK(Deflatores!H5),"",Deflatores!H5) -> 0.5 | H11: =IF(ISBLANK(Deflatores!I5),"",Deflatores!I5) | I11: =IF(F11=0,Deflatores!K5,F11*G11) -> 0 | J11: =IF($L$11<>0,I11/$L$11,"") | L11: ='Info Gerais'!Q6 -> 0
B12: =""&Deflatores!B6 -> Exclusão | D12: =""&Deflatores!G6 -> E | E12: =IF(D12="","",COUNTIF(Contagem_PF!C$8:C$606,D12)) -> 0 | F12: =SUMIF(Contagem_PF!$C$8:$C$606,Deflatores!G6,Contagem_PF!$J$8:$J$606) -> 0 | G12: =IF(ISBLANK(Deflatores!H6),"",Deflatores!H6) -> 0.4 | H12: =IF(ISBLANK(Deflatores!I6),"",Deflatores!I6) | I12: =IF(F12=0,Deflatores!K6,F12*G12) -> 0 | J12: =IF($L$11<>0,I12/$L$11,"")
B13: =""&Deflatores!B7 -> Alteração (50%) de função desenvolvida ou já alterada pela empresa atual | D13: =""&Deflatores!G7 -> A50 | E13: =IF(D13="","",COUNTIF(Contagem_PF!C$8:C$606,D13)) -> 0 | F13: =SUMIF(Contagem_PF!$C$8:$C$606,Deflatores!G7,Contagem_PF!$J$8:$J$606) -> 0 | G13: =IF(ISBLANK(Deflatores!H7),"",Deflatores!H7) -> 0.5 | H13: =IF(ISBLANK(Deflatores!I7),"",Deflatores!I7) | I13: =Deflatores!K7 -> 0 | J13: =IF($L$11<>0,I13/$L$11,"") | L13: Total IFPUG
B14: =""&Deflatores!B8 -> Alteração (75%) de função não desenv. e ainda não alterada pela empresa atual | D14: =""&Deflatores!G8 -> A75 | E14: =IF(D14="","",COUNTIF(Contagem_PF!C$8:C$606,D14)) -> 0 | F14: =SUMIF(Contagem_PF!$C$8:$C$606,Deflatores!G8,Contagem_PF!$J$8:$J$606) -> 0 | G14: =IF(ISBLANK(Deflatores!H8),"",Deflatores!H8) -> 0.75 | H14: =IF(ISBLANK(Deflatores!I8),"",Deflatores!I8) | I14: =Deflatores!K8 -> 0 | J14: =IF($L$11<>0,I14/$L$11,"") | L14: ='Info Gerais'!Q4 -> 0
B15: =""&Deflatores!B9 -> Alteração (75%+15%): o mesmo acima + redocumentar a função | D15: =""&Deflatores!G9 -> A90 | E15: =IF(D15="","",COUNTIF(Contagem_PF!C$8:C$606,D15)) -> 0 | F15: =SUMIF(Contagem_PF!$C$8:$C$606,Deflatores!G9,Contagem_PF!$J$8:$J$606) -> 0 | G15: =IF(ISBLANK(Deflatores!H9),"",Deflatores!H9) -> 0.9 | H15: =IF(ISBLANK(Deflatores!I9),"",Deflatores!I9) | I15: =Deflatores!K9 -> 0 | J15: =IF($L$11<>0,I15/$L$11,"")
B16: =""&Deflatores!B10 -> Migração de Dados | D16: =""&Deflatores!G10 -> PMD | E16: =IF(D16="","",COUNTIF(Contagem_PF!C$8:C$606,D16)) -> 0 | F16: =SUMIF(Contagem_PF!$C$8:$C$606,Deflatores!G10,Contagem_PF!$J$8:$J$606) -> 0 | G16: =IF(ISBLANK(Deflatores!H10),"",Deflatores!H10) -> 1 | H16: =IF(ISBLANK(Deflatores!I10),"",Deflatores!I10) | I16: =Deflatores!K10 -> 0 | J16: =IF($L$11<>0,I16/$L$11,"")
B17: =""&Deflatores!B11 -> Corretiva (sem conhecimento do Fator de Impacto) | D17: =""&Deflatores!G11 -> COR | E17: =IF(D17="","",COUNTIF(Contagem_PF!C$8:C$606,D17)) -> 0 | F17: =SUMIF(Contagem_PF!$C$8:$C$606,Deflatores!G11,Contagem_PF!$J$8:$J$606) -> 0 | G17: =IF(ISBLANK(Deflatores!H11),"",Deflatores!H11) -> 0.5 | H17: =IF(ISBLANK(Deflatores!I11),"",Deflatores!I11) | I17: =Deflatores!K11 -> 0 | J17: =IF($L$11<>0,I17/$L$11,"")
B18: =""&Deflatores!B12 -> Corretiva (50%) - Fora da garantia (mesma empresa) | D18: =""&Deflatores!G12 -> COR50 | E18: =IF(D18="","",COUNTIF(Contagem_PF!C$8:C$606,D18)) -> 0 | F18: =SUMIF(Contagem_PF!$C$8:$C$606,Deflatores!G12,Contagem_PF!$J$8:$J$606) -> 0 | G18: =IF(ISBLANK(Deflatores!H12),"",Deflatores!H12) -> 0.5 | H18: =IF(ISBLANK(Deflatores!I12),"",Deflatores!I12) | I18: =Deflatores!K12 -> 0 | J18: =IF($L$11<>0,I18/$L$11,"")
B19: =""&Deflatores!B13 -> Corretiva (75%) - Fora da garantia (outra empresa) | D19: =""&Deflatores!G13 -> COR75 | E19: =IF(D19="","",COUNTIF(Contagem_PF!C$8:C$606,D19)) -> 0 | F19: =SUMIF(Contagem_PF!$C$8:$C$606,Deflatores!G13,Contagem_PF!$J$8:$J$606) -> 0 | G19: =IF(ISBLANK(Deflatores!H13),"",Deflatores!H13) -> 0.75 | H19: =IF(ISBLANK(Deflatores!I13),"",Deflatores!I13) | I19: =Deflatores!K13 -> 0 | J19: =IF($L$11<>0,I19/$L$11,"")
B20: =""&Deflatores!B14 -> Corretiva (75%+15%) - Fora da garantia (outra empresa) + Redocumentação | D20: =""&Deflatores!G14 -> COR90 | E20: =IF(D20="","",COUNTIF(Contagem_PF!C$8:C$606,D20)) -> 0 | F20: =SUMIF(Contagem_PF!$C$8:$C$606,Deflatores!G14,Contagem_PF!$J$8:$J$606) -> 0 | G20: =IF(ISBLANK(Deflatores!H14),"",Deflatores!H14) -> 0.9 | H20: =IF(ISBLANK(Deflatores!I14),"",Deflatores!I14) | I20: =Deflatores!K14 -> 0 | J20: =IF($L$11<>0,I20/$L$11,"")
B21: =""&Deflatores!B15 -> Corretiva em Garantia | D21: =""&Deflatores!G15 -> GAR | E21: =IF(D21="","",COUNTIF(Contagem_PF!C$8:C$606,D21)) -> 0 | F21: =SUMIF(Contagem_PF!$C$8:$C$606,Deflatores!G15,Contagem_PF!$J$8:$J$606) -> 0 | G21: =IF(ISBLANK(Deflatores!H15),"",Deflatores!H15) -> 0 | H21: =IF(ISBLANK(Deflatores!I15),"",Deflatores!I15) | I21: =Deflatores!K15 -> 0 | J21: =IF($L$11<>0,I21/$L$11,"")
B22: =""&Deflatores!B16 -> Mudança de Plataforma - Linguagem de Programação | D22: =""&Deflatores!G16 -> MLP | E22: =IF(D22="","",COUNTIF(Contagem_PF!C$8:C$606,D22)) -> 0 | F22: =SUMIF(Contagem_PF!$C$8:$C$606,Deflatores!G16,Contagem_PF!$J$8:$J$606) -> 0 | G22: =IF(ISBLANK(Deflatores!H16),"",Deflatores!H16) -> 1 | H22: =IF(ISBLANK(Deflatores!I16),"",Deflatores!I16) | I22: =Deflatores!K16 -> 0 | J22: =IF($L$11<>0,I22/$L$11,"")
B23: =""&Deflatores!B17 -> Mudança de Plataforma - Banco de Dados (outro paradigma) | D23: =""&Deflatores!G17 -> MBO | E23: =IF(D23="","",COUNTIF(Contagem_PF!C$8:C$606,D23)) -> 0 | F23: =SUMIF(Contagem_PF!$C$8:$C$606,Deflatores!G17,Contagem_PF!$J$8:$J$606) -> 0 | G23: =IF(ISBLANK(Deflatores!H17),"",Deflatores!H17) -> 1 | H23: =IF(ISBLANK(Deflatores!I17),"",Deflatores!I17) | I23: =Deflatores!K17 -> 0 | J23: =IF($L$11<>0,I23/$L$11,"")
B24: =""&Deflatores!B18 -> Mudança de Plataforma - Banco de Dados (mesmo paradigma com alterações) | D24: =""&Deflatores!G18 -> MBM | E24: =IF(D24="","",COUNTIF(Contagem_PF!C$8:C$606,D24)) -> 0 | F24: =SUMIF(Contagem_PF!$C$8:$C$606,Deflatores!G18,Contagem_PF!$J$8:$J$606) -> 0 | G24: =IF(ISBLANK(Deflatores!H18),"",Deflatores!H18) -> 0.3 | H24: =IF(ISBLANK(Deflatores!I18),"",Deflatores!I18) | I24: =Deflatores!K18 -> 0 | J24: =IF($L$11<>0,I24/$L$11,"")
B25: =""&Deflatores!B19 -> Atualização de Versão – Linguagem de Programação | D25: =""&Deflatores!G19 -> ALP | E25: =IF(D25="","",COUNTIF(Contagem_PF!C$8:C$606,D25)) -> 0 | F25: =SUMIF(Contagem_PF!$C$8:$C$606,Deflatores!G19,Contagem_PF!$J$8:$J$606) -> 0 | G25: =IF(ISBLANK(Deflatores!H19),"",Deflatores!H19) -> 0.3 | H25: =IF(ISBLANK(Deflatores!I19),"",Deflatores!I19) | I25: =Deflatores!K19 -> 0 | J25: =IF($L$11<>0,I25/$L$11,"")
B26: =""&Deflatores!B20 -> Atualização de Versão – Browser | D26: =""&Deflatores!G20 -> AVB | E26: =IF(D26="","",COUNTIF(Contagem_PF!C$8:C$606,D26)) -> 0 | F26: =SUMIF(Contagem_PF!$C$8:$C$606,Deflatores!G20,Contagem_PF!$J$8:$J$606) -> 0 | G26: =IF(ISBLANK(Deflatores!H20),"",Deflatores!H20) -> 0.3 | H26: =IF(ISBLANK(Deflatores!I20),"",Deflatores!I20) | I26: =Deflatores!K20 -> 0 | J26: =IF($L$11<>0,I26/$L$11,"")
... B44: =""&Deflatores!B38 | D44: =""&Deflatores!G38 -> . | E44: =IF(D44="","",COUNTIF(Contagem_PF!C$8:C$606,D44)) -> 0 | F44: =SUMIF(Contagem_PF!$C$8:$C$606,Deflatores!G38,Contagem_PF!$J$8:$J$606) -> 0 | G44: =IF(ISBLANK(Deflatores!H38),"",Deflatores!H38) | H44: =IF(ISBLANK(Deflatores!I38),"",Deflatores!I38) | I44: =Deflatores!K38 -> 0 | J44: =IF($L$11<>0,I44/$L$11,"")
B46: Itens não Funcionais (Tipo de Função) | E46: Quantidade | H46: Contrib. Fixa | I46: PF Deflator FS | J46: % LOCAL
B47: =""&Deflatores!B42 -> Páginas Estáticas | D47: =""&Deflatores!G42 -> PAG | E47: =Deflatores!J42 -> 0 | H47: =IF(ISBLANK(Deflatores!H42),"",Deflatores!H42) -> 0.6 | I47: =IF(ISNUMBER(H47),E47*H47,"") -> 0 | J47: =IF(ISNUMBER(I47),IF($L$11<>0,I47/$L$11,""),"")
B48: =""&Deflatores!B43 -> Manutenção Cosmética (atrelada a algo não funcional) | D48: =""&Deflatores!G43 -> COSNF | E48: =Deflatores!J43 -> 0 | H48: =IF(ISBLANK(Deflatores!H43),"",Deflatores!H43) -> 0.6 | I48: =IF(ISNUMBER(H48),E48*H48,"") -> 0 | J48: =IF(ISNUMBER(I48),IF($L$11<>0,I48/$L$11,""),"")
B49: =""&Deflatores!B44 -> Dados de Código | D49: =""&Deflatores!G44 -> DC | E49: =Deflatores!J44 -> 0 | H49: =IF(ISBLANK(Deflatores!H44),"",Deflatores!H44) -> 0 | I49: =IF(ISNUMBER(H49),E49*H49,"") -> 0 | J49: =IF(ISNUMBER(I49),IF($L$11<>0,I49/$L$11,""),"")
B50: =""&Deflatores!B45 | D50: =""&Deflatores!G45 -> . | E50: =Deflatores!J45 -> 0 | H50: =IF(ISBLANK(Deflatores!H45),"",Deflatores!H45) | I50: =IF(ISNUMBER(H50),E50*H50,"") | J50: =IF(ISNUMBER(I50),IF($L$11<>0,I50/$L$11,""),"")
B51: =""&Deflatores!B46 | D51: =""&Deflatores!G46 -> . | E51: =Deflatores!J46 -> 0 | H51: =IF(ISBLANK(Deflatores!H46),"",Deflatores!H46) | I51: =IF(ISNUMBER(H51),E51*H51,"") | J51: =IF(ISNUMBER(I51),IF($L$11<>0,I51/$L$11,""),"")
B52: =""&Deflatores!B47 | D52: =""&Deflatores!G47 -> . | E52: =Deflatores!J47 -> 0 | H52: =IF(ISBLANK(Deflatores!H47),"",Deflatores!H47) | I52: =IF(ISNUMBER(H52),E52*H52,"") | J52: =IF(ISNUMBER(I52),IF($L$11<>0,I52/$L$11,""),"")
B53: =""&Deflatores!B48 | D53: =""&Deflatores!G48 -> . | E53: =Deflatores!J48 -> 0 | H53: =IF(ISBLANK(Deflatores!H48),"",Deflatores!H48) | I53: =IF(ISNUMBER(H53),E53*H53,"") | J53: =IF(ISNUMBER(I53),IF($L$11<>0,I53/$L$11,""),"")
B54: =""&Deflatores!B49 | D54: =""&Deflatores!G49 -> . | E54: =Deflatores!J49 -> 0 | H54: =IF(ISBLANK(Deflatores!H49),"",Deflatores!H49) | I54: =IF(ISNUMBER(H54),E54*H54,"") | J54: =IF(ISNUMBER(I54),IF($L$11<>0,I54/$L$11,""),"")
B55: =""&Deflatores!B50 | D55: =""&Deflatores!G50 -> . | E55: =Deflatores!J50 -> 0 | H55: =IF(ISBLANK(Deflatores!H50),"",Deflatores!H50) | I55: =IF(ISNUMBER(H55),E55*H55,"") | J55: =IF(ISNUMBER(I55),IF($L$11<>0,I55/$L$11,""),"")
B56: =""&Deflatores!B51 | D56: =""&Deflatores!G51 -> . | E56: =Deflatores!J51 -> 0 | H56: =IF(ISBLANK(Deflatores!H51),"",Deflatores!H51) | I56: =IF(ISNUMBER(H56),E56*H56,"") | J56: =IF(ISNUMBER(I56),IF($L$11<>0,I56/$L$11,""),"")
B57: =""&Deflatores!B52 | D57: =""&Deflatores!G52 -> . | E57: =Deflatores!J52 -> 0 | H57: =IF(ISBLANK(Deflatores!H52),"",Deflatores!H52) | I57: =IF(ISNUMBER(H57),E57*H57,"") | J57: =IF(ISNUMBER(I57),IF($L$11<>0,I57/$L$11,""),"")
B58: =""&Deflatores!B53 | D58: =""&Deflatores!G53 -> . | E58: =Deflatores!J53 -> 0 | H58: =IF(ISBLANK(Deflatores!H53),"",Deflatores!H53) | I58: =IF(ISNUMBER(H58),E58*H58,"") | J58: =IF(ISNUMBER(I58),IF($L$11<>0,I58/$L$11,""),"")
... B69: =""&Deflatores!B64 | D69: =""&Deflatores!G64 -> . | E69: =Deflatores!J64 -> 0 | H69: =IF(ISBLANK(Deflatores!H64),"",Deflatores!H64) | I69: =IF(ISNUMBER(H69),E69*H69,"") | J69: =IF(ISNUMBER(I69),IF($L$11<>0,I69/$L$11,""),"")
