Workbook
Name INM: 'Tipo Projeto'!$J$3:INDEX('Tipo Projeto'!$J$3:$J$100,COUNTIF('Tipo Projeto'!$J$3:$J$100,"?*"))
Name Matriz_INM: 'Tipo Projeto'!$J$3:$L$40
Name Matriz_UST: 'Tipo Projeto'!$D$3:INDEX('Tipo Projeto'!$D$3:$D$100,COUNTIF('Tipo Projeto'!$D$3:$D$100,"?*"))
Name PF_INM: 'AFP - INM'!$S$385
Name PF_UST: UST!$D$5
Name Print_Titles_0: 'AFP - Detalhada'!$1:$9
Name Print_Titles_0: 'AFP - Estimativa'!$1:$9
Name Print_Titles_0: 'AFP - Indicativa'!$1:$9
Name Print_Titles_0: 'AFP - INM'!$1:$9
Name Print_Titles_0: UST!$1:$9
Name Print_Titles_0_0: 'AFP - Detalhada'!$1:$9
Name Print_Titles_0_0: 'AFP - Estimativa'!$1:$9
Name Print_Titles_0_0: 'AFP - Indicativa'!$1:$9
Name Print_Titles_0_0: 'AFP - INM'!$1:$9
Name Print_Titles_0_0: UST!$1:$9
Name Print_Titles_0_0_0: 'AFP - Detalhada'!$1:$9
Name Print_Titles_0_0_0: 'AFP - Estimativa'!$1:$9
Name Print_Titles_0_0_0: 'AFP - Indicativa'!$1:$9
Name Print_Titles_0_0_0: 'AFP - INM'!$1:$9
Name Print_Titles_0_0_0: UST!$1:$9
Name Print_Titles_0_0_0_0: 'AFP - Detalhada'!$1:$9
Name Print_Titles_0_0_0_0: 'AFP - Estimativa'!$1:$9
Name Print_Titles_0_0_0_0: 'AFP - Indicativa'!$1:$9
Name Print_Titles_0_0_0_0: 'AFP - INM'!$1:$9
Name Print_Titles_0_0_0_0: UST!$1:$9
Name Tipo_Contagem: Resumo!$B$5
Name TipoProjeto: 'Tipo Projeto'!$A$3:INDEX('Tipo Projeto'!$A$3:$A$100,COUNTIF('Tipo Projeto'!$A$3:$A$100,"?*"))
Name TipoSistema: 'Tipo Sistema'!$A$2:$A$8
Name UST: 'Tipo Projeto'!$D$2:$D$53

Sheet Instrução de Uso

Sheet Resumo
A1: Template V.2.0 | B1: Contagem de Pontos de Função
A3: Identificação
A4: O.S.: | E4: Tipo de Atividade: | F4: Desenvolvimento ou Manutenção
A5: Tipo de Contagem: | E5: Aplicação:
A6: Elaborador da contagem: | E6: Data da Contagem: | F6: =IF($B$5="Detalhada",IF('AFP - Detalhada'!N4<>"",'AFP - Detalhada'!N4,""),IF($B$5="Estimativa",IF('AFP - Estimativa'!H4<>"",'AFP - Estimativa'!H4,""),IF($B$5="Indicativa",IF('AFP - Indicativa'!G4<>"",'AFP - Indicativa'!G4,""),"")))
A7: Revisor da contagem: | B7: =IF($B$5="Detalhada",IF('AFP - Detalhada'!N5<>"",'AFP - Detalhada'!N5,""),IF($B$5="Estimativa",IF('AFP - Estimativa'!H5<>"",'AFP - Estimativa'!H5,""),IF($B$5="Indicativa",IF('AFP - Indicativa'!G5<>"",'AFP - Indicativa'!G5,""),""))) | E7: Data da Revisão: | F7: =IF($B$5="Detalhada",IF('AFP - Detalhada'!N6<>"",'AFP - Detalhada'!N6,""),IF($B$5="Estimativa",IF('AFP - Estimativa'!H6<>"",'AFP - Estimativa'!H6,""),IF($B$5="Indicativa",IF('AFP - Indicativa'!G6<>"",'AFP - Indicativa'!G6,""),"")))
A9: Propósito da Contagem
A12: Escopo da Contagem
A15: Quadro Resumo | E15: Projeto de Desenvolvimento e Manutenção
A16: Arquivo Lógico Interno (ALI) | C16: =IF((IF($B$5="Detalhada",SUMIF('AFP - Detalhada'!$G$10:$G$1324,"ALI",'AFP - Detalhada'!$Q$10:$Q$1324),IF($B$5="Estimativa",SUMIF('AFP - Estimativa'!$H$10:$H$1082,"ALI",'AFP - Estimativa'!$I$10:$I$1082)*(1+'AFP - Estimativa'!$C$6),IF($B$5="Indicativa",SUMIF('AFP - Indicativa'!$G$10:$G$108,"ALI",'AFP - Indicativa'!$H$10:$H$108)*(1+'AFP - Indicativa'!$E$6))))),IF($B$5="Detalhada",SUMIF('AFP - Detalhada'!$G$10:$G$1324,"ALI",'AFP - Detalhada'!$Q$10:$Q$1324),IF($B$5="Estimativa",SUMIF('AFP - Estimativa'!$H$10:$H$1082,"ALI",'AFP - Estimativa'!$I$10:$I$1082)*(1+'AFP - Estimativa'!$C$6),IF($B$5="Indicativa",SUMIF('AFP - Indicativa'!$G$10:$G$108,"ALI",'AFP - Indicativa'!$H$10:$H$108)*(1+'AFP - Indicativa'!$E$6)))),"") | E16: Distribuição de Esforço por Fase do Projeto (conforme item 6.1.2.1 do SISP 2.0)
A17: Arquivo de Interface Externa (AIE) | C17: =IF((IF($B$5="Detalhada",SUMIF('AFP - Detalhada'!$G$10:$G$1324,"AIE",'AFP - Detalhada'!$Q$10:$Q$1324),IF($B$5="Estimativa",SUMIF('AFP - Estimativa'!$H$10:$H$1082,"AIE",'AFP - Estimativa'!$I$10:$I$1082)*(1+'AFP - Estimativa'!$C$6),IF($B$5="Indicativa",SUMIF('AFP - Indicativa'!$G$10:$G$108,"AIE",'AFP - Indicativa'!$H$10:$H$108)*(1+'AFP - Indicativa'!$E$6))))),(IF($B$5="Detalhada",SUMIF('AFP - Detalhada'!$G$10:$G$1324,"AIE",'AFP - Detalhada'!$Q$10:$Q$1324),IF($B$5="Estimativa",SUMIF('AFP - Estimativa'!$H$10:$H$1082,"AIE",'AFP - Estimativa'!$I$10:$I$1082)*(1+'AFP - Estimativa'!$C$6),IF($B$5="Indicativa",SUMIF('AFP - Indicativa'!$G$10:$G$108,"AIE",'AFP - Indicativa'!$H$10:$H$108)*(1+'AFP - Indicativa'!$E$6))))),"")
A18: Consulta Externa (CE) | C18: =IF($B$5="Detalhada",SUMIF('AFP - Detalhada'!$G$10:$G$1324,"CE",'AFP - Detalhada'!$Q$10:$Q$1324),IF($B$5="Estimativa",SUMIF('AFP - Estimativa'!$H$10:$H$1082,"CE",'AFP - Estimativa'!$I$10:$I$1082)*(1+'AFP - Estimativa'!$C$6),"")) | E18: Implementação | G18: 0.4
A19: Entrada Externa (EE) | C19: =IF($B$5="Detalhada",SUMIF('AFP - Detalhada'!$G$10:$G$1324,"EE",'AFP - Detalhada'!$Q$10:$Q$1324),IF($B$5="Estimativa",SUMIF('AFP - Estimativa'!$H$10:$H$1082,"EE",'AFP - Estimativa'!$I$10:$I$1082)*(1+'AFP - Estimativa'!$C$6),"")) | E19: Design e Arquitetura | G19: 0.1
A20: Saída Externa (SE) | C20: =IF($B$5="Detalhada",SUMIF('AFP - Detalhada'!$G$10:$G$1324,"SE",'AFP - Detalhada'!$Q$10:$Q$1324),IF($B$5="Estimativa",SUMIF('AFP - Estimativa'!$H$10:$H$1082,"SE",'AFP - Estimativa'!$I$10:$I$1082)*(1+'AFP - Estimativa'!$C$6),"")) | E20: Engenharia de Requisitos | G20: 0.25
A21: INM | C21: =PF_INM -> 0 | E21: Implantação | G21: 0.05
A22: UST | C22: =UST!K404 -> 0 | E22: Homologação | G22: 0.05
A23: Total (A) | C23: =SUM(C16:C22) -> 0 | E23: Testes | G23: 0.15
E24: Percentual de Esforço (E) | G24: =SUM(G18:G23) -> 1
A25: Projeto de Redocumentação de Requisitos
E26: =CONCATENATE("Quantidade Final (A) x ",IF(F4<>"",IF(F4="Desenvolvimento ou manutenção","(E1)","(E2)"),"")) -> Quantidade Final (A) x (E1) | G26: =C23*IF(F4<>"",IF(F4="Desenvolvimento ou manutenção",G24,C30),0) -> 0
A27: Distribuição de Esforço conforme item 4.11 do SISP | E27: Fator de criticidade | G27: 1
E28: Quantidade Final Ajustada | G28: =G26*G27 -> 0
A29: Redocumentação somente requisitos | C29: 0.2 | E29: Total de PF Bruto | G29: =IF(Tipo_Contagem="Estimativa",(SUM('AFP - Estimativa'!K11:K1081))+'AFP - INM'!S385,IF(Tipo_Contagem="Detalhada",(SUM('AFP - Detalhada'!O10:P1323))+'AFP - INM'!S385,'AFP - Indicativa'!H109)) -> 0
A30: Percentual de Esforço (E2) | C30: =SUM(C29:C29) -> 0.2

Sheet AFP - Detalhada
A1: =Resumo!A1 -> Template V.2.0 | C1: Contagem de Pontos de Função Contagem Detalhada
G3: Elaborador da contagem: | T3: Validação/Controle de Divergência Fábrica de Métricas/Cliente | W3: Elaborador da contagem: | AD3: Fábrica de Métricas
E4: Situação: | G4: Data da Contagem: | W4: Data da Contagem:
A5: Contagem Fábrica de Software: | D5: =$Q$1325+'AFP - INM'!$S385 -> 0 | E5: =IF(D6=0,"",IF(D5<>D6,"Em Divergência","Concluído")) | G5: Revisor da contagem: | W5: Revisor da contagem:
A6: Contagem Fábrica de Métricas: | D6: =$AG$1325+'AFP - INM'!$AI385 -> 0 | G6: Data da Revisão: | W6: Data da Revisão:
A8: ID | B8: Tipo Projeto | C8: Fator Ajuste | D8: Módulo | E8: Requisito | F8: Processos elementares | G8: Tipo | H8: TD / DER | J8: RLR / ALR | N8: Complexidade | Q8: PF | R8: Observação/Parecer Técnico | T8: Validação | U8: Tipo Projeto | V8: Fator Ajuste | W8: Tipo | X8: TD / DER | Z8: RLR / ALR | AD8: Complexidade | AG8: PF | AH8: Parecer Técnico | AJ8: Resposta Fábrica de Software | AL8: Parecer Final | AM8: Validação Final
H9: Qtd. | I9: Descrição | J9: Qtd. | K9: Descrição | L9: C_T | M9: C_D | O9: PF_T | P9: PF_D | X9: Qtd. | Y9: Descrição | Z9: Qtd. | AA9: Descrição | AB9: C_T | AC9: C_D | AE9: PF_T | AF9: PF_D
C10: =IF(B10<>"",VLOOKUP(B10,'Tipo Projeto'!$A$3:$B$35,2,0),0) -> 0 | L10: =IF(G10="EE",IF(OR(AND(OR(J10=1,J10=0),H10>0,H10<5),AND(OR(J10=1,J10=0),H10>4,H10<16),AND(J10=2,H10>0,H10<5)),"Simples",IF(OR(AND(OR(J10=1,J10=0),H10>15),AND(J10=2,H10>4,H10<16),AND(J10>2,H10>0,H10<5)),"Médio",IF(OR(AND(J10=2,H10>15),AND(J10>2,H10>4,H10<16),AND(J10>2,H10>15)),"Complexo",""))), IF(OR(G10="CE",G10="SE"),IF(OR(AND(OR(J10=1,J10=0),H10>0,H10<6),AND(OR(J10=1,J10=0),H10>5,H10<20),AND(J10>1,J10<4,H10>0,H10<6)),"Simples",IF(OR(AND(OR(J10=1,J10=0),H10>19),AND(J10>1,J10<4,H10>5,H10<20),AND(J10>3,H10>0,H10<6)),"Médio",IF(OR(AND(J10>1,J10<4,H10>19),AND(J10>3,H10>5,H10<20),AND(J10>3,H10>19)),"Complexo",""))),"")) | M10: =IF(G10="ALI",IF(OR(AND(OR(J10=1,J10=0),H10>0,H10<20),AND(OR(J10=1,J10=0),H10>19,H10<51),AND(J10>1,J10<6,H10>0,H10<20)),"Simples",IF(OR(AND(OR(J10=1,J10=0),H10>50),AND(J10>1,J10<6,H10>19,H10<51),AND(J10>5,H10>0,H10<20)),"Médio",IF(OR(AND(J10>1,J10<6,H10>50),AND(J10>5,H10>19,H10<51),AND(J10>5,H10>50)),"Complexo",""))), IF(G10="AIE",IF(OR(AND(OR(J10=1, J10=0),H10>0,H10<20),AND(OR(J10=1, J10=0),H10>19,H10<51),AND(J10>1,J10<6,H10>0,H10<20)),"Simples",IF(OR(AND(OR(J10=1, J10=0),H10>50),AND(J10>1,J10<6,H10>19,H10<51),AND(J10>5,H10>0,H10<20)),"Médio",IF(OR(AND(J10>1,J10<6,H10>50),AND(J10>5,H10>19,H10<51),AND(J10>5,H10>50)),"Complexo",""))),"")) | N10: =IF(L10="",M10,IF(M10="",L10,"")) | O10: =IF(AND(OR(G10="EE",G10="CE"),N10="Simples"),3, IF(AND(OR(G10="EE",G10="CE"),N10="Médio"),4, IF(AND(OR(G10="EE",G10="CE"),N10="Complexo"),6, IF(AND(G10="SE",N10="Simples"),4, IF(AND(G10="SE",N10="Médio"),5, IF(AND(G10="SE",N10="Complexo"),7,0)))))) -> 0 | P10: =IF(AND(G10="ALI",M10="Simples"),7, IF(AND(G10="ALI",M10="Médio"),10, IF(AND(G10="ALI",M10="Complexo"),15, IF(AND(G10="AIE",M10="Simples"),5, IF(AND(G10="AIE",M10="Médio"),7, IF(AND(G10="AIE",M10="Complexo"),10,0)))))) -> 0 | Q10: =IF(B10<>"Manutenção em interface",IF(B10<>"Desenv., Manutenção e Publicação de Páginas Estáticas",(O10+P10)*C10,C10),C10) -> 0 | V10: =IF(U10<>"",VLOOKUP(U10,'Tipo Projeto'!$A$3:$B$35,2,0),0) -> 0 | AB10: =IF(W10="EE",IF(OR(AND(OR(Z10=1,Z10=0),X10>0,X10<5),AND(OR(Z10=1,Z10=0),X10>4,X10<16),AND(Z10=2,X10>0,X10<5)),"Simples",IF(OR(AND(OR(Z10=1,Z10=0),X10>15),AND(Z10=2,X10>4,X10<16),AND(Z10>2,X10>0,X10<5)),"Médio",IF(OR(AND(Z10=2,X10>15),AND(Z10>2,X10>4,X10<16),AND(Z10>2,X10>15)),"Complexo",""))), IF(OR(W10="CE",W10="SE"),IF(OR(AND(OR(Z10=1,Z10=0),X10>0,X10<6),AND(OR(Z10=1,Z10=0),X10>5,X10<20),AND(Z10>1,Z10<4,X10>0,X10<6)),"Simples",IF(OR(AND(OR(Z10=1,Z10=0),X10>19),AND(Z10>1,Z10<4,X10>5,X10<20),AND(Z10>3,X10>0,X10<6)),"Médio",IF(OR(AND(Z10>1,Z10<4,X10>19),AND(Z10>3,X10>5,X10<20),AND(Z10>3,X10>19)),"Complexo",""))),"")) | AC10: =IF(W10="ALI",IF(OR(AND(OR(Z10=1,Z10=0),X10>0,X10<20),AND(OR(Z10=1,Z10=0),X10>19,X10<51),AND(Z10>1,Z10<6,X10>0,X10<20)),"Simples",IF(OR(AND(OR(Z10=1,Z10=0),X10>50),AND(Z10>1,Z10<6,X10>19,X10<51),AND(Z10>5,X10>0,X10<20)),"Médio",IF(OR(AND(Z10>1,Z10<6,X10>50),AND(Z10>5,X10>19,X10<51),AND(Z10>5,X10>50)),"Complexo",""))), IF(W10="AIE",IF(OR(AND(OR(Z10=1, Z10=0),X10>0,X10<20),AND(OR(Z10=1, Z10=0),X10>19,X10<51),AND(Z10>1,Z10<6,X10>0,X10<20)),"Simples",IF(OR(AND(OR(Z10=1, Z10=0),X10>50),AND(Z10>1,Z10<6,X10>19,X10<51),AND(Z10>5,X10>0,X10<20)),"Médio",IF(OR(AND(Z10>1,Z10<6,X10>50),AND(Z10>5,X10>19,X10<51),AND(Z10>5,X10>50)),"Complexo",""))),"")) | AD10: =IF(AB10="",AC10,IF(AC10="",AB10,"")) | AE10: =IF(AND(OR(W10="EE",W10="CE"),AD10="Simples"),3, IF(AND(OR(W10="EE",W10="CE"),AD10="Médio"),4, IF(AND(OR(W10="EE",W10="CE"),AD10="Complexo"),6, IF(AND(W10="SE",AD10="Simples"),4, IF(AND(W10="SE",AD10="Médio"),5, IF(AND(W10="SE",AD10="Complexo"),7,0)))))) -> 0 | AF10: =IF(AND(W10="ALI",AC10="Simples"),7, IF(AND(W10="ALI",AC10="Médio"),10, IF(AND(W10="ALI",AC10="Complexo"),15, IF(AND(W10="AIE",AC10="Simples"),5, IF(AND(W10="AIE",AC10="Médio"),7, IF(AND(W10="AIE",AC10="Complexo"),10,0)))))) -> 0 | AG10: =IF(T10="OK",Q10,( IF(U10<>"Manutenção em interface",IF(U10<>"Desenv., Manutenção e Publicação de Páginas Estáticas",(AE10+AF10)*V10,V10),V10))) -> 0 | AM10: =IF(AG10=0,"",IF(AG10=Q10,"OK","Divergente"))
C11: =IF(B11<>"",VLOOKUP(B11,'Tipo Projeto'!$A$3:$B$35,2,0),0) -> 0 | L11: =IF(G11="EE",IF(OR(AND(OR(J11=1,J11=0),H11>0,H11<5),AND(OR(J11=1,J11=0),H11>4,H11<16),AND(J11=2,H11>0,H11<5)),"Simples",IF(OR(AND(OR(J11=1,J11=0),H11>15),AND(J11=2,H11>4,H11<16),AND(J11>2,H11>0,H11<5)),"Médio",IF(OR(AND(J11=2,H11>15),AND(J11>2,H11>4,H11<16),AND(J11>2,H11>15)),"Complexo",""))), IF(OR(G11="CE",G11="SE"),IF(OR(AND(OR(J11=1,J11=0),H11>0,H11<6),AND(OR(J11=1,J11=0),H11>5,H11<20),AND(J11>1,J11<4,H11>0,H11<6)),"Simples",IF(OR(AND(OR(J11=1,J11=0),H11>19),AND(J11>1,J11<4,H11>5,H11<20),AND(J11>3,H11>0,H11<6)),"Médio",IF(OR(AND(J11>1,J11<4,H11>19),AND(J11>3,H11>5,H11<20),AND(J11>3,H11>19)),"Complexo",""))),"")) | M11: =IF(G11="ALI",IF(OR(AND(OR(J11=1,J11=0),H11>0,H11<20),AND(OR(J11=1,J11=0),H11>19,H11<51),AND(J11>1,J11<6,H11>0,H11<20)),"Simples",IF(OR(AND(OR(J11=1,J11=0),H11>50),AND(J11>1,J11<6,H11>19,H11<51),AND(J11>5,H11>0,H11<20)),"Médio",IF(OR(AND(J11>1,J11<6,H11>50),AND(J11>5,H11>19,H11<51),AND(J11>5,H11>50)),"Complexo",""))), IF(G11="AIE",IF(OR(AND(OR(J11=1, J11=0),H11>0,H11<20),AND(OR(J11=1, J11=0),H11>19,H11<51),AND(J11>1,J11<6,H11>0,H11<20)),"Simples",IF(OR(AND(OR(J11=1, J11=0),H11>50),AND(J11>1,J11<6,H11>19,H11<51),AND(J11>5,H11>0,H11<20)),"Médio",IF(OR(AND(J11>1,J11<6,H11>50),AND(J11>5,H11>19,H11<51),AND(J11>5,H11>50)),"Complexo",""))),"")) | N11: =IF(L11="",M11,IF(M11="",L11,"")) | O11: =IF(AND(OR(G11="EE",G11="CE"),N11="Simples"),3, IF(AND(OR(G11="EE",G11="CE"),N11="Médio"),4, IF(AND(OR(G11="EE",G11="CE"),N11="Complexo"),6, IF(AND(G11="SE",N11="Simples"),4, IF(AND(G11="SE",N11="Médio"),5, IF(AND(G11="SE",N11="Complexo"),7,0)))))) -> 0 | P11: =IF(AND(G11="ALI",M11="Simples"),7, IF(AND(G11="ALI",M11="Médio"),10, IF(AND(G11="ALI",M11="Complexo"),15, IF(AND(G11="AIE",M11="Simples"),5, IF(AND(G11="AIE",M11="Médio"),7, IF(AND(G11="AIE",M11="Complexo"),10,0)))))) -> 0 | Q11: =IF(B11<>"Manutenção em interface",IF(B11<>"Desenv., Manutenção e Publicação de Páginas Estáticas",(O11+P11)*C11,C11),C11) -> 0 | V11: =IF(U11<>"",VLOOKUP(U11,'Tipo Projeto'!$A$3:$B$35,2,0),0) -> 0 | AB11: =IF(W11="EE",IF(OR(AND(OR(Z11=1,Z11=0),X11>0,X11<5),AND(OR(Z11=1,Z11=0),X11>4,X11<16),AND(Z11=2,X11>0,X11<5)),"Simples",IF(OR(AND(OR(Z11=1,Z11=0),X11>15),AND(Z11=2,X11>4,X11<16),AND(Z11>2,X11>0,X11<5)),"Médio",IF(OR(AND(Z11=2,X11>15),AND(Z11>2,X11>4,X11<16),AND(Z11>2,X11>15)),"Complexo",""))), IF(OR(W11="CE",W11="SE"),IF(OR(AND(OR(Z11=1,Z11=0),X11>0,X11<6),AND(OR(Z11=1,Z11=0),X11>5,X11<20),AND(Z11>1,Z11<4,X11>0,X11<6)),"Simples",IF(OR(AND(OR(Z11=1,Z11=0),X11>19),AND(Z11>1,Z11<4,X11>5,X11<20),AND(Z11>3,X11>0,X11<6)),"Médio",IF(OR(AND(Z11>1,Z11<4,X11>19),AND(Z11>3,X11>5,X11<20),AND(Z11>3,X11>19)),"Complexo",""))),"")) | AC11: =IF(W11="ALI",IF(OR(AND(OR(Z11=1,Z11=0),X11>0,X11<20),AND(OR(Z11=1,Z11=0),X11>19,X11<51),AND(Z11>1,Z11<6,X11>0,X11<20)),"Simples",IF(OR(AND(OR(Z11=1,Z11=0),X11>50),AND(Z11>1,Z11<6,X11>19,X11<51),AND(Z11>5,X11>0,X11<20)),"Médio",IF(OR(AND(Z11>1,Z11<6,X11>50),AND(Z11>5,X11>19,X11<51),AND(Z11>5,X11>50)),"Complexo",""))), IF(W11="AIE",IF(OR(AND(OR(Z11=1, Z11=0),X11>0,X11<20),AND(OR(Z11=1, Z11=0),X11>19,X11<51),AND(Z11>1,Z11<6,X11>0,X11<20)),"Simples",IF(OR(AND(OR(Z11=1, Z11=0),X11>50),AND(Z11>1,Z11<6,X11>19,X11<51),AND(Z11>5,X11>0,X11<20)),"Médio",IF(OR(AND(Z11>1,Z11<6,X11>50),AND(Z11>5,X11>19,X11<51),AND(Z11>5,X11>50)),"Complexo",""))),"")) | AD11: =IF(AB11="",AC11,IF(AC11="",AB11,"")) | AE11: =IF(AND(OR(W11="EE",W11="CE"),AD11="Simples"),3, IF(AND(OR(W11="EE",W11="CE"),AD11="Médio"),4, IF(AND(OR(W11="EE",W11="CE"),AD11="Complexo"),6, IF(AND(W11="SE",AD11="Simples"),4, IF(AND(W11="SE",AD11="Médio"),5, IF(AND(W11="SE",AD11="Complexo"),7,0)))))) -> 0 | AF11: =IF(AND(W11="ALI",AC11="Simples"),7, IF(AND(W11="ALI",AC11="Médio"),10, IF(AND(W11="ALI",AC11="Complexo"),15, IF(AND(W11="AIE",AC11="Simples"),5, IF(AND(W11="AIE",AC11="Médio"),7, IF(AND(W11="AIE",AC11="Complexo"),10,0)))))) -> 0 | AG11: =IF(T11="OK",Q11,( IF(U11<>"Manutenção em interface",IF(U11<>"Desenv., Manutenção e Publicação de Páginas Estáticas",(AE11+AF11)*V11,V11),V11))) -> 0 | AM11: =IF(AG11=0,"",IF(AG11=Q11,"OK","Divergente"))
C12: =IF(B12<>"",VLOOKUP(B12,'Tipo Projeto'!$A$3:$B$35,2,0),0) -> 0 | L12: =IF(G12="EE",IF(OR(AND(OR(J12=1,J12=0),H12>0,H12<5),AND(OR(J12=1,J12=0),H12>4,H12<16),AND(J12=2,H12>0,H12<5)),"Simples",IF(OR(AND(OR(J12=1,J12=0),H12>15),AND(J12=2,H12>4,H12<16),AND(J12>2,H12>0,H12<5)),"Médio",IF(OR(AND(J12=2,H12>15),AND(J12>2,H12>4,H12<16),AND(J12>2,H12>15)),"Complexo",""))), IF(OR(G12="CE",G12="SE"),IF(OR(AND(OR(J12=1,J12=0),H12>0,H12<6),AND(OR(J12=1,J12=0),H12>5,H12<20),AND(J12>1,J12<4,H12>0,H12<6)),"Simples",IF(OR(AND(OR(J12=1,J12=0),H12>19),AND(J12>1,J12<4,H12>5,H12<20),AND(J12>3,H12>0,H12<6)),"Médio",IF(OR(AND(J12>1,J12<4,H12>19),AND(J12>3,H12>5,H12<20),AND(J12>3,H12>19)),"Complexo",""))),"")) | M12: =IF(G12="ALI",IF(OR(AND(OR(J12=1,J12=0),H12>0,H12<20),AND(OR(J12=1,J12=0),H12>19,H12<51),AND(J12>1,J12<6,H12>0,H12<20)),"Simples",IF(OR(AND(OR(J12=1,J12=0),H12>50),AND(J12>1,J12<6,H12>19,H12<51),AND(J12>5,H12>0,H12<20)),"Médio",IF(OR(AND(J12>1,J12<6,H12>50),AND(J12>5,H12>19,H12<51),AND(J12>5,H12>50)),"Complexo",""))), IF(G12="AIE",IF(OR(AND(OR(J12=1, J12=0),H12>0,H12<20),AND(OR(J12=1, J12=0),H12>19,H12<51),AND(J12>1,J12<6,H12>0,H12<20)),"Simples",IF(OR(AND(OR(J12=1, J12=0),H12>50),AND(J12>1,J12<6,H12>19,H12<51),AND(J12>5,H12>0,H12<20)),"Médio",IF(OR(AND(J12>1,J12<6,H12>50),AND(J12>5,H12>19,H12<51),AND(J12>5,H12>50)),"Complexo",""))),"")) | N12: =IF(L12="",M12,IF(M12="",L12,"")) | O12: =IF(AND(OR(G12="EE",G12="CE"),N12="Simples"),3, IF(AND(OR(G12="EE",G12="CE"),N12="Médio"),4, IF(AND(OR(G12="EE",G12="CE"),N12="Complexo"),6, IF(AND(G12="SE",N12="Simples"),4, IF(AND(G12="SE",N12="Médio"),5, IF(AND(G12="SE",N12="Complexo"),7,0)))))) -> 0 | P12: =IF(AND(G12="ALI",M12="Simples"),7, IF(AND(G12="ALI",M12="Médio"),10, IF(AND(G12="ALI",M12="Complexo"),15, IF(AND(G12="AIE",M12="Simples"),5, IF(AND(G12="AIE",M12="Médio"),7, IF(AND(G12="AIE",M12="Complexo"),10,0)))))) -> 0 | Q12: =IF(B12<>"Manutenção em interface",IF(B12<>"Desenv., Manutenção e Publicação de Páginas Estáticas",(O12+P12)*C12,C12),C12) -> 0 | V12: =IF(U12<>"",VLOOKUP(U12,'Tipo Projeto'!$A$3:$B$35,2,0),0) -> 0 | AB12: =IF(W12="EE",IF(OR(AND(OR(Z12=1,Z12=0),X12>0,X12<5),AND(OR(Z12=1,Z12=0),X12>4,X12<16),AND(Z12=2,X12>0,X12<5)),"Simples",IF(OR(AND(OR(Z12=1,Z12=0),X12>15),AND(Z12=2,X12>4,X12<16),AND(Z12>2,X12>0,X12<5)),"Médio",IF(OR(AND(Z12=2,X12>15),AND(Z12>2,X12>4,X12<16),AND(Z12>2,X12>15)),"Complexo",""))), IF(OR(W12="CE",W12="SE"),IF(OR(AND(OR(Z12=1,Z12=0),X12>0,X12<6),AND(OR(Z12=1,Z12=0),X12>5,X12<20),AND(Z12>1,Z12<4,X12>0,X12<6)),"Simples",IF(OR(AND(OR(Z12=1,Z12=0),X12>19),AND(Z12>1,Z12<4,X12>5,X12<20),AND(Z12>3,X12>0,X12<6)),"Médio",IF(OR(AND(Z12>1,Z12<4,X12>19),AND(Z12>3,X12>5,X12<20),AND(Z12>3,X12>19)),"Complexo",""))),"")) | AC12: =IF(W12="ALI",IF(OR(AND(OR(Z12=1,Z12=0),X12>0,X12<20),AND(OR(Z12=1,Z12=0),X12>19,X12<51),AND(Z12>1,Z12<6,X12>0,X12<20)),"Simples",IF(OR(AND(OR(Z12=1,Z12=0),X12>50),AND(Z12>1,Z12<6,X12>19,X12<51),AND(Z12>5,X12>0,X12<20)),"Médio",IF(OR(AND(Z12>1,Z12<6,X12>50),AND(Z12>5,X12>19,X12<51),AND(Z12>5,X12>50)),"Complexo",""))), IF(W12="AIE",IF(OR(AND(OR(Z12=1, Z12=0),X12>0,X12<20),AND(OR(Z12=1, Z12=0),X12>19,X12<51),AND(Z12>1,Z12<6,X12>0,X12<20)),"Simples",IF(OR(AND(OR(Z12=1, Z12=0),X12>50),AND(Z12>1,Z12<6,X12>19,X12<51),AND(Z12>5,X12>0,X12<20)),"Médio",IF(OR(AND(Z12>1,Z12<6,X12>50),AND(Z12>5,X12>19,X12<51),AND(Z12>5,X12>50)),"Complexo",""))),"")) | AD12: =IF(AB12="",AC12,IF(AC12="",AB12,"")) | AE12: =IF(AND(OR(W12="EE",W12="CE"),AD12="Simples"),3, IF(AND(OR(W12="EE",W12="CE"),AD12="Médio"),4, IF(AND(OR(W12="EE",W12="CE"),AD12="Complexo"),6, IF(AND(W12="SE",AD12="Simples"),4, IF(AND(W12="SE",AD12="Médio"),5, IF(AND(W12="SE",AD12="Complexo"),7,0)))))) -> 0 | AF12: =IF(AND(W12="ALI",AC12="Simples"),7, IF(AND(W12="ALI",AC12="Médio"),10, IF(AND(W12="ALI",AC12="Complexo"),15, IF(AND(W12="AIE",AC12="Simples"),5, IF(AND(W12="AIE",AC12="Médio"),7, IF(AND(W12="AIE",AC12="Complexo"),10,0)))))) -> 0 | AG12: =IF(T12="OK",Q12,( IF(U12<>"Manutenção em interface",IF(U12<>"Desenv., Manutenção e Publicação de Páginas Estáticas",(AE12+AF12)*V12,V12),V12))) -> 0 | AM12: =IF(AG12=0,"",IF(AG12=Q12,"OK","Divergente"))
C13: =IF(B13<>"",VLOOKUP(B13,'Tipo Projeto'!$A$3:$B$35,2,0),0) -> 0 | L13: =IF(G13="EE",IF(OR(AND(OR(J13=1,J13=0),H13>0,H13<5),AND(OR(J13=1,J13=0),H13>4,H13<16),AND(J13=2,H13>0,H13<5)),"Simples",IF(OR(AND(OR(J13=1,J13=0),H13>15),AND(J13=2,H13>4,H13<16),AND(J13>2,H13>0,H13<5)),"Médio",IF(OR(AND(J13=2,H13>15),AND(J13>2,H13>4,H13<16),AND(J13>2,H13>15)),"Complexo",""))), IF(OR(G13="CE",G13="SE"),IF(OR(AND(OR(J13=1,J13=0),H13>0,H13<6),AND(OR(J13=1,J13=0),H13>5,H13<20),AND(J13>1,J13<4,H13>0,H13<6)),"Simples",IF(OR(AND(OR(J13=1,J13=0),H13>19),AND(J13>1,J13<4,H13>5,H13<20),AND(J13>3,H13>0,H13<6)),"Médio",IF(OR(AND(J13>1,J13<4,H13>19),AND(J13>3,H13>5,H13<20),AND(J13>3,H13>19)),"Complexo",""))),"")) | M13: =IF(G13="ALI",IF(OR(AND(OR(J13=1,J13=0),H13>0,H13<20),AND(OR(J13=1,J13=0),H13>19,H13<51),AND(J13>1,J13<6,H13>0,H13<20)),"Simples",IF(OR(AND(OR(J13=1,J13=0),H13>50),AND(J13>1,J13<6,H13>19,H13<51),AND(J13>5,H13>0,H13<20)),"Médio",IF(OR(AND(J13>1,J13<6,H13>50),AND(J13>5,H13>19,H13<51),AND(J13>5,H13>50)),"Complexo",""))), IF(G13="AIE",IF(OR(AND(OR(J13=1, J13=0),H13>0,H13<20),AND(OR(J13=1, J13=0),H13>19,H13<51),AND(J13>1,J13<6,H13>0,H13<20)),"Simples",IF(OR(AND(OR(J13=1, J13=0),H13>50),AND(J13>1,J13<6,H13>19,H13<51),AND(J13>5,H13>0,H13<20)),"Médio",IF(OR(AND(J13>1,J13<6,H13>50),AND(J13>5,H13>19,H13<51),AND(J13>5,H13>50)),"Complexo",""))),"")) | N13: =IF(L13="",M13,IF(M13="",L13,"")) | O13: =IF(AND(OR(G13="EE",G13="CE"),N13="Simples"),3, IF(AND(OR(G13="EE",G13="CE"),N13="Médio"),4, IF(AND(OR(G13="EE",G13="CE"),N13="Complexo"),6, IF(AND(G13="SE",N13="Simples"),4, IF(AND(G13="SE",N13="Médio"),5, IF(AND(G13="SE",N13="Complexo"),7,0)))))) -> 0 | P13: =IF(AND(G13="ALI",M13="Simples"),7, IF(AND(G13="ALI",M13="Médio"),10, IF(AND(G13="ALI",M13="Complexo"),15, IF(AND(G13="AIE",M13="Simples"),5, IF(AND(G13="AIE",M13="Médio"),7, IF(AND(G13="AIE",M13="Complexo"),10,0)))))) -> 0 | Q13: =IF(B13<>"Manutenção em interface",IF(B13<>"Desenv., Manutenção e Publicação de Páginas Estáticas",(O13+P13)*C13,C13),C13) -> 0 | V13: =IF(U13<>"",VLOOKUP(U13,'Tipo Projeto'!$A$3:$B$35,2,0),0) -> 0 | AB13: =IF(W13="EE",IF(OR(AND(OR(Z13=1,Z13=0),X13>0,X13<5),AND(OR(Z13=1,Z13=0),X13>4,X13<16),AND(Z13=2,X13>0,X13<5)),"Simples",IF(OR(AND(OR(Z13=1,Z13=0),X13>15),AND(Z13=2,X13>4,X13<16),AND(Z13>2,X13>0,X13<5)),"Médio",IF(OR(AND(Z13=2,X13>15),AND(Z13>2,X13>4,X13<16),AND(Z13>2,X13>15)),"Complexo",""))), IF(OR(W13="CE",W13="SE"),IF(OR(AND(OR(Z13=1,Z13=0),X13>0,X13<6),AND(OR(Z13=1,Z13=0),X13>5,X13<20),AND(Z13>1,Z13<4,X13>0,X13<6)),"Simples",IF(OR(AND(OR(Z13=1,Z13=0),X13>19),AND(Z13>1,Z13<4,X13>5,X13<20),AND(Z13>3,X13>0,X13<6)),"Médio",IF(OR(AND(Z13>1,Z13<4,X13>19),AND(Z13>3,X13>5,X13<20),AND(Z13>3,X13>19)),"Complexo",""))),"")) | AC13: =IF(W13="ALI",IF(OR(AND(OR(Z13=1,Z13=0),X13>0,X13<20),AND(OR(Z13=1,Z13=0),X13>19,X13<51),AND(Z13>1,Z13<6,X13>0,X13<20)),"Simples",IF(OR(AND(OR(Z13=1,Z13=0),X13>50),AND(Z13>1,Z13<6,X13>19,X13<51),AND(Z13>5,X13>0,X13<20)),"Médio",IF(OR(AND(Z13>1,Z13<6,X13>50),AND(Z13>5,X13>19,X13<51),AND(Z13>5,X13>50)),"Complexo",""))), IF(W13="AIE",IF(OR(AND(OR(Z13=1, Z13=0),X13>0,X13<20),AND(OR(Z13=1, Z13=0),X13>19,X13<51),AND(Z13>1,Z13<6,X13>0,X13<20)),"Simples",IF(OR(AND(OR(Z13=1, Z13=0),X13>50),AND(Z13>1,Z13<6,X13>19,X13<51),AND(Z13>5,X13>0,X13<20)),"Médio",IF(OR(AND(Z13>1,Z13<6,X13>50),AND(Z13>5,X13>19,X13<51),AND(Z13>5,X13>50)),"Complexo",""))),"")) | AD13: =IF(AB13="",AC13,IF(AC13="",AB13,"")) | AE13: =IF(AND(OR(W13="EE",W13="CE"),AD13="Simples"),3, IF(AND(OR(W13="EE",W13="CE"),AD13="Médio"),4, IF(AND(OR(W13="EE",W13="CE"),AD13="Complexo"),6, IF(AND(W13="SE",AD13="Simples"),4, IF(AND(W13="SE",AD13="Médio"),5, IF(AND(W13="SE",AD13="Complexo"),7,0)))))) -> 0 | AF13: =IF(AND(W13="ALI",AC13="Simples"),7, IF(AND(W13="ALI",AC13="Médio"),10, IF(AND(W13="ALI",AC13="Complexo"),15, IF(AND(W13="AIE",AC13="Simples"),5, IF(AND(W13="AIE",AC13="Médio"),7, IF(AND(W13="AIE",AC13="Complexo"),10,0)))))) -> 0 | AG13: =IF(T13="OK",Q13,( IF(U13<>"Manutenção em interface",IF(U13<>"Desenv., Manutenção e Publicação de Páginas Estáticas",(AE13+AF13)*V13,V13),V13))) -> 0 | AM13: =IF(AG13=0,"",IF(AG13=Q13,"OK","Divergente"))
C14: =IF(B14<>"",VLOOKUP(B14,'Tipo Projeto'!$A$3:$B$35,2,0),0) -> 0 | L14: =IF(G14="EE",IF(OR(AND(OR(J14=1,J14=0),H14>0,H14<5),AND(OR(J14=1,J14=0),H14>4,H14<16),AND(J14=2,H14>0,H14<5)),"Simples",IF(OR(AND(OR(J14=1,J14=0),H14>15),AND(J14=2,H14>4,H14<16),AND(J14>2,H14>0,H14<5)),"Médio",IF(OR(AND(J14=2,H14>15),AND(J14>2,H14>4,H14<16),AND(J14>2,H14>15)),"Complexo",""))), IF(OR(G14="CE",G14="SE"),IF(OR(AND(OR(J14=1,J14=0),H14>0,H14<6),AND(OR(J14=1,J14=0),H14>5,H14<20),AND(J14>1,J14<4,H14>0,H14<6)),"Simples",IF(OR(AND(OR(J14=1,J14=0),H14>19),AND(J14>1,J14<4,H14>5,H14<20),AND(J14>3,H14>0,H14<6)),"Médio",IF(OR(AND(J14>1,J14<4,H14>19),AND(J14>3,H14>5,H14<20),AND(J14>3,H14>19)),"Complexo",""))),"")) | M14: =IF(G14="ALI",IF(OR(AND(OR(J14=1,J14=0),H14>0,H14<20),AND(OR(J14=1,J14=0),H14>19,H14<51),AND(J14>1,J14<6,H14>0,H14<20)),"Simples",IF(OR(AND(OR(J14=1,J14=0),H14>50),AND(J14>1,J14<6,H14>19,H14<51),AND(J14>5,H14>0,H14<20)),"Médio",IF(OR(AND(J14>1,J14<6,H14>50),AND(J14>5,H14>19,H14<51),AND(J14>5,H14>50)),"Complexo",""))), IF(G14="AIE",IF(OR(AND(OR(J14=1, J14=0),H14>0,H14<20),AND(OR(J14=1, J14=0),H14>19,H14<51),AND(J14>1,J14<6,H14>0,H14<20)),"Simples",IF(OR(AND(OR(J14=1, J14=0),H14>50),AND(J14>1,J14<6,H14>19,H14<51),AND(J14>5,H14>0,H14<20)),"Médio",IF(OR(AND(J14>1,J14<6,H14>50),AND(J14>5,H14>19,H14<51),AND(J14>5,H14>50)),"Complexo",""))),"")) | N14: =IF(L14="",M14,IF(M14="",L14,"")) | O14: =IF(AND(OR(G14="EE",G14="CE"),N14="Simples"),3, IF(AND(OR(G14="EE",G14="CE"),N14="Médio"),4, IF(AND(OR(G14="EE",G14="CE"),N14="Complexo"),6, IF(AND(G14="SE",N14="Simples"),4, IF(AND(G14="SE",N14="Médio"),5, IF(AND(G14="SE",N14="Complexo"),7,0)))))) -> 0 | P14: =IF(AND(G14="ALI",M14="Simples"),7, IF(AND(G14="ALI",M14="Médio"),10, IF(AND(G14="ALI",M14="Complexo"),15, IF(AND(G14="AIE",M14="Simples"),5, IF(AND(G14="AIE",M14="Médio"),7, IF(AND(G14="AIE",M14="Complexo"),10,0)))))) -> 0 | Q14: =IF(B14<>"Manutenção em interface",IF(B14<>"Desenv., Manutenção e Publicação de Páginas Estáticas",(O14+P14)*C14,C14),C14) -> 0 | V14: =IF(U14<>"",VLOOKUP(U14,'Tipo Projeto'!$A$3:$B$35,2,0),0) -> 0 | AB14: =IF(W14="EE",IF(OR(AND(OR(Z14=1,Z14=0),X14>0,X14<5),AND(OR(Z14=1,Z14=0),X14>4,X14<16),AND(Z14=2,X14>0,X14<5)),"Simples",IF(OR(AND(OR(Z14=1,Z14=0),X14>15),AND(Z14=2,X14>4,X14<16),AND(Z14>2,X14>0,X14<5)),"Médio",IF(OR(AND(Z14=2,X14>15),AND(Z14>2,X14>4,X14<16),AND(Z14>2,X14>15)),"Complexo",""))), IF(OR(W14="CE",W14="SE"),IF(OR(AND(OR(Z14=1,Z14=0),X14>0,X14<6),AND(OR(Z14=1,Z14=0),X14>5,X14<20),AND(Z14>1,Z14<4,X14>0,X14<6)),"Simples",IF(OR(AND(OR(Z14=1,Z14=0),X14>19),AND(Z14>1,Z14<4,X14>5,X14<20),AND(Z14>3,X14>0,X14<6)),"Médio",IF(OR(AND(Z14>1,Z14<4,X14>19),AND(Z14>3,X14>5,X14<20),AND(Z14>3,X14>19)),"Complexo",""))),"")) | AC14: =IF(W14="ALI",IF(OR(AND(OR(Z14=1,Z14=0),X14>0,X14<20),AND(OR(Z14=1,Z14=0),X14>19,X14<51),AND(Z14>1,Z14<6,X14>0,X14<20)),"Simples",IF(OR(AND(OR(Z14=1,Z14=0),X14>50),AND(Z14>1,Z14<6,X14>19,X14<51),AND(Z14>5,X14>0,X14<20)),"Médio",IF(OR(AND(Z14>1,Z14<6,X14>50),AND(Z14>5,X14>19,X14<51),AND(Z14>5,X14>50)),"Complexo",""))), IF(W14="AIE",IF(OR(AND(OR(Z14=1, Z14=0),X14>0,X14<20),AND(OR(Z14=1, Z14=0),X14>19,X14<51),AND(Z14>1,Z14<6,X14>0,X14<20)),"Simples",IF(OR(AND(OR(Z14=1, Z14=0),X14>50),AND(Z14>1,Z14<6,X14>19,X14<51),AND(Z14>5,X14>0,X14<20)),"Médio",IF(OR(AND(Z14>1,Z14<6,X14>50),AND(Z14>5,X14>19,X14<51),AND(Z14>5,X14>50)),"Complexo",""))),"")) | AD14: =IF(AB14="",AC14,IF(AC14="",AB14,"")) | AE14: =IF(AND(OR(W14="EE",W14="CE"),AD14="Simples"),3, IF(AND(OR(W14="EE",W14="CE"),AD14="Médio"),4, IF(AND(OR(W14="EE",W14="CE"),AD14="Complexo"),6, IF(AND(W14="SE",AD14="Simples"),4, IF(AND(W14="SE",AD14="Médio"),5, IF(AND(W14="SE",AD14="Complexo"),7,0)))))) -> 0 | AF14: =IF(AND(W14="ALI",AC14="Simples"),7, IF(AND(W14="ALI",AC14="Médio"),10, IF(AND(W14="ALI",AC14="Complexo"),15, IF(AND(W14="AIE",AC14="Simples"),5, IF(AND(W14="AIE",AC14="Médio"),7, IF(AND(W14="AIE",AC14="Complexo"),10,0)))))) -> 0 | AG14: =IF(T14="OK",Q14,( IF(U14<>"Manutenção em interface",IF(U14<>"Desenv., Manutenção e Publicação de Páginas Estáticas",(AE14+AF14)*V14,V14),V14))) -> 0 | AM14: =IF(AG14=0,"",IF(AG14=Q14,"OK","Divergente"))
C15: =IF(B15<>"",VLOOKUP(B15,'Tipo Projeto'!$A$3:$B$35,2,0),0) -> 0 | L15: =IF(G15="EE",IF(OR(AND(OR(J15=1,J15=0),H15>0,H15<5),AND(OR(J15=1,J15=0),H15>4,H15<16),AND(J15=2,H15>0,H15<5)),"Simples",IF(OR(AND(OR(J15=1,J15=0),H15>15),AND(J15=2,H15>4,H15<16),AND(J15>2,H15>0,H15<5)),"Médio",IF(OR(AND(J15=2,H15>15),AND(J15>2,H15>4,H15<16),AND(J15>2,H15>15)),"Complexo",""))), IF(OR(G15="CE",G15="SE"),IF(OR(AND(OR(J15=1,J15=0),H15>0,H15<6),AND(OR(J15=1,J15=0),H15>5,H15<20),AND(J15>1,J15<4,H15>0,H15<6)),"Simples",IF(OR(AND(OR(J15=1,J15=0),H15>19),AND(J15>1,J15<4,H15>5,H15<20),AND(J15>3,H15>0,H15<6)),"Médio",IF(OR(AND(J15>1,J15<4,H15>19),AND(J15>3,H15>5,H15<20),AND(J15>3,H15>19)),"Complexo",""))),"")) | M15: =IF(G15="ALI",IF(OR(AND(OR(J15=1,J15=0),H15>0,H15<20),AND(OR(J15=1,J15=0),H15>19,H15<51),AND(J15>1,J15<6,H15>0,H15<20)),"Simples",IF(OR(AND(OR(J15=1,J15=0),H15>50),AND(J15>1,J15<6,H15>19,H15<51),AND(J15>5,H15>0,H15<20)),"Médio",IF(OR(AND(J15>1,J15<6,H15>50),AND(J15>5,H15>19,H15<51),AND(J15>5,H15>50)),"Complexo",""))), IF(G15="AIE",IF(OR(AND(OR(J15=1, J15=0),H15>0,H15<20),AND(OR(J15=1, J15=0),H15>19,H15<51),AND(J15>1,J15<6,H15>0,H15<20)),"Simples",IF(OR(AND(OR(J15=1, J15=0),H15>50),AND(J15>1,J15<6,H15>19,H15<51),AND(J15>5,H15>0,H15<20)),"Médio",IF(OR(AND(J15>1,J15<6,H15>50),AND(J15>5,H15>19,H15<51),AND(J15>5,H15>50)),"Complexo",""))),"")) | N15: =IF(L15="",M15,IF(M15="",L15,"")) | O15: =IF(AND(OR(G15="EE",G15="CE"),N15="Simples"),3, IF(AND(OR(G15="EE",G15="CE"),N15="Médio"),4, IF(AND(OR(G15="EE",G15="CE"),N15="Complexo"),6, IF(AND(G15="SE",N15="Simples"),4, IF(AND(G15="SE",N15="Médio"),5, IF(AND(G15="SE",N15="Complexo"),7,0)))))) -> 0 | P15: =IF(AND(G15="ALI",M15="Simples"),7, IF(AND(G15="ALI",M15="Médio"),10, IF(AND(G15="ALI",M15="Complexo"),15, IF(AND(G15="AIE",M15="Simples"),5, IF(AND(G15="AIE",M15="Médio"),7, IF(AND(G15="AIE",M15="Complexo"),10,0)))))) -> 0 | Q15: =IF(B15<>"Manutenção em interface",IF(B15<>"Desenv., Manutenção e Publicação de Páginas Estáticas",(O15+P15)*C15,C15),C15) -> 0 | V15: =IF(U15<>"",VLOOKUP(U15,'Tipo Projeto'!$A$3:$B$35,2,0),0) -> 0 | AB15: =IF(W15="EE",IF(OR(AND(OR(Z15=1,Z15=0),X15>0,X15<5),AND(OR(Z15=1,Z15=0),X15>4,X15<16),AND(Z15=2,X15>0,X15<5)),"Simples",IF(OR(AND(OR(Z15=1,Z15=0),X15>15),AND(Z15=2,X15>4,X15<16),AND(Z15>2,X15>0,X15<5)),"Médio",IF(OR(AND(Z15=2,X15>15),AND(Z15>2,X15>4,X15<16),AND(Z15>2,X15>15)),"Complexo",""))), IF(OR(W15="CE",W15="SE"),IF(OR(AND(OR(Z15=1,Z15=0),X15>0,X15<6),AND(OR(Z15=1,Z15=0),X15>5,X15<20),AND(Z15>1,Z15<4,X15>0,X15<6)),"Simples",IF(OR(AND(OR(Z15=1,Z15=0),X15>19),AND(Z15>1,Z15<4,X15>5,X15<20),AND(Z15>3,X15>0,X15<6)),"Médio",IF(OR(AND(Z15>1,Z15<4,X15>19),AND(Z15>3,X15>5,X15<20),AND(Z15>3,X15>19)),"Complexo",""))),"")) | AC15: =IF(W15="ALI",IF(OR(AND(OR(Z15=1,Z15=0),X15>0,X15<20),AND(OR(Z15=1,Z15=0),X15>19,X15<51),AND(Z15>1,Z15<6,X15>0,X15<20)),"Simples",IF(OR(AND(OR(Z15=1,Z15=0),X15>50),AND(Z15>1,Z15<6,X15>19,X15<51),AND(Z15>5,X15>0,X15<20)),"Médio",IF(OR(AND(Z15>1,Z15<6,X15>50),AND(Z15>5,X15>19,X15<51),AND(Z15>5,X15>50)),"Complexo",""))), IF(W15="AIE",IF(OR(AND(OR(Z15=1, Z15=0),X15>0,X15<20),AND(OR(Z15=1, Z15=0),X15>19,X15<51),AND(Z15>1,Z15<6,X15>0,X15<20)),"Simples",IF(OR(AND(OR(Z15=1, Z15=0),X15>50),AND(Z15>1,Z15<6,X15>19,X15<51),AND(Z15>5,X15>0,X15<20)),"Médio",IF(OR(AND(Z15>1,Z15<6,X15>50),AND(Z15>5,X15>19,X15<51),AND(Z15>5,X15>50)),"Complexo",""))),"")) | AD15: =IF(AB15="",AC15,IF(AC15="",AB15,"")) | AE15: =IF(AND(OR(W15="EE",W15="CE"),AD15="Simples"),3, IF(AND(OR(W15="EE",W15="CE"),AD15="Médio"),4, IF(AND(OR(W15="EE",W15="CE"),AD15="Complexo"),6, IF(AND(W15="SE",AD15="Simples"),4, IF(AND(W15="SE",AD15="Médio"),5, IF(AND(W15="SE",AD15="Complexo"),7,0)))))) -> 0 | AF15: =IF(AND(W15="ALI",AC15="Simples"),7, IF(AND(W15="ALI",AC15="Médio"),10, IF(AND(W15="ALI",AC15="Complexo"),15, IF(AND(W15="AIE",AC15="Simples"),5, IF(AND(W15="AIE",AC15="Médio"),7, IF(AND(W15="AIE",AC15="Complexo"),10,0)))))) -> 0 | AG15: =IF(T15="OK",Q15,( IF(U15<>"Manutenção em interface",IF(U15<>"Desenv., Manutenção e Publicação de Páginas Estáticas",(AE15+AF15)*V15,V15),V15))) -> 0 | AM15: =IF(AG15=0,"",IF(AG15=Q15,"OK","Divergente"))
C16: =IF(B16<>"",VLOOKUP(B16,'Tipo Projeto'!$A$3:$B$35,2,0),0) -> 0 | L16: =IF(G16="EE",IF(OR(AND(OR(J16=1,J16=0),H16>0,H16<5),AND(OR(J16=1,J16=0),H16>4,H16<16),AND(J16=2,H16>0,H16<5)),"Simples",IF(OR(AND(OR(J16=1,J16=0),H16>15),AND(J16=2,H16>4,H16<16),AND(J16>2,H16>0,H16<5)),"Médio",IF(OR(AND(J16=2,H16>15),AND(J16>2,H16>4,H16<16),AND(J16>2,H16>15)),"Complexo",""))), IF(OR(G16="CE",G16="SE"),IF(OR(AND(OR(J16=1,J16=0),H16>0,H16<6),AND(OR(J16=1,J16=0),H16>5,H16<20),AND(J16>1,J16<4,H16>0,H16<6)),"Simples",IF(OR(AND(OR(J16=1,J16=0),H16>19),AND(J16>1,J16<4,H16>5,H16<20),AND(J16>3,H16>0,H16<6)),"Médio",IF(OR(AND(J16>1,J16<4,H16>19),AND(J16>3,H16>5,H16<20),AND(J16>3,H16>19)),"Complexo",""))),"")) | M16: =IF(G16="ALI",IF(OR(AND(OR(J16=1,J16=0),H16>0,H16<20),AND(OR(J16=1,J16=0),H16>19,H16<51),AND(J16>1,J16<6,H16>0,H16<20)),"Simples",IF(OR(AND(OR(J16=1,J16=0),H16>50),AND(J16>1,J16<6,H16>19,H16<51),AND(J16>5,H16>0,H16<20)),"Médio",IF(OR(AND(J16>1,J16<6,H16>50),AND(J16>5,H16>19,H16<51),AND(J16>5,H16>50)),"Complexo",""))), IF(G16="AIE",IF(OR(AND(OR(J16=1, J16=0),H16>0,H16<20),AND(OR(J16=1, J16=0),H16>19,H16<51),AND(J16>1,J16<6,H16>0,H16<20)),"Simples",IF(OR(AND(OR(J16=1, J16=0),H16>50),AND(J16>1,J16<6,H16>19,H16<51),AND(J16>5,H16>0,H16<20)),"Médio",IF(OR(AND(J16>1,J16<6,H16>50),AND(J16>5,H16>19,H16<51),AND(J16>5,H16>50)),"Complexo",""))),"")) | N16: =IF(L16="",M16,IF(M16="",L16,"")) | O16: =IF(AND(OR(G16="EE",G16="CE"),N16="Simples"),3, IF(AND(OR(G16="EE",G16="CE"),N16="Médio"),4, IF(AND(OR(G16="EE",G16="CE"),N16="Complexo"),6, IF(AND(G16="SE",N16="Simples"),4, IF(AND(G16="SE",N16="Médio"),5, IF(AND(G16="SE",N16="Complexo"),7,0)))))) -> 0 | P16: =IF(AND(G16="ALI",M16="Simples"),7, IF(AND(G16="ALI",M16="Médio"),10, IF(AND(G16="ALI",M16="Complexo"),15, IF(AND(G16="AIE",M16="Simples"),5, IF(AND(G16="AIE",M16="Médio"),7, IF(AND(G16="AIE",M16="Complexo"),10,0)))))) -> 0 | Q16: =IF(B16<>"Manutenção em interface",IF(B16<>"Desenv., Manutenção e Publicação de Páginas Estáticas",(O16+P16)*C16,C16),C16) -> 0 | V16: =IF(U16<>"",VLOOKUP(U16,'Tipo Projeto'!$A$3:$B$35,2,0),0) -> 0 | AB16: =IF(W16="EE",IF(OR(AND(OR(Z16=1,Z16=0),X16>0,X16<5),AND(OR(Z16=1,Z16=0),X16>4,X16<16),AND(Z16=2,X16>0,X16<5)),"Simples",IF(OR(AND(OR(Z16=1,Z16=0),X16>15),AND(Z16=2,X16>4,X16<16),AND(Z16>2,X16>0,X16<5)),"Médio",IF(OR(AND(Z16=2,X16>15),AND(Z16>2,X16>4,X16<16),AND(Z16>2,X16>15)),"Complexo",""))), IF(OR(W16="CE",W16="SE"),IF(OR(AND(OR(Z16=1,Z16=0),X16>0,X16<6),AND(OR(Z16=1,Z16=0),X16>5,X16<20),AND(Z16>1,Z16<4,X16>0,X16<6)),"Simples",IF(OR(AND(OR(Z16=1,Z16=0),X16>19),AND(Z16>1,Z16<4,X16>5,X16<20),AND(Z16>3,X16>0,X16<6)),"Médio",IF(OR(AND(Z16>1,Z16<4,X16>19),AND(Z16>3,X16>5,X16<20),AND(Z16>3,X16>19)),"Complexo",""))),"")) | AC16: =IF(W16="ALI",IF(OR(AND(OR(Z16=1,Z16=0),X16>0,X16<20),AND(OR(Z16=1,Z16=0),X16>19,X16<51),AND(Z16>1,Z16<6,X16>0,X16<20)),"Simples",IF(OR(AND(OR(Z16=1,Z16=0),X16>50),AND(Z16>1,Z16<6,X16>19,X16<51),AND(Z16>5,X16>0,X16<20)),"Médio",IF(OR(AND(Z16>1,Z16<6,X16>50),AND(Z16>5,X16>19,X16<51),AND(Z16>5,X16>50)),"Complexo",""))), IF(W16="AIE",IF(OR(AND(OR(Z16=1, Z16=0),X16>0,X16<20),AND(OR(Z16=1, Z16=0),X16>19,X16<51),AND(Z16>1,Z16<6,X16>0,X16<20)),"Simples",IF(OR(AND(OR(Z16=1, Z16=0),X16>50),AND(Z16>1,Z16<6,X16>19,X16<51),AND(Z16>5,X16>0,X16<20)),"Médio",IF(OR(AND(Z16>1,Z16<6,X16>50),AND(Z16>5,X16>19,X16<51),AND(Z16>5,X16>50)),"Complexo",""))),"")) | AD16: =IF(AB16="",AC16,IF(AC16="",AB16,"")) | AE16: =IF(AND(OR(W16="EE",W16="CE"),AD16="Simples"),3, IF(AND(OR(W16="EE",W16="CE"),AD16="Médio"),4, IF(AND(OR(W16="EE",W16="CE"),AD16="Complexo"),6, IF(AND(W16="SE",AD16="Simples"),4, IF(AND(W16="SE",AD16="Médio"),5, IF(AND(W16="SE",AD16="Complexo"),7,0)))))) -> 0 | AF16: =IF(AND(W16="ALI",AC16="Simples"),7, IF(AND(W16="ALI",AC16="Médio"),10, IF(AND(W16="ALI",AC16="Complexo"),15, IF(AND(W16="AIE",AC16="Simples"),5, IF(AND(W16="AIE",AC16="Médio"),7, IF(AND(W16="AIE",AC16="Complexo"),10,0)))))) -> 0 | AG16: =IF(T16="OK",Q16,( IF(U16<>"Manutenção em interface",IF(U16<>"Desenv., Manutenção e Publicação de Páginas Estáticas",(AE16+AF16)*V16,V16),V16))) -> 0 | AM16: =IF(AG16=0,"",IF(AG16=Q16,"OK","Divergente"))
C17: =IF(B17<>"",VLOOKUP(B17,'Tipo Projeto'!$A$3:$B$35,2,0),0) -> 0 | L17: =IF(G17="EE",IF(OR(AND(OR(J17=1,J17=0),H17>0,H17<5),AND(OR(J17=1,J17=0),H17>4,H17<16),AND(J17=2,H17>0,H17<5)),"Simples",IF(OR(AND(OR(J17=1,J17=0),H17>15),AND(J17=2,H17>4,H17<16),AND(J17>2,H17>0,H17<5)),"Médio",IF(OR(AND(J17=2,H17>15),AND(J17>2,H17>4,H17<16),AND(J17>2,H17>15)),"Complexo",""))), IF(OR(G17="CE",G17="SE"),IF(OR(AND(OR(J17=1,J17=0),H17>0,H17<6),AND(OR(J17=1,J17=0),H17>5,H17<20),AND(J17>1,J17<4,H17>0,H17<6)),"Simples",IF(OR(AND(OR(J17=1,J17=0),H17>19),AND(J17>1,J17<4,H17>5,H17<20),AND(J17>3,H17>0,H17<6)),"Médio",IF(OR(AND(J17>1,J17<4,H17>19),AND(J17>3,H17>5,H17<20),AND(J17>3,H17>19)),"Complexo",""))),"")) | M17: =IF(G17="ALI",IF(OR(AND(OR(J17=1,J17=0),H17>0,H17<20),AND(OR(J17=1,J17=0),H17>19,H17<51),AND(J17>1,J17<6,H17>0,H17<20)),"Simples",IF(OR(AND(OR(J17=1,J17=0),H17>50),AND(J17>1,J17<6,H17>19,H17<51),AND(J17>5,H17>0,H17<20)),"Médio",IF(OR(AND(J17>1,J17<6,H17>50),AND(J17>5,H17>19,H17<51),AND(J17>5,H17>50)),"Complexo",""))), IF(G17="AIE",IF(OR(AND(OR(J17=1, J17=0),H17>0,H17<20),AND(OR(J17=1, J17=0),H17>19,H17<51),AND(J17>1,J17<6,H17>0,H17<20)),"Simples",IF(OR(AND(OR(J17=1, J17=0),H17>50),AND(J17>1,J17<6,H17>19,H17<51),AND(J17>5,H17>0,H17<20)),"Médio",IF(OR(AND(J17>1,J17<6,H17>50),AND(J17>5,H17>19,H17<51),AND(J17>5,H17>50)),"Complexo",""))),"")) | N17: =IF(L17="",M17,IF(M17="",L17,"")) | O17: =IF(AND(OR(G17="EE",G17="CE"),N17="Simples"),3, IF(AND(OR(G17="EE",G17="CE"),N17="Médio"),4, IF(AND(OR(G17="EE",G17="CE"),N17="Complexo"),6, IF(AND(G17="SE",N17="Simples"),4, IF(AND(G17="SE",N17="Médio"),5, IF(AND(G17="SE",N17="Complexo"),7,0)))))) -> 0 | P17: =IF(AND(G17="ALI",M17="Simples"),7, IF(AND(G17="ALI",M17="Médio"),10, IF(AND(G17="ALI",M17="Complexo"),15, IF(AND(G17="AIE",M17="Simples"),5, IF(AND(G17="AIE",M17="Médio"),7, IF(AND(G17="AIE",M17="Complexo"),10,0)))))) -> 0 | Q17: =IF(B17<>"Manutenção em interface",IF(B17<>"Desenv., Manutenção e Publicação de Páginas Estáticas",(O17+P17)*C17,C17),C17) -> 0 | V17: =IF(U17<>"",VLOOKUP(U17,'Tipo Projeto'!$A$3:$B$35,2,0),0) -> 0 | AB17: =IF(W17="EE",IF(OR(AND(OR(Z17=1,Z17=0),X17>0,X17<5),AND(OR(Z17=1,Z17=0),X17>4,X17<16),AND(Z17=2,X17>0,X17<5)),"Simples",IF(OR(AND(OR(Z17=1,Z17=0),X17>15),AND(Z17=2,X17>4,X17<16),AND(Z17>2,X17>0,X17<5)),"Médio",IF(OR(AND(Z17=2,X17>15),AND(Z17>2,X17>4,X17<16),AND(Z17>2,X17>15)),"Complexo",""))), IF(OR(W17="CE",W17="SE"),IF(OR(AND(OR(Z17=1,Z17=0),X17>0,X17<6),AND(OR(Z17=1,Z17=0),X17>5,X17<20),AND(Z17>1,Z17<4,X17>0,X17<6)),"Simples",IF(OR(AND(OR(Z17=1,Z17=0),X17>19),AND(Z17>1,Z17<4,X17>5,X17<20),AND(Z17>3,X17>0,X17<6)),"Médio",IF(OR(AND(Z17>1,Z17<4,X17>19),AND(Z17>3,X17>5,X17<20),AND(Z17>3,X17>19)),"Complexo",""))),"")) | AC17: =IF(W17="ALI",IF(OR(AND(OR(Z17=1,Z17=0),X17>0,X17<20),AND(OR(Z17=1,Z17=0),X17>19,X17<51),AND(Z17>1,Z17<6,X17>0,X17<20)),"Simples",IF(OR(AND(OR(Z17=1,Z17=0),X17>50),AND(Z17>1,Z17<6,X17>19,X17<51),AND(Z17>5,X17>0,X17<20)),"Médio",IF(OR(AND(Z17>1,Z17<6,X17>50),AND(Z17>5,X17>19,X17<51),AND(Z17>5,X17>50)),"Complexo",""))), IF(W17="AIE",IF(OR(AND(OR(Z17=1, Z17=0),X17>0,X17<20),AND(OR(Z17=1, Z17=0),X17>19,X17<51),AND(Z17>1,Z17<6,X17>0,X17<20)),"Simples",IF(OR(AND(OR(Z17=1, Z17=0),X17>50),AND(Z17>1,Z17<6,X17>19,X17<51),AND(Z17>5,X17>0,X17<20)),"Médio",IF(OR(AND(Z17>1,Z17<6,X17>50),AND(Z17>5,X17>19,X17<51),AND(Z17>5,X17>50)),"Complexo",""))),"")) | AD17: =IF(AB17="",AC17,IF(AC17="",AB17,"")) | AE17: =IF(AND(OR(W17="EE",W17="CE"),AD17="Simples"),3, IF(AND(OR(W17="EE",W17="CE"),AD17="Médio"),4, IF(AND(OR(W17="EE",W17="CE"),AD17="Complexo"),6, IF(AND(W17="SE",AD17="Simples"),4, IF(AND(W17="SE",AD17="Médio"),5, IF(AND(W17="SE",AD17="Complexo"),7,0)))))) -> 0 | AF17: =IF(AND(W17="ALI",AC17="Simples"),7, IF(AND(W17="ALI",AC17="Médio"),10, IF(AND(W17="ALI",AC17="Complexo"),15, IF(AND(W17="AIE",AC17="Simples"),5, IF(AND(W17="AIE",AC17="Médio"),7, IF(AND(W17="AIE",AC17="Complexo"),10,0)))))) -> 0 | AG17: =IF(T17="OK",Q17,( IF(U17<>"Manutenção em interface",IF(U17<>"Desenv., Manutenção e Publicação de Páginas Estáticas",(AE17+AF17)*V17,V17),V17))) -> 0 | AM17: =IF(AG17=0,"",IF(AG17=Q17,"OK","Divergente"))
C18: =IF(B18<>"",VLOOKUP(B18,'Tipo Projeto'!$A$3:$B$35,2,0),0) -> 0 | L18: =IF(G18="EE",IF(OR(AND(OR(J18=1,J18=0),H18>0,H18<5),AND(OR(J18=1,J18=0),H18>4,H18<16),AND(J18=2,H18>0,H18<5)),"Simples",IF(OR(AND(OR(J18=1,J18=0),H18>15),AND(J18=2,H18>4,H18<16),AND(J18>2,H18>0,H18<5)),"Médio",IF(OR(AND(J18=2,H18>15),AND(J18>2,H18>4,H18<16),AND(J18>2,H18>15)),"Complexo",""))), IF(OR(G18="CE",G18="SE"),IF(OR(AND(OR(J18=1,J18=0),H18>0,H18<6),AND(OR(J18=1,J18=0),H18>5,H18<20),AND(J18>1,J18<4,H18>0,H18<6)),"Simples",IF(OR(AND(OR(J18=1,J18=0),H18>19),AND(J18>1,J18<4,H18>5,H18<20),AND(J18>3,H18>0,H18<6)),"Médio",IF(OR(AND(J18>1,J18<4,H18>19),AND(J18>3,H18>5,H18<20),AND(J18>3,H18>19)),"Complexo",""))),"")) | M18: =IF(G18="ALI",IF(OR(AND(OR(J18=1,J18=0),H18>0,H18<20),AND(OR(J18=1,J18=0),H18>19,H18<51),AND(J18>1,J18<6,H18>0,H18<20)),"Simples",IF(OR(AND(OR(J18=1,J18=0),H18>50),AND(J18>1,J18<6,H18>19,H18<51),AND(J18>5,H18>0,H18<20)),"Médio",IF(OR(AND(J18>1,J18<6,H18>50),AND(J18>5,H18>19,H18<51),AND(J18>5,H18>50)),"Complexo",""))), IF(G18="AIE",IF(OR(AND(OR(J18=1, J18=0),H18>0,H18<20),AND(OR(J18=1, J18=0),H18>19,H18<51),AND(J18>1,J18<6,H18>0,H18<20)),"Simples",IF(OR(AND(OR(J18=1, J18=0),H18>50),AND(J18>1,J18<6,H18>19,H18<51),AND(J18>5,H18>0,H18<20)),"Médio",IF(OR(AND(J18>1,J18<6,H18>50),AND(J18>5,H18>19,H18<51),AND(J18>5,H18>50)),"Complexo",""))),"")) | N18: =IF(L18="",M18,IF(M18="",L18,"")) | O18: =IF(AND(OR(G18="EE",G18="CE"),N18="Simples"),3, IF(AND(OR(G18="EE",G18="CE"),N18="Médio"),4, IF(AND(OR(G18="EE",G18="CE"),N18="Complexo"),6, IF(AND(G18="SE",N18="Simples"),4, IF(AND(G18="SE",N18="Médio"),5, IF(AND(G18="SE",N18="Complexo"),7,0)))))) -> 0 | P18: =IF(AND(G18="ALI",M18="Simples"),7, IF(AND(G18="ALI",M18="Médio"),10, IF(AND(G18="ALI",M18="Complexo"),15, IF(AND(G18="AIE",M18="Simples"),5, IF(AND(G18="AIE",M18="Médio"),7, IF(AND(G18="AIE",M18="Complexo"),10,0)))))) -> 0 | Q18: =IF(B18<>"Manutenção em interface",IF(B18<>"Desenv., Manutenção e Publicação de Páginas Estáticas",(O18+P18)*C18,C18),C18) -> 0 | V18: =IF(U18<>"",VLOOKUP(U18,'Tipo Projeto'!$A$3:$B$35,2,0),0) -> 0 | AB18: =IF(W18="EE",IF(OR(AND(OR(Z18=1,Z18=0),X18>0,X18<5),AND(OR(Z18=1,Z18=0),X18>4,X18<16),AND(Z18=2,X18>0,X18<5)),"Simples",IF(OR(AND(OR(Z18=1,Z18=0),X18>15),AND(Z18=2,X18>4,X18<16),AND(Z18>2,X18>0,X18<5)),"Médio",IF(OR(AND(Z18=2,X18>15),AND(Z18>2,X18>4,X18<16),AND(Z18>2,X18>15)),"Complexo",""))), IF(OR(W18="CE",W18="SE"),IF(OR(AND(OR(Z18=1,Z18=0),X18>0,X18<6),AND(OR(Z18=1,Z18=0),X18>5,X18<20),AND(Z18>1,Z18<4,X18>0,X18<6)),"Simples",IF(OR(AND(OR(Z18=1,Z18=0),X18>19),AND(Z18>1,Z18<4,X18>5,X18<20),AND(Z18>3,X18>0,X18<6)),"Médio",IF(OR(AND(Z18>1,Z18<4,X18>19),AND(Z18>3,X18>5,X18<20),AND(Z18>3,X18>19)),"Complexo",""))),"")) | AC18: =IF(W18="ALI",IF(OR(AND(OR(Z18=1,Z18=0),X18>0,X18<20),AND(OR(Z18=1,Z18=0),X18>19,X18<51),AND(Z18>1,Z18<6,X18>0,X18<20)),"Simples",IF(OR(AND(OR(Z18=1,Z18=0),X18>50),AND(Z18>1,Z18<6,X18>19,X18<51),AND(Z18>5,X18>0,X18<20)),"Médio",IF(OR(AND(Z18>1,Z18<6,X18>50),AND(Z18>5,X18>19,X18<51),AND(Z18>5,X18>50)),"Complexo",""))), IF(W18="AIE",IF(OR(AND(OR(Z18=1, Z18=0),X18>0,X18<20),AND(OR(Z18=1, Z18=0),X18>19,X18<51),AND(Z18>1,Z18<6,X18>0,X18<20)),"Simples",IF(OR(AND(OR(Z18=1, Z18=0),X18>50),AND(Z18>1,Z18<6,X18>19,X18<51),AND(Z18>5,X18>0,X18<20)),"Médio",IF(OR(AND(Z18>1,Z18<6,X18>50),AND(Z18>5,X18>19,X18<51),AND(Z18>5,X18>50)),"Complexo",""))),"")) | AD18: =IF(AB18="",AC18,IF(AC18="",AB18,"")) | AE18: =IF(AND(OR(W18="EE",W18="CE"),AD18="Simples"),3, IF(AND(OR(W18="EE",W18="CE"),AD18="Médio"),4, IF(AND(OR(W18="EE",W18="CE"),AD18="Complexo"),6, IF(AND(W18="SE",AD18="Simples"),4, IF(AND(W18="SE",AD18="Médio"),5, IF(AND(W18="SE",AD18="Complexo"),7,0)))))) -> 0 | AF18: =IF(AND(W18="ALI",AC18="Simples"),7, IF(AND(W18="ALI",AC18="Médio"),10, IF(AND(W18="ALI",AC18="Complexo"),15, IF(AND(W18="AIE",AC18="Simples"),5, IF(AND(W18="AIE",AC18="Médio"),7, IF(AND(W18="AIE",AC18="Complexo"),10,0)))))) -> 0 | AG18: =IF(T18="OK",Q18,( IF(U18<>"Manutenção em interface",IF(U18<>"Desenv., Manutenção e Publicação de Páginas Estáticas",(AE18+AF18)*V18,V18),V18))) -> 0 | AM18: =IF(AG18=0,"",IF(AG18=Q18,"OK","Divergente"))
C19: =IF(B19<>"",VLOOKUP(B19,'Tipo Projeto'!$A$3:$B$35,2,0),0) -> 0 | L19: =IF(G19="EE",IF(OR(AND(OR(J19=1,J19=0),H19>0,H19<5),AND(OR(J19=1,J19=0),H19>4,H19<16),AND(J19=2,H19>0,H19<5)),"Simples",IF(OR(AND(OR(J19=1,J19=0),H19>15),AND(J19=2,H19>4,H19<16),AND(J19>2,H19>0,H19<5)),"Médio",IF(OR(AND(J19=2,H19>15),AND(J19>2,H19>4,H19<16),AND(J19>2,H19>15)),"Complexo",""))), IF(OR(G19="CE",G19="SE"),IF(OR(AND(OR(J19=1,J19=0),H19>0,H19<6),AND(OR(J19=1,J19=0),H19>5,H19<20),AND(J19>1,J19<4,H19>0,H19<6)),"Simples",IF(OR(AND(OR(J19=1,J19=0),H19>19),AND(J19>1,J19<4,H19>5,H19<20),AND(J19>3,H19>0,H19<6)),"Médio",IF(OR(AND(J19>1,J19<4,H19>19),AND(J19>3,H19>5,H19<20),AND(J19>3,H19>19)),"Complexo",""))),"")) | M19: =IF(G19="ALI",IF(OR(AND(OR(J19=1,J19=0),H19>0,H19<20),AND(OR(J19=1,J19=0),H19>19,H19<51),AND(J19>1,J19<6,H19>0,H19<20)),"Simples",IF(OR(AND(OR(J19=1,J19=0),H19>50),AND(J19>1,J19<6,H19>19,H19<51),AND(J19>5,H19>0,H19<20)),"Médio",IF(OR(AND(J19>1,J19<6,H19>50),AND(J19>5,H19>19,H19<51),AND(J19>5,H19>50)),"Complexo",""))), IF(G19="AIE",IF(OR(AND(OR(J19=1, J19=0),H19>0,H19<20),AND(OR(J19=1, J19=0),H19>19,H19<51),AND(J19>1,J19<6,H19>0,H19<20)),"Simples",IF(OR(AND(OR(J19=1, J19=0),H19>50),AND(J19>1,J19<6,H19>19,H19<51),AND(J19>5,H19>0,H19<20)),"Médio",IF(OR(AND(J19>1,J19<6,H19>50),AND(J19>5,H19>19,H19<51),AND(J19>5,H19>50)),"Complexo",""))),"")) | N19: =IF(L19="",M19,IF(M19="",L19,"")) | O19: =IF(AND(OR(G19="EE",G19="CE"),N19="Simples"),3, IF(AND(OR(G19="EE",G19="CE"),N19="Médio"),4, IF(AND(OR(G19="EE",G19="CE"),N19="Complexo"),6, IF(AND(G19="SE",N19="Simples"),4, IF(AND(G19="SE",N19="Médio"),5, IF(AND(G19="SE",N19="Complexo"),7,0)))))) -> 0 | P19: =IF(AND(G19="ALI",M19="Simples"),7, IF(AND(G19="ALI",M19="Médio"),10, IF(AND(G19="ALI",M19="Complexo"),15, IF(AND(G19="AIE",M19="Simples"),5, IF(AND(G19="AIE",M19="Médio"),7, IF(AND(G19="AIE",M19="Complexo"),10,0)))))) -> 0 | Q19: =IF(B19<>"Manutenção em interface",IF(B19<>"Desenv., Manutenção e Publicação de Páginas Estáticas",(O19+P19)*C19,C19),C19) -> 0 | V19: =IF(U19<>"",VLOOKUP(U19,'Tipo Projeto'!$A$3:$B$35,2,0),0) -> 0 | AB19: =IF(W19="EE",IF(OR(AND(OR(Z19=1,Z19=0),X19>0,X19<5),AND(OR(Z19=1,Z19=0),X19>4,X19<16),AND(Z19=2,X19>0,X19<5)),"Simples",IF(OR(AND(OR(Z19=1,Z19=0),X19>15),AND(Z19=2,X19>4,X19<16),AND(Z19>2,X19>0,X19<5)),"Médio",IF(OR(AND(Z19=2,X19>15),AND(Z19>2,X19>4,X19<16),AND(Z19>2,X19>15)),"Complexo",""))), IF(OR(W19="CE",W19="SE"),IF(OR(AND(OR(Z19=1,Z19=0),X19>0,X19<6),AND(OR(Z19=1,Z19=0),X19>5,X19<20),AND(Z19>1,Z19<4,X19>0,X19<6)),"Simples",IF(OR(AND(OR(Z19=1,Z19=0),X19>19),AND(Z19>1,Z19<4,X19>5,X19<20),AND(Z19>3,X19>0,X19<6)),"Médio",IF(OR(AND(Z19>1,Z19<4,X19>19),AND(Z19>3,X19>5,X19<20),AND(Z19>3,X19>19)),"Complexo",""))),"")) | AC19: =IF(W19="ALI",IF(OR(AND(OR(Z19=1,Z19=0),X19>0,X19<20),AND(OR(Z19=1,Z19=0),X19>19,X19<51),AND(Z19>1,Z19<6,X19>0,X19<20)),"Simples",IF(OR(AND(OR(Z19=1,Z19=0),X19>50),AND(Z19>1,Z19<6,X19>19,X19<51),AND(Z19>5,X19>0,X19<20)),"Médio",IF(OR(AND(Z19>1,Z19<6,X19>50),AND(Z19>5,X19>19,X19<51),AND(Z19>5,X19>50)),"Complexo",""))), IF(W19="AIE",IF(OR(AND(OR(Z19=1, Z19=0),X19>0,X19<20),AND(OR(Z19=1, Z19=0),X19>19,X19<51),AND(Z19>1,Z19<6,X19>0,X19<20)),"Simples",IF(OR(AND(OR(Z19=1, Z19=0),X19>50),AND(Z19>1,Z19<6,X19>19,X19<51),AND(Z19>5,X19>0,X19<20)),"Médio",IF(OR(AND(Z19>1,Z19<6,X19>50),AND(Z19>5,X19>19,X19<51),AND(Z19>5,X19>50)),"Complexo",""))),"")) | AD19: =IF(AB19="",AC19,IF(AC19="",AB19,"")) | AE19: =IF(AND(OR(W19="EE",W19="CE"),AD19="Simples"),3, IF(AND(OR(W19="EE",W19="CE"),AD19="Médio"),4, IF(AND(OR(W19="EE",W19="CE"),AD19="Complexo"),6, IF(AND(W19="SE",AD19="Simples"),4, IF(AND(W19="SE",AD19="Médio"),5, IF(AND(W19="SE",AD19="Complexo"),7,0)))))) -> 0 | AF19: =IF(AND(W19="ALI",AC19="Simples"),7, IF(AND(W19="ALI",AC19="Médio"),10, IF(AND(W19="ALI",AC19="Complexo"),15, IF(AND(W19="AIE",AC19="Simples"),5, IF(AND(W19="AIE",AC19="Médio"),7, IF(AND(W19="AIE",AC19="Complexo"),10,0)))))) -> 0 | AG19: =IF(T19="OK",Q19,( IF(U19<>"Manutenção em interface",IF(U19<>"Desenv., Manutenção e Publicação de Páginas Estáticas",(AE19+AF19)*V19,V19),V19))) -> 0 | AM19: =IF(AG19=0,"",IF(AG19=Q19,"OK","Divergente"))
C20: =IF(B20<>"",VLOOKUP(B20,'Tipo Projeto'!$A$3:$B$35,2,0),0) -> 0 | L20: =IF(G20="EE",IF(OR(AND(OR(J20=1,J20=0),H20>0,H20<5),AND(OR(J20=1,J20=0),H20>4,H20<16),AND(J20=2,H20>0,H20<5)),"Simples",IF(OR(AND(OR(J20=1,J20=0),H20>15),AND(J20=2,H20>4,H20<16),AND(J20>2,H20>0,H20<5)),"Médio",IF(OR(AND(J20=2,H20>15),AND(J20>2,H20>4,H20<16),AND(J20>2,H20>15)),"Complexo",""))), IF(OR(G20="CE",G20="SE"),IF(OR(AND(OR(J20=1,J20=0),H20>0,H20<6),AND(OR(J20=1,J20=0),H20>5,H20<20),AND(J20>1,J20<4,H20>0,H20<6)),"Simples",IF(OR(AND(OR(J20=1,J20=0),H20>19),AND(J20>1,J20<4,H20>5,H20<20),AND(J20>3,H20>0,H20<6)),"Médio",IF(OR(AND(J20>1,J20<4,H20>19),AND(J20>3,H20>5,H20<20),AND(J20>3,H20>19)),"Complexo",""))),"")) | M20: =IF(G20="ALI",IF(OR(AND(OR(J20=1,J20=0),H20>0,H20<20),AND(OR(J20=1,J20=0),H20>19,H20<51),AND(J20>1,J20<6,H20>0,H20<20)),"Simples",IF(OR(AND(OR(J20=1,J20=0),H20>50),AND(J20>1,J20<6,H20>19,H20<51),AND(J20>5,H20>0,H20<20)),"Médio",IF(OR(AND(J20>1,J20<6,H20>50),AND(J20>5,H20>19,H20<51),AND(J20>5,H20>50)),"Complexo",""))), IF(G20="AIE",IF(OR(AND(OR(J20=1, J20=0),H20>0,H20<20),AND(OR(J20=1, J20=0),H20>19,H20<51),AND(J20>1,J20<6,H20>0,H20<20)),"Simples",IF(OR(AND(OR(J20=1, J20=0),H20>50),AND(J20>1,J20<6,H20>19,H20<51),AND(J20>5,H20>0,H20<20)),"Médio",IF(OR(AND(J20>1,J20<6,H20>50),AND(J20>5,H20>19,H20<51),AND(J20>5,H20>50)),"Complexo",""))),"")) | N20: =IF(L20="",M20,IF(M20="",L20,"")) | O20: =IF(AND(OR(G20="EE",G20="CE"),N20="Simples"),3, IF(AND(OR(G20="EE",G20="CE"),N20="Médio"),4, IF(AND(OR(G20="EE",G20="CE"),N20="Complexo"),6, IF(AND(G20="SE",N20="Simples"),4, IF(AND(G20="SE",N20="Médio"),5, IF(AND(G20="SE",N20="Complexo"),7,0)))))) -> 0 | P20: =IF(AND(G20="ALI",M20="Simples"),7, IF(AND(G20="ALI",M20="Médio"),10, IF(AND(G20="ALI",M20="Complexo"),15, IF(AND(G20="AIE",M20="Simples"),5, IF(AND(G20="AIE",M20="Médio"),7, IF(AND(G20="AIE",M20="Complexo"),10,0)))))) -> 0 | Q20: =IF(B20<>"Manutenção em interface",IF(B20<>"Desenv., Manutenção e Publicação de Páginas Estáticas",(O20+P20)*C20,C20),C20) -> 0 | V20: =IF(U20<>"",VLOOKUP(U20,'Tipo Projeto'!$A$3:$B$35,2,0),0) -> 0 | AB20: =IF(W20="EE",IF(OR(AND(OR(Z20=1,Z20=0),X20>0,X20<5),AND(OR(Z20=1,Z20=0),X20>4,X20<16),AND(Z20=2,X20>0,X20<5)),"Simples",IF(OR(AND(OR(Z20=1,Z20=0),X20>15),AND(Z20=2,X20>4,X20<16),AND(Z20>2,X20>0,X20<5)),"Médio",IF(OR(AND(Z20=2,X20>15),AND(Z20>2,X20>4,X20<16),AND(Z20>2,X20>15)),"Complexo",""))), IF(OR(W20="CE",W20="SE"),IF(OR(AND(OR(Z20=1,Z20=0),X20>0,X20<6),AND(OR(Z20=1,Z20=0),X20>5,X20<20),AND(Z20>1,Z20<4,X20>0,X20<6)),"Simples",IF(OR(AND(OR(Z20=1,Z20=0),X20>19),AND(Z20>1,Z20<4,X20>5,X20<20),AND(Z20>3,X20>0,X20<6)),"Médio",IF(OR(AND(Z20>1,Z20<4,X20>19),AND(Z20>3,X20>5,X20<20),AND(Z20>3,X20>19)),"Complexo",""))),"")) | AC20: =IF(W20="ALI",IF(OR(AND(OR(Z20=1,Z20=0),X20>0,X20<20),AND(OR(Z20=1,Z20=0),X20>19,X20<51),AND(Z20>1,Z20<6,X20>0,X20<20)),"Simples",IF(OR(AND(OR(Z20=1,Z20=0),X20>50),AND(Z20>1,Z20<6,X20>19,X20<51),AND(Z20>5,X20>0,X20<20)),"Médio",IF(OR(AND(Z20>1,Z20<6,X20>50),AND(Z20>5,X20>19,X20<51),AND(Z20>5,X20>50)),"Complexo",""))), IF(W20="AIE",IF(OR(AND(OR(Z20=1, Z20=0),X20>0,X20<20),AND(OR(Z20=1, Z20=0),X20>19,X20<51),AND(Z20>1,Z20<6,X20>0,X20<20)),"Simples",IF(OR(AND(OR(Z20=1, Z20=0),X20>50),AND(Z20>1,Z20<6,X20>19,X20<51),AND(Z20>5,X20>0,X20<20)),"Médio",IF(OR(AND(Z20>1,Z20<6,X20>50),AND(Z20>5,X20>19,X20<51),AND(Z20>5,X20>50)),"Complexo",""))),"")) | AD20: =IF(AB20="",AC20,IF(AC20="",AB20,"")) | AE20: =IF(AND(OR(W20="EE",W20="CE"),AD20="Simples"),3, IF(AND(OR(W20="EE",W20="CE"),AD20="Médio"),4, IF(AND(OR(W20="EE",W20="CE"),AD20="Complexo"),6, IF(AND(W20="SE",AD20="Simples"),4, IF(AND(W20="SE",AD20="Médio"),5, IF(AND(W20="SE",AD20="Complexo"),7,0)))))) -> 0 | AF20: =IF(AND(W20="ALI",AC20="Simples"),7, IF(AND(W20="ALI",AC20="Médio"),10, IF(AND(W20="ALI",AC20="Complexo"),15, IF(AND(W20="AIE",AC20="Simples"),5, IF(AND(W20="AIE",AC20="Médio"),7, IF(AND(W20="AIE",AC20="Complexo"),10,0)))))) -> 0 | AG20: =IF(T20="OK",Q20,( IF(U20<>"Manutenção em interface",IF(U20<>"Desenv., Manutenção e Publicação de Páginas Estáticas",(AE20+AF20)*V20,V20),V20))) -> 0 | AM20: =IF(AG20=0,"",IF(AG20=Q20,"OK","Divergente"))
C21: =IF(B21<>"",VLOOKUP(B21,'Tipo Projeto'!$A$3:$B$35,2,0),0) -> 0 | L21: =IF(G21="EE",IF(OR(AND(OR(J21=1,J21=0),H21>0,H21<5),AND(OR(J21=1,J21=0),H21>4,H21<16),AND(J21=2,H21>0,H21<5)),"Simples",IF(OR(AND(OR(J21=1,J21=0),H21>15),AND(J21=2,H21>4,H21<16),AND(J21>2,H21>0,H21<5)),"Médio",IF(OR(AND(J21=2,H21>15),AND(J21>2,H21>4,H21<16),AND(J21>2,H21>15)),"Complexo",""))), IF(OR(G21="CE",G21="SE"),IF(OR(AND(OR(J21=1,J21=0),H21>0,H21<6),AND(OR(J21=1,J21=0),H21>5,H21<20),AND(J21>1,J21<4,H21>0,H21<6)),"Simples",IF(OR(AND(OR(J21=1,J21=0),H21>19),AND(J21>1,J21<4,H21>5,H21<20),AND(J21>3,H21>0,H21<6)),"Médio",IF(OR(AND(J21>1,J21<4,H21>19),AND(J21>3,H21>5,H21<20),AND(J21>3,H21>19)),"Complexo",""))),"")) | M21: =IF(G21="ALI",IF(OR(AND(OR(J21=1,J21=0),H21>0,H21<20),AND(OR(J21=1,J21=0),H21>19,H21<51),AND(J21>1,J21<6,H21>0,H21<20)),"Simples",IF(OR(AND(OR(J21=1,J21=0),H21>50),AND(J21>1,J21<6,H21>19,H21<51),AND(J21>5,H21>0,H21<20)),"Médio",IF(OR(AND(J21>1,J21<6,H21>50),AND(J21>5,H21>19,H21<51),AND(J21>5,H21>50)),"Complexo",""))), IF(G21="AIE",IF(OR(AND(OR(J21=1, J21=0),H21>0,H21<20),AND(OR(J21=1, J21=0),H21>19,H21<51),AND(J21>1,J21<6,H21>0,H21<20)),"Simples",IF(OR(AND(OR(J21=1, J21=0),H21>50),AND(J21>1,J21<6,H21>19,H21<51),AND(J21>5,H21>0,H21<20)),"Médio",IF(OR(AND(J21>1,J21<6,H21>50),AND(J21>5,H21>19,H21<51),AND(J21>5,H21>50)),"Complexo",""))),"")) | N21: =IF(L21="",M21,IF(M21="",L21,"")) | O21: =IF(AND(OR(G21="EE",G21="CE"),N21="Simples"),3, IF(AND(OR(G21="EE",G21="CE"),N21="Médio"),4, IF(AND(OR(G21="EE",G21="CE"),N21="Complexo"),6, IF(AND(G21="SE",N21="Simples"),4, IF(AND(G21="SE",N21="Médio"),5, IF(AND(G21="SE",N21="Complexo"),7,0)))))) -> 0 | P21: =IF(AND(G21="ALI",M21="Simples"),7, IF(AND(G21="ALI",M21="Médio"),10, IF(AND(G21="ALI",M21="Complexo"),15, IF(AND(G21="AIE",M21="Simples"),5, IF(AND(G21="AIE",M21="Médio"),7, IF(AND(G21="AIE",M21="Complexo"),10,0)))))) -> 0 | Q21: =IF(B21<>"Manutenção em interface",IF(B21<>"Desenv., Manutenção e Publicação de Páginas Estáticas",(O21+P21)*C21,C21),C21) -> 0 | V21: =IF(U21<>"",VLOOKUP(U21,'Tipo Projeto'!$A$3:$B$35,2,0),0) -> 0 | AB21: =IF(W21="EE",IF(OR(AND(OR(Z21=1,Z21=0),X21>0,X21<5),AND(OR(Z21=1,Z21=0),X21>4,X21<16),AND(Z21=2,X21>0,X21<5)),"Simples",IF(OR(AND(OR(Z21=1,Z21=0),X21>15),AND(Z21=2,X21>4,X21<16),AND(Z21>2,X21>0,X21<5)),"Médio",IF(OR(AND(Z21=2,X21>15),AND(Z21>2,X21>4,X21<16),AND(Z21>2,X21>15)),"Complexo",""))), IF(OR(W21="CE",W21="SE"),IF(OR(AND(OR(Z21=1,Z21=0),X21>0,X21<6),AND(OR(Z21=1,Z21=0),X21>5,X21<20),AND(Z21>1,Z21<4,X21>0,X21<6)),"Simples",IF(OR(AND(OR(Z21=1,Z21=0),X21>19),AND(Z21>1,Z21<4,X21>5,X21<20),AND(Z21>3,X21>0,X21<6)),"Médio",IF(OR(AND(Z21>1,Z21<4,X21>19),AND(Z21>3,X21>5,X21<20),AND(Z21>3,X21>19)),"Complexo",""))),"")) | AC21: =IF(W21="ALI",IF(OR(AND(OR(Z21=1,Z21=0),X21>0,X21<20),AND(OR(Z21=1,Z21=0),X21>19,X21<51),AND(Z21>1,Z21<6,X21>0,X21<20)),"Simples",IF(OR(AND(OR(Z21=1,Z21=0),X21>50),AND(Z21>1,Z21<6,X21>19,X21<51),AND(Z21>5,X21>0,X21<20)),"Médio",IF(OR(AND(Z21>1,Z21<6,X21>50),AND(Z21>5,X21>19,X21<51),AND(Z21>5,X21>50)),"Complexo",""))), IF(W21="AIE",IF(OR(AND(OR(Z21=1, Z21=0),X21>0,X21<20),AND(OR(Z21=1, Z21=0),X21>19,X21<51),AND(Z21>1,Z21<6,X21>0,X21<20)),"Simples",IF(OR(AND(OR(Z21=1, Z21=0),X21>50),AND(Z21>1,Z21<6,X21>19,X21<51),AND(Z21>5,X21>0,X21<20)),"Médio",IF(OR(AND(Z21>1,Z21<6,X21>50),AND(Z21>5,X21>19,X21<51),AND(Z21>5,X21>50)),"Complexo",""))),"")) | AD21: =IF(AB21="",AC21,IF(AC21="",AB21,"")) | AE21: =IF(AND(OR(W21="EE",W21="CE"),AD21="Simples"),3, IF(AND(OR(W21="EE",W21="CE"),AD21="Médio"),4, IF(AND(OR(W21="EE",W21="CE"),AD21="Complexo"),6, IF(AND(W21="SE",AD21="Simples"),4, IF(AND(W21="SE",AD21="Médio"),5, IF(AND(W21="SE",AD21="Complexo"),7,0)))))) -> 0 | AF21: =IF(AND(W21="ALI",AC21="Simples"),7, IF(AND(W21="ALI",AC21="Médio"),10, IF(AND(W21="ALI",AC21="Complexo"),15, IF(AND(W21="AIE",AC21="Simples"),5, IF(AND(W21="AIE",AC21="Médio"),7, IF(AND(W21="AIE",AC21="Complexo"),10,0)))))) -> 0 | AG21: =IF(T21="OK",Q21,( IF(U21<>"Manutenção em interface",IF(U21<>"Desenv., Manutenção e Publicação de Páginas Estáticas",(AE21+AF21)*V21,V21),V21))) -> 0 | AM21: =IF(AG21=0,"",IF(AG21=Q21,"OK","Divergente"))
