Workbook
Name Lista_Estorias: 'Estórias '!$B$3:$B$99
Name ListaCTIS: Lista!$A$3:$A$33
Name ListaTipos: QuadroResumo!$B$4:$B$9

Sheet Revisão
B1: Chamado [Número] - [Sigla do Sistema]
B2: Planilha de Contagem de Ponto de Função
B3: Histórico de Alterações
B4: Versão | C4: Data | D4: Responsável | G4: Descrição
B17: Modelo 1.3

Sheet Resumo
B2: Planilha de Contagem de Pontos de Função
F3: Percentual de Aceitação | H3: 0.05 | I3: Quantidade de Itens NAP | J3: =COUNTIFS(Funções!T3:T202,"NOK") -> 0
H4: -0.05 | I4: Quantidade de Itens AP | J4: =COUNTIFS(Funções!T3:T202,"OK") -> 0
B5: =IF(OR(ISBLANK(D13),D13=0),"Aguardando Aferição da Fábrica de Software",IF(OR(ISBLANK(D20),D20=0),"Aguardando Aferição da Fábrica de Métricas",IF(OR(AND(D24>=0,D24<=H3),AND(D24<=0,D24>=H4)),"Contagem Aprovada","Contagem em Divergência"))) -> Aguardando Aferição da Fábrica de Software
B6: Contagem Fábrica de Software
B7: Contratada | D7: BASIS
B8: ID Demanda
B9: Nome do Sistema
B10: Módulo
B11: Nome do Contador
B12: Tipo de Contagem
B13: Total de PFB | D13: =QuadroResumo!G10 -> 0 | F13: Total de PFL | H13: =QuadroResumo!H10 -> 0
B14: Total de Retrabalho | D14: =SUMIF(Funções!D3:D202, "=RT1", Funções!Q3:Q202) + SUMIF(Funções!D3:D202, "=RT2", Funções!Q3:Q202) -> 0
B16: Contagem Fábrica de Métricas
B17: Contratada
B18: ID Demanda
B19: Nome do CFPS
B20: Total de PFB | D20: =QuadroResumo!G20 -> 0 | F20: Total de PFL | H20: =QuadroResumo!H20 -> 0
B21: Total de Retrabalho | D21: =SUMIF(Funções!V3:V202, "=RT1", Funções!AG3:AG202) + SUMIF(Funções!V3:V202, "=RT2", Funções!AG3:AG202) -> 0
B23: Comparação das Contagens
B24: % de Divergência | D24: =IFERROR(ROUND((D20-D13)/D13,2),0) -> 0
B26: Módulo/Demanda | D26: 19809 | G26: Total PF | I26: Total PF (Deflação) | J26: =IF(E33="x",(SUM(J31:J35)*0.75),SUM(J31:J35)) -> 0
B27: Revisor Técnico | D27: Philipe Dias de Alencar | I27: Data | J27: 41526
B28: Revisor DATASUS | I28: Data
B29: Tipo de contagem | C29: Projeto Novo
C30: Manutenção Adaptativa | I30: Ação | J30: PF
C31: Manutenção Corretiva | I31: Inclusão | J31: =QuadroResumo!J4 -> 0
C32: Manutenção Evolutiva | I32: Alteração | J32: =IF(E32="x",QuadroResumo!J5*0.6,QuadroResumo!J5) -> 0
C33: Manutenção Perfectiva | E33: x | I33: Exclusão | J33: =IF(E32="x",QuadroResumo!J6*0.4,QuadroResumo!J6) -> 0
C34: Aplicação ( Baseline ) | I34: Correção / Conversão | J34: =IF(E32="x",QuadroResumo!J7,(IF(E31="x",QuadroResumo!J7*0.75,0))) -> 0
C35: Migração de dados | I35: Itens Não Mensuráveis | J35: ='Itens Não Mensuráveis'!E16 -> 0
C36: Migração de tecnologia | F36: Informe o tipo de contagem.
B37: =CONCATENATE(B16," = ",D20," PF") -> Contagem Fábrica de Métricas = 0 PF
B38: =CONCATENATE(E20,":",H20," PF") -> :0 PF
B39: =CONCATENATE(B24,":",D24*100,"%") -> % de Divergência:0%
B41: Propósito da Contagem
B43: Escopo da Contagem
B45: Fronteira da Contagem
B47: Plataforma (Tecnologia do Sistema)
B49: Acesso ao Sistema
...

Sheet Itens Não Mensuráveis
A1: Total Itens Não Mensuráveis(PF):
A2: Item Não Mensurável | B2: Descrição | C2: PF | D2: Qtde | E2: Total PF | F2: Item Guia APF | G2: Justificativa / Evidência | I2: Validação
B3: =IF(A3="","",IF(Resumo!$D$7="CAST",VLOOKUP(A3,Lista!#REF!,2,0),VLOOKUP(A3,Lista!#REF!,2,0))) | C3: =IF(A3="","",IF(Resumo!$D$7="CAST",VLOOKUP(A3,Lista!#REF!,3,0),VLOOKUP(A3,Lista!#REF!,3,0))) | D3: 0 | E3: =IF(C3="","",D3*C3) | F3: =IF(OR(A3="",Resumo!$D$7="CTIS"),"",VLOOKUP(A3,Lista!#REF!,3,0))
B4: =IF(A4="","",IF(Resumo!$D$7="CAST",VLOOKUP(A4,Lista!#REF!,2,0),VLOOKUP(A4,Lista!#REF!,2,0))) | C4: =IF(A4="","",IF(Resumo!$D$7="CAST",VLOOKUP(A4,Lista!#REF!,3,0),VLOOKUP(A4,Lista!#REF!,3,0))) | D4: 0 | E4: =IF(C4="","",D4*C4) | F4: =IF(OR(A4="",Resumo!$D$7="CTIS"),"",VLOOKUP(A4,Lista!#REF!,3,0))
B5: =IF(A5="","",IF(Resumo!$D$7="CAST",VLOOKUP(A5,Lista!#REF!,2,0),VLOOKUP(A5,Lista!#REF!,2,0))) | C5: =IF(A5="","",IF(Resumo!$D$7="CAST",VLOOKUP(A5,Lista!#REF!,3,0),VLOOKUP(A5,Lista!#REF!,3,0))) | D5: 0 | E5: =IF(C5="","",D5*C5) | F5: =IF(OR(A5="",Resumo!$D$7="CTIS"),"",VLOOKUP(A5,Lista!#REF!,3,0))
B6: =IF(A6="","",IF(Resumo!$D$7="CAST",VLOOKUP(A6,Lista!#REF!,2,0),VLOOKUP(A6,Lista!#REF!,2,0))) | C6: =IF(A6="","",IF(Resumo!$D$7="CAST",VLOOKUP(A6,Lista!#REF!,3,0),VLOOKUP(A6,Lista!#REF!,3,0))) | D6: 0 | E6: =IF(C6="","",D6*C6) | F6: =IF(OR(A6="",Resumo!$D$7="CTIS"),"",VLOOKUP(A6,Lista!#REF!,3,0))
B7: =IF(A7="","",IF(Resumo!$D$7="CAST",VLOOKUP(A7,Lista!#REF!,2,0),VLOOKUP(A7,Lista!#REF!,2,0))) | C7: =IF(A7="","",IF(Resumo!$D$7="CAST",VLOOKUP(A7,Lista!#REF!,3,0),VLOOKUP(A7,Lista!#REF!,3,0))) | D7: 0 | E7: =IF(C7="","",D7*C7) | F7: =IF(OR(A7="",Resumo!$D$7="CTIS"),"",VLOOKUP(A7,Lista!#REF!,3,0))
B8: =IF(A8="","",IF(Resumo!$D$7="CAST",VLOOKUP(A8,Lista!#REF!,2,0),VLOOKUP(A8,Lista!#REF!,2,0))) | C8: =IF(A8="","",IF(Resumo!$D$7="CAST",VLOOKUP(A8,Lista!#REF!,3,0),VLOOKUP(A8,Lista!#REF!,3,0))) | D8: 0 | E8: =IF(C8="","",D8*C8) | F8: =IF(OR(A8="",Resumo!$D$7="CTIS"),"",VLOOKUP(A8,Lista!#REF!,3,0))
B9: =IF(A9="","",IF(Resumo!$D$7="CAST",VLOOKUP(A9,Lista!#REF!,2,0),VLOOKUP(A9,Lista!#REF!,2,0))) | C9: =IF(A9="","",IF(Resumo!$D$7="CAST",VLOOKUP(A9,Lista!#REF!,3,0),VLOOKUP(A9,Lista!#REF!,3,0))) | D9: 0 | E9: =IF(C9="","",D9*C9) | F9: =IF(OR(A9="",Resumo!$D$7="CTIS"),"",VLOOKUP(A9,Lista!#REF!,3,0))
B10: =IF(A10="","",IF(Resumo!$D$7="CAST",VLOOKUP(A10,Lista!#REF!,2,0),VLOOKUP(A10,Lista!#REF!,2,0))) | C10: =IF(A10="","",IF(Resumo!$D$7="CAST",VLOOKUP(A10,Lista!#REF!,3,0),VLOOKUP(A10,Lista!#REF!,3,0))) | D10: 0 | E10: =IF(C10="","",D10*C10) | F10: =IF(OR(A10="",Resumo!$D$7="CTIS"),"",VLOOKUP(A10,Lista!#REF!,3,0))
B11: =IF(A11="","",IF(Resumo!$D$7="CAST",VLOOKUP(A11,Lista!#REF!,2,0),VLOOKUP(A11,Lista!#REF!,2,0))) | C11: =IF(A11="","",IF(Resumo!$D$7="CAST",VLOOKUP(A11,Lista!#REF!,3,0),VLOOKUP(A11,Lista!#REF!,3,0))) | D11: 0 | E11: =IF(C11="","",D11*C11) | F11: =IF(OR(A11="",Resumo!$D$7="CTIS"),"",VLOOKUP(A11,Lista!#REF!,3,0))
B12: =IF(A12="","",IF(Resumo!$D$7="CAST",VLOOKUP(A12,Lista!#REF!,2,0),VLOOKUP(A12,Lista!#REF!,2,0))) | C12: =IF(A12="","",IF(Resumo!$D$7="CAST",VLOOKUP(A12,Lista!#REF!,3,0),VLOOKUP(A12,Lista!#REF!,3,0))) | D12: 0 | E12: =IF(C12="","",D12*C12) | F12: =IF(OR(A12="",Resumo!$D$7="CTIS"),"",VLOOKUP(A12,Lista!#REF!,3,0))
B13: =IF(A13="","",IF(Resumo!$D$7="CAST",VLOOKUP(A13,Lista!#REF!,2,0),VLOOKUP(A13,Lista!#REF!,2,0))) | C13: =IF(A13="","",IF(Resumo!$D$7="CAST",VLOOKUP(A13,Lista!#REF!,3,0),VLOOKUP(A13,Lista!#REF!,3,0))) | D13: 0 | E13: =IF(C13="","",D13*C13) | F13: =IF(OR(A13="",Resumo!$D$7="CTIS"),"",VLOOKUP(A13,Lista!#REF!,3,0))
B14: =IF(A14="","",IF(Resumo!$D$7="CAST",VLOOKUP(A14,Lista!#REF!,2,0),VLOOKUP(A14,Lista!#REF!,2,0))) | C14: =IF(A14="","",IF(Resumo!$D$7="CAST",VLOOKUP(A14,Lista!#REF!,3,0),VLOOKUP(A14,Lista!#REF!,3,0))) | D14: 0 | E14: =IF(C14="","",D14*C14) | F14: =IF(OR(A14="",Resumo!$D$7="CTIS"),"",VLOOKUP(A14,Lista!#REF!,3,0))
B15: =IF(A15="","",IF(Resumo!$D$7="CAST",VLOOKUP(A15,Lista!#REF!,2,0),VLOOKUP(A15,Lista!#REF!,2,0))) | C15: =IF(A15="","",IF(Resumo!$D$7="CAST",VLOOKUP(A15,Lista!#REF!,3,0),VLOOKUP(A15,Lista!#REF!,3,0))) | D15: 0 | E15: =IF(C15="","",D15*C15) | F15: =IF(OR(A15="",Resumo!$D$7="CTIS"),"",VLOOKUP(A15,Lista!#REF!,3,0))
D16: Total de APF | E16: =SUM(E3:E15) -> 0
B20: =Resumo!D27 -> Philipe Dias de Alencar
B21: Revisor técnico
B25: =Resumo!D28 -> 0
B26: Revisor DATASUS
B30: Cristiane Lustosa Guimarães França
B31: Gestora do Contrato

Sheet Funções
B1: Contagem da Fábrica de Software | T1: Contagem da Fábrica de Métricas | AJ1: Resposta Fábrica de Software | AK1: Resposta Fábrica de Métricas
A2: PBI | B2: Nome Estória | C2: Tipo | D2: Deflator / INM | E2: DER | F2: Descrição DER | G2: R/A | H2: Descrição R/A | I2: QTD | J2: ctl | K2: CTL2 | L2: C | M2: DF | N2: TP | O2: CP | P2: PFB | Q2: PFL | R2: Documentação (Evidência de Contagem) | T2: Validação | U2: Tipo | V2: Deflator / INM | W2: DER | X2: R/A | Y2: QTD | Z2: ctl | AA2: CTL2 | AB2: C | AC2: DF | AD2: TP | AE2: CP | AF2: PFB | AG2: PFL | AH2: Parecer Técnico
J3: =CONCATENATE(C3,L3) | K3: =CONCATENATE(C3,D3,L3,Q3) -> 0 | L3: =IF(OR(ISBLANK(E3),ISBLANK(G3)),IF(OR(C3="ALI",C3="AIE"),"L",IF(ISBLANK(C3),"","A")),IF(C3="EE",IF(G3>=3,IF(E3>=5,"H","A"),IF(G3>=2,IF(E3>=16,"H",IF(E3<=4,"L","A")),IF(E3<=15,"L","A"))),IF(OR(C3="SE",C3="CE"),IF(G3>=4,IF(E3>=6,"H","A"),IF(G3>=2,IF(E3>=20,"H",IF(E3<=5,"L","A")),IF(E3<=19,"L","A"))),IF(OR(C3="ALI",C3="AIE"),IF(G3>=6,IF(E3>=20,"H","A"),IF(G3>=2,IF(E3>=51,"H",IF(E3<=19,"L","A")),IF(E3<=50,"L","A"))))))) | M3: =IFERROR(VLOOKUP(D3,Lista!A$3:D$33,3,0),1) -> 1 | N3: =IFERROR(VLOOKUP(D3,Lista!A$3:E$33,5,0),1) -> 1 | O3: =IF(C3="INM","",IF(L3="L","Baixa",IF(L3="A","Média",IF(L3="","","Alta")))) | P3: =IF(C3="INM",M3*I3,IF(C3="ALI",IF(L3="L",7,IF(L3="A",10,15)),IF(C3="AIE",IF(L3="L",5,IF(L3="A",7,10)),IF(C3="SE",IF(L3="L",4,IF(L3="A",5,7)),IF(OR(C3="EE",C3="CE"),IF(L3="L",3,IF(L3="A",4,6)),0))))) -> 0 | Q3: =IF(C3="INM",P3,P3*M3) -> 0 | Z3: =CONCATENATE(U3,AB3) | AA3: =CONCATENATE(U3,V3,AB3,AG3) -> 0 | AB3: =IF(OR(ISBLANK(W3),ISBLANK(X3)),IF(OR(U3="ALI",U3="AIE"),"L",IF(ISBLANK(U3),"","A")),IF(U3="EE",IF(X3>=3,IF(W3>=5,"H","A"),IF(X3>=2,IF(W3>=16,"H",IF(W3<=4,"L","A")),IF(W3<=15,"L","A"))),IF(OR(U3="SE",U3="CE"),IF(X3>=4,IF(W3>=6,"H","A"),IF(X3>=2,IF(W3>=20,"H",IF(W3<=5,"L","A")),IF(W3<=19,"L","A"))),IF(OR(U3="ALI",U3="AIE"),IF(X3>=6,IF(W3>=20,"H","A"),IF(X3>=2,IF(W3>=51,"H",IF(W3<=19,"L","A")),IF(W3<=50,"L","A"))))))) | AC3: =IFERROR(VLOOKUP(V3,Lista!A$3:D$33,3,0),1) -> 1 | AD3: =IFERROR(VLOOKUP(V3,Lista!A$3:E$33,5,0),1) -> 1 | AE3: =IF(U3="INM","",IF(AB3="L","Baixa",IF(AB3="A","Média",IF(AB3="","","Alta")))) | AF3: =IF(OR(ISBLANK(T3),T3="NOK"),0,IF(U3="INM",AC3*Y3,IF(U3="ALI",IF(AB3="L",7,IF(AB3="A",10,15)),IF(U3="AIE",IF(AB3="L",5,IF(AB3="A",7,10)),IF(U3="SE",IF(AB3="L",4,IF(AB3="A",5,7)),IF(OR(U3="EE",U3="CE"),IF(AB3="L",3,IF(AB3="A",4,6)))))))) -> 0 | AG3: =IF(T3="NOK",0,IF(U3="INM",(1*AC3)*Y3,AF3*AC3)) -> 0
J4: =CONCATENATE(C4,L4) | K4: =CONCATENATE(C4,D4,L4,Q4) -> 0 | L4: =IF(OR(ISBLANK(E4),ISBLANK(G4)),IF(OR(C4="ALI",C4="AIE"),"L",IF(ISBLANK(C4),"","A")),IF(C4="EE",IF(G4>=3,IF(E4>=5,"H","A"),IF(G4>=2,IF(E4>=16,"H",IF(E4<=4,"L","A")),IF(E4<=15,"L","A"))),IF(OR(C4="SE",C4="CE"),IF(G4>=4,IF(E4>=6,"H","A"),IF(G4>=2,IF(E4>=20,"H",IF(E4<=5,"L","A")),IF(E4<=19,"L","A"))),IF(OR(C4="ALI",C4="AIE"),IF(G4>=6,IF(E4>=20,"H","A"),IF(G4>=2,IF(E4>=51,"H",IF(E4<=19,"L","A")),IF(E4<=50,"L","A"))))))) | M4: =IFERROR(VLOOKUP(D4,Lista!A$3:D$33,3,0),1) -> 1 | N4: =IFERROR(VLOOKUP(D4,Lista!A$3:E$33,5,0),1) -> 1 | O4: =IF(C4="INM","",IF(L4="L","Baixa",IF(L4="A","Média",IF(L4="","","Alta")))) | P4: =IF(C4="INM",M4*I4,IF(C4="ALI",IF(L4="L",7,IF(L4="A",10,15)),IF(C4="AIE",IF(L4="L",5,IF(L4="A",7,10)),IF(C4="SE",IF(L4="L",4,IF(L4="A",5,7)),IF(OR(C4="EE",C4="CE"),IF(L4="L",3,IF(L4="A",4,6)),0))))) -> 0 | Q4: =IF(C4="INM",P4,P4*M4) -> 0 | Z4: =CONCATENATE(U4,AB4) | AA4: =CONCATENATE(U4,V4,AB4,AG4) -> 0 | AB4: =IF(OR(ISBLANK(W4),ISBLANK(X4)),IF(OR(U4="ALI",U4="AIE"),"L",IF(ISBLANK(U4),"","A")),IF(U4="EE",IF(X4>=3,IF(W4>=5,"H","A"),IF(X4>=2,IF(W4>=16,"H",IF(W4<=4,"L","A")),IF(W4<=15,"L","A"))),IF(OR(U4="SE",U4="CE"),IF(X4>=4,IF(W4>=6,"H","A"),IF(X4>=2,IF(W4>=20,"H",IF(W4<=5,"L","A")),IF(W4<=19,"L","A"))),IF(OR(U4="ALI",U4="AIE"),IF(X4>=6,IF(W4>=20,"H","A"),IF(X4>=2,IF(W4>=51,"H",IF(W4<=19,"L","A")),IF(W4<=50,"L","A"))))))) | AC4: =IFERROR(VLOOKUP(V4,Lista!A$3:D$33,3,0),1) -> 1 | AD4: =IFERROR(VLOOKUP(V4,Lista!A$3:E$33,5,0),1) -> 1 | AE4: =IF(U4="INM","",IF(AB4="L","Baixa",IF(AB4="A","Média",IF(AB4="","","Alta")))) | AF4: =IF(OR(ISBLANK(T4),T4="NOK"),0,IF(U4="INM",AC4*Y4,IF(U4="ALI",IF(AB4="L",7,IF(AB4="A",10,15)),IF(U4="AIE",IF(AB4="L",5,IF(AB4="A",7,10)),IF(U4="SE",IF(AB4="L",4,IF(AB4="A",5,7)),IF(OR(U4="EE",U4="CE"),IF(AB4="L",3,IF(AB4="A",4,6)))))))) -> 0 | AG4: =IF(T4="NOK",0,IF(U4="INM",(1*AC4)*Y4,AF4*AC4)) -> 0
J5: =CONCATENATE(C5,L5) | K5: =CONCATENATE(C5,D5,L5,Q5) -> 0 | L5: =IF(OR(ISBLANK(E5),ISBLANK(G5)),IF(OR(C5="ALI",C5="AIE"),"L",IF(ISBLANK(C5),"","A")),IF(C5="EE",IF(G5>=3,IF(E5>=5,"H","A"),IF(G5>=2,IF(E5>=16,"H",IF(E5<=4,"L","A")),IF(E5<=15,"L","A"))),IF(OR(C5="SE",C5="CE"),IF(G5>=4,IF(E5>=6,"H","A"),IF(G5>=2,IF(E5>=20,"H",IF(E5<=5,"L","A")),IF(E5<=19,"L","A"))),IF(OR(C5="ALI",C5="AIE"),IF(G5>=6,IF(E5>=20,"H","A"),IF(G5>=2,IF(E5>=51,"H",IF(E5<=19,"L","A")),IF(E5<=50,"L","A"))))))) | M5: =IFERROR(VLOOKUP(D5,Lista!A$3:D$33,3,0),1) -> 1 | N5: =IFERROR(VLOOKUP(D5,Lista!A$3:E$33,5,0),1) -> 1 | O5: =IF(C5="INM","",IF(L5="L","Baixa",IF(L5="A","Média",IF(L5="","","Alta")))) | P5: =IF(C5="INM",M5*I5,IF(C5="ALI",IF(L5="L",7,IF(L5="A",10,15)),IF(C5="AIE",IF(L5="L",5,IF(L5="A",7,10)),IF(C5="SE",IF(L5="L",4,IF(L5="A",5,7)),IF(OR(C5="EE",C5="CE"),IF(L5="L",3,IF(L5="A",4,6)),0))))) -> 0 | Q5: =IF(C5="INM",P5,P5*M5) -> 0 | Z5: =CONCATENATE(U5,AB5) | AA5: =CONCATENATE(U5,V5,AB5,AG5) -> 0 | AB5: =IF(OR(ISBLANK(W5),ISBLANK(X5)),IF(OR(U5="ALI",U5="AIE"),"L",IF(ISBLANK(U5),"","A")),IF(U5="EE",IF(X5>=3,IF(W5>=5,"H","A"),IF(X5>=2,IF(W5>=16,"H",IF(W5<=4,"L","A")),IF(W5<=15,"L","A"))),IF(OR(U5="SE",U5="CE"),IF(X5>=4,IF(W5>=6,"H","A"),IF(X5>=2,IF(W5>=20,"H",IF(W5<=5,"L","A")),IF(W5<=19,"L","A"))),IF(OR(U5="ALI",U5="AIE"),IF(X5>=6,IF(W5>=20,"H","A"),IF(X5>=2,IF(W5>=51,"H",IF(W5<=19,"L","A")),IF(W5<=50,"L","A"))))))) | AC5: =IFERROR(VLOOKUP(V5,Lista!A$3:D$33,3,0),1) -> 1 | AD5: =IFERROR(VLOOKUP(V5,Lista!A$3:E$33,5,0),1) -> 1 | AE5: =IF(U5="INM","",IF(AB5="L","Baixa",IF(AB5="A","Média",IF(AB5="","","Alta")))) | AF5: =IF(OR(ISBLANK(T5),T5="NOK"),0,IF(U5="INM",AC5*Y5,IF(U5="ALI",IF(AB5="L",7,IF(AB5="A",10,15)),IF(U5="AIE",IF(AB5="L",5,IF(AB5="A",7,10)),IF(U5="SE",IF(AB5="L",4,IF(AB5="A",5,7)),IF(OR(U5="EE",U5="CE"),IF(AB5="L",3,IF(AB5="A",4,6)))))))) -> 0 | AG5: =IF(T5="NOK",0,IF(U5="INM",(1*AC5)*Y5,AF5*AC5)) -> 0
J6: =CONCATENATE(C6,L6) | K6: =CONCATENATE(C6,D6,L6,Q6) -> 0 | L6: =IF(OR(ISBLANK(E6),ISBLANK(G6)),IF(OR(C6="ALI",C6="AIE"),"L",IF(ISBLANK(C6),"","A")),IF(C6="EE",IF(G6>=3,IF(E6>=5,"H","A"),IF(G6>=2,IF(E6>=16,"H",IF(E6<=4,"L","A")),IF(E6<=15,"L","A"))),IF(OR(C6="SE",C6="CE"),IF(G6>=4,IF(E6>=6,"H","A"),IF(G6>=2,IF(E6>=20,"H",IF(E6<=5,"L","A")),IF(E6<=19,"L","A"))),IF(OR(C6="ALI",C6="AIE"),IF(G6>=6,IF(E6>=20,"H","A"),IF(G6>=2,IF(E6>=51,"H",IF(E6<=19,"L","A")),IF(E6<=50,"L","A"))))))) | M6: =IFERROR(VLOOKUP(D6,Lista!A$3:D$33,3,0),1) -> 1 | N6: =IFERROR(VLOOKUP(D6,Lista!A$3:E$33,5,0),1) -> 1 | O6: =IF(C6="INM","",IF(L6="L","Baixa",IF(L6="A","Média",IF(L6="","","Alta")))) | P6: =IF(C6="INM",M6*I6,IF(C6="ALI",IF(L6="L",7,IF(L6="A",10,15)),IF(C6="AIE",IF(L6="L",5,IF(L6="A",7,10)),IF(C6="SE",IF(L6="L",4,IF(L6="A",5,7)),IF(OR(C6="EE",C6="CE"),IF(L6="L",3,IF(L6="A",4,6)),0))))) -> 0 | Q6: =IF(C6="INM",P6,P6*M6) -> 0 | Z6: =CONCATENATE(U6,AB6) | AA6: =CONCATENATE(U6,V6,AB6,AG6) -> 0 | AB6: =IF(OR(ISBLANK(W6),ISBLANK(X6)),IF(OR(U6="ALI",U6="AIE"),"L",IF(ISBLANK(U6),"","A")),IF(U6="EE",IF(X6>=3,IF(W6>=5,"H","A"),IF(X6>=2,IF(W6>=16,"H",IF(W6<=4,"L","A")),IF(W6<=15,"L","A"))),IF(OR(U6="SE",U6="CE"),IF(X6>=4,IF(W6>=6,"H","A"),IF(X6>=2,IF(W6>=20,"H",IF(W6<=5,"L","A")),IF(W6<=19,"L","A"))),IF(OR(U6="ALI",U6="AIE"),IF(X6>=6,IF(W6>=20,"H","A"),IF(X6>=2,IF(W6>=51,"H",IF(W6<=19,"L","A")),IF(W6<=50,"L","A"))))))) | AC6: =IFERROR(VLOOKUP(V6,Lista!A$3:D$33,3,0),1) -> 1 | AD6: =IFERROR(VLOOKUP(V6,Lista!A$3:E$33,5,0),1) -> 1 | AE6: =IF(U6="INM","",IF(AB6="L","Baixa",IF(AB6="A","Média",IF(AB6="","","Alta")))) | AF6: =IF(OR(ISBLANK(T6),T6="NOK"),0,IF(U6="INM",AC6*Y6,IF(U6="ALI",IF(AB6="L",7,IF(AB6="A",10,15)),IF(U6="AIE",IF(AB6="L",5,IF(AB6="A",7,10)),IF(U6="SE",IF(AB6="L",4,IF(AB6="A",5,7)),IF(OR(U6="EE",U6="CE"),IF(AB6="L",3,IF(AB6="A",4,6)))))))) -> 0 | AG6: =IF(T6="NOK",0,IF(U6="INM",(1*AC6)*Y6,AF6*AC6)) -> 0
J7: =CONCATENATE(C7,L7) | K7: =CONCATENATE(C7,D7,L7,Q7) -> 0 | L7: =IF(OR(ISBLANK(E7),ISBLANK(G7)),IF(OR(C7="ALI",C7="AIE"),"L",IF(ISBLANK(C7),"","A")),IF(C7="EE",IF(G7>=3,IF(E7>=5,"H","A"),IF(G7>=2,IF(E7>=16,"H",IF(E7<=4,"L","A")),IF(E7<=15,"L","A"))),IF(OR(C7="SE",C7="CE"),IF(G7>=4,IF(E7>=6,"H","A"),IF(G7>=2,IF(E7>=20,"H",IF(E7<=5,"L","A")),IF(E7<=19,"L","A"))),IF(OR(C7="ALI",C7="AIE"),IF(G7>=6,IF(E7>=20,"H","A"),IF(G7>=2,IF(E7>=51,"H",IF(E7<=19,"L","A")),IF(E7<=50,"L","A"))))))) | M7: =IFERROR(VLOOKUP(D7,Lista!A$3:D$33,3,0),1) -> 1 | N7: =IFERROR(VLOOKUP(D7,Lista!A$3:E$33,5,0),1) -> 1 | O7: =IF(C7="INM","",IF(L7="L","Baixa",IF(L7="A","Média",IF(L7="","","Alta")))) | P7: =IF(C7="INM",M7*I7,IF(C7="ALI",IF(L7="L",7,IF(L7="A",10,15)),IF(C7="AIE",IF(L7="L",5,IF(L7="A",7,10)),IF(C7="SE",IF(L7="L",4,IF(L7="A",5,7)),IF(OR(C7="EE",C7="CE"),IF(L7="L",3,IF(L7="A",4,6)),0))))) -> 0 | Q7: =IF(C7="INM",P7,P7*M7) -> 0 | Z7: =CONCATENATE(U7,AB7) | AA7: =CONCATENATE(U7,V7,AB7,AG7) -> 0 | AB7: =IF(OR(ISBLANK(W7),ISBLANK(X7)),IF(OR(U7="ALI",U7="AIE"),"L",IF(ISBLANK(U7),"","A")),IF(U7="EE",IF(X7>=3,IF(W7>=5,"H","A"),IF(X7>=2,IF(W7>=16,"H",IF(W7<=4,"L","A")),IF(W7<=15,"L","A"))),IF(OR(U7="SE",U7="CE"),IF(X7>=4,IF(W7>=6,"H","A"),IF(X7>=2,IF(W7>=20,"H",IF(W7<=5,"L","A")),IF(W7<=19,"L","A"))),IF(OR(U7="ALI",U7="AIE"),IF(X7>=6,IF(W7>=20,"H","A"),IF(X7>=2,IF(W7>=51,"H",IF(W7<=19,"L","A")),IF(W7<=50,"L","A"))))))) | AC7: =IFERROR(VLOOKUP(V7,Lista!A$3:D$33,3,0),1) -> 1 | AD7: =IFERROR(VLOOKUP(V7,Lista!A$3:E$33,5,0),1) -> 1 | AE7: =IF(U7="INM","",IF(AB7="L","Baixa",IF(AB7="A","Média",IF(AB7="","","Alta")))) | AF7: =IF(OR(ISBLANK(T7),T7="NOK"),0,IF(U7="INM",AC7*Y7,IF(U7="ALI",IF(AB7="L",7,IF(AB7="A",10,15)),IF(U7="AIE",IF(AB7="L",5,IF(AB7="A",7,10)),IF(U7="SE",IF(AB7="L",4,IF(AB7="A",5,7)),IF(OR(U7="EE",U7="CE"),IF(AB7="L",3,IF(AB7="A",4,6)))))))) -> 0 | AG7: =IF(T7="NOK",0,IF(U7="INM",(1*AC7)*Y7,AF7*AC7)) -> 0
J8: =CONCATENATE(C8,L8) | K8: =CONCATENATE(C8,D8,L8,Q8) -> 0 | L8: =IF(OR(ISBLANK(E8),ISBLANK(G8)),IF(OR(C8="ALI",C8="AIE"),"L",IF(ISBLANK(C8),"","A")),IF(C8="EE",IF(G8>=3,IF(E8>=5,"H","A"),IF(G8>=2,IF(E8>=16,"H",IF(E8<=4,"L","A")),IF(E8<=15,"L","A"))),IF(OR(C8="SE",C8="CE"),IF(G8>=4,IF(E8>=6,"H","A"),IF(G8>=2,IF(E8>=20,"H",IF(E8<=5,"L","A")),IF(E8<=19,"L","A"))),IF(OR(C8="ALI",C8="AIE"),IF(G8>=6,IF(E8>=20,"H","A"),IF(G8>=2,IF(E8>=51,"H",IF(E8<=19,"L","A")),IF(E8<=50,"L","A"))))))) | M8: =IFERROR(VLOOKUP(D8,Lista!A$3:D$33,3,0),1) -> 1 | N8: =IFERROR(VLOOKUP(D8,Lista!A$3:E$33,5,0),1) -> 1 | O8: =IF(C8="INM","",IF(L8="L","Baixa",IF(L8="A","Média",IF(L8="","","Alta")))) | P8: =IF(C8="INM",M8*I8,IF(C8="ALI",IF(L8="L",7,IF(L8="A",10,15)),IF(C8="AIE",IF(L8="L",5,IF(L8="A",7,10)),IF(C8="SE",IF(L8="L",4,IF(L8="A",5,7)),IF(OR(C8="EE",C8="CE"),IF(L8="L",3,IF(L8="A",4,6)),0))))) -> 0 | Q8: =IF(C8="INM",P8,P8*M8) -> 0 | Z8: =CONCATENATE(U8,AB8) | AA8: =CONCATENATE(U8,V8,AB8,AG8) -> 0 | AB8: =IF(OR(ISBLANK(W8),ISBLANK(X8)),IF(OR(U8="ALI",U8="AIE"),"L",IF(ISBLANK(U8),"","A")),IF(U8="EE",IF(X8>=3,IF(W8>=5,"H","A"),IF(X8>=2,IF(W8>=16,"H",IF(W8<=4,"L","A")),IF(W8<=15,"L","A"))),IF(OR(U8="SE",U8="CE"),IF(X8>=4,IF(W8>=6,"H","A"),IF(X8>=2,IF(W8>=20,"H",IF(W8<=5,"L","A")),IF(W8<=19,"L","A"))),IF(OR(U8="ALI",U8="AIE"),IF(X8>=6,IF(W8>=20,"H","A"),IF(X8>=2,IF(W8>=51,"H",IF(W8<=19,"L","A")),IF(W8<=50,"L","A"))))))) | AC8: =IFERROR(VLOOKUP(V8,Lista!A$3:D$33,3,0),1) -> 1 | AD8: =IFERROR(VLOOKUP(V8,Lista!A$3:E$33,5,0),1) -> 1 | AE8: =IF(U8="INM","",IF(AB8="L","Baixa",IF(AB8="A","Média",IF(AB8="","","Alta")))) | AF8: =IF(OR(ISBLANK(T8),T8="NOK"),0,IF(U8="INM",AC8*Y8,IF(U8="ALI",IF(AB8="L",7,IF(AB8="A",10,15)),IF(U8="AIE",IF(AB8="L",5,IF(AB8="A",7,10)),IF(U8="SE",IF(AB8="L",4,IF(AB8="A",5,7)),IF(OR(U8="EE",U8="CE"),IF(AB8="L",3,IF(AB8="A",4,6)))))))) -> 0 | AG8: =IF(T8="NOK",0,IF(U8="INM",(1*AC8)*Y8,AF8*AC8)) -> 0
J9: =CONCATENATE(C9,L9) | K9: =CONCATENATE(C9,D9,L9,Q9) -> 0 | L9: =IF(OR(ISBLANK(E9),ISBLANK(G9)),IF(OR(C9="ALI",C9="AIE"),"L",IF(ISBLANK(C9),"","A")),IF(C9="EE",IF(G9>=3,IF(E9>=5,"H","A"),IF(G9>=2,IF(E9>=16,"H",IF(E9<=4,"L","A")),IF(E9<=15,"L","A"))),IF(OR(C9="SE",C9="CE"),IF(G9>=4,IF(E9>=6,"H","A"),IF(G9>=2,IF(E9>=20,"H",IF(E9<=5,"L","A")),IF(E9<=19,"L","A"))),IF(OR(C9="ALI",C9="AIE"),IF(G9>=6,IF(E9>=20,"H","A"),IF(G9>=2,IF(E9>=51,"H",IF(E9<=19,"L","A")),IF(E9<=50,"L","A"))))))) | M9: =IFERROR(VLOOKUP(D9,Lista!A$3:D$33,3,0),1) -> 1 | N9: =IFERROR(VLOOKUP(D9,Lista!A$3:E$33,5,0),1) -> 1 | O9: =IF(C9="INM","",IF(L9="L","Baixa",IF(L9="A","Média",IF(L9="","","Alta")))) | P9: =IF(C9="INM",M9*I9,IF(C9="ALI",IF(L9="L",7,IF(L9="A",10,15)),IF(C9="AIE",IF(L9="L",5,IF(L9="A",7,10)),IF(C9="SE",IF(L9="L",4,IF(L9="A",5,7)),IF(OR(C9="EE",C9="CE"),IF(L9="L",3,IF(L9="A",4,6)),0))))) -> 0 | Q9: =IF(C9="INM",P9,P9*M9) -> 0 | Z9: =CONCATENATE(U9,AB9) | AA9: =CONCATENATE(U9,V9,AB9,AG9) -> 0 | AB9: =IF(OR(ISBLANK(W9),ISBLANK(X9)),IF(OR(U9="ALI",U9="AIE"),"L",IF(ISBLANK(U9),"","A")),IF(U9="EE",IF(X9>=3,IF(W9>=5,"H","A"),IF(X9>=2,IF(W9>=16,"H",IF(W9<=4,"L","A")),IF(W9<=15,"L","A"))),IF(OR(U9="SE",U9="CE"),IF(X9>=4,IF(W9>=6,"H","A"),IF(X9>=2,IF(W9>=20,"H",IF(W9<=5,"L","A")),IF(W9<=19,"L","A"))),IF(OR(U9="ALI",U9="AIE"),IF(X9>=6,IF(W9>=20,"H","A"),IF(X9>=2,IF(W9>=51,"H",IF(W9<=19,"L","A")),IF(W9<=50,"L","A"))))))) | AC9: =IFERROR(VLOOKUP(V9,Lista!A$3:D$33,3,0),1) -> 1 | AD9: =IFERROR(VLOOKUP(V9,Lista!A$3:E$33,5,0),1) -> 1 | AE9: =IF(U9="INM","",IF(AB9="L","Baixa",IF(AB9="A","Média",IF(AB9="","","Alta")))) | AF9: =IF(OR(ISBLANK(T9),T9="NOK"),0,IF(U9="INM",AC9*Y9,IF(U9="ALI",IF(AB9="L",7,IF(AB9="A",10,15)),IF(U9="AIE",IF(AB9="L",5,IF(AB9="A",7,10)),IF(U9="SE",IF(AB9="L",4,IF(AB9="A",5,7)),IF(OR(U9="EE",U9="CE"),IF(AB9="L",3,IF(AB9="A",4,6)))))))) -> 0 | AG9: =IF(T9="NOK",0,IF(U9="INM",(1*AC9)*Y9,AF9*AC9)) -> 0
J10: =CONCATENATE(C10,L10) | K10: =CONCATENATE(C10,D10,L10,Q10) -> 0 | L10: =IF(OR(ISBLANK(E10),ISBLANK(G10)),IF(OR(C10="ALI",C10="AIE"),"L",IF(ISBLANK(C10),"","A")),IF(C10="EE",IF(G10>=3,IF(E10>=5,"H","A"),IF(G10>=2,IF(E10>=16,"H",IF(E10<=4,"L","A")),IF(E10<=15,"L","A"))),IF(OR(C10="SE",C10="CE"),IF(G10>=4,IF(E10>=6,"H","A"),IF(G10>=2,IF(E10>=20,"H",IF(E10<=5,"L","A")),IF(E10<=19,"L","A"))),IF(OR(C10="ALI",C10="AIE"),IF(G10>=6,IF(E10>=20,"H","A"),IF(G10>=2,IF(E10>=51,"H",IF(E10<=19,"L","A")),IF(E10<=50,"L","A"))))))) | M10: =IFERROR(VLOOKUP(D10,Lista!A$3:D$33,3,0),1) -> 1 | N10: =IFERROR(VLOOKUP(D10,Lista!A$3:E$33,5,0),1) -> 1 | O10: =IF(C10="INM","",IF(L10="L","Baixa",IF(L10="A","Média",IF(L10="","","Alta")))) | P10: =IF(C10="INM",M10*I10,IF(C10="ALI",IF(L10="L",7,IF(L10="A",10,15)),IF(C10="AIE",IF(L10="L",5,IF(L10="A",7,10)),IF(C10="SE",IF(L10="L",4,IF(L10="A",5,7)),IF(OR(C10="EE",C10="CE"),IF(L10="L",3,IF(L10="A",4,6)),0))))) -> 0 | Q10: =IF(C10="INM",P10,P10*M10) -> 0 | Z10: =CONCATENATE(U10,AB10) | AA10: =CONCATENATE(U10,V10,AB10,AG10) -> 0 | AB10: =IF(OR(ISBLANK(W10),ISBLANK(X10)),IF(OR(U10="ALI",U10="AIE"),"L",IF(ISBLANK(U10),"","A")),IF(U10="EE",IF(X10>=3,IF(W10>=5,"H","A"),IF(X10>=2,IF(W10>=16,"H",IF(W10<=4,"L","A")),IF(W10<=15,"L","A"))),IF(OR(U10="SE",U10="CE"),IF(X10>=4,IF(W10>=6,"H","A"),IF(X10>=2,IF(W10>=20,"H",IF(W10<=5,"L","A")),IF(W10<=19,"L","A"))),IF(OR(U10="ALI",U10="AIE"),IF(X10>=6,IF(W10>=20,"H","A"),IF(X10>=2,IF(W10>=51,"H",IF(W10<=19,"L","A")),IF(W10<=50,"L","A"))))))) | AC10: =IFERROR(VLOOKUP(V10,Lista!A$3:D$33,3,0),1) -> 1 | AD10: =IFERROR(VLOOKUP(V10,Lista!A$3:E$33,5,0),1) -> 1 | AE10: =IF(U10="INM","",IF(AB10="L","Baixa",IF(AB10="A","Média",IF(AB10="","","Alta")))) | AF10: =IF(OR(ISBLANK(T10),T10="NOK"),0,IF(U10="INM",AC10*Y10,IF(U10="ALI",IF(AB10="L",7,IF(AB10="A",10,15)),IF(U10="AIE",IF(AB10="L",5,IF(AB10="A",7,10)),IF(U10="SE",IF(AB10="L",4,IF(AB10="A",5,7)),IF(OR(U10="EE",U10="CE"),IF(AB10="L",3,IF(AB10="A",4,6)))))))) -> 0 | AG10: =IF(T10="NOK",0,IF(U10="INM",(1*AC10)*Y10,AF10*AC10)) -> 0
J11: =CONCATENATE(C11,L11) | K11: =CONCATENATE(C11,D11,L11,Q11) -> 0 | L11: =IF(OR(ISBLANK(E11),ISBLANK(G11)),IF(OR(C11="ALI",C11="AIE"),"L",IF(ISBLANK(C11),"","A")),IF(C11="EE",IF(G11>=3,IF(E11>=5,"H","A"),IF(G11>=2,IF(E11>=16,"H",IF(E11<=4,"L","A")),IF(E11<=15,"L","A"))),IF(OR(C11="SE",C11="CE"),IF(G11>=4,IF(E11>=6,"H","A"),IF(G11>=2,IF(E11>=20,"H",IF(E11<=5,"L","A")),IF(E11<=19,"L","A"))),IF(OR(C11="ALI",C11="AIE"),IF(G11>=6,IF(E11>=20,"H","A"),IF(G11>=2,IF(E11>=51,"H",IF(E11<=19,"L","A")),IF(E11<=50,"L","A"))))))) | M11: =IFERROR(VLOOKUP(D11,Lista!A$3:D$33,3,0),1) -> 1 | N11: =IFERROR(VLOOKUP(D11,Lista!A$3:E$33,5,0),1) -> 1 | O11: =IF(C11="INM","",IF(L11="L","Baixa",IF(L11="A","Média",IF(L11="","","Alta")))) | P11: =IF(C11="INM",M11*I11,IF(C11="ALI",IF(L11="L",7,IF(L11="A",10,15)),IF(C11="AIE",IF(L11="L",5,IF(L11="A",7,10)),IF(C11="SE",IF(L11="L",4,IF(L11="A",5,7)),IF(OR(C11="EE",C11="CE"),IF(L11="L",3,IF(L11="A",4,6)),0))))) -> 0 | Q11: =IF(C11="INM",P11,P11*M11) -> 0 | Z11: =CONCATENATE(U11,AB11) | AA11: =CONCATENATE(U11,V11,AB11,AG11) -> 0 | AB11: =IF(OR(ISBLANK(W11),ISBLANK(X11)),IF(OR(U11="ALI",U11="AIE"),"L",IF(ISBLANK(U11),"","A")),IF(U11="EE",IF(X11>=3,IF(W11>=5,"H","A"),IF(X11>=2,IF(W11>=16,"H",IF(W11<=4,"L","A")),IF(W11<=15,"L","A"))),IF(OR(U11="SE",U11="CE"),IF(X11>=4,IF(W11>=6,"H","A"),IF(X11>=2,IF(W11>=20,"H",IF(W11<=5,"L","A")),IF(W11<=19,"L","A"))),IF(OR(U11="ALI",U11="AIE"),IF(X11>=6,IF(W11>=20,"H","A"),IF(X11>=2,IF(W11>=51,"H",IF(W11<=19,"L","A")),IF(W11<=50,"L","A"))))))) | AC11: =IFERROR(VLOOKUP(V11,Lista!A$3:D$33,3,0),1) -> 1 | AD11: =IFERROR(VLOOKUP(V11,Lista!A$3:E$33,5,0),1) -> 1 | AE11: =IF(U11="INM","",IF(AB11="L","Baixa",IF(AB11="A","Média",IF(AB11="","","Alta")))) | AF11: =IF(OR(ISBLANK(T11),T11="NOK"),0,IF(U11="INM",AC11*Y11,IF(U11="ALI",IF(AB11="L",7,IF(AB11="A",10,15)),IF(U11="AIE",IF(AB11="L",5,IF(AB11="A",7,10)),IF(U11="SE",IF(AB11="L",4,IF(AB11="A",5,7)),IF(OR(U11="EE",U11="CE"),IF(AB11="L",3,IF(AB11="A",4,6)))))))) -> 0 | AG11: =IF(T11="NOK",0,IF(U11="INM",(1*AC11)*Y11,AF11*AC11)) -> 0
J12: =CONCATENATE(C12,L12) | K12: =CONCATENATE(C12,D12,L12,Q12) -> 0 | L12: =IF(OR(ISBLANK(E12),ISBLANK(G12)),IF(OR(C12="ALI",C12="AIE"),"L",IF(ISBLANK(C12),"","A")),IF(C12="EE",IF(G12>=3,IF(E12>=5,"H","A"),IF(G12>=2,IF(E12>=16,"H",IF(E12<=4,"L","A")),IF(E12<=15,"L","A"))),IF(OR(C12="SE",C12="CE"),IF(G12>=4,IF(E12>=6,"H","A"),IF(G12>=2,IF(E12>=20,"H",IF(E12<=5,"L","A")),IF(E12<=19,"L","A"))),IF(OR(C12="ALI",C12="AIE"),IF(G12>=6,IF(E12>=20,"H","A"),IF(G12>=2,IF(E12>=51,"H",IF(E12<=19,"L","A")),IF(E12<=50,"L","A"))))))) | M12: =IFERROR(VLOOKUP(D12,Lista!A$3:D$33,3,0),1) -> 1 | N12: =IFERROR(VLOOKUP(D12,Lista!A$3:E$33,5,0),1) -> 1 | O12: =IF(C12="INM","",IF(L12="L","Baixa",IF(L12="A","Média",IF(L12="","","Alta")))) | P12: =IF(C12="INM",M12*I12,IF(C12="ALI",IF(L12="L",7,IF(L12="A",10,15)),IF(C12="AIE",IF(L12="L",5,IF(L12="A",7,10)),IF(C12="SE",IF(L12="L",4,IF(L12="A",5,7)),IF(OR(C12="EE",C12="CE"),IF(L12="L",3,IF(L12="A",4,6)),0))))) -> 0 | Q12: =IF(C12="INM",P12,P12*M12) -> 0 | Z12: =CONCATENATE(U12,AB12) | AA12: =CONCATENATE(U12,V12,AB12,AG12) -> 0 | AB12: =IF(OR(ISBLANK(W12),ISBLANK(X12)),IF(OR(U12="ALI",U12="AIE"),"L",IF(ISBLANK(U12),"","A")),IF(U12="EE",IF(X12>=3,IF(W12>=5,"H","A"),IF(X12>=2,IF(W12>=16,"H",IF(W12<=4,"L","A")),IF(W12<=15,"L","A"))),IF(OR(U12="SE",U12="CE"),IF(X12>=4,IF(W12>=6,"H","A"),IF(X12>=2,IF(W12>=20,"H",IF(W12<=5,"L","A")),IF(W12<=19,"L","A"))),IF(OR(U12="ALI",U12="AIE"),IF(X12>=6,IF(W12>=20,"H","A"),IF(X12>=2,IF(W12>=51,"H",IF(W12<=19,"L","A")),IF(W12<=50,"L","A"))))))) | AC12: =IFERROR(VLOOKUP(V12,Lista!A$3:D$33,3,0),1) -> 1 | AD12: =IFERROR(VLOOKUP(V12,Lista!A$3:E$33,5,0),1) -> 1 | AE12: =IF(U12="INM","",IF(AB12="L","Baixa",IF(AB12="A","Média",IF(AB12="","","Alta")))) | AF12: =IF(OR(ISBLANK(T12),T12="NOK"),0,IF(U12="INM",AC12*Y12,IF(U12="ALI",IF(AB12="L",7,IF(AB12="A",10,15)),IF(U12="AIE",IF(AB12="L",5,IF(AB12="A",7,10)),IF(U12="SE",IF(AB12="L",4,IF(AB12="A",5,7)),IF(OR(U12="EE",U12="CE"),IF(AB12="L",3,IF(AB12="A",4,6)))))))) -> 0 | AG12: =IF(T12="NOK",0,IF(U12="INM",(1*AC12)*Y12,AF12*AC12)) -> 0
J13: =CONCATENATE(C13,L13) | K13: =CONCATENATE(C13,D13,L13,Q13) -> 0 | L13: =IF(OR(ISBLANK(E13),ISBLANK(G13)),IF(OR(C13="ALI",C13="AIE"),"L",IF(ISBLANK(C13),"","A")),IF(C13="EE",IF(G13>=3,IF(E13>=5,"H","A"),IF(G13>=2,IF(E13>=16,"H",IF(E13<=4,"L","A")),IF(E13<=15,"L","A"))),IF(OR(C13="SE",C13="CE"),IF(G13>=4,IF(E13>=6,"H","A"),IF(G13>=2,IF(E13>=20,"H",IF(E13<=5,"L","A")),IF(E13<=19,"L","A"))),IF(OR(C13="ALI",C13="AIE"),IF(G13>=6,IF(E13>=20,"H","A"),IF(G13>=2,IF(E13>=51,"H",IF(E13<=19,"L","A")),IF(E13<=50,"L","A"))))))) | M13: =IFERROR(VLOOKUP(D13,Lista!A$3:D$33,3,0),1) -> 1 | N13: =IFERROR(VLOOKUP(D13,Lista!A$3:E$33,5,0),1) -> 1 | O13: =IF(C13="INM","",IF(L13="L","Baixa",IF(L13="A","Média",IF(L13="","","Alta")))) | P13: =IF(C13="INM",M13*I13,IF(C13="ALI",IF(L13="L",7,IF(L13="A",10,15)),IF(C13="AIE",IF(L13="L",5,IF(L13="A",7,10)),IF(C13="SE",IF(L13="L",4,IF(L13="A",5,7)),IF(OR(C13="EE",C13="CE"),IF(L13="L",3,IF(L13="A",4,6)),0))))) -> 0 | Q13: =IF(C13="INM",P13,P13*M13) -> 0 | Z13: =CONCATENATE(U13,AB13) | AA13: =CONCATENATE(U13,V13,AB13,AG13) -> 0 | AB13: =IF(OR(ISBLANK(W13),ISBLANK(X13)),IF(OR(U13="ALI",U13="AIE"),"L",IF(ISBLANK(U13),"","A")),IF(U13="EE",IF(X13>=3,IF(W13>=5,"H","A"),IF(X13>=2,IF(W13>=16,"H",IF(W13<=4,"L","A")),IF(W13<=15,"L","A"))),IF(OR(U13="SE",U13="CE"),IF(X13>=4,IF(W13>=6,"H","A"),IF(X13>=2,IF(W13>=20,"H",IF(W13<=5,"L","A")),IF(W13<=19,"L","A"))),IF(OR(U13="ALI",U13="AIE"),IF(X13>=6,IF(W13>=20,"H","A"),IF(X13>=2,IF(W13>=51,"H",IF(W13<=19,"L","A")),IF(W13<=50,"L","A"))))))) | AC13: =IFERROR(VLOOKUP(V13,Lista!A$3:D$33,3,0),1) -> 1 | AD13: =IFERROR(VLOOKUP(V13,Lista!A$3:E$33,5,0),1) -> 1 | AE13: =IF(U13="INM","",IF(AB13="L","Baixa",IF(AB13="A","Média",IF(AB13="","","Alta")))) | AF13: =IF(OR(ISBLANK(T13),T13="NOK"),0,IF(U13="INM",AC13*Y13,IF(U13="ALI",IF(AB13="L",7,IF(AB13="A",10,15)),IF(U13="AIE",IF(AB13="L",5,IF(AB13="A",7,10)),IF(U13="SE",IF(AB13="L",4,IF(AB13="A",5,7)),IF(OR(U13="EE",U13="CE"),IF(AB13="L",3,IF(AB13="A",4,6)))))))) -> 0 | AG13: =IF(T13="NOK",0,IF(U13="INM",(1*AC13)*Y13,AF13*AC13)) -> 0
J14: =CONCATENATE(C14,L14) | K14: =CONCATENATE(C14,D14,L14,Q14) -> 0 | L14: =IF(OR(ISBLANK(E14),ISBLANK(G14)),IF(OR(C14="ALI",C14="AIE"),"L",IF(ISBLANK(C14),"","A")),IF(C14="EE",IF(G14>=3,IF(E14>=5,"H","A"),IF(G14>=2,IF(E14>=16,"H",IF(E14<=4,"L","A")),IF(E14<=15,"L","A"))),IF(OR(C14="SE",C14="CE"),IF(G14>=4,IF(E14>=6,"H","A"),IF(G14>=2,IF(E14>=20,"H",IF(E14<=5,"L","A")),IF(E14<=19,"L","A"))),IF(OR(C14="ALI",C14="AIE"),IF(G14>=6,IF(E14>=20,"H","A"),IF(G14>=2,IF(E14>=51,"H",IF(E14<=19,"L","A")),IF(E14<=50,"L","A"))))))) | M14: =IFERROR(VLOOKUP(D14,Lista!A$3:D$33,3,0),1) -> 1 | N14: =IFERROR(VLOOKUP(D14,Lista!A$3:E$33,5,0),1) -> 1 | O14: =IF(C14="INM","",IF(L14="L","Baixa",IF(L14="A","Média",IF(L14="","","Alta")))) | P14: =IF(C14="INM",M14*I14,IF(C14="ALI",IF(L14="L",7,IF(L14="A",10,15)),IF(C14="AIE",IF(L14="L",5,IF(L14="A",7,10)),IF(C14="SE",IF(L14="L",4,IF(L14="A",5,7)),IF(OR(C14="EE",C14="CE"),IF(L14="L",3,IF(L14="A",4,6)),0))))) -> 0 | Q14: =IF(C14="INM",P14,P14*M14) -> 0 | Z14: =CONCATENATE(U14,AB14) | AA14: =CONCATENATE(U14,V14,AB14,AG14) -> 0 | AB14: =IF(OR(ISBLANK(W14),ISBLANK(X14)),IF(OR(U14="ALI",U14="AIE"),"L",IF(ISBLANK(U14),"","A")),IF(U14="EE",IF(X14>=3,IF(W14>=5,"H","A"),IF(X14>=2,IF(W14>=16,"H",IF(W14<=4,"L","A")),IF(W14<=15,"L","A"))),IF(OR(U14="SE",U14="CE"),IF(X14>=4,IF(W14>=6,"H","A"),IF(X14>=2,IF(W14>=20,"H",IF(W14<=5,"L","A")),IF(W14<=19,"L","A"))),IF(OR(U14="ALI",U14="AIE"),IF(X14>=6,IF(W14>=20,"H","A"),IF(X14>=2,IF(W14>=51,"H",IF(W14<=19,"L","A")),IF(W14<=50,"L","A"))))))) | AC14: =IFERROR(VLOOKUP(V14,Lista!A$3:D$33,3,0),1) -> 1 | AD14: =IFERROR(VLOOKUP(V14,Lista!A$3:E$33,5,0),1) -> 1 | AE14: =IF(U14="INM","",IF(AB14="L","Baixa",IF(AB14="A","Média",IF(AB14="","","Alta")))) | AF14: =IF(OR(ISBLANK(T14),T14="NOK"),0,IF(U14="INM",AC14*Y14,IF(U14="ALI",IF(AB14="L",7,IF(AB14="A",10,15)),IF(U14="AIE",IF(AB14="L",5,IF(AB14="A",7,10)),IF(U14="SE",IF(AB14="L",4,IF(AB14="A",5,7)),IF(OR(U14="EE",U14="CE"),IF(AB14="L",3,IF(AB14="A",4,6)))))))) -> 0 | AG14: =IF(T14="NOK",0,IF(U14="INM",(1*AC14)*Y14,AF14*AC14)) -> 0
... J202: =CONCATENATE(C202,L202) | K202: =CONCATENATE(C202,D202,L202,Q202) -> 0 | L202: =IF(OR(ISBLANK(E202),ISBLANK(G202)),IF(OR(C202="ALI",C202="AIE"),"L",IF(ISBLANK(C202),"","A")),IF(C202="EE",IF(G202>=3,IF(E202>=5,"H","A"),IF(G202>=2,IF(E202>=16,"H",IF(E202<=4,"L","A")),IF(E202<=15,"L","A"))),IF(OR(C202="SE",C202="CE"),IF(G202>=4,IF(E202>=6,"H","A"),IF(G202>=2,IF(E202>=20,"H",IF(E202<=5,"L","A")),IF(E202<=19,"L","A"))),IF(OR(C202="ALI",C202="AIE"),IF(G202>=6,IF(E202>=20,"H","A"),IF(G202>=2,IF(E202>=51,"H",IF(E202<=19,"L","A")),IF(E202<=50,"L","A"))))))) | M202: =IFERROR(VLOOKUP(D202,Lista!A$3:D$33,3,0),1) -> 1 | N202: =IFERROR(VLOOKUP(D202,Lista!A$3:E$33,5,0),1) -> 1 | O202: =IF(C202="INM","",IF(L202="L","Baixa",IF(L202="A","Média",IF(L202="","","Alta")))) | P202: =IF(C202="INM",M202*I202,IF(C202="ALI",IF(L202="L",7,IF(L202="A",10,15)),IF(C202="AIE",IF(L202="L",5,IF(L202="A",7,10)),IF(C202="SE",IF(L202="L",4,IF(L202="A",5,7)),IF(OR(C202="EE",C202="CE"),IF(L202="L",3,IF(L202="A",4,6)),0))))) -> 0 | Q202: =IF(C202="INM",P202,P202*M202) -> 0 | Z202: =CONCATENATE(U202,AB202) | AA202: =CONCATENATE(U202,V202,AB202,AG202) -> 0 | AB202: =IF(OR(ISBLANK(W202),ISBLANK(X202)),IF(OR(U202="ALI",U202="AIE"),"L",IF(ISBLANK(U202),"","A")),IF(U202="EE",IF(X202>=3,IF(W202>=5,"H","A"),IF(X202>=2,IF(W202>=16,"H",IF(W202<=4,"L","A")),IF(W202<=15,"L","A"))),IF(OR(U202="SE",U202="CE"),IF(X202>=4,IF(W202>=6,"H","A"),IF(X202>=2,IF(W202>=20,"H",IF(W202<=5,"L","A")),IF(W202<=19,"L","A"))),IF(OR(U202="ALI",U202="AIE"),IF(X202>=6,IF(W202>=20,"H","A"),IF(X202>=2,IF(W202>=51,"H",IF(W202<=19,"L","A")),IF(W202<=50,"L","A"))))))) | AC202: =IFERROR(VLOOKUP(V202,Lista!A$3:D$33,3,0),1) -> 1 | AD202: =IFERROR(VLOOKUP(V202,Lista!A$3:E$33,5,0),1) -> 1 | AE202: =IF(U202="INM","",IF(AB202="L","Baixa",IF(AB202="A","Média",IF(AB202="","","Alta")))) | AF202: =IF(OR(ISBLANK(T202),T202="NOK"),0,IF(U202="INM",AC202*Y202,IF(U202="ALI",IF(AB202="L",7,IF(AB202="A",10,15)),IF(U202="AIE",IF(AB202="L",5,IF(AB202="A",7,10)),IF(U202="SE",IF(AB202="L",4,IF(AB202="A",5,7)),IF(OR(U202="EE",U202="CE"),IF(AB202="L",3,IF(AB202="A",4,6)))))))) -> 0 | AG202: =IF(T202="NOK",0,IF(U202="INM",(1*AC202)*Y202,AF202*AC202)) -> 0

Sheet QuadroResumo
B2: Quadro Resumo Fábrica de Software
C3: Inclusão | D3: Alteração | E3: Exclusão | F3: Conversão | G3: Total PFB | H3: Total PFL
B4: ALI | C4: =SUMPRODUCT((Funções!$C$3:$C$203=B4)*(Funções!$D$3:$D$203="I")) -> 0 | D4: =SUMPRODUCT((Funções!$C$3:$C$203=B4)*(Funções!$D$3:$D$203="A")) -> 0 | E4: =SUMPRODUCT((Funções!$C$3:$C$203=B4)*(Funções!$D$3:$D$203="E")) -> 0 | F4: =SUMPRODUCT((Funções!$C$3:$C$203=B4)*(Funções!$D$3:$D$203="C")) -> 0 | G4: =SUMIF(Funções!$C$3:$C$203,B4,Funções!$P$3:$P$203) -> 0 | H4: =SUMIF(Funções!$C$3:$C$203,B4,Funções!$Q$3:$Q$203) -> 0 | I4: Inclusão | J4: =SUMIF(Funções!D3:D203,"=I",Funções!P3:P203) -> 0
B5: AIE | C5: =SUMPRODUCT((Funções!$C$3:$C$203=B5)*(Funções!$D$3:$D$203="I")) -> 0 | D5: =SUMPRODUCT((Funções!$C$3:$C$203=B5)*(Funções!$D$3:$D$203="A")) -> 0 | E5: =SUMPRODUCT((Funções!$C$3:$C$203=B5)*(Funções!$D$3:$D$203="E")) -> 0 | F5: =SUMPRODUCT((Funções!$C$3:$C$203=B5)*(Funções!$D$3:$D$203="C")) -> 0 | G5: =SUMIF(Funções!$C$3:$C$203,B5,Funções!$P$3:$P$203) -> 0 | H5: =SUMIF(Funções!$C$3:$C$203,B5,Funções!$Q$3:$Q$203) -> 0 | I5: Alteração | J5: =SUMIF(Funções!D3:D203,"=A",Funções!P3:P203) -> 0
B6: EE | C6: =SUMPRODUCT((Funções!$C$3:$C$203=B6)*(Funções!$D$3:$D$203="I")) -> 0 | D6: =SUMPRODUCT((Funções!$C$3:$C$203=B6)*(Funções!$D$3:$D$203="A")) -> 0 | E6: =SUMPRODUCT((Funções!$C$3:$C$203=B6)*(Funções!$D$3:$D$203="E")) -> 0 | F6: =SUMPRODUCT((Funções!$C$3:$C$203=B6)*(Funções!$D$3:$D$203="C")) -> 0 | G6: =SUMIF(Funções!$C$3:$C$203,B6,Funções!$P$3:$P$203) -> 0 | H6: =SUMIF(Funções!$C$3:$C$203,B6,Funções!$Q$3:$Q$203) -> 0 | I6: Exclusão | J6: =SUMIF(Funções!D3:D203,"=E",Funções!P3:P203) -> 0
B7: CE | C7: =SUMPRODUCT((Funções!$C$3:$C$203=B7)*(Funções!$D$3:$D$203="I")) -> 0 | D7: =SUMPRODUCT((Funções!$C$3:$C$203=B7)*(Funções!$D$3:$D$203="A")) -> 0 | E7: =SUMPRODUCT((Funções!$C$3:$C$203=B7)*(Funções!$D$3:$D$203="E")) -> 0 | F7: =SUMPRODUCT((Funções!$C$3:$C$203=B7)*(Funções!$D$3:$D$203="C")) -> 0 | G7: =SUMIF(Funções!$C$3:$C$203,B7,Funções!$P$3:$P$203) -> 0 | H7: =SUMIF(Funções!$C$3:$C$203,B7,Funções!$Q$3:$Q$203) -> 0 | I7: Conversão | J7: =SUMIF(Funções!D3:D203,"=C",Funções!P3:P203) -> 0
B8: SE | C8: =SUMPRODUCT((Funções!$C$3:$C$203=B8)*(Funções!$D$3:$D$203="I")) -> 0 | D8: =SUMPRODUCT((Funções!$C$3:$C$203=B8)*(Funções!$D$3:$D$203="A")) -> 0 | E8: =SUMPRODUCT((Funções!$C$3:$C$203=B8)*(Funções!$D$3:$D$203="E")) -> 0 | F8: =SUMPRODUCT((Funções!$C$3:$C$203=B8)*(Funções!$D$3:$D$203="C")) -> 0 | G8: =SUMIF(Funções!$C$3:$C$203,B8,Funções!$P$3:$P$203) -> 0 | H8: =SUMIF(Funções!$C$3:$C$203,B8,Funções!$Q$3:$Q$203) -> 0
B9: INM | G9: =SUMIF(Funções!$C$3:$C$203,B9,Funções!$P$3:$P$203) -> 0 | H9: =SUMIF(Funções!$C$3:$C$203,B9,Funções!$Q$3:$Q$203) -> 0
B10: Total | C10: =SUM(C4:C8) -> 0 | D10: =SUM(D4:D8) -> 0 | E10: =SUM(E4:E8) -> 0 | F10: =SUM(F4:F8) -> 0 | G10: =SUM(G4:G9) -> 0 | H10: =SUM(H4:H9) -> 0
B12: Quadro Resumo Fábrica de Métricas
C13: Inclusão | D13: Alteração | E13: Exclusão | F13: Conversão | G13: Total PFB | H13: Total PFL
B14: ALI | C14: =SUMPRODUCT((Funções!$U$3:$U$203=B14)*(Funções!$V$3:$V$203="I")*(Funções!$AF$3:$AF$203>0)) -> 0 | D14: =SUMPRODUCT((Funções!$U$3:$U$203=B14)*(Funções!$V$3:$V$203="A")*(Funções!$AF$3:$AF$203>0)) -> 0 | E14: =SUMPRODUCT((Funções!$U$3:$U$203=B14)*(Funções!$V$3:$V$203="E")*(Funções!$AF$3:$AF$203>0)) -> 0 | F14: =SUMPRODUCT((Funções!$U$3:$U$203=B14)*(Funções!$V$3:$V$203="C")*(Funções!$AF$3:$AF$203>0)) -> 0 | G14: =SUMIF(Funções!$U$3:$U$203,B14,Funções!$AF$3:$AF$203) -> 0 | H14: =SUMIF(Funções!$U$3:$U$203,B14,Funções!$AG$3:$AG$203) -> 0 | I14: Inclusão | J14: =SUMIF(Funções!D14:D214,"=I",Funções!P14:P214) -> 0
B15: AIE | C15: =SUMPRODUCT((Funções!$U$3:$U$203=B15)*(Funções!$V$3:$V$203="I")*(Funções!$AF$3:$AF$203>0)) -> 0 | D15: =SUMPRODUCT((Funções!$U$3:$U$203=B15)*(Funções!$V$3:$V$203="A")*(Funções!$AF$3:$AF$203>0)) -> 0 | E15: =SUMPRODUCT((Funções!$U$3:$U$203=B15)*(Funções!$V$3:$V$203="E")*(Funções!$AF$3:$AF$203>0)) -> 0 | F15: =SUMPRODUCT((Funções!$U$3:$U$203=B15)*(Funções!$V$3:$V$203="C")*(Funções!$AF$3:$AF$203>0)) -> 0 | G15: =SUMIF(Funções!$U$3:$U$203,B15,Funções!$AF$3:$AF$203) -> 0 | H15: =SUMIF(Funções!$U$3:$U$203,B15,Funções!$AG$3:$AG$203) -> 0 | I15: Alteração | J15: =SUMIF(Funções!D14:D214,"=A",Funções!P14:P214) -> 0
B16: EE | C16: =SUMPRODUCT((Funções!$U$3:$U$203=B16)*(Funções!$V$3:$V$203="I")*(Funções!$AF$3:$AF$203>0)) -> 0 | D16: =SUMPRODUCT((Funções!$U$3:$U$203=B16)*(Funções!$V$3:$V$203="A")*(Funções!$AF$3:$AF$203>0)) -> 0 | E16: =SUMPRODUCT((Funções!$U$3:$U$203=B16)*(Funções!$V$3:$V$203="E")*(Funções!$AF$3:$AF$203>0)) -> 0 | F16: =SUMPRODUCT((Funções!$U$3:$U$203=B16)*(Funções!$V$3:$V$203="C")*(Funções!$AF$3:$AF$203>0)) -> 0 | G16: =SUMIF(Funções!$U$3:$U$203,B16,Funções!$AF$3:$AF$203) -> 0 | H16: =SUMIF(Funções!$U$3:$U$203,B16,Funções!$AG$3:$AG$203) -> 0 | I16: Exclusão | J16: =SUMIF(Funções!D14:D214,"=E",Funções!P14:P214) -> 0
B17: CE | C17: =SUMPRODUCT((Funções!$U$3:$U$203=B17)*(Funções!$V$3:$V$203="I")*(Funções!$AF$3:$AF$203>0)) -> 0 | D17: =SUMPRODUCT((Funções!$U$3:$U$203=B17)*(Funções!$V$3:$V$203="A")*(Funções!$AF$3:$AF$203>0)) -> 0 | E17: =SUMPRODUCT((Funções!$U$3:$U$203=B17)*(Funções!$V$3:$V$203="E")*(Funções!$AF$3:$AF$203>0)) -> 0 | F17: =SUMPRODUCT((Funções!$U$3:$U$203=B17)*(Funções!$V$3:$V$203="C")*(Funções!$AF$3:$AF$203>0)) -> 0 | G17: =SUMIF(Funções!$U$3:$U$203,B17,Funções!$AF$3:$AF$203) -> 0 | H17: =SUMIF(Funções!$U$3:$U$203,B17,Funções!$AG$3:$AG$203) -> 0 | I17: Conversão | J17: =SUMIF(Funções!D14:D214,"=C",Funções!P14:P214) -> 0
B18: SE | C18: =SUMPRODUCT((Funções!$U$3:$U$203=B18)*(Funções!$V$3:$V$203="I")*(Funções!$AF$3:$AF$203>0)) -> 0 | D18: =SUMPRODUCT((Funções!$U$3:$U$203=B18)*(Funções!$V$3:$V$203="A")*(Funções!$AF$3:$AF$203>0)) -> 0 | E18: =SUMPRODUCT((Funções!$U$3:$U$203=B18)*(Funções!$V$3:$V$203="E")*(Funções!$AF$3:$AF$203>0)) -> 0 | F18: =SUMPRODUCT((Funções!$U$3:$U$203=B18)*(Funções!$V$3:$V$203="C")*(Funções!$AF$3:$AF$203>0)) -> 0 | G18: =SUMIF(Funções!$U$3:$U$203,B18,Funções!$AF$3:$AF$203) -> 0 | H18: =SUMIF(Funções!$U$3:$U$203,B18,Funções!$AG$3:$AG$203) -> 0
B19: INM | G19: =SUMIF(Funções!$U$3:$U$203,B19,Funções!$AF$3:$AF$203) -> 0 | H19: =SUMIF(Funções!$U$3:$U$203,B19,Funções!$AG$3:$AG$203) -> 0
B20: Total | C20: =SUM(C14:C19) -> 0 | D20: =SUM(D14:D19) -> 0 | E20: =SUM(E14:E19) -> 0 | F20: =SUM(F14:F19) -> 0 | G20: =SUM(G14:G19) -> 0 | H20: =SUM(H14:H19) -> 0

Sheet Lista
A1: Lista de Itens Não Mensuráveis
A2: Código | B2: Descrição | C2: Valor | D2: Referência | E2: Tipo
A3: I | B3: Projeto de Melhoria - Funcionalidades Incluídas – serão remuneradas em 100% do valor do ponto de função, vezes a quantidade de PF da(s) fase(s) contratada(s); | C3: 1 | D3: Roteiro de Métricas de Software do SISP - Item 4.2 | E3: PC
A4: NA | B4: Item não mensurável. Indica que o contador viu a funcionalidade, mas ela não deve ser contada. | C4: 0 | D4: Item não mensurável | E4: PC
A5: A1 | B5: Projeto de Melhoria - Funcionalidades Alteradas - Funcionalidade de sistema desenvolvida ou mantida por meio de um projeto de melhoria pela empresa contratada. | C5: 0.5 | D5: Roteiro de Métricas de Software do SISP - Item 4.2 | E5: PC
A6: A2 | B6: Projeto de Melhoria - Funcionalidades Alteradas - Funcionalidade de sistema não desenvolvida ou mantida por meio de um projeto de melhoria pela empresa contratada e sem necessidade de redocumentação da funcionalidade. | C6: 0.75 | D6: Roteiro de Métricas de Software do SISP - Item 4.2 | E6: PC
A7: A3 | B7: Projeto de Melhoria - Funcionalidades Alteradas - Funcionalidade de sistema não desenvolvida ou mantida por meio de um projeto de melhoria pela empresa contratada e com necessidade de redocumentação da funcionalidade. | C7: 0.9 | D7: Roteiro de Métricas de Software do SISP - Item 4.2 | E7: PC
A8: E | B8: Projeto de Melhoria - Funcionalidades Excluídas - serão remuneradas em 30% do valor do ponto de função vezes a quantidade de PF da(s) fase(s). | C8: 0.3 | D8: Roteiro de Métricas de Software do SISP - Item 4.2 | E8: PC
A9: MC1 | B9: Manutenção corretiva quando estiver fora da garantia e a correção for feita pela mesma empresa que desenvolveu a funcionalidade. | C9: 0.5 | D9: Roteiro de Métricas de Software do SISP - Item 4.4 | E9: PC
A10: MC2 | B10: Manutenção corretiva quando estiver fora da garantia e a correção for feita por empresa diferente daquela que desenvolveu a funcionalidade. | C10: 0.75 | D10: Roteiro de Métricas de Software do SISP - Item 4.4 | E10: PC
A11: MP1 | B11: Nesta categoria encontram-se as demandas de redesenvolvimento de sistemas em outra linguagem de programação. | C11: 1 | D11: Roteiro de Métricas de Software do SISP - Item 4.5.1 | E11: PC
A12: MP2 | B12: Nesta categoria encontram-se as demandas de redesenvolvimento de sistemas para utilizar um outro sistema gerenciador de banco de dados, caso a demanda de redesenvolvimento seja de um sistema gerenciador de banco de dados relacional para outro relacional. | C12: 0.3 | D12: Roteiro de Métricas de Software do SISP - Item 4.5.2 | E12: PC
A13: AV1 | B13: Nesta categoria encontram-se as demandas de atualização de versão de linguagem de programação de sistemas. | C13: 0.3 | D13: Roteiro de Métricas de Software do SISP - Item 4.6.1 | E13: PC
A14: AV2 | B14: Nesta categoria encontram-se as demandas de atualização de aplicações Web para executar em novas versões de um mesmo browser e para suportar a execução em mais de um browser. É importante destacar que este tipo de procedimento usualmente é realizado quando é necessário resolver algum problema de incompatibilidade. | C14: 0.3 | D14: Roteiro de Métricas de Software do SISP - Item 4.6.2 | E14: PC
... A33: RT2 | B33: Retrabalho causado por alteração de interface | C33: 0.6 | D33: Roteiro de Métricas de Software do SISP - Item 6.1.2 | E33: PF

Sheet Estórias 
B2: Número Estória | C2: Quantidade PF
C3: =SUMIF(Funções!$A$3:$A$202,B3,Funções!$AG$3:$AG$202) -> 0
C4: =SUMIF(Funções!$A$3:$A$202,B4,Funções!$AG$3:$AG$202) -> 0
C5: =SUMIF(Funções!$A$3:$A$202,B5,Funções!$AG$3:$AG$202) -> 0
C6: =SUMIF(Funções!$A$3:$A$202,B6,Funções!$AG$3:$AG$202) -> 0
C7: =SUMIF(Funções!$A$3:$A$202,B7,Funções!$AG$3:$AG$202) -> 0
C8: =SUMIF(Funções!$A$3:$A$202,B8,Funções!$AG$3:$AG$202) -> 0
C9: =SUMIF(Funções!$A$3:$A$202,B9,Funções!$AG$3:$AG$202) -> 0
C10: =SUMIF(Funções!$A$3:$A$202,B10,Funções!$AG$3:$AG$202) -> 0
C11: =SUMIF(Funções!$A$3:$A$202,B11,Funções!$AG$3:$AG$202) -> 0
C12: =SUMIF(Funções!$A$3:$A$202,B12,Funções!$AG$3:$AG$202) -> 0
C13: =SUMIF(Funções!$A$3:$A$202,B13,Funções!$AG$3:$AG$202) -> 0
C14: =SUMIF(Funções!$A$3:$A$202,B14,Funções!$AG$3:$AG$202) -> 0
... C99: =SUMIF(Funções!$A$3:$A$202,B99,Funções!$AG$3:$AG$202) -> 0

Sheet Regras
A4: 4.1 | B4: Projeto de Desenvolvimento | C4: 1 | D4: SISP

Sheet PF por Funcionalidade
A1: Nº | B1: Funcionalidade | C1: PF Ajust.
