Workbook
Name CF: Funções!$K$8:$K$113
Name Data: Contagem!$Z$7
Name Projeto: Contagem!$F$6
Name Responsável: Contagem!$F$7
Name Revisão: Contagem!$Z$8
Name Revisor: Contagem!$F$8
Name UFPB: Contagem!$AA$12
Name VAF: #REF!
Name VAFA: #REF!
Name VAFB: #REF!

Sheet Contagem
A1: Identificação da Contagem - v5
A4: Empresa | F4: BASIS Tecnologia | R4: R$/PF | T4: 0 | W4: Custo | Y4: =Y5*T4 -> 0
A5: Sistema/Subsistema | W5: PF | Y5: =SUM(AA11:AA14) -> 0
A6: Projeto
A7: Responsável | W7: Criação
A8: Revisor | W8: Revisão
A10: Tipo de contagem | C10: Estimativa | O10: Sumário | Q10: PF não Ajustado | W10: Fat.Impacto | AA10: PF Local
C11: Projeto de Desenvolvimento | Q11: ADD | S11: =Sumário!E55 -> 0 | W11: 1 | AA11: =S11*W11 -> 0
C12: Projeto de Melhoria | Q12: CHG | S12: =Sumário!E56 -> 0 | W12: 0.3 | AA12: =S12*W12 -> 0
C13: Aplicação ( Baseline ) | Q13: DEL | S13: =Sumário!E57 -> 0 | W13: 0.3 | AA13: =S13*W13 -> 0
C14: Documentação de Legados | Q14: TST | S14: =Sumário!E58 -> 0 | W14: 0.15 | AA14: =S14*W14 -> 0
K16: Propósito da Contagem
K40: Escopo da Contagem

Sheet Funções
A1: Planilha de contagem de ponto de função - v5
A4: =Contagem!A5&" : "&Contagem!F5 -> Sistema/Subsistema : | G4: =Contagem!A6&" : "&Contagem!F6 -> Projeto :
A5: =Contagem!A7&" : "&Contagem!F7 -> Responsável : | G5: =Contagem!A8&" : "&Contagem!F8 -> Revisor :
A6: =Contagem!A4&" : "&Contagem!F4 -> Empresa : BASIS Tecnologia | F6: =Contagem!R4&" = "&VALUE(Contagem!T4) -> R$/PF = 0 | H6: =" Custo= "&DOLLAR(Contagem!Y4) -> Custo= R$ 0,00 | N6: ="PFB = "&VALUE(Contagem!Y5) -> PFB = 0
A7: Processo Elementar ou Grupo de Dados | G7: Tipo | H7: (I/A/E/T/D) | I7: TD | J7: AR/TR | K7: ctl | L7: C | M7: Complex. | N7: PF | O7: PF Local | P7: Observações
P14: GSOL01930358
P39: GSOL01921420
P80: GSOL01926817
P81: GSOL01926817
P94: GSOL01927926
P111: GSOL01934134
P143: GSOL01040124
P148: GSOL01932059
K290: =CONCATENATE(G290,L290) | L290: =IF(OR(ISBLANK(I290),ISBLANK(J290)),IF(OR(G290="ALI",G290="AIE"),"L",IF(ISBLANK(G290),"","A")),IF(G290="EE",IF(J290>=3,IF(I290>=5,"H","A"),IF(J290>=2,IF(I290>=16,"H",IF(I290<=4,"L","A")),IF(I290<=15,"L","A"))),IF(OR(G290="SE",G290="CE"),IF(J290>=4,IF(I290>=6,"H","A"),IF(J290>=2,IF(I290>=20,"H",IF(I290<=5,"L","A")),IF(I290<=19,"L","A"))),IF(OR(G290="ALI",G290="AIE"),IF(J290>=6,IF(I290>=20,"H","A"),IF(J290>=2,IF(I290>=51,"H",IF(I290<=19,"L","A")),IF(I290<=50,"L","A"))))))) | M290: =IF(L290="L","Baixa",IF(L290="A","Média",IF(L290="","","Alta"))) | O290: =IF(H290="I",N290*Contagem!$W$11,IF(H290="E",N290*Contagem!$W$13,IF(H290="A",N290*Contagem!$W$12,IF(H290="T",N290*Contagem!$W$14,""))))
K291: =CONCATENATE(G291,L291) | L291: =IF(OR(ISBLANK(I291),ISBLANK(J291)),IF(OR(G291="ALI",G291="AIE"),"L",IF(ISBLANK(G291),"","A")),IF(G291="EE",IF(J291>=3,IF(I291>=5,"H","A"),IF(J291>=2,IF(I291>=16,"H",IF(I291<=4,"L","A")),IF(I291<=15,"L","A"))),IF(OR(G291="SE",G291="CE"),IF(J291>=4,IF(I291>=6,"H","A"),IF(J291>=2,IF(I291>=20,"H",IF(I291<=5,"L","A")),IF(I291<=19,"L","A"))),IF(OR(G291="ALI",G291="AIE"),IF(J291>=6,IF(I291>=20,"H","A"),IF(J291>=2,IF(I291>=51,"H",IF(I291<=19,"L","A")),IF(I291<=50,"L","A"))))))) | M291: =IF(L291="L","Baixa",IF(L291="A","Média",IF(L291="","","Alta"))) | O291: =IF(H291="I",N291*Contagem!$W$11,IF(H291="E",N291*Contagem!$W$13,IF(H291="A",N291*Contagem!$W$12,IF(H291="T",N291*Contagem!$W$14,""))))
K293: =CONCATENATE(G293,L293) | L293: =IF(OR(ISBLANK(I293),ISBLANK(J293)),IF(OR(G293="ALI",G293="AIE"),"L",IF(ISBLANK(G293),"","A")),IF(G293="EE",IF(J293>=3,IF(I293>=5,"H","A"),IF(J293>=2,IF(I293>=16,"H",IF(I293<=4,"L","A")),IF(I293<=15,"L","A"))),IF(OR(G293="SE",G293="CE"),IF(J293>=4,IF(I293>=6,"H","A"),IF(J293>=2,IF(I293>=20,"H",IF(I293<=5,"L","A")),IF(I293<=19,"L","A"))),IF(OR(G293="ALI",G293="AIE"),IF(J293>=6,IF(I293>=20,"H","A"),IF(J293>=2,IF(I293>=51,"H",IF(I293<=19,"L","A")),IF(I293<=50,"L","A"))))))) | M293: =IF(L293="L","Baixa",IF(L293="A","Média",IF(L293="","","Alta"))) | O293: =IF(H293="I",N293*Contagem!$W$11,IF(H293="E",N293*Contagem!$W$13,IF(H293="A",N293*Contagem!$W$12,IF(H293="T",N293*Contagem!$W$14,""))))
K294: =CONCATENATE(G294,L294) | L294: =IF(OR(ISBLANK(I294),ISBLANK(J294)),IF(OR(G294="ALI",G294="AIE"),"L",IF(ISBLANK(G294),"","A")),IF(G294="EE",IF(J294>=3,IF(I294>=5,"H","A"),IF(J294>=2,IF(I294>=16,"H",IF(I294<=4,"L","A")),IF(I294<=15,"L","A"))),IF(OR(G294="SE",G294="CE"),IF(J294>=4,IF(I294>=6,"H","A"),IF(J294>=2,IF(I294>=20,"H",IF(I294<=5,"L","A")),IF(I294<=19,"L","A"))),IF(OR(G294="ALI",G294="AIE"),IF(J294>=6,IF(I294>=20,"H","A"),IF(J294>=2,IF(I294>=51,"H",IF(I294<=19,"L","A")),IF(I294<=50,"L","A"))))))) | M294: =IF(L294="L","Baixa",IF(L294="A","Média",IF(L294="","","Alta"))) | O294: =IF(H294="I",N294*Contagem!$W$11,IF(H294="E",N294*Contagem!$W$13,IF(H294="A",N294*Contagem!$W$12,IF(H294="T",N294*Contagem!$W$14,""))))
K295: =CONCATENATE(G295,L295) | L295: =IF(OR(ISBLANK(I295),ISBLANK(J295)),IF(OR(G295="ALI",G295="AIE"),"L",IF(ISBLANK(G295),"","A")),IF(G295="EE",IF(J295>=3,IF(I295>=5,"H","A"),IF(J295>=2,IF(I295>=16,"H",IF(I295<=4,"L","A")),IF(I295<=15,"L","A"))),IF(OR(G295="SE",G295="CE"),IF(J295>=4,IF(I295>=6,"H","A"),IF(J295>=2,IF(I295>=20,"H",IF(I295<=5,"L","A")),IF(I295<=19,"L","A"))),IF(OR(G295="ALI",G295="AIE"),IF(J295>=6,IF(I295>=20,"H","A"),IF(J295>=2,IF(I295>=51,"H",IF(I295<=19,"L","A")),IF(I295<=50,"L","A"))))))) | M295: =IF(L295="L","Baixa",IF(L295="A","Média",IF(L295="","","Alta"))) | O295: =IF(H295="I",N295*Contagem!$W$11,IF(H295="E",N295*Contagem!$W$13,IF(H295="A",N295*Contagem!$W$12,IF(H295="T",N295*Contagem!$W$14,""))))
K296: =CONCATENATE(G296,L296) | L296: =IF(OR(ISBLANK(I296),ISBLANK(J296)),IF(OR(G296="ALI",G296="AIE"),"L",IF(ISBLANK(G296),"","A")),IF(G296="EE",IF(J296>=3,IF(I296>=5,"H","A"),IF(J296>=2,IF(I296>=16,"H",IF(I296<=4,"L","A")),IF(I296<=15,"L","A"))),IF(OR(G296="SE",G296="CE"),IF(J296>=4,IF(I296>=6,"H","A"),IF(J296>=2,IF(I296>=20,"H",IF(I296<=5,"L","A")),IF(I296<=19,"L","A"))),IF(OR(G296="ALI",G296="AIE"),IF(J296>=6,IF(I296>=20,"H","A"),IF(J296>=2,IF(I296>=51,"H",IF(I296<=19,"L","A")),IF(I296<=50,"L","A"))))))) | M296: =IF(L296="L","Baixa",IF(L296="A","Média",IF(L296="","","Alta"))) | O296: =IF(H296="I",N296*Contagem!$W$11,IF(H296="E",N296*Contagem!$W$13,IF(H296="A",N296*Contagem!$W$12,IF(H296="T",N296*Contagem!$W$14,""))))
K297: =CONCATENATE(G297,L297) | L297: =IF(OR(ISBLANK(I297),ISBLANK(J297)),IF(OR(G297="ALI",G297="AIE"),"L",IF(ISBLANK(G297),"","A")),IF(G297="EE",IF(J297>=3,IF(I297>=5,"H","A"),IF(J297>=2,IF(I297>=16,"H",IF(I297<=4,"L","A")),IF(I297<=15,"L","A"))),IF(OR(G297="SE",G297="CE"),IF(J297>=4,IF(I297>=6,"H","A"),IF(J297>=2,IF(I297>=20,"H",IF(I297<=5,"L","A")),IF(I297<=19,"L","A"))),IF(OR(G297="ALI",G297="AIE"),IF(J297>=6,IF(I297>=20,"H","A"),IF(J297>=2,IF(I297>=51,"H",IF(I297<=19,"L","A")),IF(I297<=50,"L","A"))))))) | M297: =IF(L297="L","Baixa",IF(L297="A","Média",IF(L297="","","Alta"))) | O297: =IF(H297="I",N297*Contagem!$W$11,IF(H297="E",N297*Contagem!$W$13,IF(H297="A",N297*Contagem!$W$12,IF(H297="T",N297*Contagem!$W$14,""))))
K298: =CONCATENATE(G298,L298) | L298: =IF(OR(ISBLANK(I298),ISBLANK(J298)),IF(OR(G298="ALI",G298="AIE"),"L",IF(ISBLANK(G298),"","A")),IF(G298="EE",IF(J298>=3,IF(I298>=5,"H","A"),IF(J298>=2,IF(I298>=16,"H",IF(I298<=4,"L","A")),IF(I298<=15,"L","A"))),IF(OR(G298="SE",G298="CE"),IF(J298>=4,IF(I298>=6,"H","A"),IF(J298>=2,IF(I298>=20,"H",IF(I298<=5,"L","A")),IF(I298<=19,"L","A"))),IF(OR(G298="ALI",G298="AIE"),IF(J298>=6,IF(I298>=20,"H","A"),IF(J298>=2,IF(I298>=51,"H",IF(I298<=19,"L","A")),IF(I298<=50,"L","A"))))))) | M298: =IF(L298="L","Baixa",IF(L298="A","Média",IF(L298="","","Alta"))) | O298: =IF(H298="I",N298*Contagem!$W$11,IF(H298="E",N298*Contagem!$W$13,IF(H298="A",N298*Contagem!$W$12,IF(H298="T",N298*Contagem!$W$14,""))))
K299: =CONCATENATE(G299,L299) | L299: =IF(OR(ISBLANK(I299),ISBLANK(J299)),IF(OR(G299="ALI",G299="AIE"),"L",IF(ISBLANK(G299),"","A")),IF(G299="EE",IF(J299>=3,IF(I299>=5,"H","A"),IF(J299>=2,IF(I299>=16,"H",IF(I299<=4,"L","A")),IF(I299<=15,"L","A"))),IF(OR(G299="SE",G299="CE"),IF(J299>=4,IF(I299>=6,"H","A"),IF(J299>=2,IF(I299>=20,"H",IF(I299<=5,"L","A")),IF(I299<=19,"L","A"))),IF(OR(G299="ALI",G299="AIE"),IF(J299>=6,IF(I299>=20,"H","A"),IF(J299>=2,IF(I299>=51,"H",IF(I299<=19,"L","A")),IF(I299<=50,"L","A"))))))) | M299: =IF(L299="L","Baixa",IF(L299="A","Média",IF(L299="","","Alta"))) | O299: =IF(H299="I",N299*Contagem!$W$11,IF(H299="E",N299*Contagem!$W$13,IF(H299="A",N299*Contagem!$W$12,IF(H299="T",N299*Contagem!$W$14,""))))
K300: =CONCATENATE(G300,L300) | L300: =IF(OR(ISBLANK(I300),ISBLANK(J300)),IF(OR(G300="ALI",G300="AIE"),"L",IF(ISBLANK(G300),"","A")),IF(G300="EE",IF(J300>=3,IF(I300>=5,"H","A"),IF(J300>=2,IF(I300>=16,"H",IF(I300<=4,"L","A")),IF(I300<=15,"L","A"))),IF(OR(G300="SE",G300="CE"),IF(J300>=4,IF(I300>=6,"H","A"),IF(J300>=2,IF(I300>=20,"H",IF(I300<=5,"L","A")),IF(I300<=19,"L","A"))),IF(OR(G300="ALI",G300="AIE"),IF(J300>=6,IF(I300>=20,"H","A"),IF(J300>=2,IF(I300>=51,"H",IF(I300<=19,"L","A")),IF(I300<=50,"L","A"))))))) | M300: =IF(L300="L","Baixa",IF(L300="A","Média",IF(L300="","","Alta"))) | O300: =IF(H300="I",N300*Contagem!$W$11,IF(H300="E",N300*Contagem!$W$13,IF(H300="A",N300*Contagem!$W$12,IF(H300="T",N300*Contagem!$W$14,""))))
K301: =CONCATENATE(G301,L301) | L301: =IF(OR(ISBLANK(I301),ISBLANK(J301)),IF(OR(G301="ALI",G301="AIE"),"L",IF(ISBLANK(G301),"","A")),IF(G301="EE",IF(J301>=3,IF(I301>=5,"H","A"),IF(J301>=2,IF(I301>=16,"H",IF(I301<=4,"L","A")),IF(I301<=15,"L","A"))),IF(OR(G301="SE",G301="CE"),IF(J301>=4,IF(I301>=6,"H","A"),IF(J301>=2,IF(I301>=20,"H",IF(I301<=5,"L","A")),IF(I301<=19,"L","A"))),IF(OR(G301="ALI",G301="AIE"),IF(J301>=6,IF(I301>=20,"H","A"),IF(J301>=2,IF(I301>=51,"H",IF(I301<=19,"L","A")),IF(I301<=50,"L","A"))))))) | M301: =IF(L301="L","Baixa",IF(L301="A","Média",IF(L301="","","Alta"))) | O301: =IF(H301="I",N301*Contagem!$W$11,IF(H301="E",N301*Contagem!$W$13,IF(H301="A",N301*Contagem!$W$12,IF(H301="T",N301*Contagem!$W$14,""))))
K302: =CONCATENATE(G302,L302) | L302: =IF(OR(ISBLANK(I302),ISBLANK(J302)),IF(OR(G302="ALI",G302="AIE"),"L",IF(ISBLANK(G302),"","A")),IF(G302="EE",IF(J302>=3,IF(I302>=5,"H","A"),IF(J302>=2,IF(I302>=16,"H",IF(I302<=4,"L","A")),IF(I302<=15,"L","A"))),IF(OR(G302="SE",G302="CE"),IF(J302>=4,IF(I302>=6,"H","A"),IF(J302>=2,IF(I302>=20,"H",IF(I302<=5,"L","A")),IF(I302<=19,"L","A"))),IF(OR(G302="ALI",G302="AIE"),IF(J302>=6,IF(I302>=20,"H","A"),IF(J302>=2,IF(I302>=51,"H",IF(I302<=19,"L","A")),IF(I302<=50,"L","A"))))))) | M302: =IF(L302="L","Baixa",IF(L302="A","Média",IF(L302="","","Alta"))) | O302: =IF(H302="I",N302*Contagem!$W$11,IF(H302="E",N302*Contagem!$W$13,IF(H302="A",N302*Contagem!$W$12,IF(H302="T",N302*Contagem!$W$14,""))))
... K435: =CONCATENATE(G435,L435) | L435: =IF(OR(ISBLANK(I435),ISBLANK(J435)),IF(OR(G435="ALI",G435="AIE"),"L",IF(ISBLANK(G435),"","A")),IF(G435="EE",IF(J435>=3,IF(I435>=5,"H","A"),IF(J435>=2,IF(I435>=16,"H",IF(I435<=4,"L","A")),IF(I435<=15,"L","A"))),IF(OR(G435="SE",G435="CE"),IF(J435>=4,IF(I435>=6,"H","A"),IF(J435>=2,IF(I435>=20,"H",IF(I435<=5,"L","A")),IF(I435<=19,"L","A"))),IF(OR(G435="ALI",G435="AIE"),IF(J435>=6,IF(I435>=20,"H","A"),IF(J435>=2,IF(I435>=51,"H",IF(I435<=19,"L","A")),IF(I435<=50,"L","A"))))))) | M435: =IF(L435="L","Baixa",IF(L435="A","Média",IF(L435="","","Alta"))) | O435: =IF(H435="I",N435*Contagem!$W$11,IF(H435="E",N435*Contagem!$W$13,IF(H435="A",N435*Contagem!$W$12,IF(H435="T",N435*Contagem!$W$14,""))))
K436: CE | L436: =IF(OR(ISBLANK(I436),ISBLANK(J436)),IF(OR(G436="ALI",G436="AIE"),"L",IF(ISBLANK(G436),"","A")),IF(G436="EE",IF(J436>=3,IF(I436>=5,"H","A"),IF(J436>=2,IF(I436>=16,"H",IF(I436<=4,"L","A")),IF(I436<=15,"L","A"))),IF(OR(G436="SE",G436="CE"),IF(J436>=4,IF(I436>=6,"H","A"),IF(J436>=2,IF(I436>=20,"H",IF(I436<=5,"L","A")),IF(I436<=19,"L","A"))),IF(OR(G436="ALI",G436="AIE"),IF(J436>=6,IF(I436>=20,"H","A"),IF(J436>=2,IF(I436>=51,"H",IF(I436<=19,"L","A")),IF(I436<=50,"L","A"))))))) | M436: =IF(L436="L","Baixa",IF(L436="A","Média",IF(L436="","","Alta"))) | O436: =IF(H436="I",N436*Contagem!$W$11,IF(H436="E",N436*Contagem!$W$13,IF(H436="A",N436*Contagem!$W$12,IF(H436="T",N436*Contagem!$W$14,""))))
K437: =CONCATENATE(G437,L437) | L437: =IF(OR(ISBLANK(I437),ISBLANK(J437)),IF(OR(G437="ALI",G437="AIE"),"L",IF(ISBLANK(G437),"","A")),IF(G437="EE",IF(J437>=3,IF(I437>=5,"H","A"),IF(J437>=2,IF(I437>=16,"H",IF(I437<=4,"L","A")),IF(I437<=15,"L","A"))),IF(OR(G437="SE",G437="CE"),IF(J437>=4,IF(I437>=6,"H","A"),IF(J437>=2,IF(I437>=20,"H",IF(I437<=5,"L","A")),IF(I437<=19,"L","A"))),IF(OR(G437="ALI",G437="AIE"),IF(J437>=6,IF(I437>=20,"H","A"),IF(J437>=2,IF(I437>=51,"H",IF(I437<=19,"L","A")),IF(I437<=50,"L","A"))))))) | M437: =IF(L437="L","Baixa",IF(L437="A","Média",IF(L437="","","Alta"))) | O437: =IF(H437="I",N437*Contagem!$W$11,IF(H437="E",N437*Contagem!$W$13,IF(H437="A",N437*Contagem!$W$12,IF(H437="T",N437*Contagem!$W$14,""))))
K438: =CONCATENATE(G438,L438) | L438: =IF(OR(ISBLANK(I438),ISBLANK(J438)),IF(OR(G438="ALI",G438="AIE"),"L",IF(ISBLANK(G438),"","A")),IF(G438="EE",IF(J438>=3,IF(I438>=5,"H","A"),IF(J438>=2,IF(I438>=16,"H",IF(I438<=4,"L","A")),IF(I438<=15,"L","A"))),IF(OR(G438="SE",G438="CE"),IF(J438>=4,IF(I438>=6,"H","A"),IF(J438>=2,IF(I438>=20,"H",IF(I438<=5,"L","A")),IF(I438<=19,"L","A"))),IF(OR(G438="ALI",G438="AIE"),IF(J438>=6,IF(I438>=20,"H","A"),IF(J438>=2,IF(I438>=51,"H",IF(I438<=19,"L","A")),IF(I438<=50,"L","A"))))))) | M438: =IF(L438="L","Baixa",IF(L438="A","Média",IF(L438="","","Alta"))) | O438: =IF(H438="I",N438*Contagem!$W$11,IF(H438="E",N438*Contagem!$W$13,IF(H438="A",N438*Contagem!$W$12,IF(H438="T",N438*Contagem!$W$14,""))))
K439: =CONCATENATE(G439,L439) | L439: =IF(OR(ISBLANK(I439),ISBLANK(J439)),IF(OR(G439="ALI",G439="AIE"),"L",IF(ISBLANK(G439),"","A")),IF(G439="EE",IF(J439>=3,IF(I439>=5,"H","A"),IF(J439>=2,IF(I439>=16,"H",IF(I439<=4,"L","A")),IF(I439<=15,"L","A"))),IF(OR(G439="SE",G439="CE"),IF(J439>=4,IF(I439>=6,"H","A"),IF(J439>=2,IF(I439>=20,"H",IF(I439<=5,"L","A")),IF(I439<=19,"L","A"))),IF(OR(G439="ALI",G439="AIE"),IF(J439>=6,IF(I439>=20,"H","A"),IF(J439>=2,IF(I439>=51,"H",IF(I439<=19,"L","A")),IF(I439<=50,"L","A"))))))) | M439: =IF(L439="L","Baixa",IF(L439="A","Média",IF(L439="","","Alta"))) | O439: =IF(H439="I",N439*Contagem!$W$11,IF(H439="E",N439*Contagem!$W$13,IF(H439="A",N439*Contagem!$W$12,IF(H439="T",N439*Contagem!$W$14,""))))
K440: =CONCATENATE(G440,L440) | L440: =IF(OR(ISBLANK(I440),ISBLANK(J440)),IF(OR(G440="ALI",G440="AIE"),"L",IF(ISBLANK(G440),"","A")),IF(G440="EE",IF(J440>=3,IF(I440>=5,"H","A"),IF(J440>=2,IF(I440>=16,"H",IF(I440<=4,"L","A")),IF(I440<=15,"L","A"))),IF(OR(G440="SE",G440="CE"),IF(J440>=4,IF(I440>=6,"H","A"),IF(J440>=2,IF(I440>=20,"H",IF(I440<=5,"L","A")),IF(I440<=19,"L","A"))),IF(OR(G440="ALI",G440="AIE"),IF(J440>=6,IF(I440>=20,"H","A"),IF(J440>=2,IF(I440>=51,"H",IF(I440<=19,"L","A")),IF(I440<=50,"L","A"))))))) | M440: =IF(L440="L","Baixa",IF(L440="A","Média",IF(L440="","","Alta"))) | O440: =IF(H440="I",N440*Contagem!$W$11,IF(H440="E",N440*Contagem!$W$13,IF(H440="A",N440*Contagem!$W$12,IF(H440="T",N440*Contagem!$W$14,""))))
K441: =CONCATENATE(G441,L441) | L441: =IF(OR(ISBLANK(I441),ISBLANK(J441)),IF(OR(G441="ALI",G441="AIE"),"L",IF(ISBLANK(G441),"","A")),IF(G441="EE",IF(J441>=3,IF(I441>=5,"H","A"),IF(J441>=2,IF(I441>=16,"H",IF(I441<=4,"L","A")),IF(I441<=15,"L","A"))),IF(OR(G441="SE",G441="CE"),IF(J441>=4,IF(I441>=6,"H","A"),IF(J441>=2,IF(I441>=20,"H",IF(I441<=5,"L","A")),IF(I441<=19,"L","A"))),IF(OR(G441="ALI",G441="AIE"),IF(J441>=6,IF(I441>=20,"H","A"),IF(J441>=2,IF(I441>=51,"H",IF(I441<=19,"L","A")),IF(I441<=50,"L","A"))))))) | M441: =IF(L441="L","Baixa",IF(L441="A","Média",IF(L441="","","Alta"))) | O441: =IF(H441="I",N441*Contagem!$W$11,IF(H441="E",N441*Contagem!$W$13,IF(H441="A",N441*Contagem!$W$12,IF(H441="T",N441*Contagem!$W$14,""))))
K442: =CONCATENATE(G442,L442) | L442: =IF(OR(ISBLANK(I442),ISBLANK(J442)),IF(OR(G442="ALI",G442="AIE"),"L",IF(ISBLANK(G442),"","A")),IF(G442="EE",IF(J442>=3,IF(I442>=5,"H","A"),IF(J442>=2,IF(I442>=16,"H",IF(I442<=4,"L","A")),IF(I442<=15,"L","A"))),IF(OR(G442="SE",G442="CE"),IF(J442>=4,IF(I442>=6,"H","A"),IF(J442>=2,IF(I442>=20,"H",IF(I442<=5,"L","A")),IF(I442<=19,"L","A"))),IF(OR(G442="ALI",G442="AIE"),IF(J442>=6,IF(I442>=20,"H","A"),IF(J442>=2,IF(I442>=51,"H",IF(I442<=19,"L","A")),IF(I442<=50,"L","A"))))))) | M442: =IF(L442="L","Baixa",IF(L442="A","Média",IF(L442="","","Alta"))) | O442: =IF(H442="I",N442*Contagem!$W$11,IF(H442="E",N442*Contagem!$W$13,IF(H442="A",N442*Contagem!$W$12,IF(H442="T",N442*Contagem!$W$14,""))))
K443: =CONCATENATE(G443,L443) | L443: =IF(OR(ISBLANK(I443),ISBLANK(J443)),IF(OR(G443="ALI",G443="AIE"),"L",IF(ISBLANK(G443),"","A")),IF(G443="EE",IF(J443>=3,IF(I443>=5,"H","A"),IF(J443>=2,IF(I443>=16,"H",IF(I443<=4,"L","A")),IF(I443<=15,"L","A"))),IF(OR(G443="SE",G443="CE"),IF(J443>=4,IF(I443>=6,"H","A"),IF(J443>=2,IF(I443>=20,"H",IF(I443<=5,"L","A")),IF(I443<=19,"L","A"))),IF(OR(G443="ALI",G443="AIE"),IF(J443>=6,IF(I443>=20,"H","A"),IF(J443>=2,IF(I443>=51,"H",IF(I443<=19,"L","A")),IF(I443<=50,"L","A"))))))) | M443: =IF(L443="L","Baixa",IF(L443="A","Média",IF(L443="","","Alta"))) | O443: =IF(H443="I",N443*Contagem!$W$11,IF(H443="E",N443*Contagem!$W$13,IF(H443="A",N443*Contagem!$W$12,IF(H443="T",N443*Contagem!$W$14,""))))
K444: =CONCATENATE(G444,L444) | L444: =IF(OR(ISBLANK(I444),ISBLANK(J444)),IF(OR(G444="ALI",G444="AIE"),"L",IF(ISBLANK(G444),"","A")),IF(G444="EE",IF(J444>=3,IF(I444>=5,"H","A"),IF(J444>=2,IF(I444>=16,"H",IF(I444<=4,"L","A")),IF(I444<=15,"L","A"))),IF(OR(G444="SE",G444="CE"),IF(J444>=4,IF(I444>=6,"H","A"),IF(J444>=2,IF(I444>=20,"H",IF(I444<=5,"L","A")),IF(I444<=19,"L","A"))),IF(OR(G444="ALI",G444="AIE"),IF(J444>=6,IF(I444>=20,"H","A"),IF(J444>=2,IF(I444>=51,"H",IF(I444<=19,"L","A")),IF(I444<=50,"L","A"))))))) | M444: =IF(L444="L","Baixa",IF(L444="A","Média",IF(L444="","","Alta"))) | O444: =IF(H444="I",N444*Contagem!$W$11,IF(H444="E",N444*Contagem!$W$13,IF(H444="A",N444*Contagem!$W$12,IF(H444="T",N444*Contagem!$W$14,""))))
K445: =CONCATENATE(G445,L445) | L445: =IF(OR(ISBLANK(I445),ISBLANK(J445)),IF(OR(G445="ALI",G445="AIE"),"L",IF(ISBLANK(G445),"","A")),IF(G445="EE",IF(J445>=3,IF(I445>=5,"H","A"),IF(J445>=2,IF(I445>=16,"H",IF(I445<=4,"L","A")),IF(I445<=15,"L","A"))),IF(OR(G445="SE",G445="CE"),IF(J445>=4,IF(I445>=6,"H","A"),IF(J445>=2,IF(I445>=20,"H",IF(I445<=5,"L","A")),IF(I445<=19,"L","A"))),IF(OR(G445="ALI",G445="AIE"),IF(J445>=6,IF(I445>=20,"H","A"),IF(J445>=2,IF(I445>=51,"H",IF(I445<=19,"L","A")),IF(I445<=50,"L","A"))))))) | M445: =IF(L445="L","Baixa",IF(L445="A","Média",IF(L445="","","Alta"))) | O445: =IF(H445="I",N445*Contagem!$W$11,IF(H445="E",N445*Contagem!$W$13,IF(H445="A",N445*Contagem!$W$12,IF(H445="T",N445*Contagem!$W$14,""))))
K446: =CONCATENATE(G446,L446) | L446: =IF(OR(ISBLANK(I446),ISBLANK(J446)),IF(OR(G446="ALI",G446="AIE"),"L",IF(ISBLANK(G446),"","A")),IF(G446="EE",IF(J446>=3,IF(I446>=5,"H","A"),IF(J446>=2,IF(I446>=16,"H",IF(I446<=4,"L","A")),IF(I446<=15,"L","A"))),IF(OR(G446="SE",G446="CE"),IF(J446>=4,IF(I446>=6,"H","A"),IF(J446>=2,IF(I446>=20,"H",IF(I446<=5,"L","A")),IF(I446<=19,"L","A"))),IF(OR(G446="ALI",G446="AIE"),IF(J446>=6,IF(I446>=20,"H","A"),IF(J446>=2,IF(I446>=51,"H",IF(I446<=19,"L","A")),IF(I446<=50,"L","A"))))))) | M446: =IF(L446="L","Baixa",IF(L446="A","Média",IF(L446="","","Alta"))) | O446: =IF(H446="I",N446*Contagem!$W$11,IF(H446="E",N446*Contagem!$W$13,IF(H446="A",N446*Contagem!$W$12,IF(H446="T",N446*Contagem!$W$14,""))))
K447: =CONCATENATE(G447,L447) | L447: =IF(OR(ISBLANK(I447),ISBLANK(J447)),IF(OR(G447="ALI",G447="AIE"),"L",IF(ISBLANK(G447),"","A")),IF(G447="EE",IF(J447>=3,IF(I447>=5,"H","A"),IF(J447>=2,IF(I447>=16,"H",IF(I447<=4,"L","A")),IF(I447<=15,"L","A"))),IF(OR(G447="SE",G447="CE"),IF(J447>=4,IF(I447>=6,"H","A"),IF(J447>=2,IF(I447>=20,"H",IF(I447<=5,"L","A")),IF(I447<=19,"L","A"))),IF(OR(G447="ALI",G447="AIE"),IF(J447>=6,IF(I447>=20,"H","A"),IF(J447>=2,IF(I447>=51,"H",IF(I447<=19,"L","A")),IF(I447<=50,"L","A"))))))) | M447: =IF(L447="L","Baixa",IF(L447="A","Média",IF(L447="","","Alta"))) | O447: =IF(H447="I",N447*Contagem!$W$11,IF(H447="E",N447*Contagem!$W$13,IF(H447="A",N447*Contagem!$W$12,IF(H447="T",N447*Contagem!$W$14,""))))
K448: =CONCATENATE(G448,L448) | L448: =IF(OR(ISBLANK(I448),ISBLANK(J448)),IF(OR(G448="ALI",G448="AIE"),"L",IF(ISBLANK(G448),"","A")),IF(G448="EE",IF(J448>=3,IF(I448>=5,"H","A"),IF(J448>=2,IF(I448>=16,"H",IF(I448<=4,"L","A")),IF(I448<=15,"L","A"))),IF(OR(G448="SE",G448="CE"),IF(J448>=4,IF(I448>=6,"H","A"),IF(J448>=2,IF(I448>=20,"H",IF(I448<=5,"L","A")),IF(I448<=19,"L","A"))),IF(OR(G448="ALI",G448="AIE"),IF(J448>=6,IF(I448>=20,"H","A"),IF(J448>=2,IF(I448>=51,"H",IF(I448<=19,"L","A")),IF(I448<=50,"L","A"))))))) | M448: =IF(L448="L","Baixa",IF(L448="A","Média",IF(L448="","","Alta"))) | O448: =IF(H448="I",N448*Contagem!$W$11,IF(H448="E",N448*Contagem!$W$13,IF(H448="A",N448*Contagem!$W$12,IF(H448="T",N448*Contagem!$W$14,""))))
... K500: =CONCATENATE(G500,L500) | L500: =IF(OR(ISBLANK(I500),ISBLANK(J500)),IF(OR(G500="ALI",G500="AIE"),"L",IF(ISBLANK(G500),"","A")),IF(G500="EE",IF(J500>=3,IF(I500>=5,"H","A"),IF(J500>=2,IF(I500>=16,"H",IF(I500<=4,"L","A")),IF(I500<=15,"L","A"))),IF(OR(G500="SE",G500="CE"),IF(J500>=4,IF(I500>=6,"H","A"),IF(J500>=2,IF(I500>=20,"H",IF(I500<=5,"L","A")),IF(I500<=19,"L","A"))),IF(OR(G500="ALI",G500="AIE"),IF(J500>=6,IF(I500>=20,"H","A"),IF(J500>=2,IF(I500>=51,"H",IF(I500<=19,"L","A")),IF(I500<=50,"L","A"))))))) | M500: =IF(L500="L","Baixa",IF(L500="A","Média",IF(L500="","","Alta"))) | O500: =IF(H500="I",N500*Contagem!$W$11,IF(H500="E",N500*Contagem!$W$13,IF(H500="A",N500*Contagem!$W$12,IF(H500="T",N500*Contagem!$W$14,""))))

Sheet Sumário
A1: Sumário da Contagem - v5
A4: =Contagem!A5&" : "&Contagem!F5 -> Sistema/Subsistema : | F4: =Contagem!A6&" : "&Contagem!F6 -> Projeto :
A5: =Contagem!A7&" : "&Contagem!F7 -> Responsável : | F5: =Contagem!A8&" : "&Contagem!F8 -> Revisor :
A6: =Contagem!A4&" : "&Contagem!F4 -> Empresa : BASIS Tecnologia | F6: =Contagem!R4&" = "&VALUE(Contagem!T4) -> R$/PF = 0 | H6: =" Custo= "&DOLLAR(Contagem!Y4) -> Custo= R$ 0,00 | L6: ="PFB = "&VALUE(Contagem!Y5) -> PFB = 0
A7: Tipo de Função | C7: Complexidade Funcional | G7: Total por Complexidade | I7: %
B10: EE | C10: =COUNTIF(CF,"EEL") -> 0 | E10: Baixa | F10: x 3 | G10: =C10*3 -> 0
C11: =COUNTIF(CF,"EEA") -> 0 | E11: Média | F11: x 4 | G11: =C11*4 -> 0
C12: =COUNTIF(CF,"EEH") -> 0 | E12: Alta | F12: x 6 | G12: =C12*6 -> 0
B14: Total | C14: =SUM(C10:C12) -> 0 | F14: Total | G14: =SUM(G10:G12) -> 0 | I14: =IF($G$45<>0,G14/$G$45,"")
B17: SE | C17: =COUNTIF(CF,"SEL") -> 0 | E17: Baixa | F17: x 4 | G17: =C17*4 -> 0
C18: =COUNTIF(CF,"SEA") -> 0 | E18: Média | F18: x 5 | G18: =C18*5 -> 0
C19: =COUNTIF(CF,"SEH") -> 0 | E19: Alta | F19: x 7 | G19: =C19*7 -> 0
B21: Total | C21: =SUM(C17:C19) -> 0 | F21: Total | G21: =SUM(G17:G19) -> 0 | I21: =IF($G$45<>0,G21/$G$45,"")
B24: CE | C24: =COUNTIF(CF,"CEL") -> 0 | E24: Baixa | F24: x 3 | G24: =C24*3 -> 0
C25: =COUNTIF(CF,"CEA") -> 0 | E25: Média | F25: x 4 | G25: =C25*4 -> 0
C26: =COUNTIF(CF,"CEH") -> 0 | E26: Alta | F26: x 6 | G26: =C26*6 -> 0
B28: Total | C28: =SUM(C24:C26) -> 0 | F28: Total | G28: =SUM(G24:G26) -> 0 | I28: =IF($G$45<>0,G28/$G$45,"")
B31: ALI | C31: =COUNTIF(CF,"ALIL") -> 0 | E31: Baixa | F31: x 7 | G31: =C31*7 -> 0
C32: =COUNTIF(CF,"ALIA") -> 0 | E32: Média | F32: x 10 | G32: =C32*10 -> 0
C33: =COUNTIF(CF,"ALIH") -> 0 | E33: Alta | F33: x 15 | G33: =C33*15 -> 0
B35: Total | C35: =SUM(C31:C33) -> 0 | F35: Total | G35: =SUM(G31:G33) -> 0 | I35: =IF($G$45<>0,G35/$G$45,"")
B38: AIE | C38: =COUNTIF(CF,"AIEL") -> 0 | E38: Baixa | F38: x 5 | G38: =C38*5 -> 0
C39: =COUNTIF(CF,"AIEA") -> 0 | E39: Média | F39: x 7 | G39: =C39*7 -> 0
C40: =COUNTIF(CF,"AIEH") -> 0 | E40: Alta | F40: x 10 | G40: =C40*10 -> 0
B42: Total | C42: =SUM(C38:C40) -> 0 | F42: Total | G42: =SUM(G38:G40) -> 0 | I42: =IF($G$45<>0,G42/$G$45,"")
B45: Total PF não ajustados (contagem detalhada) | G45: =SUM(G14+G21+G28+G35+G42) -> 0
B46: Total PF não ajustados (contagem estimativa) | G46: =(C10+C11+C12)*4+(C17+C18+C19)*5+(C24+C25+C26)*4+(C31+C32+C33)*7+(C38+C39+C40)*5 -> 0
B47: Total PF não ajustados (contagem indicativa) | G47: =(C31+C32+C33)*35+(C38+C39+C40)*15 -> 0
B53: Total de PF Ajustados pelo FI
E54: NÃO AJS | F54: FI | G54: LOCAL | I54: TOTAL PF
B55: INCLUSÃO (ADD) | E55: =SUMIF(Funções!$H$8:$H$10014,"I",Funções!$N$8:$N$10014) -> 0 | F55: =Contagem!W11 -> 1 | G55: =F55*E55 -> 0 | I55: =Contagem!Y5 -> 0
B56: ALTERAÇÃO (CHG) | E56: =SUMIF(Funções!$H$8:$H$10014,"A",Funções!$N$8:$N$10014) -> 0 | F56: =Contagem!W12 -> 0.3 | G56: =F56*E56 -> 0
B57: EXCLUSÃO (DEL) | E57: =SUMIF(Funções!$H$8:$H$10014,"E",Funções!$N$8:$N$10014) -> 0 | F57: =Contagem!W13 -> 0.3 | G57: =F57*E57 -> 0
B58: TESTE (TST) | E58: =SUMIF(Funções!$H$8:$H$10014,"T",Funções!$N$8:$N$10014) -> 0 | F58: =Contagem!W14 -> 0.15 | G58: =F58*E58 -> 0
B60: Total de PF por disciplina (INM + Implementação)
E61: % | G61: CALC
B62: REQUISITOS | E62: 0.22 | G62: =I$55*E62 -> 0
B63: ANÁLISE E PROJETO | E63: 0.28 | G63: =I$55*E63 -> 0 | H63: TOTAL INM | I63: TOTAL
B64: IMPLEMENTAÇÃO | E64: 0.5 | G64: =I$55*E64 -> 0 | H64: ='Itens Não Mensuráveis'!W6 -> 0 | I64: =H64+G64 -> 0
B66: Total de PF por FASE
...

Sheet Itens Não Mensuráveis
A1: Planilha de contagem de ponto de função - ITENS NÃO MENSURÁVEIS - v5
AA2: Os itens não mensuráveis 4.1, 4.2, 6.1, 6.2, 6.3 e 6.4 não estão vinculados a um Processo Elementar e não estão sujeitos a limites de contagem; Os demais itens não mensuráveis devem ser vinculados a um Processo Elementar da aplicação e estarão limitados ao tamanho de (0,30 do PE);
A4: =Contagem!A5&" : "&Contagem!F5 -> Sistema/Subsistema : | P4: =Contagem!A4&" : "&Contagem!F4 -> Empresa : BASIS Tecnologia | U4: =Contagem!A6&" : "&Contagem!F6 -> Projeto : | W4: A ocultar
A5: =Contagem!A7&" : "&Contagem!F7 -> Responsável : | P5: =Contagem!A8&" : "&Contagem!F8 -> Revisor :
A6: ="PFB = "&SUM(T8:T113) -> PFB = 0 | P6: =IF(MIN(V8:V113)<0,"Contagem inadequada para contratação"," ") | W6: =SUM(T8:T113) -> 0
A7: Processo Elementar | G7: Tipo | H7: (I/A/E/T) | I7: TD | J7: AR/TR | K7: ctl | L7: C | M7: Complex. | N7: PF | O7: PF Local | P7: INM | Q7: Tipo mapeado | R7: Vlr unit | S7: Qtd | T7: Valor Total | U7: Vlr.acumulado | V7: Limite atingido | W7: =MIN(V8:V113) -> 0
M8: =IF(L8="L","Baixa",IF(L8="A","Média",IF(L8="","","Alta"))) | N8: =IF(ISBLANK(G8),"",IF(G8="ALI",IF(L8="L",7,IF(L8="A",10,15)),IF(G8="AIE",IF(L8="L",5,IF(L8="A",7,10)),IF(G8="SE",IF(L8="L",4,IF(L8="A",5,7)),IF(OR(G8="EE",G8="CE"),IF(L8="L",3,IF(L8="A",4,6))))))) | O8: =IF(H8="I",N8*Contagem!$W$11,IF(H8="E",N8*Contagem!$W$13,IF(H8="A",N8*Contagem!$W$12,IF(H8="T",N8*Contagem!$W$14,"")))) | T8: =IF(ISNUMBER(R8),R8*S8,"") | U8: =IF(X8="PE",0,IF(W8=0,U7,IF(ISNUMBER(W8),IF(ISNUMBER(U7),T8+U7,T8)," "))) | V8: =IF(ISNUMBER(W8),IF(X8="PE",0.3*N8,IF(X8="S",ROUND((IF(ISNUMBER(V7),V7,0))-T8,2),IF(ISNUMBER(V7),V7,0)))," ") | W8: =IF(ISNUMBER(N8),0,IF(ISNUMBER(T8),IF(X8="S",T8,0)," ")) | X8: =IF(ISNUMBER(N8),"PE",IF(ISNA(VLOOKUP(Q8,'INM - Regras'!$D$24:$F$37,3)),"",VLOOKUP(Q8,'INM - Regras'!$D$24:$F$37,3)))
B9: INM1 | K9: =CONCATENATE(G9,L9) | L9: =IF(OR(ISBLANK(I9),ISBLANK(J9)),IF(OR(G9="ALI",G9="AIE"),"L",IF(ISBLANK(G9),"","A")),IF(G9="EE",IF(J9>=3,IF(I9>=5,"H","A"),IF(J9>=2,IF(I9>=16,"H",IF(I9<=4,"L","A")),IF(I9<=15,"L","A"))),IF(OR(G9="SE",G9="CE"),IF(J9>=4,IF(I9>=6,"H","A"),IF(J9>=2,IF(I9>=20,"H",IF(I9<=5,"L","A")),IF(I9<=19,"L","A"))),IF(OR(G9="ALI",G9="AIE"),IF(J9>=6,IF(I9>=20,"H","A"),IF(J9>=2,IF(I9>=51,"H",IF(I9<=19,"L","A")),IF(I9<=50,"L","A"))))))) | M9: =IF(L9="L","Baixa",IF(L9="A","Média",IF(L9="","","Alta"))) | N9: =IF(ISBLANK(G9),"",IF(G9="ALI",IF(L9="L",7,IF(L9="A",10,15)),IF(G9="AIE",IF(L9="L",5,IF(L9="A",7,10)),IF(G9="SE",IF(L9="L",4,IF(L9="A",5,7)),IF(OR(G9="EE",G9="CE"),IF(L9="L",3,IF(L9="A",4,6))))))) | O9: =IF(H9="I",N9*Contagem!$W$11,IF(H9="E",N9*Contagem!$W$13,IF(H9="A",N9*Contagem!$W$12,IF(H9="T",N9*Contagem!$W$14,"")))) | T9: =IF(ISNUMBER(R9),R9*S9,"") | U9: =IF(X9="PE",0,IF(W9=0,U8,IF(ISNUMBER(W9),IF(ISNUMBER(U8),T9+U8,T9)," "))) | V9: =IF(ISNUMBER(W9),IF(X9="PE",0.3*N9,IF(X9="S",ROUND((IF(ISNUMBER(V8),V8,0))-T9,2),IF(ISNUMBER(V8),V8,0)))," ") | W9: =IF(ISNUMBER(N9),0,IF(ISNUMBER(T9),IF(X9="S",T9,0)," ")) | X9: =IF(ISNUMBER(N9),"PE",IF(ISNA(VLOOKUP(Q9,'INM - Regras'!$D$24:$F$37,3)),"",VLOOKUP(Q9,'INM - Regras'!$D$24:$F$37,3)))
K10: =CONCATENATE(G10,L10) | L10: =IF(OR(ISBLANK(I10),ISBLANK(J10)),IF(OR(G10="ALI",G10="AIE"),"L",IF(ISBLANK(G10),"","A")),IF(G10="EE",IF(J10>=3,IF(I10>=5,"H","A"),IF(J10>=2,IF(I10>=16,"H",IF(I10<=4,"L","A")),IF(I10<=15,"L","A"))),IF(OR(G10="SE",G10="CE"),IF(J10>=4,IF(I10>=6,"H","A"),IF(J10>=2,IF(I10>=20,"H",IF(I10<=5,"L","A")),IF(I10<=19,"L","A"))),IF(OR(G10="ALI",G10="AIE"),IF(J10>=6,IF(I10>=20,"H","A"),IF(J10>=2,IF(I10>=51,"H",IF(I10<=19,"L","A")),IF(I10<=50,"L","A"))))))) | M10: =IF(L10="L","Baixa",IF(L10="A","Média",IF(L10="","","Alta"))) | N10: =IF(ISBLANK(G10),"",IF(G10="ALI",IF(L10="L",7,IF(L10="A",10,15)),IF(G10="AIE",IF(L10="L",5,IF(L10="A",7,10)),IF(G10="SE",IF(L10="L",4,IF(L10="A",5,7)),IF(OR(G10="EE",G10="CE"),IF(L10="L",3,IF(L10="A",4,6))))))) | O10: =IF(H10="I",N10*Contagem!$W$11,IF(H10="E",N10*Contagem!$W$13,IF(H10="A",N10*Contagem!$W$12,IF(H10="T",N10*Contagem!$W$14,"")))) | T10: =IF(ISNUMBER(R10),R10*S10,"") | U10: =IF(X10="PE",0,IF(W10=0,U9,IF(ISNUMBER(W10),IF(ISNUMBER(U9),T10+U9,T10)," "))) | V10: =IF(ISNUMBER(W10),IF(X10="PE",0.3*N10,IF(X10="S",ROUND((IF(ISNUMBER(V9),V9,0))-T10,2),IF(ISNUMBER(V9),V9,0)))," ") | W10: =IF(ISNUMBER(N10),0,IF(ISNUMBER(T10),IF(X10="S",T10,0)," ")) | X10: =IF(ISNUMBER(N10),"PE",IF(ISNA(VLOOKUP(Q10,'INM - Regras'!$D$24:$F$37,3)),"",VLOOKUP(Q10,'INM - Regras'!$D$24:$F$37,3)))
K11: =CONCATENATE(G11,L11) | L11: =IF(OR(ISBLANK(I11),ISBLANK(J11)),IF(OR(G11="ALI",G11="AIE"),"L",IF(ISBLANK(G11),"","A")),IF(G11="EE",IF(J11>=3,IF(I11>=5,"H","A"),IF(J11>=2,IF(I11>=16,"H",IF(I11<=4,"L","A")),IF(I11<=15,"L","A"))),IF(OR(G11="SE",G11="CE"),IF(J11>=4,IF(I11>=6,"H","A"),IF(J11>=2,IF(I11>=20,"H",IF(I11<=5,"L","A")),IF(I11<=19,"L","A"))),IF(OR(G11="ALI",G11="AIE"),IF(J11>=6,IF(I11>=20,"H","A"),IF(J11>=2,IF(I11>=51,"H",IF(I11<=19,"L","A")),IF(I11<=50,"L","A"))))))) | M11: =IF(L11="L","Baixa",IF(L11="A","Média",IF(L11="","","Alta"))) | N11: =IF(ISBLANK(G11),"",IF(G11="ALI",IF(L11="L",7,IF(L11="A",10,15)),IF(G11="AIE",IF(L11="L",5,IF(L11="A",7,10)),IF(G11="SE",IF(L11="L",4,IF(L11="A",5,7)),IF(OR(G11="EE",G11="CE"),IF(L11="L",3,IF(L11="A",4,6))))))) | O11: =IF(H11="I",N11*Contagem!$W$11,IF(H11="E",N11*Contagem!$W$13,IF(H11="A",N11*Contagem!$W$12,IF(H11="T",N11*Contagem!$W$14,"")))) | T11: =IF(ISNUMBER(R11),R11*S11,"") | U11: =IF(X11="PE",0,IF(W11=0,U10,IF(ISNUMBER(W11),IF(ISNUMBER(U10),T11+U10,T11)," "))) | V11: =IF(ISNUMBER(W11),IF(X11="PE",0.3*N11,IF(X11="S",ROUND((IF(ISNUMBER(V10),V10,0))-T11,2),IF(ISNUMBER(V10),V10,0)))," ") | W11: =IF(ISNUMBER(N11),0,IF(ISNUMBER(T11),IF(X11="S",T11,0)," ")) | X11: =IF(ISNUMBER(N11),"PE",IF(ISNA(VLOOKUP(Q11,'INM - Regras'!$D$24:$F$37,3)),"",VLOOKUP(Q11,'INM - Regras'!$D$24:$F$37,3)))
K12: =CONCATENATE(G12,L12) | L12: =IF(OR(ISBLANK(I12),ISBLANK(J12)),IF(OR(G12="ALI",G12="AIE"),"L",IF(ISBLANK(G12),"","A")),IF(G12="EE",IF(J12>=3,IF(I12>=5,"H","A"),IF(J12>=2,IF(I12>=16,"H",IF(I12<=4,"L","A")),IF(I12<=15,"L","A"))),IF(OR(G12="SE",G12="CE"),IF(J12>=4,IF(I12>=6,"H","A"),IF(J12>=2,IF(I12>=20,"H",IF(I12<=5,"L","A")),IF(I12<=19,"L","A"))),IF(OR(G12="ALI",G12="AIE"),IF(J12>=6,IF(I12>=20,"H","A"),IF(J12>=2,IF(I12>=51,"H",IF(I12<=19,"L","A")),IF(I12<=50,"L","A"))))))) | M12: =IF(L12="L","Baixa",IF(L12="A","Média",IF(L12="","","Alta"))) | N12: =IF(ISBLANK(G12),"",IF(G12="ALI",IF(L12="L",7,IF(L12="A",10,15)),IF(G12="AIE",IF(L12="L",5,IF(L12="A",7,10)),IF(G12="SE",IF(L12="L",4,IF(L12="A",5,7)),IF(OR(G12="EE",G12="CE"),IF(L12="L",3,IF(L12="A",4,6))))))) | O12: =IF(H12="I",N12*Contagem!$W$11,IF(H12="E",N12*Contagem!$W$13,IF(H12="A",N12*Contagem!$W$12,IF(H12="T",N12*Contagem!$W$14,"")))) | T12: =IF(ISNUMBER(R12),R12*S12,"") | U12: =IF(X12="PE",0,IF(W12=0,U11,IF(ISNUMBER(W12),IF(ISNUMBER(U11),T12+U11,T12)," "))) | V12: =IF(ISNUMBER(W12),IF(X12="PE",0.3*N12,IF(X12="S",ROUND((IF(ISNUMBER(V11),V11,0))-T12,2),IF(ISNUMBER(V11),V11,0)))," ") | W12: =IF(ISNUMBER(N12),0,IF(ISNUMBER(T12),IF(X12="S",T12,0)," ")) | X12: =IF(ISNUMBER(N12),"PE",IF(ISNA(VLOOKUP(Q12,'INM - Regras'!$D$24:$F$37,3)),"",VLOOKUP(Q12,'INM - Regras'!$D$24:$F$37,3)))
K13: =CONCATENATE(G13,L13) | L13: =IF(OR(ISBLANK(I13),ISBLANK(J13)),IF(OR(G13="ALI",G13="AIE"),"L",IF(ISBLANK(G13),"","A")),IF(G13="EE",IF(J13>=3,IF(I13>=5,"H","A"),IF(J13>=2,IF(I13>=16,"H",IF(I13<=4,"L","A")),IF(I13<=15,"L","A"))),IF(OR(G13="SE",G13="CE"),IF(J13>=4,IF(I13>=6,"H","A"),IF(J13>=2,IF(I13>=20,"H",IF(I13<=5,"L","A")),IF(I13<=19,"L","A"))),IF(OR(G13="ALI",G13="AIE"),IF(J13>=6,IF(I13>=20,"H","A"),IF(J13>=2,IF(I13>=51,"H",IF(I13<=19,"L","A")),IF(I13<=50,"L","A"))))))) | M13: =IF(L13="L","Baixa",IF(L13="A","Média",IF(L13="","","Alta"))) | N13: =IF(ISBLANK(G13),"",IF(G13="ALI",IF(L13="L",7,IF(L13="A",10,15)),IF(G13="AIE",IF(L13="L",5,IF(L13="A",7,10)),IF(G13="SE",IF(L13="L",4,IF(L13="A",5,7)),IF(OR(G13="EE",G13="CE"),IF(L13="L",3,IF(L13="A",4,6))))))) | O13: =IF(H13="I",N13*Contagem!$W$11,IF(H13="E",N13*Contagem!$W$13,IF(H13="A",N13*Contagem!$W$12,IF(H13="T",N13*Contagem!$W$14,"")))) | T13: =IF(ISNUMBER(R13),R13*S13,"") | U13: =IF(X13="PE",0,IF(W13=0,U12,IF(ISNUMBER(W13),IF(ISNUMBER(U12),T13+U12,T13)," "))) | V13: =IF(ISNUMBER(W13),IF(X13="PE",0.3*N13,IF(X13="S",ROUND((IF(ISNUMBER(V12),V12,0))-T13,2),IF(ISNUMBER(V12),V12,0)))," ") | W13: =IF(ISNUMBER(N13),0,IF(ISNUMBER(T13),IF(X13="S",T13,0)," ")) | X13: =IF(ISNUMBER(N13),"PE",IF(ISNA(VLOOKUP(Q13,'INM - Regras'!$D$24:$F$37,3)),"",VLOOKUP(Q13,'INM - Regras'!$D$24:$F$37,3)))
K14: =CONCATENATE(G14,L14) | L14: =IF(OR(ISBLANK(I14),ISBLANK(J14)),IF(OR(G14="ALI",G14="AIE"),"L",IF(ISBLANK(G14),"","A")),IF(G14="EE",IF(J14>=3,IF(I14>=5,"H","A"),IF(J14>=2,IF(I14>=16,"H",IF(I14<=4,"L","A")),IF(I14<=15,"L","A"))),IF(OR(G14="SE",G14="CE"),IF(J14>=4,IF(I14>=6,"H","A"),IF(J14>=2,IF(I14>=20,"H",IF(I14<=5,"L","A")),IF(I14<=19,"L","A"))),IF(OR(G14="ALI",G14="AIE"),IF(J14>=6,IF(I14>=20,"H","A"),IF(J14>=2,IF(I14>=51,"H",IF(I14<=19,"L","A")),IF(I14<=50,"L","A"))))))) | M14: =IF(L14="L","Baixa",IF(L14="A","Média",IF(L14="","","Alta"))) | N14: =IF(ISBLANK(G14),"",IF(G14="ALI",IF(L14="L",7,IF(L14="A",10,15)),IF(G14="AIE",IF(L14="L",5,IF(L14="A",7,10)),IF(G14="SE",IF(L14="L",4,IF(L14="A",5,7)),IF(OR(G14="EE",G14="CE"),IF(L14="L",3,IF(L14="A",4,6))))))) | O14: =IF(H14="I",N14*Contagem!$W$11,IF(H14="E",N14*Contagem!$W$13,IF(H14="A",N14*Contagem!$W$12,IF(H14="T",N14*Contagem!$W$14,"")))) | T14: =IF(ISNUMBER(R14),R14*S14,"") | U14: =IF(X14="PE",0,IF(W14=0,U13,IF(ISNUMBER(W14),IF(ISNUMBER(U13),T14+U13,T14)," "))) | V14: =IF(ISNUMBER(W14),IF(X14="PE",0.3*N14,IF(X14="S",ROUND((IF(ISNUMBER(V13),V13,0))-T14,2),IF(ISNUMBER(V13),V13,0)))," ") | W14: =IF(ISNUMBER(N14),0,IF(ISNUMBER(T14),IF(X14="S",T14,0)," ")) | X14: =IF(ISNUMBER(N14),"PE",IF(ISNA(VLOOKUP(Q14,'INM - Regras'!$D$24:$F$37,3)),"",VLOOKUP(Q14,'INM - Regras'!$D$24:$F$37,3)))
K15: =CONCATENATE(G15,L15) | L15: =IF(OR(ISBLANK(I15),ISBLANK(J15)),IF(OR(G15="ALI",G15="AIE"),"L",IF(ISBLANK(G15),"","A")),IF(G15="EE",IF(J15>=3,IF(I15>=5,"H","A"),IF(J15>=2,IF(I15>=16,"H",IF(I15<=4,"L","A")),IF(I15<=15,"L","A"))),IF(OR(G15="SE",G15="CE"),IF(J15>=4,IF(I15>=6,"H","A"),IF(J15>=2,IF(I15>=20,"H",IF(I15<=5,"L","A")),IF(I15<=19,"L","A"))),IF(OR(G15="ALI",G15="AIE"),IF(J15>=6,IF(I15>=20,"H","A"),IF(J15>=2,IF(I15>=51,"H",IF(I15<=19,"L","A")),IF(I15<=50,"L","A"))))))) | M15: =IF(L15="L","Baixa",IF(L15="A","Média",IF(L15="","","Alta"))) | N15: =IF(ISBLANK(G15),"",IF(G15="ALI",IF(L15="L",7,IF(L15="A",10,15)),IF(G15="AIE",IF(L15="L",5,IF(L15="A",7,10)),IF(G15="SE",IF(L15="L",4,IF(L15="A",5,7)),IF(OR(G15="EE",G15="CE"),IF(L15="L",3,IF(L15="A",4,6))))))) | O15: =IF(H15="I",N15*Contagem!$W$11,IF(H15="E",N15*Contagem!$W$13,IF(H15="A",N15*Contagem!$W$12,IF(H15="T",N15*Contagem!$W$14,"")))) | T15: =IF(ISNUMBER(R15),R15*S15,"") | U15: =IF(X15="PE",0,IF(W15=0,U14,IF(ISNUMBER(W15),IF(ISNUMBER(U14),T15+U14,T15)," "))) | V15: =IF(ISNUMBER(W15),IF(X15="PE",0.3*N15,IF(X15="S",ROUND((IF(ISNUMBER(V14),V14,0))-T15,2),IF(ISNUMBER(V14),V14,0)))," ") | W15: =IF(ISNUMBER(N15),0,IF(ISNUMBER(T15),IF(X15="S",T15,0)," ")) | X15: =IF(ISNUMBER(N15),"PE",IF(ISNA(VLOOKUP(Q15,'INM - Regras'!$D$24:$F$37,3)),"",VLOOKUP(Q15,'INM - Regras'!$D$24:$F$37,3)))
K16: =CONCATENATE(G16,L16) | L16: =IF(OR(ISBLANK(I16),ISBLANK(J16)),IF(OR(G16="ALI",G16="AIE"),"L",IF(ISBLANK(G16),"","A")),IF(G16="EE",IF(J16>=3,IF(I16>=5,"H","A"),IF(J16>=2,IF(I16>=16,"H",IF(I16<=4,"L","A")),IF(I16<=15,"L","A"))),IF(OR(G16="SE",G16="CE"),IF(J16>=4,IF(I16>=6,"H","A"),IF(J16>=2,IF(I16>=20,"H",IF(I16<=5,"L","A")),IF(I16<=19,"L","A"))),IF(OR(G16="ALI",G16="AIE"),IF(J16>=6,IF(I16>=20,"H","A"),IF(J16>=2,IF(I16>=51,"H",IF(I16<=19,"L","A")),IF(I16<=50,"L","A"))))))) | M16: =IF(L16="L","Baixa",IF(L16="A","Média",IF(L16="","","Alta"))) | N16: =IF(ISBLANK(G16),"",IF(G16="ALI",IF(L16="L",7,IF(L16="A",10,15)),IF(G16="AIE",IF(L16="L",5,IF(L16="A",7,10)),IF(G16="SE",IF(L16="L",4,IF(L16="A",5,7)),IF(OR(G16="EE",G16="CE"),IF(L16="L",3,IF(L16="A",4,6))))))) | O16: =IF(H16="I",N16*Contagem!$W$11,IF(H16="E",N16*Contagem!$W$13,IF(H16="A",N16*Contagem!$W$12,IF(H16="T",N16*Contagem!$W$14,"")))) | T16: =IF(ISNUMBER(R16),R16*S16,"") | U16: =IF(X16="PE",0,IF(W16=0,U15,IF(ISNUMBER(W16),IF(ISNUMBER(U15),T16+U15,T16)," "))) | V16: =IF(ISNUMBER(W16),IF(X16="PE",0.3*N16,IF(X16="S",ROUND((IF(ISNUMBER(V15),V15,0))-T16,2),IF(ISNUMBER(V15),V15,0)))," ") | W16: =IF(ISNUMBER(N16),0,IF(ISNUMBER(T16),IF(X16="S",T16,0)," ")) | X16: =IF(ISNUMBER(N16),"PE",IF(ISNA(VLOOKUP(Q16,'INM - Regras'!$D$24:$F$37,3)),"",VLOOKUP(Q16,'INM - Regras'!$D$24:$F$37,3)))
K17: =CONCATENATE(G17,L17) | L17: =IF(OR(ISBLANK(I17),ISBLANK(J17)),IF(OR(G17="ALI",G17="AIE"),"L",IF(ISBLANK(G17),"","A")),IF(G17="EE",IF(J17>=3,IF(I17>=5,"H","A"),IF(J17>=2,IF(I17>=16,"H",IF(I17<=4,"L","A")),IF(I17<=15,"L","A"))),IF(OR(G17="SE",G17="CE"),IF(J17>=4,IF(I17>=6,"H","A"),IF(J17>=2,IF(I17>=20,"H",IF(I17<=5,"L","A")),IF(I17<=19,"L","A"))),IF(OR(G17="ALI",G17="AIE"),IF(J17>=6,IF(I17>=20,"H","A"),IF(J17>=2,IF(I17>=51,"H",IF(I17<=19,"L","A")),IF(I17<=50,"L","A"))))))) | M17: =IF(L17="L","Baixa",IF(L17="A","Média",IF(L17="","","Alta"))) | N17: =IF(ISBLANK(G17),"",IF(G17="ALI",IF(L17="L",7,IF(L17="A",10,15)),IF(G17="AIE",IF(L17="L",5,IF(L17="A",7,10)),IF(G17="SE",IF(L17="L",4,IF(L17="A",5,7)),IF(OR(G17="EE",G17="CE"),IF(L17="L",3,IF(L17="A",4,6))))))) | O17: =IF(H17="I",N17*Contagem!$W$11,IF(H17="E",N17*Contagem!$W$13,IF(H17="A",N17*Contagem!$W$12,IF(H17="T",N17*Contagem!$W$14,"")))) | T17: =IF(ISNUMBER(R17),R17*S17,"") | U17: =IF(X17="PE",0,IF(W17=0,U16,IF(ISNUMBER(W17),IF(ISNUMBER(U16),T17+U16,T17)," "))) | V17: =IF(ISNUMBER(W17),IF(X17="PE",0.3*N17,IF(X17="S",ROUND((IF(ISNUMBER(V16),V16,0))-T17,2),IF(ISNUMBER(V16),V16,0)))," ") | W17: =IF(ISNUMBER(N17),0,IF(ISNUMBER(T17),IF(X17="S",T17,0)," ")) | X17: =IF(ISNUMBER(N17),"PE",IF(ISNA(VLOOKUP(Q17,'INM - Regras'!$D$24:$F$37,3)),"",VLOOKUP(Q17,'INM - Regras'!$D$24:$F$37,3)))
K18: =CONCATENATE(G18,L18) | L18: =IF(OR(ISBLANK(I18),ISBLANK(J18)),IF(OR(G18="ALI",G18="AIE"),"L",IF(ISBLANK(G18),"","A")),IF(G18="EE",IF(J18>=3,IF(I18>=5,"H","A"),IF(J18>=2,IF(I18>=16,"H",IF(I18<=4,"L","A")),IF(I18<=15,"L","A"))),IF(OR(G18="SE",G18="CE"),IF(J18>=4,IF(I18>=6,"H","A"),IF(J18>=2,IF(I18>=20,"H",IF(I18<=5,"L","A")),IF(I18<=19,"L","A"))),IF(OR(G18="ALI",G18="AIE"),IF(J18>=6,IF(I18>=20,"H","A"),IF(J18>=2,IF(I18>=51,"H",IF(I18<=19,"L","A")),IF(I18<=50,"L","A"))))))) | M18: =IF(L18="L","Baixa",IF(L18="A","Média",IF(L18="","","Alta"))) | N18: =IF(ISBLANK(G18),"",IF(G18="ALI",IF(L18="L",7,IF(L18="A",10,15)),IF(G18="AIE",IF(L18="L",5,IF(L18="A",7,10)),IF(G18="SE",IF(L18="L",4,IF(L18="A",5,7)),IF(OR(G18="EE",G18="CE"),IF(L18="L",3,IF(L18="A",4,6))))))) | O18: =IF(H18="I",N18*Contagem!$W$11,IF(H18="E",N18*Contagem!$W$13,IF(H18="A",N18*Contagem!$W$12,IF(H18="T",N18*Contagem!$W$14,"")))) | R18: =IF(ISNUMBER(N18),0,IF(ISNA(VLOOKUP(Q18,'INM - Regras'!$D$24:$E$37,2)),"",VLOOKUP(Q18,'INM - Regras'!$D$24:$E$37,2))) | T18: =IF(ISNUMBER(R18),R18*S18,"") | U18: =IF(X18="PE",0,IF(W18=0,U17,IF(ISNUMBER(W18),IF(ISNUMBER(U17),T18+U17,T18)," "))) | V18: =IF(ISNUMBER(W18),IF(X18="PE",0.3*N18,IF(X18="S",ROUND((IF(ISNUMBER(V17),V17,0))-T18,2),IF(ISNUMBER(V17),V17,0)))," ") | W18: =IF(ISNUMBER(N18),0,IF(ISNUMBER(T18),IF(X18="S",T18,0)," ")) | X18: =IF(ISNUMBER(N18),"PE",IF(ISNA(VLOOKUP(Q18,'INM - Regras'!$D$24:$F$37,3)),"",VLOOKUP(Q18,'INM - Regras'!$D$24:$F$37,3)))
K19: =CONCATENATE(G19,L19) | L19: =IF(OR(ISBLANK(I19),ISBLANK(J19)),IF(OR(G19="ALI",G19="AIE"),"L",IF(ISBLANK(G19),"","A")),IF(G19="EE",IF(J19>=3,IF(I19>=5,"H","A"),IF(J19>=2,IF(I19>=16,"H",IF(I19<=4,"L","A")),IF(I19<=15,"L","A"))),IF(OR(G19="SE",G19="CE"),IF(J19>=4,IF(I19>=6,"H","A"),IF(J19>=2,IF(I19>=20,"H",IF(I19<=5,"L","A")),IF(I19<=19,"L","A"))),IF(OR(G19="ALI",G19="AIE"),IF(J19>=6,IF(I19>=20,"H","A"),IF(J19>=2,IF(I19>=51,"H",IF(I19<=19,"L","A")),IF(I19<=50,"L","A"))))))) | M19: =IF(L19="L","Baixa",IF(L19="A","Média",IF(L19="","","Alta"))) | N19: =IF(ISBLANK(G19),"",IF(G19="ALI",IF(L19="L",7,IF(L19="A",10,15)),IF(G19="AIE",IF(L19="L",5,IF(L19="A",7,10)),IF(G19="SE",IF(L19="L",4,IF(L19="A",5,7)),IF(OR(G19="EE",G19="CE"),IF(L19="L",3,IF(L19="A",4,6))))))) | O19: =IF(H19="I",N19*Contagem!$W$11,IF(H19="E",N19*Contagem!$W$13,IF(H19="A",N19*Contagem!$W$12,IF(H19="T",N19*Contagem!$W$14,"")))) | R19: =IF(ISNUMBER(N19),0,IF(ISNA(VLOOKUP(Q19,'INM - Regras'!$D$24:$E$37,2)),"",VLOOKUP(Q19,'INM - Regras'!$D$24:$E$37,2))) | T19: =IF(ISNUMBER(R19),R19*S19,"") | U19: =IF(X19="PE",0,IF(W19=0,U18,IF(ISNUMBER(W19),IF(ISNUMBER(U18),T19+U18,T19)," "))) | V19: =IF(ISNUMBER(W19),IF(X19="PE",0.3*N19,IF(X19="S",ROUND((IF(ISNUMBER(V18),V18,0))-T19,2),IF(ISNUMBER(V18),V18,0)))," ") | W19: =IF(ISNUMBER(N19),0,IF(ISNUMBER(T19),IF(X19="S",T19,0)," ")) | X19: =IF(ISNUMBER(N19),"PE",IF(ISNA(VLOOKUP(Q19,'INM - Regras'!$D$24:$F$37,3)),"",VLOOKUP(Q19,'INM - Regras'!$D$24:$F$37,3))) | Z19: Cod | AA19: Descrição | AB19: Pontuação | AC19: Vinculo com PE
K20: =CONCATENATE(G20,L20) | L20: =IF(OR(ISBLANK(I20),ISBLANK(J20)),IF(OR(G20="ALI",G20="AIE"),"L",IF(ISBLANK(G20),"","A")),IF(G20="EE",IF(J20>=3,IF(I20>=5,"H","A"),IF(J20>=2,IF(I20>=16,"H",IF(I20<=4,"L","A")),IF(I20<=15,"L","A"))),IF(OR(G20="SE",G20="CE"),IF(J20>=4,IF(I20>=6,"H","A"),IF(J20>=2,IF(I20>=20,"H",IF(I20<=5,"L","A")),IF(I20<=19,"L","A"))),IF(OR(G20="ALI",G20="AIE"),IF(J20>=6,IF(I20>=20,"H","A"),IF(J20>=2,IF(I20>=51,"H",IF(I20<=19,"L","A")),IF(I20<=50,"L","A"))))))) | M20: =IF(L20="L","Baixa",IF(L20="A","Média",IF(L20="","","Alta"))) | N20: =IF(ISBLANK(G20),"",IF(G20="ALI",IF(L20="L",7,IF(L20="A",10,15)),IF(G20="AIE",IF(L20="L",5,IF(L20="A",7,10)),IF(G20="SE",IF(L20="L",4,IF(L20="A",5,7)),IF(OR(G20="EE",G20="CE"),IF(L20="L",3,IF(L20="A",4,6))))))) | O20: =IF(H20="I",N20*Contagem!$W$11,IF(H20="E",N20*Contagem!$W$13,IF(H20="A",N20*Contagem!$W$12,IF(H20="T",N20*Contagem!$W$14,"")))) | R20: =IF(ISNUMBER(N20),0,IF(ISNA(VLOOKUP(Q20,'INM - Regras'!$D$24:$E$37,2)),"",VLOOKUP(Q20,'INM - Regras'!$D$24:$E$37,2))) | T20: =IF(ISNUMBER(R20),R20*S20,"") | U20: =IF(X20="PE",0,IF(W20=0,U19,IF(ISNUMBER(W20),IF(ISNUMBER(U19),T20+U19,T20)," "))) | V20: =IF(ISNUMBER(W20),IF(X20="PE",0.3*N20,IF(X20="S",ROUND((IF(ISNUMBER(V19),V19,0))-T20,2),IF(ISNUMBER(V19),V19,0)))," ") | W20: =IF(ISNUMBER(N20),0,IF(ISNUMBER(T20),IF(X20="S",T20,0)," ")) | X20: =IF(ISNUMBER(N20),"PE",IF(ISNA(VLOOKUP(Q20,'INM - Regras'!$D$24:$F$37,3)),"",VLOOKUP(Q20,'INM - Regras'!$D$24:$F$37,3))) | Z20: ='INM - Regras'!C24 -> 1.1 | AA20: ='INM - Regras'!D24 -> 1.1 - Mudança de posição de campos em telas, em relatórios, sem que haja alteração em elementos de dados, arquivos referenciados ou informações de controle | AB20: ='INM - Regras'!E24 -> 0.04 | AC20: ='INM - Regras'!F24 -> S
K21: =CONCATENATE(G21,L21) | L21: =IF(OR(ISBLANK(I21),ISBLANK(J21)),IF(OR(G21="ALI",G21="AIE"),"L",IF(ISBLANK(G21),"","A")),IF(G21="EE",IF(J21>=3,IF(I21>=5,"H","A"),IF(J21>=2,IF(I21>=16,"H",IF(I21<=4,"L","A")),IF(I21<=15,"L","A"))),IF(OR(G21="SE",G21="CE"),IF(J21>=4,IF(I21>=6,"H","A"),IF(J21>=2,IF(I21>=20,"H",IF(I21<=5,"L","A")),IF(I21<=19,"L","A"))),IF(OR(G21="ALI",G21="AIE"),IF(J21>=6,IF(I21>=20,"H","A"),IF(J21>=2,IF(I21>=51,"H",IF(I21<=19,"L","A")),IF(I21<=50,"L","A"))))))) | M21: =IF(L21="L","Baixa",IF(L21="A","Média",IF(L21="","","Alta"))) | N21: =IF(ISBLANK(G21),"",IF(G21="ALI",IF(L21="L",7,IF(L21="A",10,15)),IF(G21="AIE",IF(L21="L",5,IF(L21="A",7,10)),IF(G21="SE",IF(L21="L",4,IF(L21="A",5,7)),IF(OR(G21="EE",G21="CE"),IF(L21="L",3,IF(L21="A",4,6))))))) | O21: =IF(H21="I",N21*Contagem!$W$11,IF(H21="E",N21*Contagem!$W$13,IF(H21="A",N21*Contagem!$W$12,IF(H21="T",N21*Contagem!$W$14,"")))) | R21: =IF(ISNUMBER(N21),0,IF(ISNA(VLOOKUP(Q21,'INM - Regras'!$D$24:$E$37,2)),"",VLOOKUP(Q21,'INM - Regras'!$D$24:$E$37,2))) | T21: =IF(ISNUMBER(R21),R21*S21,"") | U21: =IF(X21="PE",0,IF(W21=0,U20,IF(ISNUMBER(W21),IF(ISNUMBER(U20),T21+U20,T21)," "))) | V21: =IF(ISNUMBER(W21),IF(X21="PE",0.3*N21,IF(X21="S",ROUND((IF(ISNUMBER(V20),V20,0))-T21,2),IF(ISNUMBER(V20),V20,0)))," ") | W21: =IF(ISNUMBER(N21),0,IF(ISNUMBER(T21),IF(X21="S",T21,0)," ")) | X21: =IF(ISNUMBER(N21),"PE",IF(ISNA(VLOOKUP(Q21,'INM - Regras'!$D$24:$F$37,3)),"",VLOOKUP(Q21,'INM - Regras'!$D$24:$F$37,3))) | Z21: ='INM - Regras'!C25 -> 1.2 | AA21: ='INM - Regras'!D25 -> 1.2 - Inclusão, alteração ou exclusão de rótulos/textos/imagem | AB21: ='INM - Regras'!E25 -> 0.04 | AC21: ='INM - Regras'!F25 -> S
K22: =CONCATENATE(G22,L22) | L22: =IF(OR(ISBLANK(I22),ISBLANK(J22)),IF(OR(G22="ALI",G22="AIE"),"L",IF(ISBLANK(G22),"","A")),IF(G22="EE",IF(J22>=3,IF(I22>=5,"H","A"),IF(J22>=2,IF(I22>=16,"H",IF(I22<=4,"L","A")),IF(I22<=15,"L","A"))),IF(OR(G22="SE",G22="CE"),IF(J22>=4,IF(I22>=6,"H","A"),IF(J22>=2,IF(I22>=20,"H",IF(I22<=5,"L","A")),IF(I22<=19,"L","A"))),IF(OR(G22="ALI",G22="AIE"),IF(J22>=6,IF(I22>=20,"H","A"),IF(J22>=2,IF(I22>=51,"H",IF(I22<=19,"L","A")),IF(I22<=50,"L","A"))))))) | M22: =IF(L22="L","Baixa",IF(L22="A","Média",IF(L22="","","Alta"))) | N22: =IF(ISBLANK(G22),"",IF(G22="ALI",IF(L22="L",7,IF(L22="A",10,15)),IF(G22="AIE",IF(L22="L",5,IF(L22="A",7,10)),IF(G22="SE",IF(L22="L",4,IF(L22="A",5,7)),IF(OR(G22="EE",G22="CE"),IF(L22="L",3,IF(L22="A",4,6))))))) | O22: =IF(H22="I",N22*Contagem!$W$11,IF(H22="E",N22*Contagem!$W$13,IF(H22="A",N22*Contagem!$W$12,IF(H22="T",N22*Contagem!$W$14,"")))) | R22: =IF(ISNUMBER(N22),0,IF(ISNA(VLOOKUP(Q22,'INM - Regras'!$D$24:$E$37,2)),"",VLOOKUP(Q22,'INM - Regras'!$D$24:$E$37,2))) | T22: =IF(ISNUMBER(R22),R22*S22,"") | U22: =IF(X22="PE",0,IF(W22=0,U21,IF(ISNUMBER(W22),IF(ISNUMBER(U21),T22+U21,T22)," "))) | V22: =IF(ISNUMBER(W22),IF(X22="PE",0.3*N22,IF(X22="S",ROUND((IF(ISNUMBER(V21),V21,0))-T22,2),IF(ISNUMBER(V21),V21,0)))," ") | W22: =IF(ISNUMBER(N22),0,IF(ISNUMBER(T22),IF(X22="S",T22,0)," ")) | X22: =IF(ISNUMBER(N22),"PE",IF(ISNA(VLOOKUP(Q22,'INM - Regras'!$D$24:$F$37,3)),"",VLOOKUP(Q22,'INM - Regras'!$D$24:$F$37,3))) | Z22: ='INM - Regras'!C26 -> 1.3 | AA22: ='INM - Regras'!D26 -> 1.3 - Divisão de telas/relatórios, sem mudança na funcionalidade | AB22: ='INM - Regras'!E26 -> 0.04 | AC22: ='INM - Regras'!F26 -> S
K23: =CONCATENATE(G23,L23) | L23: =IF(OR(ISBLANK(I23),ISBLANK(J23)),IF(OR(G23="ALI",G23="AIE"),"L",IF(ISBLANK(G23),"","A")),IF(G23="EE",IF(J23>=3,IF(I23>=5,"H","A"),IF(J23>=2,IF(I23>=16,"H",IF(I23<=4,"L","A")),IF(I23<=15,"L","A"))),IF(OR(G23="SE",G23="CE"),IF(J23>=4,IF(I23>=6,"H","A"),IF(J23>=2,IF(I23>=20,"H",IF(I23<=5,"L","A")),IF(I23<=19,"L","A"))),IF(OR(G23="ALI",G23="AIE"),IF(J23>=6,IF(I23>=20,"H","A"),IF(J23>=2,IF(I23>=51,"H",IF(I23<=19,"L","A")),IF(I23<=50,"L","A"))))))) | M23: =IF(L23="L","Baixa",IF(L23="A","Média",IF(L23="","","Alta"))) | N23: =IF(ISBLANK(G23),"",IF(G23="ALI",IF(L23="L",7,IF(L23="A",10,15)),IF(G23="AIE",IF(L23="L",5,IF(L23="A",7,10)),IF(G23="SE",IF(L23="L",4,IF(L23="A",5,7)),IF(OR(G23="EE",G23="CE"),IF(L23="L",3,IF(L23="A",4,6))))))) | O23: =IF(H23="I",N23*Contagem!$W$11,IF(H23="E",N23*Contagem!$W$13,IF(H23="A",N23*Contagem!$W$12,IF(H23="T",N23*Contagem!$W$14,"")))) | R23: =IF(ISNUMBER(N23),0,IF(ISNA(VLOOKUP(Q23,'INM - Regras'!$D$24:$E$37,2)),"",VLOOKUP(Q23,'INM - Regras'!$D$24:$E$37,2))) | T23: =IF(ISNUMBER(R23),R23*S23,"") | U23: =IF(X23="PE",0,IF(W23=0,U22,IF(ISNUMBER(W23),IF(ISNUMBER(U22),T23+U22,T23)," "))) | V23: =IF(ISNUMBER(W23),IF(X23="PE",0.3*N23,IF(X23="S",ROUND((IF(ISNUMBER(V22),V22,0))-T23,2),IF(ISNUMBER(V22),V22,0)))," ") | W23: =IF(ISNUMBER(N23),0,IF(ISNUMBER(T23),IF(X23="S",T23,0)," ")) | X23: =IF(ISNUMBER(N23),"PE",IF(ISNA(VLOOKUP(Q23,'INM - Regras'!$D$24:$F$37,3)),"",VLOOKUP(Q23,'INM - Regras'!$D$24:$F$37,3))) | Z23: ='INM - Regras'!C27 -> 1.4 | AA23: ='INM - Regras'!D27 -> 1.4 - Atualização de rótulos (labels) de dados sem que haja mudança de funcionalidade | AB23: ='INM - Regras'!E27 -> 0.04 | AC23: ='INM - Regras'!F27 -> S
K24: =CONCATENATE(G24,L24) | L24: =IF(OR(ISBLANK(I24),ISBLANK(J24)),IF(OR(G24="ALI",G24="AIE"),"L",IF(ISBLANK(G24),"","A")),IF(G24="EE",IF(J24>=3,IF(I24>=5,"H","A"),IF(J24>=2,IF(I24>=16,"H",IF(I24<=4,"L","A")),IF(I24<=15,"L","A"))),IF(OR(G24="SE",G24="CE"),IF(J24>=4,IF(I24>=6,"H","A"),IF(J24>=2,IF(I24>=20,"H",IF(I24<=5,"L","A")),IF(I24<=19,"L","A"))),IF(OR(G24="ALI",G24="AIE"),IF(J24>=6,IF(I24>=20,"H","A"),IF(J24>=2,IF(I24>=51,"H",IF(I24<=19,"L","A")),IF(I24<=50,"L","A"))))))) | M24: =IF(L24="L","Baixa",IF(L24="A","Média",IF(L24="","","Alta"))) | N24: =IF(ISBLANK(G24),"",IF(G24="ALI",IF(L24="L",7,IF(L24="A",10,15)),IF(G24="AIE",IF(L24="L",5,IF(L24="A",7,10)),IF(G24="SE",IF(L24="L",4,IF(L24="A",5,7)),IF(OR(G24="EE",G24="CE"),IF(L24="L",3,IF(L24="A",4,6))))))) | O24: =IF(H24="I",N24*Contagem!$W$11,IF(H24="E",N24*Contagem!$W$13,IF(H24="A",N24*Contagem!$W$12,IF(H24="T",N24*Contagem!$W$14,"")))) | R24: =IF(ISNUMBER(N24),0,IF(ISNA(VLOOKUP(Q24,'INM - Regras'!$D$24:$E$37,2)),"",VLOOKUP(Q24,'INM - Regras'!$D$24:$E$37,2))) | T24: =IF(ISNUMBER(R24),R24*S24,"") | U24: =IF(X24="PE",0,IF(W24=0,U23,IF(ISNUMBER(W24),IF(ISNUMBER(U23),T24+U23,T24)," "))) | V24: =IF(ISNUMBER(W24),IF(X24="PE",0.3*N24,IF(X24="S",ROUND((IF(ISNUMBER(V23),V23,0))-T24,2),IF(ISNUMBER(V23),V23,0)))," ") | W24: =IF(ISNUMBER(N24),0,IF(ISNUMBER(T24),IF(X24="S",T24,0)," ")) | X24: =IF(ISNUMBER(N24),"PE",IF(ISNA(VLOOKUP(Q24,'INM - Regras'!$D$24:$F$37,3)),"",VLOOKUP(Q24,'INM - Regras'!$D$24:$F$37,3))) | Z24: ='INM - Regras'!C28 -> 2.1 | AA24: ='INM - Regras'!D28 -> 2.1 - Alteração, inclusão e exclusão de valores de parâmetros hard-coded, sem alteração da lógica de processamento | AB24: ='INM - Regras'!E28 -> 0.01 | AC24: ='INM - Regras'!F28 -> S
K25: =CONCATENATE(G25,L25) | L25: =IF(OR(ISBLANK(I25),ISBLANK(J25)),IF(OR(G25="ALI",G25="AIE"),"L",IF(ISBLANK(G25),"","A")),IF(G25="EE",IF(J25>=3,IF(I25>=5,"H","A"),IF(J25>=2,IF(I25>=16,"H",IF(I25<=4,"L","A")),IF(I25<=15,"L","A"))),IF(OR(G25="SE",G25="CE"),IF(J25>=4,IF(I25>=6,"H","A"),IF(J25>=2,IF(I25>=20,"H",IF(I25<=5,"L","A")),IF(I25<=19,"L","A"))),IF(OR(G25="ALI",G25="AIE"),IF(J25>=6,IF(I25>=20,"H","A"),IF(J25>=2,IF(I25>=51,"H",IF(I25<=19,"L","A")),IF(I25<=50,"L","A"))))))) | M25: =IF(L25="L","Baixa",IF(L25="A","Média",IF(L25="","","Alta"))) | N25: =IF(ISBLANK(G25),"",IF(G25="ALI",IF(L25="L",7,IF(L25="A",10,15)),IF(G25="AIE",IF(L25="L",5,IF(L25="A",7,10)),IF(G25="SE",IF(L25="L",4,IF(L25="A",5,7)),IF(OR(G25="EE",G25="CE"),IF(L25="L",3,IF(L25="A",4,6))))))) | O25: =IF(H25="I",N25*Contagem!$W$11,IF(H25="E",N25*Contagem!$W$13,IF(H25="A",N25*Contagem!$W$12,IF(H25="T",N25*Contagem!$W$14,"")))) | R25: =IF(ISNUMBER(N25),0,IF(ISNA(VLOOKUP(Q25,'INM - Regras'!$D$24:$E$37,2)),"",VLOOKUP(Q25,'INM - Regras'!$D$24:$E$37,2))) | T25: =IF(ISNUMBER(R25),R25*S25,"") | U25: =IF(X25="PE",0,IF(W25=0,U24,IF(ISNUMBER(W25),IF(ISNUMBER(U24),T25+U24,T25)," "))) | V25: =IF(ISNUMBER(W25),IF(X25="PE",0.3*N25,IF(X25="S",ROUND((IF(ISNUMBER(V24),V24,0))-T25,2),IF(ISNUMBER(V24),V24,0)))," ") | W25: =IF(ISNUMBER(N25),0,IF(ISNUMBER(T25),IF(X25="S",T25,0)," ")) | X25: =IF(ISNUMBER(N25),"PE",IF(ISNA(VLOOKUP(Q25,'INM - Regras'!$D$24:$F$37,3)),"",VLOOKUP(Q25,'INM - Regras'!$D$24:$F$37,3))) | Z25: ='INM - Regras'!C29 -> 3.1 | AA25: ='INM - Regras'!D29 -> 3.1 - Alteração, inclusão e exclusão de mensagens de retorno ao usuário, desde que não façam parte de um ALI ou AIE | AB25: ='INM - Regras'!E29 -> 0.04 | AC25: ='INM - Regras'!F29 -> S
K26: =CONCATENATE(G26,L26) | L26: =IF(OR(ISBLANK(I26),ISBLANK(J26)),IF(OR(G26="ALI",G26="AIE"),"L",IF(ISBLANK(G26),"","A")),IF(G26="EE",IF(J26>=3,IF(I26>=5,"H","A"),IF(J26>=2,IF(I26>=16,"H",IF(I26<=4,"L","A")),IF(I26<=15,"L","A"))),IF(OR(G26="SE",G26="CE"),IF(J26>=4,IF(I26>=6,"H","A"),IF(J26>=2,IF(I26>=20,"H",IF(I26<=5,"L","A")),IF(I26<=19,"L","A"))),IF(OR(G26="ALI",G26="AIE"),IF(J26>=6,IF(I26>=20,"H","A"),IF(J26>=2,IF(I26>=51,"H",IF(I26<=19,"L","A")),IF(I26<=50,"L","A"))))))) | M26: =IF(L26="L","Baixa",IF(L26="A","Média",IF(L26="","","Alta"))) | N26: =IF(ISBLANK(G26),"",IF(G26="ALI",IF(L26="L",7,IF(L26="A",10,15)),IF(G26="AIE",IF(L26="L",5,IF(L26="A",7,10)),IF(G26="SE",IF(L26="L",4,IF(L26="A",5,7)),IF(OR(G26="EE",G26="CE"),IF(L26="L",3,IF(L26="A",4,6))))))) | O26: =IF(H26="I",N26*Contagem!$W$11,IF(H26="E",N26*Contagem!$W$13,IF(H26="A",N26*Contagem!$W$12,IF(H26="T",N26*Contagem!$W$14,"")))) | R26: =IF(ISNUMBER(N26),0,IF(ISNA(VLOOKUP(Q26,'INM - Regras'!$D$24:$E$37,2)),"",VLOOKUP(Q26,'INM - Regras'!$D$24:$E$37,2))) | T26: =IF(ISNUMBER(R26),R26*S26,"") | U26: =IF(X26="PE",0,IF(W26=0,U25,IF(ISNUMBER(W26),IF(ISNUMBER(U25),T26+U25,T26)," "))) | V26: =IF(ISNUMBER(W26),IF(X26="PE",0.3*N26,IF(X26="S",ROUND((IF(ISNUMBER(V25),V25,0))-T26,2),IF(ISNUMBER(V25),V25,0)))," ") | W26: =IF(ISNUMBER(N26),0,IF(ISNUMBER(T26),IF(X26="S",T26,0)," ")) | X26: =IF(ISNUMBER(N26),"PE",IF(ISNA(VLOOKUP(Q26,'INM - Regras'!$D$24:$F$37,3)),"",VLOOKUP(Q26,'INM - Regras'!$D$24:$F$37,3))) | Z26: ='INM - Regras'!C30 -> 4.1 | AA26: ='INM - Regras'!D30 -> 4.1 - Criação ou alteração de páginas estáticas | AB26: ='INM - Regras'!E30 -> 0.5 | AC26: ='INM - Regras'!F30 -> N
K27: =CONCATENATE(G27,L27) | L27: =IF(OR(ISBLANK(I27),ISBLANK(J27)),IF(OR(G27="ALI",G27="AIE"),"L",IF(ISBLANK(G27),"","A")),IF(G27="EE",IF(J27>=3,IF(I27>=5,"H","A"),IF(J27>=2,IF(I27>=16,"H",IF(I27<=4,"L","A")),IF(I27<=15,"L","A"))),IF(OR(G27="SE",G27="CE"),IF(J27>=4,IF(I27>=6,"H","A"),IF(J27>=2,IF(I27>=20,"H",IF(I27<=5,"L","A")),IF(I27<=19,"L","A"))),IF(OR(G27="ALI",G27="AIE"),IF(J27>=6,IF(I27>=20,"H","A"),IF(J27>=2,IF(I27>=51,"H",IF(I27<=19,"L","A")),IF(I27<=50,"L","A"))))))) | M27: =IF(L27="L","Baixa",IF(L27="A","Média",IF(L27="","","Alta"))) | N27: =IF(ISBLANK(G27),"",IF(G27="ALI",IF(L27="L",7,IF(L27="A",10,15)),IF(G27="AIE",IF(L27="L",5,IF(L27="A",7,10)),IF(G27="SE",IF(L27="L",4,IF(L27="A",5,7)),IF(OR(G27="EE",G27="CE"),IF(L27="L",3,IF(L27="A",4,6))))))) | O27: =IF(H27="I",N27*Contagem!$W$11,IF(H27="E",N27*Contagem!$W$13,IF(H27="A",N27*Contagem!$W$12,IF(H27="T",N27*Contagem!$W$14,"")))) | R27: =IF(ISNUMBER(N27),0,IF(ISNA(VLOOKUP(Q27,'INM - Regras'!$D$24:$E$37,2)),"",VLOOKUP(Q27,'INM - Regras'!$D$24:$E$37,2))) | T27: =IF(ISNUMBER(R27),R27*S27,"") | U27: =IF(X27="PE",0,IF(W27=0,U26,IF(ISNUMBER(W27),IF(ISNUMBER(U26),T27+U26,T27)," "))) | V27: =IF(ISNUMBER(W27),IF(X27="PE",0.3*N27,IF(X27="S",ROUND((IF(ISNUMBER(V26),V26,0))-T27,2),IF(ISNUMBER(V26),V26,0)))," ") | W27: =IF(ISNUMBER(N27),0,IF(ISNUMBER(T27),IF(X27="S",T27,0)," ")) | X27: =IF(ISNUMBER(N27),"PE",IF(ISNA(VLOOKUP(Q27,'INM - Regras'!$D$24:$F$37,3)),"",VLOOKUP(Q27,'INM - Regras'!$D$24:$F$37,3))) | Z27: ='INM - Regras'!C31 -> 4.2 | AA27: ='INM - Regras'!D31 -> 4.2 - Exclusão de páginas estáticas | AB27: ='INM - Regras'!E31 -> 0.1 | AC27: ='INM - Regras'!F31 -> N
K28: =CONCATENATE(G28,L28) | L28: =IF(OR(ISBLANK(I28),ISBLANK(J28)),IF(OR(G28="ALI",G28="AIE"),"L",IF(ISBLANK(G28),"","A")),IF(G28="EE",IF(J28>=3,IF(I28>=5,"H","A"),IF(J28>=2,IF(I28>=16,"H",IF(I28<=4,"L","A")),IF(I28<=15,"L","A"))),IF(OR(G28="SE",G28="CE"),IF(J28>=4,IF(I28>=6,"H","A"),IF(J28>=2,IF(I28>=20,"H",IF(I28<=5,"L","A")),IF(I28<=19,"L","A"))),IF(OR(G28="ALI",G28="AIE"),IF(J28>=6,IF(I28>=20,"H","A"),IF(J28>=2,IF(I28>=51,"H",IF(I28<=19,"L","A")),IF(I28<=50,"L","A"))))))) | M28: =IF(L28="L","Baixa",IF(L28="A","Média",IF(L28="","","Alta"))) | N28: =IF(ISBLANK(G28),"",IF(G28="ALI",IF(L28="L",7,IF(L28="A",10,15)),IF(G28="AIE",IF(L28="L",5,IF(L28="A",7,10)),IF(G28="SE",IF(L28="L",4,IF(L28="A",5,7)),IF(OR(G28="EE",G28="CE"),IF(L28="L",3,IF(L28="A",4,6))))))) | O28: =IF(H28="I",N28*Contagem!$W$11,IF(H28="E",N28*Contagem!$W$13,IF(H28="A",N28*Contagem!$W$12,IF(H28="T",N28*Contagem!$W$14,"")))) | R28: =IF(ISNUMBER(N28),0,IF(ISNA(VLOOKUP(Q28,'INM - Regras'!$D$24:$E$37,2)),"",VLOOKUP(Q28,'INM - Regras'!$D$24:$E$37,2))) | T28: =IF(ISNUMBER(R28),R28*S28,"") | U28: =IF(X28="PE",0,IF(W28=0,U27,IF(ISNUMBER(W28),IF(ISNUMBER(U27),T28+U27,T28)," "))) | V28: =IF(ISNUMBER(W28),IF(X28="PE",0.3*N28,IF(X28="S",ROUND((IF(ISNUMBER(V27),V27,0))-T28,2),IF(ISNUMBER(V27),V27,0)))," ") | W28: =IF(ISNUMBER(N28),0,IF(ISNUMBER(T28),IF(X28="S",T28,0)," ")) | X28: =IF(ISNUMBER(N28),"PE",IF(ISNA(VLOOKUP(Q28,'INM - Regras'!$D$24:$F$37,3)),"",VLOOKUP(Q28,'INM - Regras'!$D$24:$F$37,3))) | Z28: ='INM - Regras'!C32 -> 5.1 | AA28: ='INM - Regras'!D32 -> 5.1 - Parâmetros de processamento - contempla a necessidade de alteração dos valores dos parâmetros, sem que a lógica de processamento tenha sido alterada. (Exemplo: ajustar filtro para recuperar dados entre 0 e 50 ao invés de valores entre 10 e 50) | AB28: ='INM - Regras'!E32 -> 0.01 | AC28: ='INM - Regras'!F32 -> S
K29: =CONCATENATE(G29,L29) | L29: =IF(OR(ISBLANK(I29),ISBLANK(J29)),IF(OR(G29="ALI",G29="AIE"),"L",IF(ISBLANK(G29),"","A")),IF(G29="EE",IF(J29>=3,IF(I29>=5,"H","A"),IF(J29>=2,IF(I29>=16,"H",IF(I29<=4,"L","A")),IF(I29<=15,"L","A"))),IF(OR(G29="SE",G29="CE"),IF(J29>=4,IF(I29>=6,"H","A"),IF(J29>=2,IF(I29>=20,"H",IF(I29<=5,"L","A")),IF(I29<=19,"L","A"))),IF(OR(G29="ALI",G29="AIE"),IF(J29>=6,IF(I29>=20,"H","A"),IF(J29>=2,IF(I29>=51,"H",IF(I29<=19,"L","A")),IF(I29<=50,"L","A"))))))) | M29: =IF(L29="L","Baixa",IF(L29="A","Média",IF(L29="","","Alta"))) | N29: =IF(ISBLANK(G29),"",IF(G29="ALI",IF(L29="L",7,IF(L29="A",10,15)),IF(G29="AIE",IF(L29="L",5,IF(L29="A",7,10)),IF(G29="SE",IF(L29="L",4,IF(L29="A",5,7)),IF(OR(G29="EE",G29="CE"),IF(L29="L",3,IF(L29="A",4,6))))))) | O29: =IF(H29="I",N29*Contagem!$W$11,IF(H29="E",N29*Contagem!$W$13,IF(H29="A",N29*Contagem!$W$12,IF(H29="T",N29*Contagem!$W$14,"")))) | R29: =IF(ISNUMBER(N29),0,IF(ISNA(VLOOKUP(Q29,'INM - Regras'!$D$24:$E$37,2)),"",VLOOKUP(Q29,'INM - Regras'!$D$24:$E$37,2))) | T29: =IF(ISNUMBER(R29),R29*S29,"") | U29: =IF(X29="PE",0,IF(W29=0,U28,IF(ISNUMBER(W29),IF(ISNUMBER(U28),T29+U28,T29)," "))) | V29: =IF(ISNUMBER(W29),IF(X29="PE",0.3*N29,IF(X29="S",ROUND((IF(ISNUMBER(V28),V28,0))-T29,2),IF(ISNUMBER(V28),V28,0)))," ") | W29: =IF(ISNUMBER(N29),0,IF(ISNUMBER(T29),IF(X29="S",T29,0)," ")) | X29: =IF(ISNUMBER(N29),"PE",IF(ISNA(VLOOKUP(Q29,'INM - Regras'!$D$24:$F$37,3)),"",VLOOKUP(Q29,'INM - Regras'!$D$24:$F$37,3))) | Z29: ='INM - Regras'!C33 -> 6.1 | AA29: ='INM - Regras'!D33 -> 6.1 - Inclusão de tabela e funcionalidades | AB29: ='INM - Regras'!E33 -> 2.7 | AC29: ='INM - Regras'!F33 -> N
